Workbook

Sheet CONSOLIDADO
A1: ,
B2: Tablas de Gestión:
B4: SUPERVISOR | C4: ZONA | D4: TOTAL DESEMBOLSO | E4: Q DESEMBOLSO | F4: EVALUACION BCP | G4: PENDIENTE DE BACK | H4: PENDIENTE DE REMESA | I4: PENDIENTE DE DOCUMENTAR | J4: META OBJETIVO | K4: AVANCE | L4: Q EVALUACION BCP | M4: Q PENDIENTE DE BACK
B5: JIMMY COLLAZOS | C5: ='JIMMY COLLAZOS'!D3 -> TARAPOTO | D5: ='JIMMY COLLAZOS'!$F$4 -> 311900 | E5: ='JIMMY COLLAZOS'!$F$5 -> 4 | F5: ='JIMMY COLLAZOS'!$K$4 -> 0 | G5: ='JIMMY COLLAZOS'!$J$4 -> 0 | H5: ='JIMMY COLLAZOS'!$I$4 -> 0 | I5: ='JIMMY COLLAZOS'!$H$4 -> 0 | J5: ='JIMMY COLLAZOS'!E4 -> 800000 | K5: =D5/J5 -> 0.389875 | L5: ='JIMMY COLLAZOS'!$K$5 -> 0 | M5: ='JIMMY COLLAZOS'!$J$5 -> 0
B6: ALEXANDRA GUZMAN | C6: ='ALEXANDRA GUZMAN'!D3 -> PIURA | D6: ='ALEXANDRA GUZMAN'!$F$4 -> 0 | E6: ='ALEXANDRA GUZMAN'!$F$5 -> 0 | F6: ='ALEXANDRA GUZMAN'!$K$4 -> 0 | G6: ='ALEXANDRA GUZMAN'!$J$4 -> 0 | H6: ='ALEXANDRA GUZMAN'!$I$4 -> 0 | I6: ='ALEXANDRA GUZMAN'!$H$4 -> 0 | J6: 1000000 | K6: =D6/J6 -> 0 | L6: ='ALEXANDRA GUZMAN'!$K$5 -> 0 | M6: ='ALEXANDRA GUZMAN'!$J$5 -> 0
B7: RENZO CACEDA | C7: ='RENZO CACEDA'!D3 -> TRUJILLO | D7: ='RENZO CACEDA'!$F$4 -> 0 | E7: ='RENZO CACEDA'!$F$5 -> 0 | F7: ='RENZO CACEDA'!$K$4 -> 0 | G7: ='RENZO CACEDA'!$J$4 -> 0 | H7: ='RENZO CACEDA'!$I$4 -> 0 | I7: ='RENZO CACEDA'!$H$4 -> 0 | J7: 1000000 | K7: =D7/J7 -> 0 | L7: ='RENZO CACEDA'!$K$5 -> 0 | M7: ='RENZO CACEDA'!$J$5 -> 0
B8: WENDY IPANAQUÉ | C8: ='WENDY IPANEQUE'!D3 -> PIURA | D8: ='WENDY IPANEQUE'!$F$4 -> 994700 | E8: ='WENDY IPANEQUE'!$F$5 -> 14 | F8: ='WENDY IPANEQUE'!$K$4 -> 156150 | G8: ='WENDY IPANEQUE'!$J$4 -> 0 | H8: ='WENDY IPANEQUE'!$I$4 -> 0 | I8: ='WENDY IPANEQUE'!$H$4 -> 0 | J8: 1000000 | K8: =D8/J8 -> 0.9947 | L8: ='WENDY IPANEQUE'!$K$5 -> 2 | M8: ='WENDY IPANEQUE'!$J$5 -> 0
B9: ANGIE SILVERA | C9: ='ANGIE SILVERA'!D3 -> LIMA 1 | D9: ='ANGIE SILVERA'!$F$4 -> 1741550 | E9: ='ANGIE SILVERA'!$F$5 -> 24 | F9: ='ANGIE SILVERA'!$K$4 -> 0 | G9: ='ANGIE SILVERA'!$J$4 -> 0 | H9: ='ANGIE SILVERA'!$I$4 -> 0 | I9: ='ANGIE SILVERA'!$H$4 -> 0 | J9: ='ANGIE SILVERA'!E4 -> 2000000 | K9: =D9/J9 -> 0.870775 | L9: ='ANGIE SILVERA'!$K$5 -> 0 | M9: ='ANGIE SILVERA'!$J$5 -> 0
B10: KENNY MORALES | C10: ='KENNY MORALES'!D3 -> LIMA 1 | D10: ='KENNY MORALES'!$F$4 -> 820950 | E10: ='KENNY MORALES'!$F$5 -> 14 | F10: ='KENNY MORALES'!$K$4 -> 44600 | G10: ='KENNY MORALES'!$J$4 -> 0 | H10: ='KENNY MORALES'!$I$4 -> 66600 | I10: ='KENNY MORALES'!$H$4 -> 0 | J10: ='KENNY MORALES'!E4 -> 1000000 | K10: =D10/J10 -> 0.82095 | L10: ='KENNY MORALES'!$K$5 -> 2 | M10: ='KENNY MORALES'!$J$5 -> 0
B11: LUIS CHUSE | C11: ='LUIS CHUSE'!D3 -> LIMA 2 | D11: ='LUIS CHUSE'!$F$4 -> 1041850 | E11: ='LUIS CHUSE'!$F$5 -> 17 | F11: ='LUIS CHUSE'!$K$4 -> 144900 | G11: ='LUIS CHUSE'!$J$4 -> 0 | H11: ='LUIS CHUSE'!$I$4 -> 84100 | I11: ='LUIS CHUSE'!$H$4 -> 0 | J11: ='LUIS CHUSE'!E4 -> 2000000 | K11: =D11/J11 -> 0.520925 | L11: ='LUIS CHUSE'!$K$5 -> 2 | M11: ='LUIS CHUSE'!$J$5 -> 0
B12: MARIELLA PAÑAHUA | C12: ='MARIELLA PAÑAHUA'!D3 -> AYACUCHO | D12: ='MARIELLA PAÑAHUA'!$F$4 -> 611137 | E12: ='MARIELLA PAÑAHUA'!$F$5 -> 9 | F12: ='MARIELLA PAÑAHUA'!$K$4 -> 63700 | G12: ='MARIELLA PAÑAHUA'!$J$4 -> 0 | H12: ='MARIELLA PAÑAHUA'!$I$4 -> 0 | I12: ='MARIELLA PAÑAHUA'!$H$4 -> 0 | J12: ='MARIELLA PAÑAHUA'!E4 -> 800000 | K12: =D12/J12 -> 0.76392125 | L12: ='MARIELLA PAÑAHUA'!$K$5 -> 1 | M12: ='MARIELLA PAÑAHUA'!$J$5 -> 0
B13: WINNIE ESCALANTE | C13: ='WINNIE ESCALANTE'!D3 -> LIMA 1 | D13: ='WINNIE ESCALANTE'!$F$4 -> 1522360 | E13: ='WINNIE ESCALANTE'!$F$5 -> 21 | F13: ='WINNIE ESCALANTE'!$K$4 -> 0 | G13: ='WINNIE ESCALANTE'!$J$4 -> 0 | H13: ='WINNIE ESCALANTE'!$I$4 -> 0 | I13: ='WINNIE ESCALANTE'!$H$4 -> 0 | J13: ='WINNIE ESCALANTE'!E4 -> 2000000 | K13: =D13/J13 -> 0.76118 | L13: ='WINNIE ESCALANTE'!$K$5 -> 0 | M13: ='WINNIE ESCALANTE'!$J$5 -> 0
B14: JOSE LUIS QUINTEROS | C14: ='JOSE LUIS QUINTEROS'!D3 -> LIMA 1 | D14: ='JOSE LUIS QUINTEROS'!$F$4 -> 1078750 | E14: ='JOSE LUIS QUINTEROS'!$F$5 -> 13 | F14: ='JOSE LUIS QUINTEROS'!$K$4 -> 52000 | G14: ='JOSE LUIS QUINTEROS'!$J$4 -> 0 | H14: ='JOSE LUIS QUINTEROS'!$I$4 -> 77250 | I14: ='JOSE LUIS QUINTEROS'!$H$4 -> 56800 | J14: ='JOSE LUIS QUINTEROS'!E4 -> 1000000 | K14: =D14/J14 -> 1.07875 | L14: ='JOSE LUIS QUINTEROS'!$K$5 -> 1 | M14: ='JOSE LUIS QUINTEROS'!$J$5 -> 0
B15: NATHALIE ARANDA | C15: ='NATHALIE ARANDA'!D3 -> LIMA 2 | D15: ='NATHALIE ARANDA'!$F$4 -> 1460120 | E15: ='NATHALIE ARANDA'!$F$5 -> 22 | F15: ='NATHALIE ARANDA'!$K$4 -> 74600 | G15: ='NATHALIE ARANDA'!$J$4 -> 0 | H15: ='NATHALIE ARANDA'!$I$4 -> 543600 | I15: ='NATHALIE ARANDA'!$H$4 -> 34800 | J15: ='NATHALIE ARANDA'!E4 -> 500000 | K15: =D15/J15 -> 2.92024 | L15: ='NATHALIE ARANDA'!$K$5 -> 1 | M15: ='NATHALIE ARANDA'!$J$5 -> 0
B16: ARACELY VENTURA | C16: ='ARACELY VENTURA'!D3 -> CHICLAYO | D16: ='ARACELY VENTURA'!$F$4 -> 705600 | E16: ='ARACELY VENTURA'!$F$5 -> 9 | F16: ='ARACELY VENTURA'!$K$4 -> 0 | G16: ='ARACELY VENTURA'!$J$4 -> 0 | H16: ='ARACELY VENTURA'!$I$4 -> 164600 | I16: ='ARACELY VENTURA'!$H$4 -> 0 | J16: 1000000 | K16: =D16/J16 -> 0.7056 | L16: ='ARACELY VENTURA'!$K$5 -> 0 | M16: ='ARACELY VENTURA'!$J$5 -> 0
B17: JHON ZAMORA | C17: ='JHON ZAMORA'!D3 -> CHICLAYO | D17: ='JHON ZAMORA'!$F$4 -> 925450 | E17: ='JHON ZAMORA'!$F$5 -> 15 | F17: ='JHON ZAMORA'!$K$4 -> 0 | G17: ='JHON ZAMORA'!$J$4 -> 0 | H17: ='JHON ZAMORA'!$I$4 -> 0 | I17: ='JHON ZAMORA'!$H$4 -> 0 | J17: 1000000 | K17: =D17/J17 -> 0.92545 | L17: ='JHON ZAMORA'!$K$5 -> 0 | M17: ='JHON ZAMORA'!$J$5 -> 0
B18: OMAR MINAYA | C18: ='OMAR MINAYA'!D3 -> CHICLAYO | D18: ='OMAR MINAYA'!$F$4 -> 1629875 | E18: ='OMAR MINAYA'!$F$5 -> 23 | F18: ='OMAR MINAYA'!$K$4 -> 164600 | G18: ='OMAR MINAYA'!$J$4 -> 0 | H18: ='OMAR MINAYA'!$I$4 -> 12000 | I18: ='OMAR MINAYA'!$H$4 -> 0 | J18: 1000000 | K18: =D18/J18 -> 1.629875 | L18: ='OMAR MINAYA'!$K$5 -> 3 | M18: ='OMAR MINAYA'!$J$5 -> 0
B19: NAHOMI DIAZ | C19: ='NAHOMI DIAZ'!D3 -> CHICLAYO | D19: ='NAHOMI DIAZ'!$F$4 -> 2108561 | E19: ='NAHOMI DIAZ'!$F$5 -> 27 | F19: ='NAHOMI DIAZ'!$K$4 -> 65000 | G19: ='NAHOMI DIAZ'!$J$4 -> 0 | H19: ='NAHOMI DIAZ'!$I$4 -> 0 | I19: ='NAHOMI DIAZ'!$H$4 -> 0 | J19: 1000000 | K19: =D19/J19 -> 2.108561 | L19: ='NAHOMI DIAZ'!$K$5 -> 1 | M19: ='NAHOMI DIAZ'!$J$5 -> 0
B20: VIOLETA LLERENA | C20: ='VIOLETA LLERENA'!D3 -> AREQUIPA | D20: ='VIOLETA LLERENA'!$F$4 -> 617400 | E20: ='VIOLETA LLERENA'!$F$5 -> 9 | F20: ='VIOLETA LLERENA'!$K$4 -> 116000 | G20: ='VIOLETA LLERENA'!$J$4 -> 0 | H20: ='VIOLETA LLERENA'!$I$4 -> 0 | I20: ='VIOLETA LLERENA'!$H$4 -> 0 | J20: 1000000 | K20: =D20/J20 -> 0.6174 | L20: ='VIOLETA LLERENA'!$K$5 -> 3 | M20: ='VIOLETA LLERENA'!$J$5 -> 0
B21: MILUSKA LINARES | C21: ='MILUSKA LINARES'!D3 -> TRUJILLO | D21: ='MILUSKA LINARES'!$F$4 -> 0 | E21: ='MILUSKA LINARES'!$F$5 -> 0 | F21: ='MILUSKA LINARES'!$K$4 -> 0 | G21: ='MILUSKA LINARES'!$J$4 -> 0 | H21: ='MILUSKA LINARES'!$I$4 -> 0 | I21: ='MILUSKA LINARES'!$H$4 -> 0 | J21: 1000000 | K21: =D21/J21 -> 0 | L21: ='MILUSKA LINARES'!$K$5 -> 0 | M21: ='MILUSKA LINARES'!$J$5 -> 0
B22: THALIA SALOME | C22: ='THALIA SALOME'!D3 -> HUANCAYO | D22: ='THALIA SALOME'!$F$4 -> 318250 | E22: ='THALIA SALOME'!$F$5 -> 4 | F22: ='THALIA SALOME'!$K$4 -> 0 | G22: ='THALIA SALOME'!$J$4 -> 0 | H22: ='THALIA SALOME'!$I$4 -> 0 | I22: ='THALIA SALOME'!$H$4 -> 0 | J22: 1000000 | K22: =D22/J22 -> 0.31825 | L22: ='THALIA SALOME'!$K$5 -> 0 | M22: ='THALIA SALOME'!$J$5 -> 0
B23: ELIZABETH ESQUIVEL | C23: ='ELIZABETH ESQUIVEL'!D3 -> LIMA 1 | D23: ='ELIZABETH ESQUIVEL'!$F$4 -> 575950 | E23: ='ELIZABETH ESQUIVEL'!$F$5 -> 7 | F23: ='ELIZABETH ESQUIVEL'!$K$4 -> 0 | G23: ='ELIZABETH ESQUIVEL'!$J$4 -> 0 | H23: ='ELIZABETH ESQUIVEL'!$I$4 -> 0 | I23: ='ELIZABETH ESQUIVEL'!$H$4 -> 0 | J23: 500000 | K23: =D23/J23 -> 1.1519 | L23: ='ELIZABETH ESQUIVEL'!$K$5 -> 0 | M23: ='ELIZSABETH ESQUIVEL'!$J$5 -> #REF!
B24: ANA ALIAGA | C24: ='ANA ALIAGA'!D3 -> LIMA 1 | D24: ='ANA ALIAGA'!$F$4 -> 736373 | E24: ='ANA ALIAGA'!$F$5 -> 9 | F24: ='ANA ALIAGA'!$K$4 -> 0 | G24: ='ANA ALIAGA'!$J$4 -> 0 | H24: ='ANA ALIAGA'!$I$4 -> 0 | I24: ='ANA ALIAGA'!$H$4 -> 0 | J24: 1000000 | K24: =D24/J24 -> 0.736373 | L24: ='ANA ALIAGA'!$K$5 -> 0 | M24: ='ANA ALIAGA'!$J$5 -> 0
B25: MERCEDES GIRALDO | C25: ='MERCEDES GIRALDO'!D3 -> LIMA 1 | D25: ='MERCEDES GIRALDO'!$F$4 -> 1356700 | E25: ='MERCEDES GIRALDO'!$F$5 -> 16 | F25: ='MERCEDES GIRALDO'!$K$4 -> 0 | G25: ='MERCEDES GIRALDO'!$J$4 -> 0 | H25: ='MERCEDES GIRALDO'!$I$4 -> 157750 | I25: ='MERCEDES GIRALDO'!$H$4 -> 0 | J25: 1000000 | K25: =D25/J25 -> 1.3567 | L25: ='MERCEDES GIRALDO'!$K$5 -> 0 | M25: ='MERCEDES GIRALDO'!$J$5 -> 0
B26: TOTAL | D26: =SUM(D5:D25) -> 18557476 | E26: =SUM(E5:E25) -> 257 | F26: =SUM(F5:F25) -> 881550 | G26: =SUM(G5:G25) -> 0 | H26: =SUM(H5:H25) -> 1105900 | I26: =SUM(I5:I25) -> 91600 | J26: =SUM(J5:J25) -> 22600000 | K26: 76246407239819 | L26: =SUM(L5:L25) -> 16 | M26: =SUM(M5:M25) -> #REF!
B29: PLAZA | D29: TOTAL DESEMBOLSO | E29: Q DESEMBOLSO | F29: EVALUACION BCP | G29: PENDIENTE DE BACK | H29: PENDIENTE DE REMESA | I29: PENDIENTE DE DOCUMENTAR | J29: META OBJETIVO | K29: AVANCE | L29: Q EVALUACION BCP | M29: Q PENDIENTE DE BACK
B30: LIMA 1 | D30: =SUMIFS(D$5:D$25,$C$5:$C$25,$B30) -> 7832633 | E30: =SUMIFS(E$5:E$25,$C$5:$C$25,$B30) -> 104 | F30: =SUMIFS(F$5:F$25,$C$5:$C$25,$B30) -> 96600 | G30: =SUMIFS(G$5:G$25,$C$5:$C$25,$B30) -> 0 | H30: =SUMIFS(H$5:H$25,$C$5:$C$25,$B30) -> 301600 | I30: =SUMIFS(I$5:I$25,$C$5:$C$25,$B30) -> 56800 | J30: =SUMIFS(J$5:J$25,$C$5:$C$25,$B30) -> 8500000 | K30: =D30/J30 -> 0.92148624 | L30: =SUMIFS(L$5:L$25,$C$5:$C$25,$B30) -> 3 | M30: =SUMIFS(M$5:M$25,$C$5:$C$25,$B30) -> #REF!
B31: LIMA 2 | D31: =SUMIFS(D$5:D$25,$C$5:$C$25,$B31) -> 2501970 | E31: =SUMIFS(E$5:E$25,$C$5:$C$25,$B31) -> 39 | F31: =SUMIFS(F$5:F$25,$C$5:$C$25,$B31) -> 219500 | G31: =SUMIFS(G$5:G$25,$C$5:$C$25,$B31) -> 0 | H31: =SUMIFS(H$5:H$25,$C$5:$C$25,$B31) -> 627700 | I31: =SUMIFS(I$5:I$25,$C$5:$C$25,$B31) -> 34800 | J31: =SUMIFS(J$5:J$25,$C$5:$C$25,$B31) -> 2500000 | K31: =D31/J31 -> 1.000788 | L31: =SUMIFS(L$5:L$25,$C$5:$C$25,$B31) -> 3 | M31: =SUMIFS(M$5:M$25,$C$5:$C$25,$B31) -> 0
B32: NORTE | D32: =SUMIFS(D5:D25,$C$5:$C$25,"CHICLAYO")+SUMIFS(D5:D25,$C$5:$C$25,"TRUJILLO")+SUMIFS(D5:D25,$C$5:$C$25,"PIURA") -> 6364186 | E32: =SUMIFS(E5:E25,$C$5:$C$25,"CHICLAYO")+SUMIFS(E5:E25,$C$5:$C$25,"TRUJILLO")+SUMIFS(E5:E25,$C$5:$C$25,"PIURA") -> 88 | F32: =SUMIFS(F5:F25,$C$5:$C$25,"CHICLAYO")+SUMIFS(F5:F25,$C$5:$C$25,"TRUJILLO")+SUMIFS(F5:F25,$C$5:$C$25,"PIURA") -> 385750 | G32: =SUMIFS(G5:G25,$C$5:$C$25,"CHICLAYO")+SUMIFS(G5:G25,$C$5:$C$25,"TRUJILLO")+SUMIFS(G5:G25,$C$5:$C$25,"PIURA") -> 0 | H32: =SUMIFS(H5:H25,$C$5:$C$25,"CHICLAYO")+SUMIFS(H5:H25,$C$5:$C$25,"TRUJILLO")+SUMIFS(H5:H25,$C$5:$C$25,"PIURA") -> 176600 | I32: =SUMIFS(I5:I25,$C$5:$C$25,"CHICLAYO")+SUMIFS(I5:I25,$C$5:$C$25,"TRUJILLO")+SUMIFS(I5:I25,$C$5:$C$25,"PIURA") -> 0 | J32: =SUMIFS(J5:J25,$C$5:$C$25,"CHICLAYO")+SUMIFS(J5:J25,$C$5:$C$25,"TRUJILLO")+SUMIFS(J5:J25,$C$5:$C$25,"PIURA") -> 8000000 | K32: =D32/J32 -> 0.79552325 | L32: =SUMIFS(L5:L25,$C$5:$C$25,"CHICLAYO")+SUMIFS(L5:L25,$C$5:$C$25,"TRUJILLO")+SUMIFS(L5:L25,$C$5:$C$25,"PIURA") -> 6 | M32: =SUMIFS(M5:M25,$C$5:$C$25,"CHICLAYO")+SUMIFS(M5:M25,$C$5:$C$25,"TRUJILLO")+SUMIFS(M5:M25,$C$5:$C$25,"PIURA") -> 0
B33: TARAPOTO | D33: =SUMIFS(D5:D22,$C$5:$C$22,"TARAPOTO") -> 311900 | E33: =SUMIFS(E5:E22,$C$5:$C$22,"TARAPOTO") -> 4 | F33: =SUMIFS(F5:F22,$C$5:$C$22,"TARAPOTO") -> 0 | G33: =SUMIFS(G5:G22,$C$5:$C$22,"TARAPOTO") -> 0 | H33: =SUMIFS(H5:H22,$C$5:$C$22,"TARAPOTO") -> 0 | I33: =SUMIFS(I5:I22,$C$5:$C$22,"TARAPOTO") -> 0 | J33: =SUMIFS(J5:J22,$C$5:$C$22,"TARAPOTO") -> 800000 | K33: =D33/J33 -> 0.389875 | L33: =SUMIFS(L5:L22,$C$5:$C$22,"TARAPOTO") -> 0 | M33: =SUMIFS(M5:M22,$C$5:$C$22,"TARAPOTO") -> 0
B34: AYACUCHO | D34: =SUMIFS(D5:D22,$C$5:$C$22,"AYACUCHO") -> 611137 | E34: =SUMIFS(E5:E22,$C$5:$C$22,"AYACUCHO") -> 9 | F34: =SUMIFS(F5:F22,$C$5:$C$22,"AYACUCHO") -> 63700 | G34: =SUMIFS(G5:G22,$C$5:$C$22,"AYACUCHO") -> 0 | H34: =SUMIFS(H5:H22,$C$5:$C$22,"AYACUCHO") -> 0 | I34: =SUMIFS(I5:I22,$C$5:$C$22,"AYACUCHO") -> 0 | J34: =SUMIFS(J5:J22,$C$5:$C$22,"AYACUCHO") -> 800000 | K34: =D34/J34 -> 0.76392125 | L34: =SUMIFS(L5:L22,$C$5:$C$22,"AYACUCHO") -> 1 | M34: =SUMIFS(M5:M22,$C$5:$C$22,"AYACUCHO") -> 0
B35: AREQUIPA | D35: =SUMIFS(D5:D22,$C$5:$C$22,"AREQUIPA") -> 617400 | E35: =SUMIFS(E5:E22,$C$5:$C$22,"AREQUIPA") -> 9 | F35: =SUMIFS(F5:F22,$C$5:$C$22,"AREQUIPA") -> 116000 | G35: =SUMIFS(G5:G22,$C$5:$C$22,"AREQUIPA") -> 0 | H35: =SUMIFS(H5:H22,$C$5:$C$22,"AREQUIPA") -> 0 | I35: =SUMIFS(I5:I22,$C$5:$C$22,"AREQUIPA") -> 0 | J35: =SUMIFS(J5:J22,$C$5:$C$22,"AREQUIPA") -> 1000000 | K35: =D35/J35 -> 0.6174 | L35: =SUMIFS(L6:L24,$C$5:$C$22,"AREQUIPA") -> #VALUE! | M35: =SUMIFS(M6:M24,$C$5:$C$22,"AREQUIPA") -> #VALUE!
B36: HUANCAYO | D36: =SUMIFS(D$5:D$25,$C$5:$C$25,$B36) -> 318250 | E36: =SUMIFS(E$5:E$25,$C$5:$C$25,$B36) -> 4 | F36: =SUMIFS(F$5:F$25,$C$5:$C$25,$B36) -> 0 | G36: =SUMIFS(G$5:G$25,$C$5:$C$25,$B36) -> 0 | H36: =SUMIFS(H$5:H$25,$C$5:$C$25,$B36) -> 0 | I36: =SUMIFS(I$5:I$25,$C$5:$C$25,$B36) -> 0 | J36: =SUMIFS(J$5:J$25,$C$5:$C$25,$B36) -> 1000000 | K36: =D36/J36 -> 0.31825 | L36: =SUMIFS(L$5:L$25,$C$5:$C$25,$B36) -> 0 | M36: =SUMIFS(M$5:M$25,$C$5:$C$25,$B36) -> 0
B37: TOTAL | D37: =SUM(D30:D36) -> 18557476 | E37: =SUM(E30:E36) -> 257 | F37: =SUM(F30:F36) -> 881550 | G37: =SUM(G30:G36) -> 0 | H37: =SUM(H30:H36) -> 1105900 | I37: =SUM(I30:I36) -> 91600 | J37: =SUM(J30:J36) -> 22600000 | K37: =D37/J37 -> 0.82112726 | L37: =SUM(L30:L36) -> #VALUE! | M37: =SUM(M30:M36) -> #REF!

Sheet ANGIE SILVERA
D3: LIMA 1 | E3: Meta | F3: Desembolsado | G3: Avance | H3: Pendiente De Documentar | I3: Pendiente De Remesa | J3: Pendiente De Backoffice | K3: Evaluación BCP | L3: Obs Backoffice | M3: Obs BCP | N3: Rechazado
D4: S/. | E4: 2000000 | F4: =SUMIFS(OPI[MAF NETO],OPI[ESTADO],"Desembolsado") -> 1741550 | G4: =F4-E4 -> -258450 | H4: =SUMIFS(OPI[MAF NETO],OPI[ESTADO],H$3) -> 0 | I4: =SUMIFS(OPI[MAF NETO],OPI[ESTADO],I$3) -> 0 | J4: =SUMIFS(OPI[MAF NETO],OPI[ESTADO],J$3) -> 0 | K4: =SUMIFS(OPI[MAF NETO],OPI[ESTADO],K$3) -> 0 | L4: =SUMIFS(OPI[MAF NETO],OPI[ESTADO],L$3) -> 0 | M4: =SUMIFS(OPI[MAF NETO],OPI[ESTADO],M$3) -> 0 | N4: =SUMIFS(OPI[MAF NETO],OPI[ESTADO],N$3) -> 0
D5: Q / % | E5: - | F5: =COUNTIFS(OPI[ESTADO],"Desembolsado") -> 24 | G5: =IFERROR(F4/E4,"") -> 0.870775 | H5: =COUNTIFS(OPI[ESTADO],H$3) -> 0 | I5: =COUNTIFS(OPI[ESTADO],I$3) -> 0 | J5: =COUNTIFS(OPI[ESTADO],J$3) -> 0 | K5: =COUNTIFS(OPI[ESTADO],K$3) -> 0 | L5: =COUNTIFS(OPI[ESTADO],L$3) -> 0 | M5: =COUNTIFS(OPI[ESTADO],M$3) -> 0 | N5: =COUNTIFS(OPI[ESTADO],N$3) -> 0
B9: PLAZA DE VENTA | C9: FECHA DE ENVIO DE REMESA | D9: ESTADO DE REMESA | E9: FECHA DE INGRESO | F9: FECHA DE DESEMBOLSO | G9: DOCUMENTO | H9: NOMBRES Y APELLIDOS | I9: CONVENIO | J9: ESTADO | K9: MAF NETO | L9: EJECUTIVO | M9: FILE ENVIADO A BANCO | N9: FECHA DE ENVIÓ CARTA PODER A BCP | O9: COMPRA DE DEUDA REALIZADA | P9: LIBERACIÓN | Q9: FEEDBACK
B10: LIMA | D10: Aprobada | E10: 46234 | F10: 46237 | G10: 75850910 | H10: CUSI AUQUIRIMA ROYER QUELVIN | I10: PNP | J10: Desembolsado | K10: 95000 | L10: JUAN CORDOVA
B11: ICA | D11: Aprobada | E11: 46241 | F11: 46244 | G11: 74918667 | H11: PONCE HUALLANCA EDINSON MARLON | I11: PNP | J11: Desembolsado | K11: 80300 | L11: AURELIA FERNANDEZ
C12: 46244 | D12: Aprobada | E12: 46245 | F12: 46246 | G12: 47185989 | H12: PACAYA SAAVEDRA LUIS DANIEL | I12: EP | J12: Desembolsado | K12: 68700 | L12: AURELIA FERNANDEZ
B13: LIMA | D13: Aprobada | E13: 46244 | F13: 46245 | G13: 46931645 | H13: VARGAS VILDOSOLA MARCO ANTONIO | I13: PNP | J13: Desembolsado | K13: 83000 | L13: AURELIA FERNANDEZ
C14: 46241 | D14: Aprobada | E14: 46245 | F14: 46246 | G14: 70581588 | H14: DIAZ PINEDO MARIA ANGELICA | I14: PNP | J14: Desembolsado | K14: 75400 | L14: AURELIA FERNANDEZ
C15: 46244 | D15: Aprobada | E15: 46245 | F15: 46247 | G15: 44069732 | H15: TARAZONA LLANTO MIRELLA ALICIA | I15: PNP | J15: Desembolsado | K15: 20000 | L15: JUAN CORDOVA
C16: 46245 | D16: Aprobada | E16: 46247 | F16: 46251 | G16: 46371023 | H16: HUABLOCHO GUIZADO YESSENIA | I16: MGP | J16: Desembolsado | K16: 92400 | L16: AURELIA FERNANDEZ
C17: 46245 | D17: Aprobada | E17: 46247 | F17: 46248 | G17: 71098056 | H17: CHOQUE RODRIGUEZ PEDRO AURELIO | I17: MGP | J17: Desembolsado | K17: 49000 | L17: AURELIA FERNANDEZ
C18: 46245 | D18: Aprobada | E18: 46247 | F18: 46251 | G18: 47933860 | H18: HUERTAS SERNAQUE IRVIN OMAR | I18: MGP | J18: Desembolsado | K18: 75500 | L18: AURELIA FERNANDEZ
C19: 46245 | D19: Aprobada | E19: 46247 | F19: 46251 | G19: 71648848 | H19: MASLUCAN SOLANO CARLOS DANIEL | I19: EP | J19: Desembolsado | K19: 85500 | L19: MARIA LLONTOP
C20: 46247 | D20: Aprobada | E20: 46248 | F20: 46251 | G20: 47167356 | H20: LLANOS TOMASTO JOSE MIGUEL | I20: PNP | J20: Desembolsado | K20: 82300 | L20: JUAN CORDOVA
C21: 46247 | D21: Aprobada | E21: 46248 | F21: 46258 | G21: 47134517 | H21: MARTINEZ JULCA ROGER | I21: PNP | J21: Desembolsado | K21: 77500 | L21: JUAN CORDOVA
C22: 46247 | D22: Aprobada | E22: 46251 | F22: 46252 | G22: 72262874 | H22: MONTENEGRO ESTELA GEIBER | I22: PNP | J22: Desembolsado | K22: 81500 | L22: AURELIA FERNANDEZ
C23: 46247 | D23: Aprobada | E23: 46251 | F23: 46253 | G23: 71442909 | H23: ROJAS FLORES JESUS LEONARDO | I23: PNP | J23: Desembolsado | K23: 51500 | L23: AURELIA FERNANDEZ
C24: 46251 | D24: Aprobada | E24: 46252 | F24: 46253 | G24: 72671282 | H24: SAENZ GAMERO ESTUARDO GIACCOMO ALESSANDRO | I24: EP | J24: Desembolsado | K24: 85000 | L24: MARIA LLONTOP
C25: 46252 | D25: Aprobada | E25: 46253 | F25: 46259 | G25: 76071012 | H25: DAMASO LEGUIA JORGE ALFREDO JUNIOR | I25: PNP | J25: Desembolsado | K25: 77300 | L25: YESICA HEREDIA
... C33: 46260 | D33: Aprobada | E33: 46261 | F33: 46262 | G33: 74374761 | H33: GONZALES GONZALES EDIN YOEL | I33: PNP | J33: Desembolsado | K33: 73000 | L33: AURELIA FERNANDEZ

Sheet NAHOMI DIAZ
D3: CHICLAYO | E3: Meta | F3: Desembolsado | G3: Avance | H3: Pendiente De Documentar | I3: Pendiente De Remesa | J3: Pendiente De Backoffice | K3: Evaluación BCP | L3: Obs Backoffice | M3: Obs BCP | N3: Rechazado
D4: S/. | E4: 1000000 | F4: =SUMIFS(OPI_11[MAF NETO],OPI_11[ESTADO],"Desembolsado") -> 2108561 | G4: =F4-E4 -> 1108561 | H4: =SUMIFS(OPI_11[MAF NETO],OPI_11[ESTADO],H$3) -> 0 | I4: =SUMIFS(OPI_11[MAF NETO],OPI_11[ESTADO],I$3) -> 0 | J4: =SUMIFS(OPI_11[MAF NETO],OPI_11[ESTADO],J$3) -> 0 | K4: =SUMIFS(OPI_11[MAF NETO],OPI_11[ESTADO],K$3) -> 65000 | L4: =SUMIFS(OPI_11[MAF NETO],OPI_11[ESTADO],L$3) -> 0 | M4: =SUMIFS(OPI_11[MAF NETO],OPI_11[ESTADO],M$3) -> 151055 | N4: =SUMIFS(OPI_11[MAF NETO],OPI_11[ESTADO],N$3) -> 809950
D5: Q / % | E5: - | F5: =COUNTIFS(OPI_11[ESTADO],"Desembolsado") -> 27 | G5: =IFERROR(F4/E4,"") -> 2.108561 | H5: =COUNTIFS(OPI_11[ESTADO],H$3) -> 0 | I5: =COUNTIFS(OPI_11[ESTADO],I$3) -> 0 | J5: =COUNTIFS(OPI_11[ESTADO],J$3) -> 0 | K5: =COUNTIFS(OPI_11[ESTADO],K$3) -> 1 | L5: =COUNTIFS(OPI_11[ESTADO],L$3) -> 0 | M5: =COUNTIFS(OPI_11[ESTADO],M$3) -> 2 | N5: =COUNTIFS(OPI_11[ESTADO],N$3) -> 11
B9: PLAZA DE VENTA | C9: FECHA DE ENVIO DE REMESA | D9: ESTADO DE REMESA | E9: FECHA DE INGRESO | F9: FECHA DE DESEMBOLSO | G9: DOCUMENTO | H9: NOMBRES Y APELLIDOS | I9: CONVENIO | J9: ESTADO | K9: MAF NETO | L9: EJECUTIVO | M9: FILE ENVIADO A BANCO | N9: FECHA DE ENVIÓ CARTA PODER A BCP | O9: COMPRA DE DEUDA REALIZADA | P9: LIBERACIÓN | Q9: FEEDBACK
D10: Aprobada | G10: 74150135 | H10: FERRER BENITES SERGIO SEBASTIAN | I10: EJERCITO | J10: Desembolsado | K10: 88300 | L10: EYLIN VELASCO
D11: Aprobada | G11: 77060050 | H11: LOPEZ MARCOS BRAYAN ANTONIO | I11: PNP | J11: Rechazado | K11: 79200 | L11: EYLIN VELASCO | Q11: CLIENTE EN CPP
D12: Aprobada | G12: 72467967 | H12: PORTOCARRERO INFANTES KARINA STEPHANI | I12: EJERCITO | J12: Desembolsado | K12: 14822 | L12: EYLIN VELASCO
D13: Aprobada | G13: 72637149 | H13: GONZALES DAVILA JHOJAN JHAIR | I13: PNP | J13: Rechazado | K13: 72400 | L13: EYLIN VELASCO
D14: Aprobada | G14: 47239818 | H14: DIAZ PEREZ EDWIN JOEL | I14: PNP | J14: Desembolsado | K14: 82250 | L14: EYLIN VELASCO | M14: Si
D15: Aprobada | G15: 74969973 | H15: SIESQUEN DIAZ KEVIN ANDERSON | I15: PNP | J15: Desembolsado | K15: 80700 | L15: EYLIN VELASCO | M15: Si
D16: Aprobada | G16: 77529142 | H16: LLONTOP FARRO DENNYS JESUS | I16: PNP | J16: Desembolsado | K16: 64050 | L16: EYLIN VELASCO
D17: Aprobada | G17: 48039696 | H17: TEVES TINTAYA KATHERINE MILUSKA | I17: PNP | J17: Desembolsado | K17: 68700 | L17: EYLIN VELASCO
D18: Aprobada | G18: 75066361 | H18: DE LA CRUZ NAVARRETE ANGEL FARY | I18: PNP | J18: Desembolsado | K18: 71100 | L18: EYLIN VELASCO
C19: 46255 | D19: Aprobada | G19: 48363308 | H19: RIVERA QUISPE ADIN JOEL | I19: PNP | J19: Desembolsado | K19: 78500 | L19: EYLIN VELASCO
C20: 46255 | D20: Aprobada | G20: 72752565 | H20: SANCHEZ LOAYZA KEVIN ALONSO | I20: PNP | J20: Desembolsado | K20: 82600 | L20: EYLIN VELASCO
C21: 46256 | D21: Aprobada | G21: 75619081 | H21: ROMAN OLARTE JOSEFH LUIS | I21: EJERCITO | J21: Rechazado | K21: 86500 | L21: EYLIN VELASCO | Q21: DESISTIO
C22: 46229 | D22: Aprobada | G22: 43399740 | H22: ESPINO SORIA WILINGTHON JESUS | I22: EJERCITO | J22: Desembolsado | K22: 93900 | L22: EYLIN VELASCO
C23: 46261 | D23: Enviada | G23: 47175399 | H23: COTERA ROJAS PEDRO JUNIOR | I23: EJERCITO | J23: Desembolsado | K23: 95600 | L23: EYLIN VELASCO
D24: Aprobada | G24: 72980174 | H24: PINEDO SERVAN JOSE MANUEL | I24: PNP | J24: Desembolsado | K24: 65400 | L24: FIORELA DELGADO
D25: Aprobada | G25: 72751746 | H25: SALDAÑA PELAEZ ROSA GLADYS MILAGROS | I25: PNP | J25: Desembolsado | K25: 94600 | L25: FIORELA DELGADO
D26: Aprobada | G26: 75493599 | H26: CORONADO VIDAURRE EDWARD | I26: EJERCITO | J26: Rechazado | K26: 71400 | L26: JOSE CORTEZ | Q26: NO FIRMO
D27: Aprobada | G27: 45262744 | H27: HAYDEN SALAZAR MELISSA MERCEDES | I27: EJERCITO | J27: Rechazado | K27: 40000 | L27: JOSE CORTEZ
C28: 46256 | D28: Rechazada | G28: 72301326 | H28: MIRANDA VARGAS ALEJANDRO MARTIN | I28: EJERCITO | J28: Rechazado | K28: 92000 | L28: JOSE CORTEZ | Q28: CAYO CPP
C29: 46256 | D29: Aprobada | G29: 72942500 | H29: TORRES RIOS FRANK CARLOS | I29: EJERCITO | J29: Desembolsado | K29: 65000 | L29: JOSE CORTEZ
C30: 46256 | D30: Aprobada | G30: 47677371 | H30: BRAVO ROJAS JUAN PORFIRIO | I30: EJERCITO | J30: Desembolsado | K30: 99080 | L30: JOSE CORTEZ
C31: 46258 | D31: Rechazada | G31: 70771203 | H31: ARONI VEGA GOMER KEVYN | I31: EJERCITO | J31: Rechazado | K31: 70470 | L31: JOSE CORTEZ | Q31: CARTERA TRANSFERIDA
C32: 46258 | D32: Enviada | G32: 70777584 | H32: VALDEZ ROJAS ALVARO SAMUEL | I32: EJERCITO | J32: Desembolsado | K32: 76500 | L32: JOSE CORTEZ
C33: 46229 | D33: Aprobada | G33: 74565365 | H33: CESPEDES PINARES JORGE LUIS | I33: EJERCITO | J33: Rechazado | K33: 86680 | L33: JOSE CORTEZ | Q33: CARTERA TRANSFERIDA
C34: 46261 | D34: Enviada | G34: 72734015 | H34: JULCA GONZALES FRANCIS GIANPIERRE | I34: EJERCITO | J34: Desembolsado | K34: 90850 | L34: JOSE CORTEZ
C35: 46261 | D35: Rechazada | G35: 73812702 | H35: SANCHEZ GALVEZ PIERO CESAR | I35: EJERCITO | J35: Rechazado | K35: 56000 | L35: JOSE CORTEZ | Q35: CARTERA TRANSFERIDA
B36: CHICLAYO | D36: Aprobada | G36: 73018920 | H36: GALLO SOTO,LEONARDO MIGUEL | I36: PNP | J36: Desembolsado | K36: 77539 | L36: JUDITH FARRO
D37: Aprobada | G37: 75389848 | H37: RUIZ ROJAS,ANGELO JAVIER | I37: PNP | J37: Obs BCP | K37: 67955 | L37: JUDITH FARRO
D38: Rechazada | G38: 46146763 | H38: VERGARA HUALLPAROMACHI AMILCAR | I38: PNP | J38: Rechazado | K38: 83300 | L38: JUDITH FARRO
D39: Aprobada | G39: 45840620 | H39: ALVAREZ GARCIA JAMES ANTONY | I39: PNP | J39: Desembolsado | K39: 71400 | L39: PIERO LOPEZ
D40: Aprobada | G40: 45709668 | H40: ALARCON MENOR MARIA YOHANA | I40: PNP | J40: Desembolsado | K40: 92300 | L40: PIERO LOPEZ | M40: Si
D41: Aprobada | G41: 46107693 | H41: PERALTA ALHUAY GUISSELLA KATHY | I41: PNP | J41: Desembolsado | K41: 72300 | L41: PIERO LOPEZ
D42: Aprobada | G42: 48211384 | H42: GUERRERO HUAMAN ELVIS BETO | I42: PNP | J42: Desembolsado | K42: 78300 | L42: PIERO LOPEZ
D43: Aprobada | G43: 47567773 | H43: CARHUACHAGUA CAPCHA JORDAN MARVIN | I43: PNP | J43: Desembolsado | K43: 80000 | L43: PIERO LOPEZ
C44: 46229 | D44: Enviada | G44: 73830703 | H44: CUSI YARASCA MIGUEL ANGEL | I44: EJERCITO | J44: Desembolsado | K44: 85000 | L44: PIERO LOPEZ
C45: 46229 | D45: Aprobada | G45: 74624781 | H45: SANTISTEBAN CHERO JANETH | I45: PNP | J45: Desembolsado | K45: 73420 | L45: PIERO LOPEZ
...

Sheet JHON ZAMORA
D3: CHICLAYO | E3: Meta | F3: Desembolsado | G3: Avance | H3: Pendiente De Documentar | I3: Pendiente De Remesa | J3: Pendiente De Backoffice | K3: Evaluación BCP | L3: Obs Backoffice | M3: Obs BCP | N3: Rechazado
D4: S/. | E4: 1000000 | F4: =SUMIFS(OPI_3[MAF NETO],OPI_3[ESTADO],"Desembolsado") -> 925450 | G4: =F4-E4 -> -74550 | H4: =SUMIFS(OPI_3[MAF NETO],OPI_3[ESTADO],H$3) -> 0 | I4: =SUMIFS(OPI_3[MAF NETO],OPI_3[ESTADO],I$3) -> 0 | J4: =SUMIFS(OPI_3[MAF NETO],OPI_3[ESTADO],J$3) -> 0 | K4: =SUMIFS(OPI_3[MAF NETO],OPI_3[ESTADO],K$3) -> 0 | L4: =SUMIFS(OPI_3[MAF NETO],OPI_3[ESTADO],L$3) -> 0 | M4: =SUMIFS(OPI_3[MAF NETO],OPI_3[ESTADO],M$3) -> 0 | N4: =SUMIFS(OPI_3[MAF NETO],OPI_3[ESTADO],N$3) -> 77360
D5: Q / % | E5: - | F5: =COUNTIFS(OPI_3[ESTADO],"Desembolsado") -> 15 | G5: =IFERROR(F4/E4,"") -> 0.92545 | H5: =COUNTIFS(OPI_3[ESTADO],H$3) -> 0 | I5: =COUNTIFS(OPI_3[ESTADO],I$3) -> 0 | J5: =COUNTIFS(OPI_3[ESTADO],J$3) -> 0 | K5: =COUNTIFS(OPI_3[ESTADO],K$3) -> 0 | L5: =COUNTIFS(OPI_3[ESTADO],L$3) -> 0 | M5: =COUNTIFS(OPI_3[ESTADO],M$3) -> 0 | N5: =COUNTIFS(OPI_3[ESTADO],N$3) -> 1
B9: PLAZA DE VENTA | C9: FECHA DE ENVIO DE REMESA | D9: ESTADO DE REMESA | E9: FECHA DE INGRESO | F9: FECHA DE DESEMBOLSO | G9: DOCUMENTO | H9: NOMBRES Y APELLIDOS | I9: CONVENIO | J9: ESTADO | K9: MAF NETO | L9: EJECUTIVO | M9: FILE ENVIADO A BANCO | N9: FECHA DE ENVIÓ CARTA PODER A BCP | O9: COMPRA DE DEUDA REALIZADA | P9: LIBERACIÓN | Q9: FEEDBACK
B10: CHICLAYO | C10: 46233 | D10: Aprobada | E10: 46233 | F10: 46237 | G10: 73377048 | H10: LLATAS RIMARACHIN JORGE LUIS | I10: PNP | J10: Desembolsado | K10: 83100 | L10: FLOR LLATAS
B11: CHICLAYO | C11: 46233 | D11: Aprobada | E11: 46233 | F11: 46238 | G11: 71824277 | H11: URIARTE RENTERIA SOFIA STEFANI | I11: PNP | J11: Desembolsado | K11: 77700 | L11: FLOR LLATAS
B12: CHICLAYO | C12: 46233 | D12: Aprobada | E12: 46233 | F12: 46238 | G12: 42047411 | H12: EDGAR SMITH CUMPEN LARA | I12: PNP | J12: Desembolsado | K12: 37200 | L12: FLOR LLATAS
B13: CHICLAYO | C13: 46239 | D13: Aprobada | E13: 46239 | F13: 46241 | G13: 75338267 | H13: ZARATE DIAZ HAYDY MAYDELIT | I13: PNP | J13: Desembolsado | K13: 79860 | L13: FLOR LLATAS
B14: CHICLAYO | C14: 46239 | D14: Aprobada | E14: 46239 | F14: 46239 | G14: 72729971 | H14: RELUZ CALDERON RICARDO ENRIQUE | I14: PNP | J14: Desembolsado | K14: 77340 | L14: FLOR LLATAS
B15: CHICLAYO | C15: 46239 | D15: Aprobada | E15: 46239 | F15: 46241 | G15: 76097234 | H15: HUAMAN IMAN,EDGARD STIWER ADOLFO | I15: PNP | J15: Desembolsado | K15: 82280 | L15: FLOR LLATAS | P15: <<<<<<<<<<<<<<<<<<
B16: CHICLAYO | C16: 3/08/0206 | D16: Aprobada | E16: 46239 | F16: 46239 | G16: 45464725 | H16: CASTRO LLANCO BRIAN OMAR | I16: PNP | J16: Desembolsado | K16: 16000 | L16: FLOR LLATAS
B17: CHICLAYO | C17: 46246 | D17: Aprobada | E17: 46246 | G17: 72781164 | H17: FIGUEROA CADENAS HERNAN EDGARDO | I17: PNP | J17: Desembolsado | K17: 29000 | L17: FLOR LLATAS
B18: CHICLAYO | C18: 46251 | D18: Aprobada | E18: 46252 | F18: 46252 | G18: 72368192 | H18: MACALOPU SIRLOPU CATERYN YAJAYRA | I18: PNP | J18: Desembolsado | K18: 25000 | L18: FLOR LLATAS
B19: CHICLAYO | C19: 46258 | D19: Rechazada | G19: 48409811 | H19: MUCHA HUARACA JHOEL KENDELL | I19: PNP | J19: Rechazado | K19: 77360 | L19: FLOR LLATAS | Q19: REMESA APROB CON IBK
B20: CHICLAYO | C20: 46253 | D20: Aprobada | E20: 46254 | G20: 46975057 | H20: FLORES VALLES ANGEL | I20: PNP | J20: Desembolsado | K20: 53500 | L20: ERICK GUEVARA
B21: CHICLAYO | C21: 46253 | D21: Aprobada | E21: 46254 | G21: 73495802 | H21: GUERRERO ZULUETA LUIS ARMANDO | I21: PNP | J21: Desembolsado | K21: 67100 | L21: ERICK GUEVARA
B22: CHICLAYO | C22: 46259 | D22: Aprobada | E22: 46259 | G22: 74387078 | H22: ASTUDILLOS SANCHEZ CHRISTIAN JIM | I22: PNP | J22: Desembolsado | K22: 82250 | L22: FLOR LLATAS
B23: CHICLAYO | C23: 46259 | D23: Aprobada | E23: 46259 | G23: 46842201 | H23: ZURITA ALEJANDRIA WILLIAN WALTER | I23: PNP | J23: Desembolsado | K23: 77450 | L23: ERICK GUEVARA
B24: CHICLAYO | C24: 46260 | D24: Aprobada | E24: 46261 | F24: 46261 | G24: 45593624 | H24: ZULOETA DAVILA MARIA LUCIA | I24: PNP | J24: Desembolsado | K24: 50350 | L24: ERICK GUEVARA
B25: CHICLAYO | C25: 46261 | D25: Aprobada | E25: 46261 | G25: 44519435 | H25: HERNANDEZ ROSALES JOSUE ALBERTO | I25: PNP | J25: Desembolsado | K25: 87320 | L25: FLOR LLATAS

Sheet WENDY IPANEQUE
D3: PIURA | E3: Meta | F3: Desembolsado | G3: Avance | H3: Pendiente De Documentar | I3: Pendiente De Remesa | J3: Pendiente De Backoffice | K3: Evaluación BCP | L3: Obs Backoffice | M3: Obs BCP | N3: Rechazado
D4: S/. | E4: 1000000 | F4: =SUMIFS(OPI_14[MAF NETO],OPI_14[ESTADO],"Desembolsado") -> 994700 | G4: =F4-E4 -> -5300 | H4: =SUMIFS(OPI_14[MAF NETO],OPI_14[ESTADO],H$3) -> 0 | I4: =SUMIFS(OPI_14[MAF NETO],OPI_14[ESTADO],I$3) -> 0 | J4: =SUMIFS(OPI_14[MAF NETO],OPI_14[ESTADO],J$3) -> 0 | K4: =SUMIFS(OPI_14[MAF NETO],OPI_14[ESTADO],K$3) -> 156150 | L4: =SUMIFS(OPI_14[MAF NETO],OPI_14[ESTADO],L$3) -> 0 | M4: =SUMIFS(OPI_14[MAF NETO],OPI_14[ESTADO],M$3) -> 82000 | N4: =SUMIFS(OPI_14[MAF NETO],OPI_14[ESTADO],N$3) -> 495800
D5: Q / % | E5: - | F5: =COUNTIFS(OPI_14[ESTADO],"Desembolsado") -> 14 | G5: =IFERROR(F4/E4,"") -> 0.9947 | H5: =COUNTIFS(OPI_14[ESTADO],H$3) -> 0 | I5: =COUNTIFS(OPI_14[ESTADO],I$3) -> 0 | J5: =COUNTIFS(OPI_14[ESTADO],J$3) -> 0 | K5: =COUNTIFS(OPI_14[ESTADO],K$3) -> 2 | L5: =COUNTIFS(OPI_14[ESTADO],L$3) -> 0 | M5: =COUNTIFS(OPI_14[ESTADO],M$3) -> 1 | N5: =COUNTIFS(OPI_14[ESTADO],N$3) -> 7
B9: PLAZA DE VENTA | C9: FECHA DE ENVIO DE REMESA | D9: ESTADO DE REMESA | E9: FECHA DE INGRESO | F9: FECHA DE DESEMBOLSO | G9: DOCUMENTO | H9: NOMBRES Y APELLIDOS | I9: CONVENIO | J9: ESTADO | K9: MAF NETO | L9: EJECUTIVO | M9: FILE ENVIADO A BANCO | N9: FECHA DE ENVIÓ CARTA PODER A BCP | O9: COMPRA DE DEUDA REALIZADA | P9: LIBERACIÓN | Q9: FEEDBACK
B10: PIURA | C10: 46224 | D10: Aprobada | F10: 46238 | G10: 42992200 | H10: PALOMARES VALENTIN JUDITH BEATRIZ | I10: PNP | J10: Desembolsado | K10: 40000 | L10: WENDY IPANAQUE | M10: No | Q10: LINEA NUEVA: REALIZADO
B11: PIURA | C11: 46238 | D11: Aprobada | F11: 46241 | G11: 74403000 | H11: RODRIGUEZ ORTIZ JORGE LUIS | I11: PNP | J11: Desembolsado | K11: 79500 | L11: WENDY IPANAQUE | M11: No | Q11: CD BBVA: CD REALIZADO
B12: PIURA | C12: 46238 | D12: Aprobada | F12: 46248 | G12: 47331215 | H12: ALLASI SANCHEZ JORGE JAIRO | I12: PNP | J12: Desembolsado | K12: 81750 | L12: WENDY IPANAQUE | M12: No | Q12: LINEA NUEVA: REALIZADO
B13: PIURA | C13: 46239 | D13: Aprobada | F13: 46247 | G13: 02831131 | H13: TIMANA RIVAS ROSA | I13: ESSALUD | J13: Desembolsado | K13: 47450 | L13: WENDY IPANAQUE | Q13: CD BANCOM: CD REALIZADO
B14: PIURA | C14: 46239 | D14: Aprobada | F14: 46248 | G14: 43623113 | H14: HERRERA PINTADO ELOY ANDRES | I14: ESSALUD | J14: Desembolsado | K14: 59800 | L14: WENDY IPANAQUE | Q14: CD BANCOM: CD REALIZADO
B15: PIURA | C15: 46238 | D15: Rechazada | G15: 70483707 | H15: ISMINIO REATEGUI CESAR KINDER | I15: EP | J15: Rechazado | K15: 80400 | L15: KRIS BARRAGAN RODRIGUEZ | Q15: CD INTERBANK: REINGRESAR EL 18 DE AGOSTO PARA QUE LE AUMENTE EL MONTO. PENDIENTE RECONFIRMACION DEL CLIENTE
B16: PIURA | C16: 46238 | D16: Aprobada | F16: 46248 | G16: 75756343 | H16: SANDOVAL ZUÑIGA KEVIN ELIAN | I16: EJERCITO | J16: Desembolsado | K16: 86200 | L16: WENDY IPANAQUE | Q16: CD BBVA: CD REALIZADO
B17: PIURA | C17: 46238 | D17: Aprobada | G17: 72807596 | H17: VARELA RUIZ PIERO ALEJANDRO | I17: EP | J17: Rechazado | K17: 81500 | L17: KRIS BARRAGAN RODRIGUEZ | Q17: CD BBVA. PENDIENTE RPTA DE DESEMBOLSO
B18: PIURA | C18: 46239 | D18: Rechazada | G18: 71275212 | H18: CASTRO FARFAN CHRISTIAN | I18: EP | J18: Rechazado | K18: 81300 | L18: KRIS BARRAGAN RODRIGUEZ | Q18: CD BBVA: SE CAYO VENTA
B19: PIURA | C19: 46239 | D19: Rechazada | G19: 45198946 | H19: ANCAJIMA ALARCON ELMER ALEXANDER | I19: ESSALUD | J19: Rechazado | K19: 0 | L19: GINO SANDOVAL ROMAN | Q19: CD BANBIF: SE CAYO VENTA
B20: PIURA | C20: 46239 | D20: Aprobada | F20: 46241 | G20: 70382529 | H20: CASTILLO VILELA CRISTIAN ANDERSON | I20: PNP | J20: Desembolsado | K20: 78500 | L20: WENDY IPANAQUE | Q20: CS SCOTIABANK Y NACION: CD REALIZADO
B21: PIURA | C21: 46244 | D21: Aprobada | F21: 46245 | G21: 76427389 | H21: OBREGON CACERES CARLA ROSMERI | I21: PNP | J21: Desembolsado | K21: 50000 | L21: WENDY IPANAQUE | Q21: CD SCOTIABANK: PENDIENTE CD
B22: PIURA | C22: 46245 | D22: Aprobada | F22: 46259 | G22: 03892055 | H22: ESCOBAR REVOLLEDO NORMA VIRGINIA | I22: LUCIANO CASTILLO | J22: Desembolsado | K22: 136800 | L22: WENDY IPANAQUE | Q22: CD BANBIF: PENDIENTE RPTA DE DESEMBOLSOS
B23: PIURA | C23: 46245 | D23: Rechazada | G23: 42590269 | H23: VELASQUEZ MEZONES OMAR | I23: PNP | J23: Rechazado | K23: 90400 | L23: KRIS BARRAGAN RODRIGUEZ | Q23: CD SCOTIABANK: SE CAYO VENTA
B24: PIURA | C24: 46246 | D24: Rechazada | G24: 76259702 | H24: ABAD CHUQUIHUANGA ANYILI MERLITA | I24: PNP | J24: Rechazado | K24: 81700 | L24: MIXSY SANJINEZ BERMEO | Q24: CD INTERBANK: CTE ESPERARÁ SETIEMBRE
B25: PIURA | C25: 46247 | D25: Aprobada | F25: 46248 | G25: 70368042 | H25: RUIZ GARCIA MARLON JEAN PIERRE | I25: PNP | J25: Desembolsado | K25: 72800 | L25: WENDY IPANAQUE | Q25: CD SCOTIABANK: CD REALIZADO
B26: PIURA | C26: 46247 | D26: Aprobada | F26: 46259 | G26: 70010234 | H26: AVILA PIMINCHUMO ARMANDO EDINSON | I26: PNP | J26: Desembolsado | K26: 70600 | L26: WENDY IPANAQUE
B27: PIURA | C27: 46247 | D27: Aprobada | F27: 46254 | G27: 74967466 | H27: AGUILAR HERNANDEZ JEAN PAUL | I27: PNP | J27: Desembolsado | K27: 56000 | L27: WENDY IPANAQUE
B28: PIURA | C28: 46247 | D28: Aprobada | G28: 71743882 | H28: MANTILLA GALARRETA LUIS MARTIR | I28: PNP | J28: Rechazado | K28: 80500 | L28: KRIS BARRAGAN RODRIGUEZ
B29: PIURA | C29: 46251 | D29: Aprobada | G29: 70509951 | H29: ARELLANO LEON BRAYAN DAIL | I29: EJERCITO | J29: Obs BCP | K29: 82000 | L29: WENDY IPANAQUE
B30: PIURA | C30: 46255 | D30: Aprobada | F30: 46261 | G30: 47588730 | H30: TOCTO FLORES ELSA KATHERINE | I30: HOSP. CHULUCANAS | J30: Desembolsado | K30: 72000 | L30: WENDY IPANAQUE
B31: PIURA | C31: 46260 | D31: Aprobada | G31: 80262692 | H31: COLUPU PURIZACA WALTER | I31: MPV | J31: Evaluación BCP | K31: 83800 | L31: WENDY IPANAQUE | Q31: CD IBK Y REHABILITADORA: PENDIENTE RPTA DESEMBOLSOS
B32: PIURA | C32: 46260 | D32: Aprobada | G32: 42984845 | H32: ZAPATA OLAVARRIA CHRISTIAN EDWAR | I32: MPV | J32: Evaluación BCP | K32: 72350 | L32: WENDY IPANAQUE | Q32: CD BANCOM Y REHABILITADORA: PENDIENTE RPTA DESEMBOLSOS
B33: PIURA | C33: 46261 | D33: Aprobada | G33: 76819231 | H33: AGUILAR MARTINEZ FELIX JORDAN | I33: PNP | J33: Desembolsado | K33: 63300 | L33: WENDY IPANAQUE | Q33: CD IBK: REMESA ENVIADA, PENDIENTE RPTA
B34: PIURA | C34: 46261 | D34: Aprobada

Sheet OMAR MINAYA
D3: CHICLAYO | E3: Meta | F3: Desembolsado | G3: Avance | H3: Pendiente De Documentar | I3: Pendiente De Remesa | J3: Pendiente De Backoffice | K3: Evaluación BCP | L3: Obs Backoffice | M3: Obs BCP | N3: Rechazado
D4: S/. | E4: 1000000 | F4: =SUMIFS(OPI_5[MAF NETO],OPI_5[ESTADO],"Desembolsado") -> 1629875 | G4: =F4-E4 -> 629875 | H4: =SUMIFS(OPI_5[MAF NETO],OPI_5[ESTADO],H$3) -> 0 | I4: =SUMIFS(OPI_5[MAF NETO],OPI_5[ESTADO],I$3) -> 12000 | J4: =SUMIFS(OPI_5[MAF NETO],OPI_5[ESTADO],J$3) -> 0 | K4: =SUMIFS(OPI_5[MAF NETO],OPI_5[ESTADO],K$3) -> 164600 | L4: =SUMIFS(OPI_5[MAF NETO],OPI_5[ESTADO],L$3) -> 0 | M4: =SUMIFS(OPI_5[MAF NETO],OPI_5[ESTADO],M$3) -> 70000 | N4: =SUMIFS(OPI_5[MAF NETO],OPI_5[ESTADO],N$3) -> 525650
D5: Q / % | E5: - | F5: =COUNTIFS(OPI_5[ESTADO],"Desembolsado") -> 23 | G5: =IFERROR(F4/E4,"") -> 1.629875 | H5: =COUNTIFS(OPI_5[ESTADO],H$3) -> 0 | I5: =COUNTIFS(OPI_5[ESTADO],I$3) -> 1 | J5: =COUNTIFS(OPI_5[ESTADO],J$3) -> 0 | K5: =COUNTIFS(OPI_5[ESTADO],K$3) -> 3 | L5: =COUNTIFS(OPI_5[ESTADO],L$3) -> 0 | M5: =COUNTIFS(OPI_5[ESTADO],M$3) -> 1 | N5: =COUNTIFS(OPI_5[ESTADO],N$3) -> 7
B9: PLAZA DE VENTA | C9: FECHA DE ENVIO DE REMESA | D9: ESTADO DE REMESA | E9: FECHA DE INGRESO | F9: FECHA DE DESEMBOLSO | G9: DOCUMENTO | H9: NOMBRES Y APELLIDOS | I9: CONVENIO | J9: ESTADO | K9: MAF NETO | L9: EJECUTIVO | M9: FILE ENVIADO A BANCO | N9: FECHA DE ENVIÓ CARTA PODER A BCP | O9: COMPRA DE DEUDA REALIZADA | P9: LIBERACIÓN | Q9: FEEDBACK
B10: CHICLAYO | C10: 46252 | D10: Aprobada | E10: 46253 | F10: 46254 | G10: 73804924 | H10: CERNA MENDOZA CARLO MARIO | I10: ESSALUD | J10: Desembolsado | K10: 35800 | L10: ANA FARRO
B11: CHICLAYO | D11: Aprobada | G11: 40910774 | H11: YUPANQUI NAVARRO EDERSON | I11: EJERCITO | J11: Rechazado | K11: 95100 | L11: ANA FARRO
B12: CHICLAYO | C12: 46246 | D12: Aprobada | E12: 46247 | F12: 46252 | G12: 75493599 | H12: ROSALES REYES JEAN PIERO | I12: EPEJERCITO | J12: Desembolsado | K12: 79100 | L12: CESAR SIESQUEN
B13: CHICLAYO | C13: 46244 | D13: Aprobada | E13: 46244 | F13: 46248 | G13: 73245610 | H13: CALLE NEIRA ANTHONY JHOSELIN | I13: EJERCITO | J13: Desembolsado | K13: 6000 | L13: CESAR SIESQUEN
B14: CHICLAYO | C14: 46246 | D14: Aprobada | E14: 46251 | F14: 46255 | G14: 74307118 | H14: HUAMAN TAIRO LENIN MIGUEL FRANCISCO | I14: EJERCITO | J14: Desembolsado | K14: 67835 | L14: CESAR SIESQUEN | Q14: SE INGRESA EL 16
B15: CHICLAYO | C15: 46241 | D15: Rechazada | E15: ------------------------------------ | F15: ------------------------------------- | G15: 76095329 | H15: ARCE FLORES LUIS ALFREDO | I15: PNP | J15: Desembolsado | K15: 67700 | L15: GABRIELA VELASQUEZ
B16: CHICLAYO | C16: 46247 | D16: Aprobada | E16: 46247 | F16: 46251 | G16: 73199746 | H16: VILCA TORRES RONALDO | I16: EJERCITO | J16: Desembolsado | K16: 96950 | L16: GABRIELA VELASQUEZ
B17: CHICLAYO | C17: 46258 | D17: Aprobada | G17: 48297343 | H17: HUAMANI QUISPE JHON WILLIAN | I17: EJERCITO | J17: Evaluación BCP | K17: 24000 | L17: GABRIELA VELASQUEZ
B18: CHICLAYO | C18: 46260 | D18: Aprobada | G18: 75202880 | H18: CORDOVA QUESADA ROCIO MARILIN | I18: EJERCITO | J18: Evaluación BCP | K18: 89600 | L18: GABRIELA VELASQUEZ
B19: CHICLAYO | C19: 46258 | D19: Rechazada | G19: 76643587 | H19: ORTIZ AREVALO DOYSI MAIDELI | I19: MARINA | J19: Rechazado | K19: 40000 | L19: HENRY
B20: CHICLAYO | C20: 46233 | D20: Aprobada | E20: 46237 | F20: 46241 | G20: 75937974 | H20: MARCO ANTONIO CALDERON ZAMBRANO | I20: PNP | J20: Desembolsado | K20: 81050 | L20: KAROL MIÑAN
B21: CHICLAYO | C21: 46242 | D21: Aprobada | E21: 46245 | F21: 46246 | G21: 75175687 | H21: LUIS EDUARDO CHUMPITAZ TEJADA | I21: EJERCITO | J21: Desembolsado | K21: 78450 | L21: KAROL MIÑAN
B22: CHICLAYO | C22: 46255 | D22: Aprobada | G22: 73609607 | H22: DUEÑAS MONTAÑEZ ALEXANDER | I22: EJERCITO | J22: Desembolsado | K22: 18600 | L22: KAROL MIÑAN
B23: CHICLAYO | D23: Enviada | G23: 40129077 | H23: VASQUEZ DIAZ JOSE HUGO | I23: EJERCITO | J23: Pendiente De Remesa | K23: 12000 | L23: KAROL MIÑAN
B24: CHICLAYO | C24: ----------------------------- | D24: Rechazada | E24: ------------------------------------ | F24: -------------------------------------- | G24: 77290387 | H24: CEDILLO YNFANTE KENYI JAMPIER | I24: PNP | J24: Rechazado | K24: 72300 | L24: MEDALITH
B25: CHICLAYO | C25: 46255 | D25: Aprobada | G25: 46466484 | H25: CLAUDIA CRISTINA MARRUFO DIAZ | I25: ESSALUD | J25: Rechazado | K25: 100000 | L25: MILAGROS LIMO
B26: CHICLAYO | C26: 46244 | D26: Aprobada | G26: 45862279 | H26: TERRONES LLANOS PASCUAL | I26: PNP | J26: Desembolsado | K26: 51500 | L26: YOVANA BACA
B27: CHICLAYO | C27: 46239 | D27: Aprobada | G27: 75449894 | H27: SALVADOR CORREA JOSE EDGARDO | I27: PNP | J27: Desembolsado | K27: 46450 | L27: YOVANA BACA
B28: CHICLAYO | C28: 46234 | D28: Aprobada | E28: 46238 | F28: 46241 | G28: 78551156 | H28: CARLOS SANDOVAL DENNYS FRANLEY | I28: EJERCITO | J28: Desembolsado | K28: 92490 | L28: YURIKO OSPINO
B29: CHICLAYO | C29: 46241 | D29: Aprobada | E29: 46241 | F29: 46244 | G29: 74916358 | H29: SENMACHE BUITRON ALEXIS JAIR | I29: PNP | J29: Desembolsado | K29: 82250 | L29: YURIKO OSPINO
B30: CHICLAYO | C30: 46239 | D30: Aprobada | E30: 46245 | F30: 46248 | G30: 46406734 | H30: GUERRERO ELERA SAMUEL JORSINHO | I30: MARINA | J30: Desembolsado | K30: 25000 | L30: YURIKO OSPINO
B31: CHICLAYO | C31: 46242 | D31: Aprobada | E31: 46247 | F31: 46251 | G31: 40580977 | H31: DE LA CRUZ GRAJEDA ABRAHAM FELIX | I31: EJERCITO | J31: Desembolsado | K31: 173400 | L31: YURIKO OSPINO
B32: CHICLAYO | C32: 46246 | D32: Aprobada | E32: 46251 | F32: 46253 | G32: 70245957 | H32: MUÑOZ ARBOLEDA JAIRO ANGELLO | I32: PNP | J32: Desembolsado | K32: 83000 | L32: YURIKO OSPINO | Q32: SE INGRESA 16
B33: CHICLAYO | C33: ------------------------- | D33: Aprobada | E33: --------------------------- | F33: ------------------------------- | G33: 71401455 | H33: QUICHCA GIRON JULIO AYOROS | I33: EJERCITO | J33: Rechazado | K33: 78200 | L33: YURIKO OSPINO | Q33: FIRMA SABADO
B34: CHICLAYO | C34: 46245 | D34: Aprobada | E34: 46247 | F34: 46253 | G34: 71620010 | H34: CHAVARRY ROJAS CARLOS SERGIO | I34: PNP | J34: Desembolsado | K34: 96200 | L34: YURIKO OSPINO
B35: CHICLAYO | C35: 46246 | D35: Aprobada | E35: 46249 | F35: 46252 | G35: 74660561 | H35: XENA SANIT AQUISI SEGURA | I35: EJERCITO | J35: Desembolsado | K35: 84300 | L35: YURIKO OSPINO | Q35: PENDIENTE FIRMAS
B36: CHICLAYO | C36: 46251 | D36: Aprobada | E36: 46254 | F36: 46256 | G36: 47145953 | H36: ACEVEDO LOPEZ DIEGO JOEL | I36: MARINA | J36: Desembolsado | K36: 83800 | L36: YURIKO OSPINO
B37: CHICLAYO | C37: 46252 | D37: Aprobada | E37: 46253 | G37: 46309599 | H37: ANGELES ROJAS LEYZY ROMINA | I37: ESSALUD | J37: Rechazado | K37: 63450 | L37: YURIKO OSPINO
B38: CHICLAYO | C38: 46253 | D38: Aprobada | E38: 46253 | G38: 42266231 | H38: VALVERDE CRIOLLO MARLON FERNANDO | I38: EJERCITO | J38: Desembolsado | K38: 86100 | L38: YURIKO OSPINO
B39: CHICLAYO | C39: 46258 | D39: Aprobada | G39: 74769536 | H39: OLAECHEA SALCEDO JOSEPH EDUARDO | I39: EJERCITO | J39: Obs BCP | K39: 70000 | L39: YURIKO OSPINO
B40: CHICLAYO | C40: 46258 | D40: Aprobada | G40: 18178794 | H40: PORTELLA DEZA HUBERT AUGUSTO | I40: HRL | J40: Desembolsado | K40: 41000 | L40: YURIKO OSPINO
B41: CHICLAYO | C41: 46258 | D41: Aprobada | G41: 45002268 | H41: BAMBAREN BARBOZA IVAN RICARDO | I41: PNP | J41: Desembolsado | K41: 82600 | L41: YURIKO OSPINO
B42: CHICLAYO | C42: 46259 | D42: Aprobada | G42: 15753995 | H42: PADILLA FALCON AMERICO JAVIER | I42: MARINA | J42: Evaluación BCP | K42: 51000 | L42: YURIKO OSPINO
B43: CHICLAYO | C43: 46260 | D43: Rechazada | E43: ---------------------- | F43: -------------------------------------- | G43: 71810775 | H43: AGUERO ARCOS TYSON HAMES | I43: EJERCITO | J43: Rechazado | K43: 76600 | L43: YURIKO OSPINO
B44: CHICLAYO | C44: 46260 | D44: Aprobada | G44: 76001406 | H44: AHUANARI TUPULLIMA ROIBER | I44: EJERCITO | J44: Desembolsado | K44: 70300 | L44: YURIKO OSPINO

Sheet NATHALIE ARANDA
D3: LIMA 2 | E3: Meta | F3: Desembolsado | G3: Avance | H3: Pendiente De Documentar | I3: Pendiente De Remesa | J3: Pendiente De Backoffice | K3: Evaluación BCP | L3: Obs Backoffice | M3: Obs BCP | N3: Rechazado
D4: S/. | E4: 500000 | F4: =SUMIFS(OPI_12[MAF NETO],OPI_12[ESTADO],"Desembolsado") -> 1460120 | G4: =F4-E4 -> 960120 | H4: =SUMIFS(OPI_12[MAF NETO],OPI_12[ESTADO],H$3) -> 34800 | I4: =SUMIFS(OPI_12[MAF NETO],OPI_12[ESTADO],I$3) -> 543600 | J4: =SUMIFS(OPI_12[MAF NETO],OPI_12[ESTADO],J$3) -> 0 | K4: =SUMIFS(OPI_12[MAF NETO],OPI_12[ESTADO],K$3) -> 74600 | L4: =SUMIFS(OPI_12[MAF NETO],OPI_12[ESTADO],L$3) -> 0 | M4: =SUMIFS(OPI_12[MAF NETO],OPI_12[ESTADO],M$3) -> 0 | N4: =SUMIFS(OPI_12[MAF NETO],OPI_12[ESTADO],N$3) -> 0
D5: Q / % | E5: - | F5: =COUNTIFS(OPI_12[ESTADO],"Desembolsado") -> 22 | G5: =IFERROR(F4/E4,"") -> 2.92024 | H5: =COUNTIFS(OPI_12[ESTADO],H$3) -> 1 | I5: =COUNTIFS(OPI_12[ESTADO],I$3) -> 8 | J5: =COUNTIFS(OPI_12[ESTADO],J$3) -> 0 | K5: =COUNTIFS(OPI_12[ESTADO],K$3) -> 1 | L5: =COUNTIFS(OPI_12[ESTADO],L$3) -> 0 | M5: =COUNTIFS(OPI_12[ESTADO],M$3) -> 0 | N5: =COUNTIFS(OPI_12[ESTADO],N$3) -> 0
B9: PLAZA DE VENTA | C9: FECHA DE ENVIO DE REMESA | D9: ESTADO DE REMESA | E9: FECHA DE INGRESO | F9: FECHA DE DESEMBOLSO | G9: DOCUMENTO | H9: NOMBRES Y APELLIDOS | I9: CONVENIO | J9: ESTADO | K9: MAF NETO | L9: EJECUTIVO | M9: FILE ENVIADO A BANCO | N9: FECHA DE ENVIÓ CARTA PODER A BCP | O9: COMPRA DE DEUDA REALIZADA | P9: LIBERACIÓN | Q9: FEEDBACK
B10: CHICLAYO | C10: 46225 | D10: Aprobada | E10: 46233 | F10: 46239 | G10: 43292897 | H10: MIGUEL ANGEL CORONADO NAVARRO | I10: EP | J10: Desembolsado | K10: 70600 | L10: EVELYN GUTIERREZ | N10: 46241 | O10: Si | P10: Si
B11: LIMA | C11: 46233 | D11: Aprobada | E11: 46233 | F11: 46238 | G11: 72952758 | H11: YHON WASHINGTON QUISPE CAHUASCANCO | I11: PNP | J11: Desembolsado | K11: 79700 | L11: URSULA LOPEZ | N11: 46239 | O11: Si | P11: Si
B12: LIMA | C12: 46234 | D12: Aprobada | E12: 46241 | F12: 46245 | G12: 71265965 | H12: ALEXIS RAUL VELASQUEZ HERNANDEZ | I12: PNP | J12: Desembolsado | K12: 72420 | L12: MERLY ROJAS | N12: 46246 | O12: Si | P12: No
B13: LIMA | C13: 46235 | D13: Aprobada | E13: 46238 | F13: 46246 | G13: 72951201 | H13: JOSUE ANDERSON NIETO PISCONTE | I13: PNP | J13: Desembolsado | K13: 45100 | L13: EVELYN GUTIERREZ | N13: 46247 | O13: Si | P13: Si
B14: LIMA | C14: 46241 | D14: Aprobada | E14: 46244 | F14: 46251 | G14: 45630165 | H14: HUGO MEDINA GUZMAN | I14: MGP | J14: Desembolsado | K14: 96600 | L14: MERLY ROJAS | N14: 46252 | O14: Si | P14: Si
B15: LIMA | C15: 46244 | D15: Aprobada | E15: 46245 | F15: 46247 | G15: 71819593 | H15: LEONARDO BRAYAN AMBROSIO SILVA | I15: PNP | J15: Desembolsado | K15: 41800 | L15: MERLY ROJAS | N15: 46247 | O15: Si | P15: Si
B16: LIMA | C16: 46230 | D16: Aprobada | E16: 46232 | F16: 46237 | G16: 47510821 | H16: CLEIFER BENITO MORE CARRION | I16: PNP | J16: Desembolsado | K16: 25000 | L16: MELINA LEYVA
B17: LIMA | C17: 46230 | D17: Aprobada | E17: 46233 | F17: 46238 | G17: 45026737 | H17: LILIANA SALAZAR PONCE | I17: DIRIS LIMA NORTE | J17: Desembolsado | K17: 10000 | L17: MELINA LEYVA
B18: TUMBES | C18: 46247 | D18: Aprobada | E18: 46251 | F18: 46253 | G18: 47552360 | H18: RICHARD MARX GALAN VILLASECA | I18: PNP | J18: Desembolsado | K18: 76000 | L18: EVELYN GUTIERREZ | N18: 46258
B19: LIMA | C19: 46249 | D19: Aprobada | E19: 46251 | F19: 46254 | G19: 76055611 | H19: CHAYANNE JHUSBER CAMPOS GAVILAN | I19: PNP | J19: Desembolsado | K19: 71900 | L19: MELINA LEYVA | N19: 46253
B20: LIMA | C20: 46253 | D20: Aprobada | E20: 46254 | F20: 46259 | G20: 48459291 | H20: ARNOLD DANIEL MENA TERNERO | I20: PNP | J20: Desembolsado | K20: 82400 | L20: MELINA LEYVA | N20: 46258
B21: LIMA | C21: 46249 | D21: Aprobada | E21: 46251 | F21: 46255 | G21: 76631630 | H21: JEREMY JESUS CAMARENA FLORIANO | I21: PNP | J21: Desembolsado | K21: 77250 | L21: MERLY ROJAS | N21: 46253
B22: HUARAZ | C22: 46253 | D22: Aprobada | E22: 46254 | F22: 46258 | G22: 47710721 | H22: MARVIN MISAEL ROQUE RODRIGUEZ | I22: PNP | J22: Desembolsado | K22: 83550 | L22: EVELYN GUTIERREZ | N22: 46266
B23: LIMA | C23: 46234 | D23: Aprobada | E23: 46237 | F23: 46247 | G23: 75474833 | H23: LUIS EDUARDO LLACSAHUACHE ALBERCA | I23: PNP | J23: Desembolsado | K23: 5000 | L23: MERLY ROJAS
B24: LIMA | C24: 46234 | D24: Aprobada | E24: 46238 | F24: 46241 | G24: 70336421 | H24: JOSE LUIS CAPUÑAY FARRO | I24: EP | J24: Desembolsado | K24: 90100 | L24: MERLY ROJAS
B25: LIMA | C25: 46239 | D25: Aprobada | E25: 46235 | F25: 46247 | G25: 47356489 | H25: JOSEPH RODOLFO RAMOS ACEBEDO | I25: PNP | J25: Desembolsado | K25: 81700 | L25: MERLY ROJAS
B26: HUANUCO | C26: 46258 | D26: Aprobada | E26: 46259 | F26: 46262 | G26: 75357867 | H26: EMERSON OMAR VICTORIO PARIONA | I26: MGP | J26: Desembolsado | K26: 84300 | L26: EVELYN GUTIERREZ | N26: 46266
B27: LIMA | C27: 46254 | D27: Rechazada | E27: 46255 | G27: 72201915 | H27: LENIN FERNANDO HERNANDEZ ZAPATA | I27: EP | J27: Pendiente De Remesa | K27: 69000 | L27: MELINA LEYVA
B28: IQUITOS | C28: 46255 | D28: Aprobada | E28: 46258 | F28: 46261 | G28: 73091410 | H28: ANGEL BRADLI FERREYRA PINEDO | I28: MGP | J28: Desembolsado | K28: 62150 | L28: EVELYN GUTIERREZ
B29: TACNA | C29: 46259 | D29: Aprobada | E29: 46261 | F29: 46266 | G29: 46559043 | H29: JORGE ANDRE LINARES PORTUGAL | I29: PNP | J29: Desembolsado | K29: 84200 | L29: EVELYN GUTIERREZ
B30: LIMA | G30: 76651507 | H30: KEITH PATRICK MARTINEZ RAMIREZ | I30: MGP | J30: Pendiente De Remesa | K30: 88800 | L30: EVELYN GUTIERREZ
B31: LIMA | C31: 46261 | D31: Aprobada | E31: 46261 | F31: 46265 | G31: 45978640 | H31: EVELYN SABRINA URBINA QUISPE | I31: EP | J31: Desembolsado | K31: 74500 | L31: MERLY ROJAS | N31: 46266
B32: LIMA | C32: 46261 | D32: Aprobada | E32: 46261 | F32: 46265 | G32: 40680333 | H32: VERONICA CRISTINA HUAMAN ALEGRE | I32: EP | J32: Desembolsado | K32: 79800 | L32: MERLY ROJAS | N32: 46266
B33: LIMA | C33: 46265 | D33: Enviada | G33: 45387374 | H33: MATT CHERIE DEL AGUILA RAMIREZ | I33: MGP | J33: Pendiente De Remesa | K33: 99000 | L33: EVELYN GUTIERREZ
B34: LIMA | C34: 46261 | D34: Aprobada | E34: 46262 | G34: 76670984 | H34: ANSONY MARCOS MUÑOZ TEMOCHE | I34: PNP | J34: Evaluación BCP | K34: 74600 | L34: MERLY ROJAS
B35: LIMA | C35: 46261 | D35: Rechazada | G35: 47869895 | H35: ROSSEMARY VILCA SANCHEZ | I35: PNP | J35: Pendiente De Remesa | K35: 78700 | L35: MELINA LEYVA
B36: LIMA | C36: 46262 | D36: Aprobada | E36: 46265 | F36: 46266 | G36: 43506674 | H36: SHENO CHRISTIAN MUNGI CASTILLON | I36: PNP | J36: Desembolsado | K36: 66050 | L36: MELINA LEYVA
B37: HUANCAYO | C37: 46266 | D37: Enviada | G37: 74854997 | H37: ROYER CAMILO ALVARADO OTEO | I37: PNP | J37: Pendiente De Documentar | K37: 34800 | L37: EVELYN GUTIERREZ
B38: LIMA | C38: 46266 | D38: Enviada | G38: 41843888 | H38: WENDY JACQUELINE VALENZUELA QUINTANA | I38: DIRIS LIMA NORTE | J38: Pendiente De Remesa | K38: 54400 | L38: MELINA LEYVA
B39: LIMA | C39: 46266 | D39: Enviada | G39: 72892973 | H39: MAURICIO RODRIGO UBILLUS LOZADA | I39: EP | J39: Pendiente De Remesa | K39: 30000 | L39: EVELYN GUTIERREZ
B40: LA MERCED | C40: 46267 | G40: 47893379 | H40: ELVIS KELVIN CARBAJAL HUAMAN | I40: PNP | J40: Pendiente De Remesa | K40: 76450 | L40: EVELYN GUTIERREZ
B41: YURIMAGUAS | G41: 42971795 | H41: BERTHA NOELIA REQUEJO SANCHEZ | I41: PNP | J41: Pendiente De Remesa | K41: 47250 | L41: EVELYN GUTIERREZ
B42: PLAZA DE VENTA | C42: 46267 | D42: Enviada | G42: 46134037 | H42: PEDRO LUIS MORAN HUAPAYA | I42: EP | K42: 105100 | L42: EVELYN GUTIERREZ

Sheet LUIS CHUSE
D3: LIMA 2 | E3: Meta | F3: Desembolsado | G3: Avance | H3: Pendiente De Documentar | I3: Pendiente De Remesa | J3: Pendiente De Backoffice | K3: Evaluación BCP | L3: Obs Backoffice | M3: Obs BCP | N3: Rechazado
D4: S/. | E4: 2000000 | F4: =SUMIFS(OPI_7[MAF NETO],OPI_7[ESTADO],"Desembolsado") -> 1041850 | G4: =F4-E4 -> -958150 | H4: =SUMIFS(OPI_7[MAF NETO],OPI_7[ESTADO],H$3) -> 0 | I4: =SUMIFS(OPI_7[MAF NETO],OPI_7[ESTADO],I$3) -> 84100 | J4: =SUMIFS(OPI_7[MAF NETO],OPI_7[ESTADO],J$3) -> 0 | K4: =SUMIFS(OPI_7[MAF NETO],OPI_7[ESTADO],K$3) -> 144900 | L4: =SUMIFS(OPI_7[MAF NETO],OPI_7[ESTADO],L$3) -> 0 | M4: =SUMIFS(OPI_7[MAF NETO],OPI_7[ESTADO],M$3) -> 0 | N4: =SUMIFS(OPI_7[MAF NETO],OPI_7[ESTADO],N$3) -> 0
D5: Q / % | E5: - | F5: =COUNTIFS(OPI_7[ESTADO],"Desembolsado") -> 17 | G5: =IFERROR(F4/E4,"") -> 0.520925 | H5: =COUNTIFS(OPI_7[ESTADO],H$3) -> 0 | I5: =COUNTIFS(OPI_7[ESTADO],I$3) -> 1 | J5: =COUNTIFS(OPI_7[ESTADO],J$3) -> 0 | K5: =COUNTIFS(OPI_7[ESTADO],K$3) -> 2 | L5: =COUNTIFS(OPI_7[ESTADO],L$3) -> 0 | M5: =COUNTIFS(OPI_7[ESTADO],M$3) -> 0 | N5: =COUNTIFS(OPI_7[ESTADO],N$3) -> 11
B9: PLAZA DE VENTA | C9: FECHA DE ENVIO DE REMESA | D9: ESTADO DE REMESA | E9: FECHA DE INGRESO | F9: FECHA DE DESEMBOLSO | G9: DOCUMENTO | H9: NOMBRES Y APELLIDOS | I9: CONVENIO | J9: ESTADO | K9: MAF NETO | L9: EJECUTIVO | M9: FILE ENVIADO A BANCO | N9: FECHA DE ENVIÓ CARTA PODER A BCP | O9: COMPRA DE DEUDA REALIZADA | P9: LIBERACIÓN | Q9: FEEDBACK
B10: LIMA | C10: 46228 | D10: Aprobada | E10: 46236 | G10: 74710347 | H10: DIOS SALVATIERRA FABRIZZIO PIERO | I10: PNP | J10: Rechazado | K10: 0 | L10: MERLY ROJAS | M10: Si
B11: LIMA | C11: 46228 | D11: Aprobada | G11: 44767826 | H11: POMA CUEVAS HELEN DIANA | I11: MGP | J11: Desembolsado | K11: 49000 | L11: KELLY SARMIENTO | M11: Si
B12: LIMA | C12: 46244 | D12: Aprobada | G12: 09835595 | H12: LUJAN FLORES CESAR MARTIN | I12: EP | J12: Rechazado | K12: 0 | L12: LEYDI MENDOZA
B13: LIMA | C13: 46230 | D13: Aprobada | G13: 47510821 | H13: MORE CARRION CLEIFER BENITO | I13: PNP | J13: Rechazado | K13: 0 | L13: MELINA LEYVA | M13: Si
B14: LIMA | C14: 46244 | D14: Aprobada | G14: 44198597 | H14: ESPINOZA NICOLAS SEGUNDO JESUS | I14: EP | J14: Rechazado | K14: 0 | L14: LEYDI MENDOZA
B15: LIMA | C15: 46230 | D15: Aprobada | G15: 45026737 | H15: SALAZAR PONCE LILIANA | I15: DIRIS LIMA NORTE | J15: Rechazado | K15: 0 | L15: MELINA LEYVA
B16: LIMA | C16: 46246 | D16: Aprobada | G16: 21559718 | H16: ALMEIDA DONAIRE ROBERTO SANTIAGO | I16: ESSALUD | J16: Desembolsado | K16: 121100 | L16: JOSSEF PFARE | M16: Si
B17: LIMA | C17: 46221 | D17: Aprobada | G17: 71919146 | H17: DANGLES GARCIA WILLY | I17: EP | J17: Desembolsado | K17: 79600 | L17: KELLY SARMIENTO | M17: Si
B18: LIMA | C18: 46234 | D18: Aprobada | E18: 46237 | G18: 75474833 | H18: LLACSAHUACHE ALBERCA LUIS EDUARDO | I18: PNP | J18: Rechazado | K18: 0 | L18: MERLY ROJAS
B19: LIMA | C19: 46234 | D19: Aprobada | E19: 46238 | G19: 70336421 | H19: CAPUÑAY FARRO JOSE LUIS | I19: EP | J19: Rechazado | K19: 0 | L19: MERLY ROJAS | M19: Si
B20: LIMA | C20: 46245 | D20: Rechazada | G20: 75713932 | H20: UWAK RODRIGUEZ FIORELA VIVIANA | I20: EP | J20: Rechazado | K20: 0 | L20: LUIS MENDOZA
B21: LIMA | C21: 46239 | D21: Aprobada | E21: 46235 | G21: 47356489 | H21: RAMOS ACEBEDO JOSEPH RODOLFO | I21: PNP | J21: Rechazado | K21: 0 | L21: MERLY ROJAS
B22: LIMA | C22: 46245 | D22: Aprobada | G22: 70947975 | H22: ESTRADA GARCIA DAVID ERGILIO | I22: MV | J22: Desembolsado | K22: 108000 | L22: JOSSEF PFARE
B23: LIMA | C23: 46235 | D23: Rechazada | G23: 45243293 | H23: ARCAYA VICENTE JAVIER ELADIO | I23: PNP | J23: Rechazado | K23: 0 | L23: CAROL URBISAGASTEGUI
B24: LIMA | C24: 46246 | D24: Aprobada | G24: 76420240 | H24: IBARRA SULCA DANIEL EDUARDO | I24: PNP | J24: Desembolsado | K24: 68100 | L24: KATTY ALLCA | M24: Si
B25: LIMA | C25: 46246 | D25: Aprobada | G25: 45606880 | H25: SURCO CCOHUA HONORATO | I25: DIRIS LIMA CENTRO | J25: Desembolsado | K25: 50000 | L25: JOSSEF PFARE
B26: LIMA | C26: 46246 | D26: Aprobada | G26: 42017270 | H26: MORALES VALDEZ CINTHIA LISBET | I26: ESSALUD | J26: Desembolsado | K26: 30000 | L26: JOSSEF PFARE
B27: LIMA | C27: 46246 | D27: Aprobada | G27: 47105330 | H27: MILLA MILLA YESENIA GISELA | I27: PNP | J27: Desembolsado | K27: 57000 | L27: KELLY SARMIENTO | M27: Si
B28: LIMA | C28: 46245 | D28: Aprobada | G28: 42309475 | H28: MENDOZA ATENCIO VERONICA MIRIAM | I28: DIRIS LIMA CENTRO | J28: Desembolsado | K28: 20000 | L28: KELLY SARMIENTO
B29: LIMA | C29: 46251 | D29: Aprobada | G29: 42843597 | H29: CIENFUEGOS VIERA WILLDER ALFONSO | I29: PNP | J29: Desembolsado | K29: 20000 | L29: CAROL URBISAGASTEGUI | O29: No
B30: LIMA | C30: 46254 | D30: Aprobada | G30: 45188824 | H30: RAMOS PACORA SULLY YING | I30: EP | J30: Desembolsado | K30: 60000 | L30: LUIS MENDOZA
B31: LIMA | C31: 46254 | D31: Aprobada | F31: SETIEMBRE | G31: 60379216 | H31: LEON GONGORA MARI CRUZ | I31: EP | J31: Evaluación BCP | K31: 86400 | L31: KELLY SARMIENTO
B32: LIMA | C32: 46254 | D32: Rechazada | G32: 43592506 | H32: MICHAEL HERBIS ESCOBAR VELASQUEZ | I32: EP | J32: Rechazado | K32: 0 | L32: LEYDI MENDOZA
B33: LIMA | C33: 46254 | D33: Aprobada | G33: 40238253 | H33: CUTIPA GOMEZ CAROLINA INES | I33: ESSALUD | J33: Desembolsado | K33: 33300 | L33: JOSSEF PFARE
B34: LIMA | C34: 46254 | D34: Aprobada | F34: SETIEMBRE | G34: 75334253 | H34: FERNANDO RAUL NARVAEZ MEDINA | I34: MGP | J34: Desembolsado | K34: 60300 | L34: KELLY SARMIENTO
B35: LIMA | C35: 46259 | D35: Aprobada | G35: 75996537 | H35: NIZAMA GASPAR DIANA HILLARY DNI: 75996537 | I35: EP | J35: Desembolsado | K35: 25150 | L35: KELLY SARMIENTO
B36: LIMA | C36: 46259 | D36: Aprobada | G36: 47514265 | H36: JARAMILLO DUEÑAS NIKSON ROSNEL | I36: MGP | J36: Desembolsado | K36: 86100 | L36: KELLY SARMIENTO | M36: Si
B37: LIMA | C37: 46259 | D37: Aprobada | F37: SETIEMBRE | G37: 76694259 | H37: ALVARO DEL AGUILA SANGAMA | I37: MGP | J37: Desembolsado | K37: 92700 | L37: KELLY SARMIENTO
B38: LIMA | C38: 46259 | D38: Aprobada | G38: 74648868 | H38: SANCHEZ ROMERO LUIS ANGEL | I38: MGP | J38: Desembolsado | K38: 81500 | L38: KELLY SARMIENTO | M38: Si
B39: LIMA | C39: 46262 | D39: Aprobada | F39: SETIEMBRE | G39: 09497204 | H39: CARLOS RAFAEL TIPULA | I39: PNP | J39: Evaluación BCP | K39: 58500 | L39: CARLOS ESPINOZA
B40: LIMA | C40: 46265 | D40: Enviada | F40: SETIEMBRE | G40: 70339397 | H40: SOL JHOANA MADELINE MESIAS GONZALES | I40: EP | J40: Pendiente De Remesa | K40: 84100 | L40: LEYDI MENDOZA
B41: LIMA | C41: 46266 | D41: Aprobada | F41: SETIEMBRE | G41: 45608713 | H41: EFRAIN ENRIQUEZ SALINAS -45608713

Sheet ANA ALIAGA
D3: LIMA 1 | E3: Meta | F3: Desembolsado | G3: Avance | H3: Pendiente De Documentar | I3: Pendiente De Remesa | J3: Pendiente De Backoffice | K3: Evaluación BCP | L3: Obs Backoffice | M3: Obs BCP | N3: Rechazado
D4: S/. | E4: 1000000 | F4: =SUMIFS(OPI_20[MAF NETO],OPI_20[ESTADO],"Desembolsado") -> 736373 | G4: =F4-E4 -> -263627 | H4: =SUMIFS(OPI_20[MAF NETO],OPI_20[ESTADO],H$3) -> 0 | I4: =SUMIFS(OPI_20[MAF NETO],OPI_20[ESTADO],I$3) -> 0 | J4: =SUMIFS(OPI_20[MAF NETO],OPI_20[ESTADO],J$3) -> 0 | K4: =SUMIFS(OPI_20[MAF NETO],OPI_20[ESTADO],K$3) -> 0 | L4: =SUMIFS(OPI_20[MAF NETO],OPI_20[ESTADO],L$3) -> 0 | M4: =SUMIFS(OPI_20[MAF NETO],OPI_20[ESTADO],M$3) -> 0 | N4: =SUMIFS(OPI_20[MAF NETO],OPI_20[ESTADO],N$3) -> 0
D5: Q / % | E5: - | F5: =COUNTIFS(OPI_20[ESTADO],"Desembolsado") -> 9 | G5: =IFERROR(F4/E4,"") -> 0.736373 | H5: =COUNTIFS(OPI_20[ESTADO],H$3) -> 0 | I5: =COUNTIFS(OPI_20[ESTADO],I$3) -> 0 | J5: =COUNTIFS(OPI_20[ESTADO],J$3) -> 0 | K5: =COUNTIFS(OPI_20[ESTADO],K$3) -> 0 | L5: =COUNTIFS(OPI_20[ESTADO],L$3) -> 0 | M5: =COUNTIFS(OPI_20[ESTADO],M$3) -> 0 | N5: =COUNTIFS(OPI_20[ESTADO],N$3) -> 5
B9: PLAZA DE VENTA | C9: FECHA DE ENVIO DE REMESA | D9: ESTADO DE REMESA | E9: FECHA DE INGRESO | F9: FECHA DE DESEMBOLSO | G9: DOCUMENTO | H9: NOMBRES Y APELLIDOS | I9: CONVENIO | J9: ESTADO | K9: MAF NETO | L9: EJECUTIVO | M9: FILE ENVIADO A BANCO | N9: FECHA DE ENVIÓ CARTA PODER A BCP | O9: COMPRA DE DEUDA REALIZADA | P9: LIBERACIÓN | Q9: FEEDBACK
B10: LIMA | C10: 46246 | D10: Aprobada | G10: 40158154 | H10: ROJAS BAUTISTA ANDERSON | I10: EP | J10: Desembolsado | K10: 152400 | L10: CESAR MANUYAMA | N10: CARLA GAMARRA
C11: 46246 | D11: Aprobada | G11: 42155801 | H11: VASQUEZ BUITRON,ROCIO MARIA EUGENIA | I11: PNP | J11: Rechazado | K11: 0 | L11: CESAR MANUYAMA
C12: 46248 | D12: Aprobada | G12: 42250485 | H12: PURIZACA VILCHEZ JUAN GUILLERMO | I12: MINJUS | J12: Rechazado | K12: 0 | L12: CESAR MANUYAMA
C13: 46248 | D13: Aprobada | G13: 45071771 | H13: VIDAL ADRIANZEN ALEXIS ANTONIO | I13: MINJUS | J13: Desembolsado | K13: 108150 | L13: CESAR MANUYAMA | N13: MAX DUEÑAS
C14: 46249 | D14: Aprobada | G14: 75157780 | H14: CASTRO TUCTO JHON ALFREDO | I14: EP | J14: Desembolsado | K14: 85600 | L14: CESAR MANUYAMA
C15: 46249 | D15: Aprobada | G15: 70336859 | H15: BRYAN ERICK FRANCO CCALLO | I15: EP | J15: Desembolsado | K15: 107900 | L15: CESAR MANUYAMA
