Workbook

Sheet CONSOLIDADO
A1: ,
B2: Tablas de Gestión:
B4: SUPERVISOR | C4: ZONA | D4: TOTAL DESEMBOLSO | E4: Q DESEMBOLSO | F4: EVALUACION BCP | G4: PENDIENTE DE BACK | H4: PENDIENTE DE REMESA | I4: PENDIENTE DE DOCUMENTAR | J4: META OBJETIVO | K4: AVANCE | L4: Q EVALUACION BCP | M4: Q PENDIENTE DE BACK
B5: JIMMY COLLAZOS | C5: ='JIMMY COLLAZOS'!D3 -> TARAPOTO | D5: ='JIMMY COLLAZOS'!$F$4 -> 331600 | E5: ='JIMMY COLLAZOS'!$F$5 -> 6 | F5: ='JIMMY COLLAZOS'!$K$4 -> 73000 | G5: ='JIMMY COLLAZOS'!$J$4 -> 0 | H5: ='JIMMY COLLAZOS'!$I$4 -> 0 | I5: ='JIMMY COLLAZOS'!$H$4 -> 0 | J5: ='JIMMY COLLAZOS'!E4 -> 800000 | K5: =D5/J5 -> 0.4145 | L5: ='JIMMY COLLAZOS'!$K$5 -> 1 | M5: ='JIMMY COLLAZOS'!$J$5 -> 0
B6: ALEXANDRA GUZMAN | C6: ='ALEXANDRA GUZMAN'!D3 -> PIURA | D6: ='ALEXANDRA GUZMAN'!$F$4 -> 0 | E6: ='ALEXANDRA GUZMAN'!$F$5 -> 0 | F6: ='ALEXANDRA GUZMAN'!$K$4 -> 0 | G6: ='ALEXANDRA GUZMAN'!$J$4 -> 0 | H6: ='ALEXANDRA GUZMAN'!$I$4 -> 0 | I6: ='ALEXANDRA GUZMAN'!$H$4 -> 0 | J6: 1000000 | K6: =D6/J6 -> 0 | L6: ='ALEXANDRA GUZMAN'!$K$5 -> 0 | M6: ='ALEXANDRA GUZMAN'!$J$5 -> 0
B7: AMALIA QUINDE | C7: ='AMALIA QUINDE'!D3 -> PIURA | D7: ='AMALIA QUINDE'!$F$4 -> 162000 | E7: ='AMALIA QUINDE'!$F$5 -> 2 | F7: ='AMALIA QUINDE'!$K$4 -> 81500 | G7: ='AMALIA QUINDE'!$J$4 -> 0 | H7: ='AMALIA QUINDE'!$I$4 -> 0 | I7: ='AMALIA QUINDE'!$H$4 -> 0 | J7: 1000000 | K7: =D7/J7 -> 0.162 | L7: ='AMALIA QUINDE'!$K$5 -> 1 | M7: ='AMALIA QUINDE'!$J$5 -> 0
B8: WENDY IPANAQUÉ | C8: ='WENDY IPANEQUE'!D3 -> PIURA | D8: ='WENDY IPANEQUE'!$F$4 -> 526400 | E8: ='WENDY IPANEQUE'!$F$5 -> 8 | F8: ='WENDY IPANEQUE'!$K$4 -> 40000 | G8: ='WENDY IPANEQUE'!$J$4 -> 0 | H8: ='WENDY IPANEQUE'!$I$4 -> 0 | I8: ='WENDY IPANEQUE'!$H$4 -> 58000 | J8: 1000000 | K8: =D8/J8 -> 0.5264 | L8: ='WENDY IPANEQUE'!$K$5 -> 1 | M8: ='WENDY IPANEQUE'!$J$5 -> 0
B9: ANGIE SILVERA | C9: ='ANGIE SILVERA'!D3 -> LIMA | D9: ='ANGIE SILVERA'!$F$4 -> 2726520 | E9: ='ANGIE SILVERA'!$F$5 -> 36 | F9: ='ANGIE SILVERA'!$K$4 -> 0 | G9: ='ANGIE SILVERA'!$J$4 -> 0 | H9: ='ANGIE SILVERA'!$I$4 -> 0 | I9: ='ANGIE SILVERA'!$H$4 -> 0 | J9: ='ANGIE SILVERA'!E4 -> 2000000 | K9: =D9/J9 -> 1.36326 | L9: ='ANGIE SILVERA'!$K$5 -> 0 | M9: ='ANGIE SILVERA'!$J$5 -> 0
B10: KENNY MORALES | C10: ='KENNY MORALES'!D3 -> LIMA | D10: ='KENNY MORALES'!$F$4 -> 532500 | E10: ='KENNY MORALES'!$F$5 -> 7 | F10: ='KENNY MORALES'!$K$4 -> 354000 | G10: ='KENNY MORALES'!$J$4 -> 0 | H10: ='KENNY MORALES'!$I$4 -> 0 | I10: ='KENNY MORALES'!$H$4 -> 0 | J10: ='KENNY MORALES'!E4 -> 1000000 | K10: =D10/J10 -> 0.5325 | L10: ='KENNY MORALES'!$K$5 -> 5 | M10: ='KENNY MORALES'!$J$5 -> 0
B11: LUIS CHUSE | C11: ='LUIS CHUSE'!D3 -> LIMA | D11: ='LUIS CHUSE'!$F$4 -> 2216250 | E11: ='LUIS CHUSE'!$F$5 -> 33 | F11: ='LUIS CHUSE'!$K$4 -> 105700 | G11: ='LUIS CHUSE'!$J$4 -> 0 | H11: ='LUIS CHUSE'!$I$4 -> 0 | I11: ='LUIS CHUSE'!$H$4 -> 46000 | J11: ='LUIS CHUSE'!E4 -> 2000000 | K11: =D11/J11 -> 1.108125 | L11: ='LUIS CHUSE'!$K$5 -> 2 | M11: ='LUIS CHUSE'!$J$5 -> 0
B12: MARIELLA PAÑAHUA | C12: ='MARIELLA PAÑAHUA'!D3 -> AYACUCHO | D12: ='MARIELLA PAÑAHUA'!$F$4 -> 845150 | E12: ='MARIELLA PAÑAHUA'!$F$5 -> 13 | F12: ='MARIELLA PAÑAHUA'!$K$4 -> 225800 | G12: ='MARIELLA PAÑAHUA'!$J$4 -> 70000 | H12: ='MARIELLA PAÑAHUA'!$I$4 -> 0 | I12: ='MARIELLA PAÑAHUA'!$H$4 -> 0 | J12: ='MARIELLA PAÑAHUA'!E4 -> 800000 | K12: =D12/J12 -> 1.0564375 | L12: ='MARIELLA PAÑAHUA'!$K$5 -> 3 | M12: ='MARIELLA PAÑAHUA'!$J$5 -> 1
B13: WINNIE ESCALANTE | C13: ='WINNIE ESCALANTE'!D3 -> LIMA | D13: ='WINNIE ESCALANTE'!$F$4 -> 2030440 | E13: ='WINNIE ESCALANTE'!$F$5 -> 33 | F13: ='WINNIE ESCALANTE'!$K$4 -> 65000 | G13: ='WINNIE ESCALANTE'!$J$4 -> 0 | H13: ='WINNIE ESCALANTE'!$I$4 -> 0 | I13: ='WINNIE ESCALANTE'!$H$4 -> 0 | J13: ='WINNIE ESCALANTE'!E4 -> 2000000 | K13: =D13/J13 -> 1.01522 | L13: ='WINNIE ESCALANTE'!$K$5 -> 1 | M13: ='WINNIE ESCALANTE'!$J$5 -> 0
B14: JOSE LUIS QUINTEROS | C14: LIMA | D14: ='JOSE LUIS QUINTEROS'!$F$4 -> 721466.1 | E14: ='JOSE LUIS QUINTEROS'!$F$5 -> 10 | F14: ='JOSE LUIS QUINTEROS'!$K$4 -> 93800 | G14: ='JOSE LUIS QUINTEROS'!$J$4 -> 72900 | H14: ='JOSE LUIS QUINTEROS'!$I$4 -> 162500 | I14: ='JOSE LUIS QUINTEROS'!$H$4 -> 0 | J14: ='JOSE LUIS QUINTEROS'!E4 -> 1000000 | K14: =D14/J14 -> 0.7214661 | L14: ='JOSE LUIS QUINTEROS'!$K$5 -> 1 | M14: ='JOSE LUIS QUINTEROS'!$J$5 -> 1
B15: NATHALIE ARANDA | C15: LIMA | D15: ='NATHALIE ARANDA'!$F$4 -> 181100 | E15: ='NATHALIE ARANDA'!$F$5 -> 2 | F15: ='NATHALIE ARANDA'!$K$4 -> 233200 | G15: ='NATHALIE ARANDA'!$J$4 -> 0 | H15: ='NATHALIE ARANDA'!$I$4 -> 105900 | I15: ='NATHALIE ARANDA'!$H$4 -> 45100 | J15: ='NATHALIE ARANDA'!E4 -> 500000 | K15: =D15/J15 -> 0.3622 | L15: ='NATHALIE ARANDA'!$K$5 -> 3 | M15: ='NATHALIE ARANDA'!$J$5 -> 0
B16: JHON ZAMORA | C16: ='JHON ZAMORA'!D3 -> CHICLAYO | D16: ='JHON ZAMORA'!$F$4 -> 864480 | E16: ='JHON ZAMORA'!$F$5 -> 12 | F16: ='JHON ZAMORA'!$K$4 -> 198100 | G16: ='JHON ZAMORA'!$J$4 -> 0 | H16: ='JHON ZAMORA'!$I$4 -> 0 | I16: ='JHON ZAMORA'!$H$4 -> 0 | J16: 1000000 | K16: =D16/J16 -> 0.86448 | L16: ='JHON ZAMORA'!$K$5 -> 3 | M16: ='JHON ZAMORA'!$J$5 -> 0
B17: OMAR MINAYA | C17: ='OMAR MINAYA'!D3 -> CHICLAYO | D17: ='OMAR MINAYA'!$F$4 -> 875160 | E17: ='OMAR MINAYA'!$F$5 -> 13 | F17: ='OMAR MINAYA'!$K$4 -> 175250 | G17: ='OMAR MINAYA'!$J$4 -> 0 | H17: ='OMAR MINAYA'!$I$4 -> 0 | I17: ='OMAR MINAYA'!$H$4 -> 0 | J17: 1000000 | K17: =D17/J17 -> 0.87516 | L17: ='OMAR MINAYA'!$K$5 -> 2 | M17: ='OMAR MINAYA'!$J$5 -> 0
B18: NAHOMI DIAZ | C18: ='NAHOMI DIAZ'!D3 -> CHICLAYO | D18: ='NAHOMI DIAZ'!$F$4 -> 1781650 | E18: ='NAHOMI DIAZ'!$F$5 -> 24 | F18: ='NAHOMI DIAZ'!$K$4 -> 244700 | G18: ='NAHOMI DIAZ'!$J$4 -> 0 | H18: ='NAHOMI DIAZ'!$I$4 -> 408750 | I18: ='NAHOMI DIAZ'!$H$4 -> 79200 | J18: 1000000 | K18: =D18/J18 -> 1.78165 | L18: ='NAHOMI DIAZ'!$K$5 -> 3 | M18: ='NAHOMI DIAZ'!$J$5 -> 0
B19: VIOLETA LLERENA | C19: ='VIOLETA LLERENA'!D3 -> AREQUIPA | D19: ='VIOLETA LLERENA'!$F$4 -> 650700 | E19: ='VIOLETA LLERENA'!$F$5 -> 9 | F19: ='VIOLETA LLERENA'!$K$4 -> 0 | G19: ='VIOLETA LLERENA'!$J$4 -> 0 | H19: ='VIOLETA LLERENA'!$I$4 -> 0 | I19: ='VIOLETA LLERENA'!$H$4 -> 0 | J19: 1000000 | K19: =D19/J19 -> 0.6507 | L19: ='VIOLETA LLERENA'!$K$5 -> 0 | M19: ='VIOLETA LLERENA'!$J$5 -> 0
B20: MILUSKA LINARES | C20: TRUJILLO | D20: ='MILUSKA LINARES'!$F$4 -> 0 | E20: ='MILUSKA LINARES'!$F$5 -> 0 | F20: ='MILUSKA LINARES'!$K$4 -> 0 | G20: ='MILUSKA LINARES'!$J$4 -> 0 | H20: ='MILUSKA LINARES'!$I$4 -> 0 | I20: ='MILUSKA LINARES'!$H$4 -> 0 | J20: 1000000 | K20: =D20/J20 -> 0 | L20: ='MILUSKA LINARES'!$K$5 -> 0 | M20: ='MILUSKA LINARES'!$J$5 -> 0
B21: THALIA SALOME | C21: HUANCAYO | D21: ='THALIA SALOME'!$F$4 -> 52000 | E21: ='THALIA SALOME'!$F$5 -> 1 | F21: ='THALIA SALOME'!$K$4 -> 0 | G21: ='THALIA SALOME'!$J$4 -> 0 | H21: ='THALIA SALOME'!$I$4 -> 0 | I21: ='THALIA SALOME'!$H$4 -> 0 | J21: 1000000 | K21: =D21/J21 -> 0.052 | L21: ='THALIA SALOME'!$K$5 -> 0 | M21: ='THALIA SALOME'!$J$5 -> 0
B22: TOTAL | D22: =SUM(D5:D21) -> 14497416 | E22: =SUM(E5:E21) -> 209 | F22: =SUM(F5:F21) -> 1890050 | G22: =SUM(G5:G21) -> 142900 | H22: =SUM(H5:H21) -> 677150 | I22: =SUM(I5:I21) -> 228300 | J22: =SUM(J5:J21) -> 19100000 | K22: =D22/J22 -> 0.75902702 | L22: =SUM(L5:L21) -> 26 | M22: =SUM(M5:M21) -> 2
B25: PLAZA | D25: TOTAL DESEMBOLSO | E25: Q DESEMBOLSO | F25: EVALUACION BCP | G25: PENDIENTE DE BACK | H25: PENDIENTE DE REMESA | I25: PENDIENTE DE DOCUMENTAR | J25: META OBJETIVO | K25: AVANCE | L25: Q EVALUACION BCP | M25: Q PENDIENTE DE BACK
B26: LIMA | D26: =SUMIFS(D$5:D$21,$C$5:$C$21,$B26) -> 8408276.1 | E26: =SUMIFS(E$5:E$21,$C$5:$C$21,$B26) -> 121 | F26: =SUMIFS(F$5:F$21,$C$5:$C$21,$B26) -> 851700 | G26: =SUMIFS(G$5:G$21,$C$5:$C$21,$B26) -> 72900 | H26: =SUMIFS(H$5:H$21,$C$5:$C$21,$B26) -> 268400 | I26: =SUMIFS(I$5:I$21,$C$5:$C$21,$B26) -> 91100 | J26: =SUMIFS(J$5:J$21,$C$5:$C$21,$B26) -> 8500000 | K26: =D26/J26 -> 0.98920895 | L26: =SUMIFS(L$5:L$21,$C$5:$C$21,$B26) -> 12 | M26: =SUMIFS(M$5:M$21,$C$5:$C$21,$B26) -> 1
B27: NORTE | D27: =SUMIFS(D5:D21,$C$5:$C$21,"CHICLAYO")+SUMIFS(D5:D21,$C$5:$C$21,"TRUJILLO")+SUMIFS(D5:D21,$C$5:$C$21,"PIURA") -> 4209690 | E27: =SUMIFS(E5:E21,$C$5:$C$21,"CHICLAYO")+SUMIFS(E5:E21,$C$5:$C$21,"TRUJILLO")+SUMIFS(E5:E21,$C$5:$C$21,"PIURA") -> 59 | F27: =SUMIFS(F5:F21,$C$5:$C$21,"CHICLAYO")+SUMIFS(F5:F21,$C$5:$C$21,"TRUJILLO")+SUMIFS(F5:F21,$C$5:$C$21,"PIURA") -> 739550 | G27: =SUMIFS(G5:G21,$C$5:$C$21,"CHICLAYO")+SUMIFS(G5:G21,$C$5:$C$21,"TRUJILLO")+SUMIFS(G5:G21,$C$5:$C$21,"PIURA") -> 0 | H27: =SUMIFS(H5:H21,$C$5:$C$21,"CHICLAYO")+SUMIFS(H5:H21,$C$5:$C$21,"TRUJILLO")+SUMIFS(H5:H21,$C$5:$C$21,"PIURA") -> 408750 | I27: =SUMIFS(I5:I21,$C$5:$C$21,"CHICLAYO")+SUMIFS(I5:I21,$C$5:$C$21,"TRUJILLO")+SUMIFS(I5:I21,$C$5:$C$21,"PIURA") -> 137200 | J27: =SUMIFS(J5:J21,$C$5:$C$21,"CHICLAYO")+SUMIFS(J5:J21,$C$5:$C$21,"TRUJILLO")+SUMIFS(J5:J21,$C$5:$C$21,"PIURA") -> 7000000 | K27: =D27/J27 -> 0.60138429 | L27: =SUMIFS(L5:L21,$C$5:$C$21,"CHICLAYO")+SUMIFS(L5:L21,$C$5:$C$21,"TRUJILLO")+SUMIFS(L5:L21,$C$5:$C$21,"PIURA") -> 10 | M27: =SUMIFS(M5:M21,$C$5:$C$21,"CHICLAYO")+SUMIFS(M5:M21,$C$5:$C$21,"TRUJILLO")+SUMIFS(M5:M21,$C$5:$C$21,"PIURA") -> 0
B28: TARAPOTO | D28: =SUMIFS(D5:D21,$C$5:$C$21,"TARAPOTO") -> 331600 | E28: =SUMIFS(E5:E21,$C$5:$C$21,"TARAPOTO") -> 6 | F28: =SUMIFS(F5:F21,$C$5:$C$21,"TARAPOTO") -> 73000 | G28: =SUMIFS(G5:G21,$C$5:$C$21,"TARAPOTO") -> 0 | H28: =SUMIFS(H5:H21,$C$5:$C$21,"TARAPOTO") -> 0 | I28: =SUMIFS(I5:I21,$C$5:$C$21,"TARAPOTO") -> 0 | J28: =SUMIFS(J5:J21,$C$5:$C$21,"TARAPOTO") -> 800000 | K28: =D28/J28 -> 0.4145 | L28: =SUMIFS(L5:L21,$C$5:$C$21,"TARAPOTO") -> 1 | M28: =SUMIFS(M5:M21,$C$5:$C$21,"TARAPOTO") -> 0
B29: AYACUCHO | D29: =SUMIFS(D5:D21,$C$5:$C$21,"AYACUCHO") -> 845150 | E29: =SUMIFS(E5:E21,$C$5:$C$21,"AYACUCHO") -> 13 | F29: =SUMIFS(F5:F21,$C$5:$C$21,"AYACUCHO") -> 225800 | G29: =SUMIFS(G5:G21,$C$5:$C$21,"AYACUCHO") -> 70000 | H29: =SUMIFS(H5:H21,$C$5:$C$21,"AYACUCHO") -> 0 | I29: =SUMIFS(I5:I21,$C$5:$C$21,"AYACUCHO") -> 0 | J29: =SUMIFS(J5:J21,$C$5:$C$21,"AYACUCHO") -> 800000 | K29: =D29/J29 -> 1.0564375 | L29: =SUMIFS(L5:L21,$C$5:$C$21,"AYACUCHO") -> 3 | M29: =SUMIFS(M5:M21,$C$5:$C$21,"AYACUCHO") -> 1
B30: AREQUIPA | D30: =SUMIFS(D5:D21,$C$5:$C$21,"AREQUIPA") -> 650700 | E30: =SUMIFS(E5:E21,$C$5:$C$21,"AREQUIPA") -> 9 | F30: =SUMIFS(F5:F21,$C$5:$C$21,"AREQUIPA") -> 0 | G30: =SUMIFS(G5:G21,$C$5:$C$21,"AREQUIPA") -> 0 | H30: =SUMIFS(H5:H21,$C$5:$C$21,"AREQUIPA") -> 0 | I30: =SUMIFS(I5:I21,$C$5:$C$21,"AREQUIPA") -> 0 | J30: =SUMIFS(J5:J21,$C$5:$C$21,"AREQUIPA") -> 1000000 | K30: =D30/J30 -> 0.6507 | L30: 0.0 | M30: =SUMIFS(M6:M22,$C$5:$C$21,"TARAPOTO") -> 0
B31: TOTAL | D31: =SUM(D26:D30) -> 14445416 | E31: =SUM(E26:E30) -> 208 | F31: =SUM(F26:F30) -> 1890050 | G31: =SUM(G26:G30) -> 142900 | H31: =SUM(H26:H30) -> 677150 | I31: =SUM(I26:I30) -> 228300 | J31: =SUM(J26:J30) -> 18100000 | K31: =D31/J31 -> 0.79808929 | L31: =SUM(L26:L30) -> 26 | M31: =SUM(M26:M30) -> 2

Sheet NAHOMI DIAZ
D3: CHICLAYO | E3: Meta | F3: Desembolsado | G3: Avance | H3: Pendiente De Documentar | I3: Pendiente De Remesa | J3: Pendiente De Backoffice | K3: Evaluación BCP | L3: Obs Backoffice | M3: Obs BCP | N3: Rechazado
D4: S/. | E4: 1000000 | F4: =SUMIFS(OPI_11[MAF NETO],OPI_11[ESTADO],"Desembolsado") -> 1781650 | G4: =F4-E4 -> 781650 | H4: =SUMIFS(OPI_11[MAF NETO],OPI_11[ESTADO],H$3) -> 79200 | I4: =SUMIFS(OPI_11[MAF NETO],OPI_11[ESTADO],I$3) -> 408750 | J4: =SUMIFS(OPI_11[MAF NETO],OPI_11[ESTADO],J$3) -> 0 | K4: =SUMIFS(OPI_11[MAF NETO],OPI_11[ESTADO],K$3) -> 244700 | L4: =SUMIFS(OPI_11[MAF NETO],OPI_11[ESTADO],L$3) -> 0 | M4: =SUMIFS(OPI_11[MAF NETO],OPI_11[ESTADO],M$3) -> 0 | N4: =SUMIFS(OPI_11[MAF NETO],OPI_11[ESTADO],N$3) -> 699700
D5: Q / % | E5: - | F5: =COUNTIFS(OPI_11[ESTADO],"Desembolsado") -> 24 | G5: =IFERROR(F4/E4,"") -> 1.78165 | H5: =COUNTIFS(OPI_11[ESTADO],H$3) -> 1 | I5: =COUNTIFS(OPI_11[ESTADO],I$3) -> 5 | J5: =COUNTIFS(OPI_11[ESTADO],J$3) -> 0 | K5: =COUNTIFS(OPI_11[ESTADO],K$3) -> 3 | L5: =COUNTIFS(OPI_11[ESTADO],L$3) -> 0 | M5: =COUNTIFS(OPI_11[ESTADO],M$3) -> 0 | N5: =COUNTIFS(OPI_11[ESTADO],N$3) -> 10
B9: PLAZA DE VENTA | C9: FECHA DE ENVIO DE REMESA | D9: ESTADO DE REMESA | E9: FECHA DE INGRESO | F9: FECHA DE DESEMBOLSO | G9: DOCUMENTO | H9: NOMBRES Y APELLIDOS | I9: CONVENIO | J9: ESTADO | K9: MAF NETO | L9: EJECUTIVO | M9: FILE ENVIADO A BANCO | N9: FECHA DE ENVIÓ CARTA PODER A BCP | O9: COMPRA DE DEUDA REALIZADA | P9: LIBERACIÓN | Q9: FEEDBACK
C10: 46187 | D10: Rechazada | G10: 45820431 | H10: TINTAYA TINTAYA NETO | I10: PNP | J10: Rechazado | K10: 82250 | L10: AZUCENA BARBA | Q10: DESITIO
B11: LAMBAYEQUE | C11: 46205 | D11: Aprobada | E11: 46214 | F11: 46218 | G11: 48355262 | H11: ASTONITAS GAMONAL YESSICA RAQUEL | I11: ESSALUD | J11: Desembolsado | K11: 28600 | L11: EYLIN VELASCO
B12: LIMA | C12: 46205 | D12: Rechazada | E12: ,,, | F12: ,,, | G12: 70540043 | H12: LAZO SANCHEZ GUSTAVO JESUS | I12: EJERCITO | J12: Rechazado | K12: 20000 | L12: EYLIN VELASCO | Q12: DESITIO
C13: 46210 | D13: Aprobada | E13: 46212 | F13: 46213 | G13: 76477136 | H13: HUAMAN LAZO NIXON JHAN PIERRE | I13: PNP | J13: Desembolsado | K13: 82200 | L13: EYLIN VELASCO
C14: 46211 | D14: Aprobada | G14: 48410510 | H14: DELGADO SAMAME LUIS ALEXANDER | I14: PNP | J14: Desembolsado | K14: 81700 | L14: EYLIN VELASCO | Q14: NO APRUEBAN AN AUN
C15: 46211 | D15: Aprobada | E15: 46216 | F15: 46218 | G15: 76176312 | H15: CHECA TEJADA FRANKLYN ALEXIS | I15: PNP | J15: Desembolsado | K15: 80200 | L15: EYLIN VELASCO
C16: 46211 | D16: Aprobada | E16: 46216 | F16: 46217 | G16: 46548057 | H16: CORDOVA BERMEO LEYTON | I16: PNP | J16: Desembolsado | K16: 63000 | L16: EYLIN VELASCO
C17: 46211 | D17: Aprobada | E17: 46217 | F17: 46218 | G17: 44898565 | H17: GUARDIA SANTI OSCAR GUSTAVO | I17: PNP | J17: Desembolsado | K17: 87300 | L17: EYLIN VELASCO
C18: 46212 | D18: Aprobada | E18: 46214 | F18: 46217 | G18: 47294911 | H18: VILCA FLORES FREDY | I18: PNP | J18: Desembolsado | K18: 72400 | L18: EYLIN VELASCO
C19: 46212 | D19: Aprobada | E19: 46217 | F19: 46218 | G19: 48113624 | H19: ACOSTA CRUZADO FRANKLIN ABEL | I19: PNP | J19: Desembolsado | K19: 81700 | L19: EYLIN VELASCO
C20: 46213 | D20: Aprobada | E20: 46217 | G20: 73040397 | H20: FLORES ORDOÑEZ FELIX JAVIER | I20: PNP | J20: Desembolsado | K20: 84300 | L20: EYLIN VELASCO | M20: Si
C21: 46214 | D21: Aprobada | G21: 76962343 | H21: ZEÑA SANTOS ANTONY CONCE | I21: EJERCITO | J21: Desembolsado | K21: 62000 | L21: EYLIN VELASCO
C22: 46214 | D22: Aprobada | E22: 46217 | F22: 46218 | G22: 72931118 | H22: FERNANDEZ CADENILLAS,ANDY JOSEPTH | I22: PNP | J22: Desembolsado | K22: 64500 | L22: EYLIN VELASCO | M22: Si
C23: 46187 | D23: Aprobada | G23: 76287652 | H23: CALLIRGOS MIRES ELIAS ISAI | I23: PNP | J23: Desembolsado | K23: 62800 | L23: EYLIN VELASCO | Q23: EX CIP CADUCADO
C24: 46187 | D24: Aprobada | G24: 70587217 | H24: LIBERATO SANTIAGO JOSE ARMANDO | I24: PNP | J24: Desembolsado | K24: 71900 | L24: EYLIN VELASCO | Q24: ESPERANDO DESISTIMINTO
C25: 46218 | D25: Rechazada | G25: 73630681 | H25: HIDALGO GOMEZ WIMER ARTURO | I25: PNP | J25: Rechazado | K25: 77700 | L25: EYLIN VELASCO | Q25: DESEMBOLSO EN INTERBANK
C26: 46219 | D26: Enviada | G26: 47969819 | H26: ROJAS GUEVARA SHYMY YONATAN | I26: PNP | J26: Desembolsado | K26: 82500 | L26: EYLIN VELASCO
C27: 46586 | D27: Aprobada | G27: 48935859 | H27: DINAMAQUE TOCTO JHAN JHORDIN | I27: PNP | J27: Desembolsado | K27: 0 | L27: EYLIN VELASCO
C28: 46586 | D28: Aprobada | G28: 73052181 | H28: GOÑE GARAY MISHELL TEYLITH | I28: PNP | J28: Desembolsado | K28: 82500 | L28: EYLIN VELASCO
C29: 46588 | D29: Aprobada | G29: 44587494 | H29: MORALES LOPEZ EBER | I29: EJERCITO | J29: Rechazado | K29: 87500 | L29: EYLIN VELASCO
C30: 46589 | D30: Rechazada | G30: 77060050 | H30: LOPEZ MARCOS BRAYAN ANTONIO | I30: PNP | J30: Pendiente De Documentar | K30: 79200 | L30: EYLIN VELASCO
C31: 46592 | D31: Aprobada | G31: 71605767 | H31: TIRADO SILVA MILTON LENIN | I31: EJERCITO | J31: Desembolsado | K31: 101700 | L31: EYLIN VELASCO
C32: 46592 | D32: Aprobada | G32: 44696261 | H32: CABRERA ESPINOZA DIESEL NUEL | I32: PNP | J32: Desembolsado | K32: 92300 | L32: EYLIN VELASCO
C33: 46958 | D33: Aprobada | G33: 70751258 | H33: SANCHEZ RUIZ HANS PETER | I33: EJERCITO | J33: Rechazado | K33: 70000 | L33: EYLIN VELASCO | Q33: CARTERA TRANSFERIDA
D34: Rechazada | G34: 73489404 | H34: BARRERA LOPEZ LUCAS | I34: PNP | J34: Rechazado | K34: 82550 | L34: EYLIN VELASCO | Q34: BOLETA AGOSTO
D35: Aprobada | G35: 76294410 | H35: MORALES LUIS KAREN JACKELIN | I35: PNP | J35: Rechazado | K35: 50000 | L35: EYLIN VELASCO
C36: 46210 | D36: Aprobada | E36: 46211 | F36: 46211 | G36: 73109555 | H36: FARRO CASTILLO LUIS ENRIQUE | I36: PNP | J36: Desembolsado | K36: 82200 | L36: JUDITH FARRO
C37: 46210 | D37: Rechazada | G37: 46146763 | H37: VERGARA HUALLPAROMACHI AMILCAR | I37: PNP | J37: Pendiente De Remesa | K37: 82700 | L37: JUDITH FARRO | Q37: SIGUE APARECIENDO COMO BCP Y LO EXTORNARON
C38: 46210 | D38: Aprobada | E38: 46214 | F38: 46219 | G38: 73512709 | H38: QUISPE FLORES CHARLES ALBIN LENIN | I38: PNP | J38: Desembolsado | K38: 86400 | L38: JUDITH FARRO
C39: 46219 | D39: Aprobada | G39: 48242327 | H39: RIOJA DE LA CRUZ YIMIN DEYVI | I39: PNP | J39: Rechazado | K39: 83500 | L39: JUDITH FARRO | Q39: NO ALCANZA MONTO CD
C40: 46220 | D40: Rechazada | G40: 76280744 | H40: MONTALVAN JIMENEZ FRAY CESAR | I40: PNP | J40: Rechazado | K40: 65650 | L40: JUDITH FARRO | Q40: FALTA UNA CUOTA
C41: 46586 | D41: Aprobada | G41: 73537833 | H41: TARRILLO REGALADO FRANKLIN DELEMNER | I41: PNP | J41: Desembolsado | K41: 83000 | L41: JUDITH FARRO | Q41: EXCEPCION CIP
D42: Rechazada | G42: 47046936 | H42: JIMENEZ LOPEZ WILLIAM FERNANDO | I42: PNP | J42: Rechazado | K42: 80550 | L42: JUDITH FARRO | Q42: BOLETA JULIO
D43: Enviada | G43: 45709668 | H43: ALARCON MENOR MARIA YOHANA | I43: PNP | J43: Evaluación BCP | K43: 92300 | L43: JUDITH FARRO
D44: Enviada | G44: 73018920 | H44: GALLO SOTO,LEONARDO MIGUEL | I44: PNP | J44: Evaluación BCP | K44: 81300 | L44: JUDITH FARRO
D45: Enviada | G45: 75066361 | H45: DE LA CRUZ NAVARRETE ANGEL FARY | I45: PNP | J45: Evaluación BCP | K45: 71100 | L45: JUDITH FARRO
...

Sheet OMAR MINAYA
D3: CHICLAYO | E3: Meta | F3: Desembolsado | G3: Avance | H3: Pendiente De Documentar | I3: Pendiente De Remesa | J3: Pendiente De Backoffice | K3: Evaluación BCP | L3: Obs Backoffice | M3: Obs BCP | N3: Rechazado
D4: S/. | E4: 1000000 | F4: =SUMIFS(OPI_5[MAF NETO],OPI_5[ESTADO],"Desembolsado") -> 875160 | G4: =F4-E4 -> -124840 | H4: =SUMIFS(OPI_5[MAF NETO],OPI_5[ESTADO],H$3) -> 0 | I4: =SUMIFS(OPI_5[MAF NETO],OPI_5[ESTADO],I$3) -> 0 | J4: =SUMIFS(OPI_5[MAF NETO],OPI_5[ESTADO],J$3) -> 0 | K4: =SUMIFS(OPI_5[MAF NETO],OPI_5[ESTADO],K$3) -> 175250 | L4: =SUMIFS(OPI_5[MAF NETO],OPI_5[ESTADO],L$3) -> 0 | M4: =SUMIFS(OPI_5[MAF NETO],OPI_5[ESTADO],M$3) -> 0 | N4: =SUMIFS(OPI_5[MAF NETO],OPI_5[ESTADO],N$3) -> 706440
D5: Q / % | E5: - | F5: =COUNTIFS(OPI_5[ESTADO],"Desembolsado") -> 13 | G5: =IFERROR(F4/E4,"") -> 0.87516 | H5: =COUNTIFS(OPI_5[ESTADO],H$3) -> 0 | I5: =COUNTIFS(OPI_5[ESTADO],I$3) -> 0 | J5: =COUNTIFS(OPI_5[ESTADO],J$3) -> 0 | K5: =COUNTIFS(OPI_5[ESTADO],K$3) -> 2 | L5: =COUNTIFS(OPI_5[ESTADO],L$3) -> 0 | M5: =COUNTIFS(OPI_5[ESTADO],M$3) -> 0 | N5: =COUNTIFS(OPI_5[ESTADO],N$3) -> 9
B9: PLAZA DE VENTA | C9: FECHA DE ENVIO DE REMESA | D9: ESTADO DE REMESA | E9: FECHA DE INGRESO | F9: FECHA DE DESEMBOLSO | G9: DOCUMENTO | H9: NOMBRES Y APELLIDOS | I9: CONVENIO | J9: ESTADO | K9: MAF NETO | L9: EJECUTIVO | M9: FILE ENVIADO A BANCO | N9: FECHA DE ENVIÓ CARTA PODER A BCP | O9: COMPRA DE DEUDA REALIZADA | P9: LIBERACIÓN | Q9: FEEDBACK
B10: CHICLAYO | C10: 46208 | D10: Rechazada | E10: --------- | F10: -------------------------- | G10: 46466484 | H10: CLAUDIA CRISTINA MARRUFO DIAZ | I10: ESSALUD | J10: Rechazado | K10: 99900 | L10: MILAGROS LIMO | M10: ------------- | N10: -------------- | O10: -------- | P10: --------- | Q10: INDICA NO TIENE LIQUIDEZ
B11: CHICLAYO | C11: 46207 | D11: Aprobada | E11: 46211 | F11: 46211 | G11: 73858275 | H11: REATEGUI PINEDO ROBER | I11: MARINA | J11: Desembolsado | K11: 43000 | L11: HENRY CARCAMO | M11: No | N11: 46212 | O11: Si | P11: Si | Q11: .
B12: CHICLAYO | C12: 46209 | D12: Aprobada | E12: 46210 | F12: 46211 | G12: 75910205 | H12: ORTIZ SANCHEZ OSEPH ALAIN | I12: PNP | J12: Desembolsado | K12: 82100 | L12: YURIKO OSPINO | M12: Si | N12: 46217 | O12: Si | P12: Si | Q12: .
B13: CHICLAYO | C13: 46210 | D13: Aprobada | E13: 46212 | F13: 46217 | G13: 21886400 | H13: CHICO REYES PERCY JAVIER | I13: MARINA | J13: Desembolsado | K13: 67600 | L13: YURIKO OSPINO | M13: No | N13: 46219 | O13: Si | P13: No | Q13: .
B14: CHICLAYO | C14: 46210 | D14: Rechazada | E14: ----------- | F14: -------------------------- | G14: 74550302 | H14: CAMPOS AGUILAR MAGALI | I14: PNP | J14: Rechazado | K14: 81700 | L14: GABRIELA VELASQUEZ | M14: --------- | N14: -------- | O14: --------- | P14: ----------- | Q14: FALTA 3RA CUOTA
B15: CHICLAYO | C15: 46210 | D15: Aprobada | E15: 46211 | F15: 46212 | G15: 46929261 | H15: LIVIAPOMA VALLES NEYLL | I15: PNP | J15: Desembolsado | K15: 77700 | L15: YURIKO OSPINO | M15: Si | N15: 46216 | O15: Si | P15: Si
B16: CHICLAYO | C16: 46211 | D16: Aprobada | E16: 46216 | F16: 46217 | G16: 73598377 | H16: URRUTIA SALINAS FRANKLIN EHDUARDO | I16: PNP | J16: Desembolsado | K16: 23000 | L16: YURIKO OSPINO | N16: 46217 | O16: Si | P16: Si
B17: CHICLAYO | C17: 46211 | D17: Aprobada | F17: 31/07/0226 | G17: 44660132 | H17: CERDAN ZARATE NORBERTO | I17: EP | J17: Desembolsado | K17: 81800 | L17: YURIKO OSPINO | Q17: SE MANDO NUEVA REMESA
B18: CHICLAYO | C18: 46216 | D18: Aprobada | E18: 46224 | G18: 47395269 | H18: DAVALOS PONGO ENRIQUE | I18: PNP | J18: Desembolsado | K18: 72600 | L18: YURIKO OSPINO | Q18: FALTA LEVANTAR AN
B19: CHICLAYO | C19: 46218 | D19: Aprobada | E19: 46219 | F19: 46221 | G19: 76393921 | H19: JAIME WILY RIVERA GUERRERO | I19: PNP | J19: Desembolsado | K19: 83050 | L19: YURIKO OSPINO | Q19: ,
B20: CHICLAYO | C20: 46218 | D20: Aprobada | E20: 46221 | F20: --------------- | G20: 43538557 | H20: SOLIS BENAVENTE LUIGY MONTARELY | I20: PNP | J20: Rechazado | K20: 58000 | L20: ANA FARRO | M20: ---------------------------- | N20: ----------------------------- | O20: ----------------------- | P20: -------------------- | Q20: ,
B21: CHICLAYO | C21: 46218 | D21: Aprobada | E21: 46219 | F21: 46132 | G21: 70584256 | H21: JOSE GABRIEL AGURTO PEREZ | I21: PNP | J21: Desembolsado | K21: 83000 | L21: VICTOR CIEZA LA MADRID | Q21: SE MANDO FILE
B22: CHICLAYO | C22: 46219 | D22: Rechazada | E22: --------- | F22: --------- | G22: 46005010 | H22: PALACIOS SUXO JOSE EDUARDO | I22: EP | J22: Rechazado | K22: 25500 | L22: YURIKO OSPINO | M22: ------------- | N22: ------------------- | O22: ----------- | P22: --------------------- | Q22: ,
B23: CHICLAYO | C23: 46220 | D23: Aprobada | E23: 46223 | F23: 46223 | G23: 46367470 | H23: DANIA ARACELY CRUZ ALARCON | I23: PNP | J23: Desembolsado | K23: 92300 | L23: YURIKO OSPINO | Q23: PENDIENTE REMESA Y SE MANDO FILE
B24: CHICLAYO | C24: 46220 | D24: Rechazada | E24: ---------------------- | F24: -------------------------- | G24: 40580977 | H24: DE LA CRUZ GRAJEDA ABRAHAM FELIX | I24: EP | J24: Rechazado | K24: 173000 | L24: YURIKO OSPINO | M24: ----------------- | N24: ----------------------- | O24: ----------------- | P24: ------------------ | Q24: ,
B25: CHICLAYO | C25: 46224 | D25: Rechazada | E25: ---------------------- | F25: -------------------------- | G25: 71776287 | H25: MOGOLLON FLORES JORGE EDUARDO | I25: EP | J25: Rechazado | K25: 65350 | L25: MEDALITH GALLARDO | M25: ------------------- | N25: ----------------------- | O25: --------------------------- | P25: -------------------------
B26: CHICLAYO | C26: 46223 | D26: Aprobada | E26: 46223 | G26: 74390314 | H26: GUEVARA ANGELES WILLIAN ANTONY | I26: PNP | J26: Desembolsado | K26: 63550 | L26: YURIKO OSPINO
B27: CHICLAYO | C27: 46224 | D27: Aprobada | G27: 46392979 | H27: PINTO ARAGON,NICK JEEANLOISE | I27: PNP | J27: Desembolsado | K27: 66800 | L27: YURIKO OSPINO
B28: CHICLAYO | C28: 46225 | D28: Aprobada | E28: 46224 | G28: 46861513 | H28: COBEÑAS EFFIO JULIO MANUEL | I28: PNP | J28: Desembolsado | K28: 38660 | L28: YURIKO OSPINO
B29: CHICLAYO | C29: 46228 | D29: Rechazada | E29: ---------------------------- | F29: ---------------------------- | G29: 74769536 | H29: OLAECHEA SALCEDO JOSEPH EDUARDO | I29: PNP | J29: Rechazado | K29: 70000 | L29: YURIKO OSPINO
B30: CHICLAYO | C30: ------------ | D30: Rechazada | E30: ------------------- | F30: -------------------- | G30: 47626539 | H30: HUAMAN PALACIOS ANALY GABRIELA | I30: PNP | J30: Rechazado | K30: 84100 | L30: GABRIELA VELASQUEZ | M30: -------------------- | N30: --------------------- | O30: ----------------- | P30: ---------------- | Q30: .
B31: CHICLAYO | C31: ------------------------ | D31: Rechazada | E31: -------------------------- | F31: -------------------- | G31: 70446644 | H31: CUTIMANGO VELASQUEZ ROEL ALEX | I31: PNP | J31: Rechazado | K31: 48890 | L31: KAROL MIÑAN | M31: ------------------- | N31: -------------------------- | O31: -------------------------- | P31: ------------------------
B32: CHICLAYO | C32: 46233 | D32: Aprobada | E32: 46234 | G32: 75937974 | H32: MARCO ANTONIO CALDERON ZAMBRANO | I32: PNP | J32: Evaluación BCP | K32: 81850 | L32: KAROL MIÑAN
B33: CHICLAYO | C33: 46234 | D33: Aprobada | E33: 46234 | G33: 78551156 | H33: CARLOS SANDOVAL DENNYS FRANLEY | I33: EP | J33: Evaluación BCP | K33: 93400 | L33: YURIKO OSPINO

Sheet JHON ZAMORA
D3: CHICLAYO | E3: Meta | F3: Desembolsado | G3: Avance | H3: Pendiente De Documentar | I3: Pendiente De Remesa | J3: Pendiente De Backoffice | K3: Evaluación BCP | L3: Obs Backoffice | M3: Obs BCP | N3: Rechazado
D4: S/. | E4: 1000000 | F4: =SUMIFS(OPI_3[MAF NETO],OPI_3[ESTADO],"Desembolsado") -> 864480 | G4: =F4-E4 -> -135520 | H4: =SUMIFS(OPI_3[MAF NETO],OPI_3[ESTADO],H$3) -> 0 | I4: =SUMIFS(OPI_3[MAF NETO],OPI_3[ESTADO],I$3) -> 0 | J4: =SUMIFS(OPI_3[MAF NETO],OPI_3[ESTADO],J$3) -> 0 | K4: =SUMIFS(OPI_3[MAF NETO],OPI_3[ESTADO],K$3) -> 198100 | L4: =SUMIFS(OPI_3[MAF NETO],OPI_3[ESTADO],L$3) -> 0 | M4: =SUMIFS(OPI_3[MAF NETO],OPI_3[ESTADO],M$3) -> 0 | N4: =SUMIFS(OPI_3[MAF NETO],OPI_3[ESTADO],N$3) -> 36000
D5: Q / % | E5: - | F5: =COUNTIFS(OPI_3[ESTADO],"Desembolsado") -> 12 | G5: =IFERROR(F4/E4,"") -> 0.86448 | H5: =COUNTIFS(OPI_3[ESTADO],H$3) -> 0 | I5: =COUNTIFS(OPI_3[ESTADO],I$3) -> 0 | J5: =COUNTIFS(OPI_3[ESTADO],J$3) -> 0 | K5: =COUNTIFS(OPI_3[ESTADO],K$3) -> 3 | L5: =COUNTIFS(OPI_3[ESTADO],L$3) -> 0 | M5: =COUNTIFS(OPI_3[ESTADO],M$3) -> 0 | N5: =COUNTIFS(OPI_3[ESTADO],N$3) -> 1
B9: PLAZA DE VENTA | C9: FECHA DE ENVIO DE REMESA | D9: ESTADO DE REMESA | E9: FECHA DE INGRESO | F9: FECHA DE DESEMBOLSO | G9: DOCUMENTO | H9: NOMBRES Y APELLIDOS | I9: CONVENIO | J9: ESTADO | K9: MAF NETO | L9: EJECUTIVO | M9: FILE ENVIADO A BANCO | N9: FECHA DE ENVIÓ CARTA PODER A BCP | O9: COMPRA DE DEUDA REALIZADA | P9: LIBERACIÓN | Q9: FEEDBACK
B10: CHICLAYO | C10: 46205 | D10: Aprobada | E10: 46206 | F10: 46206 | G10: 76476905 | H10: JIMENEZ PICON DEYBY ORLEY | I10: PNP | J10: Desembolsado | K10: 73700 | L10: FLOR LLATAS
B11: CHICLAYO | C11: 46205 | D11: Aprobada | E11: 46205 | F11: 46206 | G11: 73893219 | H11: QUEA VASQUEZ KENVERLY YASMIRA | I11: PNP | J11: Desembolsado | K11: 56100 | L11: FLOR LLATAS
B12: CHICLAYO | C12: 46210 | D12: Aprobada | E12: 46211 | F12: 46211 | G12: 76036410 | H12: CUSI VILLARROEL,JOAO CLIMACO | I12: PNP | J12: Desembolsado | K12: 82200 | L12: FLOR LLATAS
B13: CHICLAYO | C13: 46210 | D13: Aprobada | E13: 46211 | F13: 46211 | G13: 42180595 | H13: MANAYAY CESPEDES DINO JOEL | I13: PNP | J13: Desembolsado | K13: 59600 | L13: FLOR LLATAS
B14: CHICLAYO | C14: 46211 | D14: Aprobada | E14: 46211 | F14: 46213 | G14: 46556570 | H14: FLORES CASTRO ELVER YOEL | I14: PNP | J14: Desembolsado | K14: 44000 | L14: FLOR LLATAS
B15: CHICLAYO | C15: 46211 | D15: Aprobada | E15: 46216 | F15: 46217 | G15: 45591401 | H15: VILLANUEVA SANCHEZ ERIKA JULIANA | I15: PNP | J15: Desembolsado | K15: 86400 | L15: FLOR LLATAS
B16: CHICLAYO | C16: 46211 | D16: Aprobada | E16: 46213 | F16: 46216 | G16: 72845496 | H16: TABOADA RIVERA CRISTHIAN ALFREDO | I16: PNP | J16: Desembolsado | K16: 72000 | L16: FLOR LLATAS
B17: CHICLAYO | C17: 46212 | D17: Aprobada | E17: 46213 | F17: 46216 | G17: 46187625 | H17: FLORES COCHACHI JESUS JAVIER | I17: PNP | J17: Desembolsado | K17: 81700 | L17: FLOR LLATAS
B18: CHICLAYO | C18: 46218 | D18: Aprobada | E18: 46218 | F18: 46223 | G18: 71081828 | H18: JIMENEZ RUIZ,LUIS MAXIMO DNI | I18: PNP | J18: Desembolsado | K18: 71100 | L18: FLOR LLATAS
B19: CHICLAYO | C19: 46218 | D19: Rechazada | G19: 71479939 | H19: LILIBETH HERRERA RAMIREZ | I19: PNP | J19: Rechazado | K19: 36000 | L19: FLOR LLATAS | Q19: SOBREGIRADA POR FACULTATIVOS
B20: CHICLAYO | C20: 46218 | D20: Aprobada | E20: 46218 | F20: 46225 | G20: 48232251 | H20: CEVALLOS FLORES JAMES JACK | I20: PNP | J20: Desembolsado | K20: 83080 | L20: FLOR LLATAS
B21: CHICLAYO | C21: 46225 | D21: Aprobada | E21: 46225 | F21: 46233 | G21: 72622896 | H21: PEREZ VILLALOBOS FRANKLIN JOSE | I21: PNP | J21: Desembolsado | K21: 71000 | L21: NICOLASA RAMOS
B22: CHICLAYO | C22: 46225 | D22: Aprobada | E22: 46225 | F22: 46234 | G22: 46059493 | H22: YNGA SANDOVAL,ERIKA MELISSA | I22: PNP | J22: Desembolsado | K22: 83600 | L22: NICOLASA RAMOS
B23: CHICLAYO | C23: 46234 | D23: Aprobada | E23: 46234 | G23: 73377048 | H23: LLATAS RIMARACHIN JORGE LUIS | I23: PNP | J23: Evaluación BCP | K23: 83100 | L23: FLOR LLATAS
B24: CHICLAYO | C24: 46234 | D24: Aprobada | E24: 46234 | G24: 71824277 | H24: URIARTE RENTERIA SOFIA STEFANY | I24: PNP | J24: Evaluación BCP | K24: 77700 | L24: FLOR LLATAS
B25: CHICLAYO | C25: 46234 | D25: Aprobada | E25: 46234 | G25: 42047411 | H25: EDGAR SMITH CUMPEN LARA | I25: PNP | J25: Evaluación BCP | K25: 37300 | L25: FLOR LLATAS

Sheet ANGIE SILVERA
D3: LIMA | E3: Meta | F3: Desembolsado | G3: Avance | H3: Pendiente De Documentar | I3: Pendiente De Remesa | J3: Pendiente De Backoffice | K3: Evaluación BCP | L3: Obs Backoffice | M3: Obs BCP | N3: Rechazado
D4: S/. | E4: 2000000 | F4: =SUMIFS(OPI[MAF NETO],OPI[ESTADO],"Desembolsado") -> 2726520 | G4: =F4-E4 -> 726520 | H4: =SUMIFS(OPI[MAF NETO],OPI[ESTADO],H$3) -> 0 | I4: =SUMIFS(OPI[MAF NETO],OPI[ESTADO],I$3) -> 0 | J4: =SUMIFS(OPI[MAF NETO],OPI[ESTADO],J$3) -> 0 | K4: =SUMIFS(OPI[MAF NETO],OPI[ESTADO],K$3) -> 0 | L4: =SUMIFS(OPI[MAF NETO],OPI[ESTADO],L$3) -> 0 | M4: =SUMIFS(OPI[MAF NETO],OPI[ESTADO],M$3) -> 0 | N4: =SUMIFS(OPI[MAF NETO],OPI[ESTADO],N$3) -> 0
D5: Q / % | E5: - | F5: =COUNTIFS(OPI[ESTADO],"Desembolsado") -> 36 | G5: =IFERROR(F4/E4,"") -> 1.36326 | H5: =COUNTIFS(OPI[ESTADO],H$3) -> 0 | I5: =COUNTIFS(OPI[ESTADO],I$3) -> 0 | J5: =COUNTIFS(OPI[ESTADO],J$3) -> 0 | K5: =COUNTIFS(OPI[ESTADO],K$3) -> 0 | L5: =COUNTIFS(OPI[ESTADO],L$3) -> 0 | M5: =COUNTIFS(OPI[ESTADO],M$3) -> 0 | N5: =COUNTIFS(OPI[ESTADO],N$3) -> 0
B9: PLAZA DE VENTA | C9: FECHA DE ENVIO DE REMESA | D9: ESTADO DE REMESA | E9: FECHA DE INGRESO | F9: FECHA DE DESEMBOLSO | G9: DOCUMENTO | H9: NOMBRES Y APELLIDOS | I9: CONVENIO | J9: ESTADO | K9: MAF NETO | L9: EJECUTIVO | M9: FILE ENVIADO A BANCO | N9: FECHA DE ENVIÓ CARTA PODER A BCP | O9: COMPRA DE DEUDA REALIZADA | P9: LIBERACIÓN | Q9: FEEDBACK
B10: LIMA | D10: Aprobada | E10: 46206 | F10: 46206 | G10: 40083839 | H10: CARBAJAL CECILIO WILMER GIOVANNI | I10: MGP | J10: Desembolsado | K10: 93800 | L10: AURELIA FERNANDEZ
B11: LIMA | C11: 46205 | D11: Aprobada | E11: 46206 | F11: 46206 | G11: 40956932 | H11: OLIVA ATUNCAR ROSMERY | I11: DIRIS ESTE | J11: Desembolsado | K11: 82000 | L11: AURELIA FERNANDEZ
B12: LIMA | C12: 46204 | D12: Aprobada | E12: 46207 | F12: 46210 | G12: 73235180 | H12: ENCARNACION GALLARDO FABIAN JESUS | I12: MGP | J12: Desembolsado | K12: 81900 | L12: AURELIA FERNANDEZ
B13: LIMA | C13: 46205 | D13: Aprobada | E13: 46207 | F13: 46209 | G13: 71199201 | H13: NAVARRO VELA AUREA ALEXANDRA NICOLE | I13: MGP | J13: Desembolsado | K13: 81500 | L13: AURELIA FERNANDEZ
B14: LIMA | C14: 46206 | D14: Aprobada | E14: 46212 | F14: 46213 | G14: 10172325 | H14: ARMAS MORALES ELIZABETH MARIA | I14: DIRIS ESTE | J14: Desembolsado | K14: 58700 | L14: AURELIA FERNANDEZ
B15: LIMA | C15: 46210 | D15: Aprobada | E15: 46212 | F15: 46213 | G15: 43432467 | H15: AYME SALCEDO CESAR FREDDY | I15: FAP | J15: Desembolsado | K15: 87000 | L15: MARIA LLONTOP
B16: TARAPOTO | C16: 46210 | D16: Aprobada | E16: 46212 | F16: 46213 | G16: 47754160 | H16: TANANTA PAIMA LEVI | I16: PNP | J16: Desembolsado | K16: 67900 | L16: AURELIA FERNANDEZ
B17: AREQUIPA | C17: 46210 | D17: Aprobada | E17: 46212 | F17: 46213 | G17: 45726757 | H17: ANDRADE MACHACA JEAN PAUL | I17: PNP | J17: Desembolsado | K17: 86590 | L17: JUAN CORDOVA
B18: TRUJILLO | C18: 46210 | D18: Aprobada | E18: 46213 | F18: 46216 | G18: 44666926 | H18: DIAZ AVALOS LUZ EDITH | I18: ESSALUD | J18: Desembolsado | K18: 105200 | L18: AURELIA FERNANDEZ
C19: 46212 | D19: Aprobada | E19: 46213 | F19: 46216 | G19: 45139936 | H19: BETETA RUBIO SEGUNDO CONSTANTINO | I19: PNP | J19: Desembolsado | K19: 87400 | L19: JUAN CORDOVA
C20: 46212 | D20: Aprobada | E20: 46213 | F20: 46217 | G20: 73582028 | H20: ARRESE PEREZ ANDERSON ANTONY | I20: PNP | J20: Desembolsado | K20: 50000 | L20: JUAN CORDOVA
C21: 46212 | D21: Aprobada | E21: 46213 | F21: 46217 | G21: 76287655 | H21: SOPLAPUCO SOPLAPUCO LUIGUI ANTONY | I21: PNP | J21: Desembolsado | K21: 76450 | L21: AURELIA FERNANDEZ
B22: LIMA | C22: 46212 | D22: Aprobada | E22: 46214 | F22: 46216 | G22: 74384926 | H22: ALARCON VASQUEZ HECTOR HUGO | I22: PNP | J22: Desembolsado | K22: 77700 | L22: MARIA LLONTOP
C23: 46210 | D23: Aprobada | E23: 46212 | F23: 46218 | G23: 40354668 | H23: SANCHEZ BARRERA MERCEDES JANET | I23: DIRIS ESTE | J23: Desembolsado | K23: 34300 | L23: AURELIA FERNANDEZ
B24: LIMA | C24: 46212 | D24: Aprobada | E24: 46213 | F24: 46219 | G24: 75334296 | H24: YARIHUAMAN REATEGUI JESUS ALBERTO | I24: PNP | J24: Desembolsado | K24: 61900 | L24: AURELIA FERNANDEZ
B25: IQUITOS | C25: 46216 | D25: Aprobada | E25: 46217 | F25: 46220 | G25: 75370617 | H25: MERCADO GONZALES JORGE EDUARDO | I25: PNP | J25: Desembolsado | K25: 67000 | L25: AURELIA FERNANDEZ
B26: LIMA | C26: 46216 | D26: Aprobada | E26: 46217 | F26: 46220 | G26: 77217734 | H26: PITTMAN PADILLA SHARON HELEN | I26: PNP | J26: Desembolsado | K26: 81500 | L26: YESICA HEREDIA
B27: LIMA | C27: 46217 | D27: Aprobada | E27: 46220 | F27: 46221 | G27: 73772658 | H27: FLORES CORONADO JHOSSELYN ANGELA | I27: PNP | J27: Desembolsado | K27: 82200 | L27: MARIA LLONTOP
B28: NAZCA | C28: 46217 | D28: Aprobada | E28: 46218 | F28: 46219 | G28: 72163611 | H28: LEON CARDENAS LUIS ALBERTO | I28: PNP | J28: Desembolsado | K28: 109400 | L28: AURELIA FERNANDEZ
B29: LIMA | C29: 46217 | D29: Aprobada | E29: 46220 | F29: 46221 | G29: 45901937 | H29: LEVANO PATIÑO PAMELA LOURDES | I29: PNP | J29: Desembolsado | K29: 85000 | L29: MARIA LLONTOP
B30: LIMA | C30: 46216 | D30: Aprobada | E30: 46217 | F30: 46223 | G30: 72510806 | H30: PEÑA GARCIA YEFERSON JUAN | I30: PNP | J30: Desembolsado | K30: 82730 | L30: JUAN CORDOVA
B31: PUCALLPA | C31: 46213 | D31: Aprobada | E31: 46218 | F31: 46223 | G31: 43255959 | H31: PIÑA HUARATAPAIRO LIMBER ERNESTO | I31: ESSALUD | J31: Desembolsado | K31: 17100 | L31: AURELIA FERNANDEZ
B32: LIMA | C32: 46217 | D32: Aprobada | E32: 46223 | F32: 46225 | G32: 46931645 | H32: VARGAS VILDOSOLA MARCO ANTONIO | I32: PNP | J32: Desembolsado | K32: 83000 | L32: JUAN CORDOVA
B33: LIMA | C33: 46217 | D33: Aprobada | E33: 46224 | F33: 46225 | G33: 10370662 | H33: QUISPE APAZA GREGORIA | I33: DIRIS NORTE | J33: Desembolsado | K33: 75450 | L33: AURELIA FERNANDEZ
B34: LIMA | C34: 46220 | D34: Aprobada | E34: 46223 | F34: 46223 | G34: 73967054 | H34: ESPINOLA ORTIZ JUAN CARLOS | I34: PNP | J34: Desembolsado | K34: 60000 | L34: JUAN CORDOVA
B35: LIMA | C35: 46223 | D35: Aprobada | E35: 46225 | F35: 46227 | G35: 72448444 | H35: PALACIOS DURAND DENNIS MARLON | I35: MGP | J35: Desembolsado | K35: 87800 | L35: AURELIA FERNANDEZ
... B38: BAGUA GRANDE | C38: 46225 | D38: Aprobada | E38: 46227 | F38: 46228 | G38: 75468583 | H38: DIAZ TERRONES KEVIN ALEXIS | I38: PNP | J38: Desembolsado | K38: 34100 | L38: AURELIA FERNANDEZ
C39: 46225 | D39: Aprobada | E39: 46227 | F39: 46230 | G39: 71831343 | H39: ESPINOZA HERRERA MICHAEL | I39: PNP | J39: Desembolsado | K39: 80000 | L39: AURELIA FERNANDEZ
C40: 46224 | D40: Aprobada | E40: 46225 | F40: 46228 | G40: 74300399 | H40: AGUILAR BERECHE YORDAN ISMAEL | I40: FAP | J40: Desembolsado | K40: 79100 | L40: MARIA LLONTOP
C41: 46224 | D41: Aprobada | E41: 46225 | F41: 46228 | G41: 74709400 | H41: ARIAS ALFARO ALBERTO PAOLO | I41: FAP | J41: Desembolsado | K41: 80100 | L41: MARIA LLONTOP
C42: 46224 | D42: Aprobada | E42: 46225 | F42: 46227 | G42: 75372222 | H42: PEÑA OVIEDO GIAN PAULO | I42: EP | J42: Desembolsado | K42: 76600 | L42: MARIA LLONTOP
C43: 46225 | D43: Aprobada | E43: 46225 | F43: 46227 | G43: 73936820 | H43: CABALLERO ARAUJO MARTHA ELENA | I43: PNP | J43: Desembolsado | K43: 84000 | L43: MARIA LLONTOP
B44: LIMA | C44: 46225 | D44: Aprobada | E44: 46227 | F44: 46230 | G44: 75420930 | H44: CALLE DAVILA POOL JUNIOR ARGENIS | I44: PNP | J44: Desembolsado | K44: 91000 | L44: JUAN CORDOVA
B45: MALA | C45: 46225 | D45: Aprobada | E45: 46227 | F45: 46228 | G45: 74697789 | H45: YALLE CHAVEZ ROBINSON ALEXIS | I45: PNP | J45: Desembolsado | K45: 68500 | L45: AURELIA FERNANDEZ

Sheet LUIS CHUSE
D3: LIMA | E3: Meta | F3: Desembolsado | G3: Avance | H3: Pendiente De Documentar | I3: Pendiente De Remesa | J3: Pendiente De Backoffice | K3: Evaluación BCP | L3: Obs Backoffice | M3: Obs BCP | N3: Rechazado
D4: S/. | E4: 2000000 | F4: =SUMIFS(OPI_7[MAF NETO],OPI_7[ESTADO],"Desembolsado") -> 2216250 | G4: =F4-E4 -> 216250 | H4: =SUMIFS(OPI_7[MAF NETO],OPI_7[ESTADO],H$3) -> 46000 | I4: =SUMIFS(OPI_7[MAF NETO],OPI_7[ESTADO],I$3) -> 0 | J4: =SUMIFS(OPI_7[MAF NETO],OPI_7[ESTADO],J$3) -> 0 | K4: =SUMIFS(OPI_7[MAF NETO],OPI_7[ESTADO],K$3) -> 105700 | L4: =SUMIFS(OPI_7[MAF NETO],OPI_7[ESTADO],L$3) -> 0 | M4: =SUMIFS(OPI_7[MAF NETO],OPI_7[ESTADO],M$3) -> 130600 | N4: =SUMIFS(OPI_7[MAF NETO],OPI_7[ESTADO],N$3) -> 65400
D5: Q / % | E5: - | F5: =COUNTIFS(OPI_7[ESTADO],"Desembolsado") -> 33 | G5: =IFERROR(F4/E4,"") -> 1.108125 | H5: =COUNTIFS(OPI_7[ESTADO],H$3) -> 1 | I5: =COUNTIFS(OPI_7[ESTADO],I$3) -> 1 | J5: =COUNTIFS(OPI_7[ESTADO],J$3) -> 0 | K5: =COUNTIFS(OPI_7[ESTADO],K$3) -> 2 | L5: =COUNTIFS(OPI_7[ESTADO],L$3) -> 0 | M5: =COUNTIFS(OPI_7[ESTADO],M$3) -> 2 | N5: =COUNTIFS(OPI_7[ESTADO],N$3) -> 4
B9: PLAZA DE VENTA | C9: FECHA DE ENVIO DE REMESA | D9: ESTADO DE REMESA | E9: FECHA DE INGRESO | F9: FECHA DE DESEMBOLSO | G9: DOCUMENTO | H9: NOMBRES Y APELLIDOS | I9: CONVENIO | J9: ESTADO | K9: MAF NETO | L9: EJECUTIVO | M9: FILE ENVIADO A BANCO | N9: FECHA DE ENVIÓ CARTA PODER A BCP | O9: COMPRA DE DEUDA REALIZADA | P9: LIBERACIÓN | Q9: FEEDBACK
B10: LIMA | C10: 46198 | D10: Aprobada | E10: 46203 | G10: 72436908 | H10: PONCE ABANTO LICETH | I10: PNP | J10: Desembolsado | K10: 78050 | L10: CARLOS ESPINOZA | N10: SI
B11: LIMA | C11: 46228 | D11: Aprobada | E11: AGOSTO | G11: 74710347 | H11: DIOS SALVATIERRA FABRIZZIO PIERO | I11: PNP | J11: Desembolsado | K11: 69000 | L11: MERLY ROJAS | N11: NO
B12: LIMA | C12: 46228 | D12: Aprobada | E12: AGOSTO | G12: 44767826 | H12: POMA CUEVAS HELEN DIANA | I12: MGP | J12: Pendiente De Documentar | K12: 46000 | L12: KELLY SARMIENTO
B13: LIMA | C13: 46199 | D13: Aprobada | G13: 77505087 | H13: PAREDES TICONA ANTONY FRANK | I13: PNP | J13: Desembolsado | K13: 67100 | L13: KELLY SARMIENTO | N13: SI
B14: LIMA | C14: 46203 | D14: Aprobada | G14: 45848403 | H14: JABO VARGAS YOHEL ROMULO | I14: PNP | J14: Desembolsado | K14: 77800 | L14: MELINA LEYVA | N14: SI
B15: LIMA | C15: 46224 | D15: Aprobada | E15: AGOSTO | F15: CAYO SBS | G15: 43327891 | H15: MORALES GARCIA DENISE IVONNE | I15: PNP | J15: Rechazado | K15: 0 | L15: JOSSEF PFARE
B16: LIMA | C16: 46205 | D16: Aprobada | G16: 48080672 | H16: LIMA QUENTA JUNNIOR MODESTO | I16: PNP | J16: Desembolsado | K16: 10000 | L16: MELINA LEYVA | N16: NO
B17: LIMA | C17: 46226 | D17: Aprobada | G17: 47717416 | H17: QUISPE ZUÑIGA RICARDO DAVID | I17: PNP | J17: Desembolsado | K17: 85300 | L17: LUIS MENDOZA
B18: LIMA | C18: 46224 | D18: Aprobada | E18: AGOSTO | G18: 09835595 | H18: LUJAN FLORES CESAR MARTIN | I18: EP | J18: Obs BCP | K18: 67000 | L18: LEYDI MENDOZA
B19: LIMA | C19: 46207 | D19: Aprobada | G19: 41979193 | H19: JULCA MACAYO LUIS ALBERTO | I19: PNP | J19: Desembolsado | K19: 72900 | L19: CARLOS ESPINOZA | N19: SI
B20: LIMA | C20: 46209 | D20: Aprobada | G20: 72401402 | H20: PORTOCARRERO ROCHA KEVIN FERNANDO | I20: MGP | J20: Desembolsado | K20: 77200 | L20: KELLY SARMIENTO | N20: SI
B21: LIMA | C21: 46209 | D21: Aprobada | G21: 77297247 | H21: ALMEYDA VICERREL CARLOS EDUARDO | I21: PNP | J21: Desembolsado | K21: 64900 | L21: KELLY SARMIENTO | N21: SI
B22: LIMA | C22: 46221 | D22: Aprobada | G22: 75657739 | H22: ZEVALLOS ESPINOZA FRANK PIERRY | I22: PNP | J22: Desembolsado | K22: 60800 | L22: CARLOS ESPINOZA | N22: SI
B23: LIMA | C23: 46211 | D23: Aprobada | G23: 72804826 | H23: CHICO PALOMINO KEVIN JOEL | I23: PNP | J23: Desembolsado | K23: 20000 | L23: MELINA LEYVA | N23: NO
B24: LIMA | C24: 46211 | D24: Aprobada | G24: 75591436 | H24: MORALES HERNANDEZ JOSE HUZLER | I24: PNP | J24: Desembolsado | K24: 20000 | L24: MELINA LEYVA | N24: SI
B25: LIMA | C25: 46211 | D25: Aprobada | G25: 76964997 | H25: PERALTA SIERRA SAMIR | I25: MGP | J25: Desembolsado | K25: 81500 | L25: KELLY SARMIENTO | N25: SI
B26: LIMA | C26: 46211 | D26: Aprobada | G26: 74039211 | H26: JIMENEZ CURI HECTOR FELIPE | I26: MGP | J26: Desembolsado | K26: 75000 | L26: KELLY SARMIENTO | N26: SI
B27: LIMA | C27: 46211 | D27: Aprobada | G27: 09634560 | H27: JARA LEYVA HILDA GLADYS | I27: ESSALUD | J27: Desembolsado | K27: 30000 | L27: MELINA LEYVA | N27: NO
B28: LIMA | C28: 46230 | D28: Aprobada | E28: AGOSTO | G28: 47510821 | H28: MORE CARRION CLEIFER BENITO | I28: PNP | J28: Desembolsado | K28: 25000 | L28: MELINA LEYVA | N28: SI
B29: LIMA | C29: 46225 | D29: Aprobada | E29: AGOSTO | G29: 44198597 | H29: ESPINOZA NICOLAS SEGUNDO JESUS | I29: EP | J29: Obs BCP | K29: 63600 | L29: LEYDI MENDOZA
B30: LIMA | C30: 46228 | D30: Aprobada | G30: 74442697 | H30: PRADO SERVA RODRIGO ALEXANDER | I30: PNP | J30: Desembolsado | K30: 69500 | L30: MERLY ROJAS | N30: SI
B31: LIMA | C31: 46211 | D31: Aprobada | E31: AGOSTO | G31: 31169449 | H31: GUIZADO MOSCOSO JANE | I31: ESSALUD | J31: Rechazado | K31: 0 | L31: JOSSEF PFARE
B32: LIMA | C32: 46211 | D32: Aprobada | G32: 40512381 | H32: PAREDES LUJAN EDUARDO SIMON | I32: ESSALUD | J32: Desembolsado | K32: 103000 | L32: CARLOS ESPINOZA | N32: SI
B33: LIMA | C33: 46211 | D33: Aprobada | G33: 46773429 | H33: RAMOS ROBLES EDWARDS KEYLER | I33: PNP | J33: Desembolsado | K33: 85000 | L33: CARLOS ESPINOZA | N33: SI
B34: LIMA | C34: 46221 | D34: Aprobada | G34: 44908222 | H34: VALDIVIA SALVADOR LORENA ISABEL | I34: PNP | J34: Desembolsado | K34: 41140 | L34: MERLY ROJAS | N34: SI
B35: LIMA | C35: 46221 | D35: Aprobada | G35: 77070960 | H35: OLANO GONZALES ANTONI | I35: PNP | J35: Desembolsado | K35: 81000 | L35: MERLY ROJAS | N35: SI
B36: LIMA | C36: 46212 | D36: Aprobada | G36: 40893802 | H36: PAMPA PARISACA LEONCIO WALTER | I36: PNP | J36: Desembolsado | K36: 89600 | L36: MELINA LEYVA | N36: SI
B37: LIMA | C37: 46214 | D37: Aprobada | E37: AGOSTO | G37: 74763004 | H37: QUISPE AYALA JOSE RAIVER | I37: PNP | J37: Rechazado | K37: 65400 | L37: KELLY SARMIENTO
B38: LIMA | C38: 46216 | D38: Aprobada | G38: 71765892 | H38: GRANADOS GUEVARA GABRIEL JESUS | I38: MGP | J38: Desembolsado | K38: 41000 | L38: KELLY SARMIENTO | N38: SI
B39: LIMA | C39: 46225 | D39: Aprobada | E39: AGOSTO | G39: 42569355 | H39: CORDOVA GUZMAN KATIUZCA | I39: PNP | J39: Rechazado | K39: 0 | L39: CARLOS ESPINOZA
B40: LIMA | C40: 46225 | D40: Aprobada | G40: 75902509 | H40: VASQUEZ VEGA MIGUEL ANGEL | I40: EP | J40: Desembolsado | K40: 78700 | L40: MERLY ROJAS | N40: SI
B41: LIMA | C41: 46216 | D41: Aprobada | G41: 72642797 | H41: CARBONEL DAVILA ADOLFO JORDAN | I41: PNP | J41: Desembolsado | K41: 84400 | L41: CARLOS ESPINOZA | N41: SI
B42: LIMA | C42: 46217 | D42: Aprobada | G42: 41868367 | H42: CORZO FLORES MIGUEL ANGEL | I42: PNP | J42: Desembolsado | K42: 85200 | L42: MERLY ROJAS | N42: NO
B43: LIMA | C43: 46218 | D43: Aprobada | G43: 71754785 | H43: GONZALES OJEDA JARO | I43: MGP | J43: Desembolsado | K43: 74360 | L43: LUIS MENDOZA
B44: LIMA | C44: 46218 | D44: Aprobada | G44: 47023361 | H44: QUISPE VENANCINO CELIA ESTEFANY | I44: EP | J44: Desembolsado | K44: 82500 | L44: MELINA LEYVA | N44: SI
B45: LIMA | C45: 46230 | D45: Aprobada | E45: AGOSTO | G45: 45026737 | H45: SALAZAR PONCE LILIANA | I45: DIRIS LIMA NORTE | J45: Evaluación BCP | K45: 10000 | L45: MELINA LEYVA
...

Sheet NATHALIE ARANDA
D3: LIMA | E3: Meta | F3: Desembolsado | G3: Avance | H3: Pendiente De Documentar | I3: Pendiente De Remesa | J3: Pendiente De Backoffice | K3: Evaluación BCP | L3: Obs Backoffice | M3: Obs BCP | N3: Rechazado
D4: S/. | E4: 500000 | F4: =SUMIFS(OPI_12[MAF NETO],OPI_12[ESTADO],"Desembolsado") -> 181100 | G4: =F4-E4 -> -318900 | H4: =SUMIFS(OPI_12[MAF NETO],OPI_12[ESTADO],H$3) -> 45100 | I4: =SUMIFS(OPI_12[MAF NETO],OPI_12[ESTADO],I$3) -> 105900 | J4: =SUMIFS(OPI_12[MAF NETO],OPI_12[ESTADO],J$3) -> 0 | K4: =SUMIFS(OPI_12[MAF NETO],OPI_12[ESTADO],K$3) -> 233200 | L4: =SUMIFS(OPI_12[MAF NETO],OPI_12[ESTADO],L$3) -> 0 | M4: =SUMIFS(OPI_12[MAF NETO],OPI_12[ESTADO],M$3) -> 0 | N4: =SUMIFS(OPI_12[MAF NETO],OPI_12[ESTADO],N$3) -> 0
D5: Q / % | E5: - | F5: =COUNTIFS(OPI_12[ESTADO],"Desembolsado") -> 2 | G5: =IFERROR(F4/E4,"") -> 0.3622 | H5: =COUNTIFS(OPI_12[ESTADO],H$3) -> 1 | I5: =COUNTIFS(OPI_12[ESTADO],I$3) -> 1 | J5: =COUNTIFS(OPI_12[ESTADO],J$3) -> 0 | K5: =COUNTIFS(OPI_12[ESTADO],K$3) -> 3 | L5: =COUNTIFS(OPI_12[ESTADO],L$3) -> 0 | M5: =COUNTIFS(OPI_12[ESTADO],M$3) -> 0 | N5: =COUNTIFS(OPI_12[ESTADO],N$3) -> 2
B9: PLAZA DE VENTA | C9: FECHA DE ENVIO DE REMESA | D9: ESTADO DE REMESA | E9: FECHA DE INGRESO | F9: FECHA DE DESEMBOLSO | G9: DOCUMENTO | H9: NOMBRES Y APELLIDOS | I9: CONVENIO | J9: ESTADO | K9: MAF NETO | L9: EJECUTIVO | M9: FILE ENVIADO A BANCO | N9: FECHA DE ENVIÓ CARTA PODER A BCP | O9: COMPRA DE DEUDA REALIZADA | P9: LIBERACIÓN | Q9: FEEDBACK
B10: LIMA | C10: 46217 | D10: Aprobada | E10: 46218 | F10: 46219 | G10: 76038684 | H10: WILMER CHAHUA CASIMIRO | I10: PNP | J10: Desembolsado | K10: 67400 | L10: URSULA LOPEZ | M10: No | N10: ENVIADO | O10: No | P10: No
B11: HUACHO | C11: 46218 | D11: Rechazada | G11: 74418106 | H11: JHORDAN CULLAMPE POQUIOMA | I11: PNP | J11: Rechazado | K11: 0 | L11: EVELYN GUTIERREZ
B12: LIMA | C12: 46220 | D12: Rechazada | G12: 44727770 | H12: ARTURO GIL BASTIDAS LAZO | I12: PNP | J12: Rechazado | K12: 0 | L12: EVELYN GUTIERREZ | M12: No | N12: PENDIENTE | O12: No
B13: LIMA | C13: 46225 | D13: Aprobada | E13: 46227 | F13: 46230 | G13: 73383138 | H13: BYRON OSWALDO RUBIO VEGAS | I13: EP | J13: Desembolsado | K13: 113700 | L13: EVELYN GUTIERREZ | M13: No | N13: ENVIADO 31/07 | O13: No | P13: No
B14: CHICLAYO | C14: 46225 | D14: Aprobada | E14: 46233 | G14: 43292897 | H14: MIGUEL ANGEL CORONADO NAVARRO | I14: EP | J14: Evaluación BCP | K14: 71300 | L14: EVELYN GUTIERREZ | M14: No | N14: PENDIENTE | O14: No | P14: No
B15: LIMA | C15: 46233 | D15: Aprobada | E15: 46233 | G15: 72952758 | H15: YHON WASHINGTON QUISPE CAHUASCANCO | I15: PNP | J15: Evaluación BCP | K15: 79700 | L15: URSULA LOPEZ | M15: No | N15: PENDIENTE | O15: No | P15: No
B16: LIMA | C16: 46234 | D16: Aprobada | E16: 46234 | G16: 71265965 | H16: ALEXIS RAUL VELASQUEZ HERNANDEZ | I16: PNP | J16: Evaluación BCP | K16: 82200 | L16: JACKELINE PAREDES
B17: LIMA | C17: 46235 | D17: Aprobada | E17: 46238 | G17: 72951201 | H17: JOSUE ANDERSON NIETO PISCONTE | I17: PNP | J17: Pendiente De Documentar | K17: 45100 | L17: EVELYN GUTIERREZ
B18: AYACUCHO | C18: 46238 | E18: 46238 | G18: 43803097 | H18: CARLOS NICOLAS MACEDO HUMEREZ | I18: PNP | J18: Pendiente De Remesa | K18: 105900 | L18: EVELYN GUTIERREZ

Sheet JIMMY COLLAZOS
D3: TARAPOTO | E3: Meta | F3: Desembolsado | G3: Avance | H3: Pendiente De Documentar | I3: Pendiente De Remesa | J3: Pendiente De Backoffice | K3: Evaluación BCP | L3: Obs Backoffice | M3: Obs BCP | N3: Rechazado
D4: S/. | E4: 800000 | F4: =SUMIFS(OPI_4[MAF NETO],OPI_4[ESTADO],"Desembolsado") -> 331600 | G4: =F4-E4 -> -468400 | H4: =SUMIFS(OPI_4[MAF NETO],OPI_4[ESTADO],H$3) -> 0 | I4: =SUMIFS(OPI_4[MAF NETO],OPI_4[ESTADO],I$3) -> 0 | J4: =SUMIFS(OPI_4[MAF NETO],OPI_4[ESTADO],J$3) -> 0 | K4: =SUMIFS(OPI_4[MAF NETO],OPI_4[ESTADO],K$3) -> 73000 | L4: =SUMIFS(OPI_4[MAF NETO],OPI_4[ESTADO],L$3) -> 0 | M4: =SUMIFS(OPI_4[MAF NETO],OPI_4[ESTADO],M$3) -> 0 | N4: =SUMIFS(OPI_4[MAF NETO],OPI_4[ESTADO],N$3) -> 0
D5: Q / % | E5: - | F5: =COUNTIFS(OPI_4[ESTADO],"Desembolsado") -> 6 | G5: =IFERROR(F4/E4,"") -> 0.4145 | H5: =COUNTIFS(OPI_4[ESTADO],H$3) -> 0 | I5: =COUNTIFS(OPI_4[ESTADO],I$3) -> 0 | J5: =COUNTIFS(OPI_4[ESTADO],J$3) -> 0 | K5: =COUNTIFS(OPI_4[ESTADO],K$3) -> 1 | L5: =COUNTIFS(OPI_4[ESTADO],L$3) -> 0 | M5: =COUNTIFS(OPI_4[ESTADO],M$3) -> 0 | N5: =COUNTIFS(OPI_4[ESTADO],N$3) -> 2
B9: PLAZA DE VENTA | C9: FECHA DE ENVIO DE REMESA | D9: ESTADO DE REMESA | E9: FECHA DE INGRESO | F9: FECHA DE DESEMBOLSO | G9: DOCUMENTO | H9: NOMBRES Y APELLIDOS | I9: CONVENIO | J9: ESTADO | K9: MAF NETO | L9: EJECUTIVO | M9: FILE ENVIADO A BANCO | N9: FECHA DE ENVIÓ CARTA PODER A BCP | O9: COMPRA DE DEUDA REALIZADA | P9: LIBERACIÓN | Q9: FEEDBACK
B10: TARAPOTO | C10: 46195 | D10: Aprobada | E10: 46205 | G10: 71666083 | H10: CRISTIAN NILO MAS TORRES | I10: PNP | J10: Desembolsado | K10: 49450 | L10: ALCIDES FERNANDEZ PERALTA
B11: TARAPOTO | C11: 46212 | D11: Aprobada | G11: 41252243 | H11: PAOLA LILIANA PAREDES MACEDO | I11: PNP | J11: Desembolsado | K11: 67300 | L11: ALCIDES FERNANDEZ PERALTA
B12: TARAPOTO | C12: 46226 | D12: Rechazada | G12: 76432673 | H12: QUIÑONES RAMIREZ CHRISTIAN PAOLO | I12: PNP | J12: Rechazado | K12: 0 | L12: ELVIS ACOSTA BARBARAN | Q12: CLIENTE CON 02 CUOTAS DESCONTADAS, ESPERAR AGOSTO 2026
B13: TARAPOTO | C13: 46211 | D13: Aprobada | E13: 46211 | G13: 72627235 | H13: CARLOS ALBERTO SALINAS PAIMA | I13: PNP | J13: Desembolsado | K13: 39550 | L13: ELVIS ACOSTA BARBARAN
B14: TARAPOTO | C14: 46217 | D14: Aprobada | E14: 46219 | G14: 72213184 | H14: MORI MIRABAL CESAR ALEXIS | I14: PNP | J14: Desembolsado | K14: 46500 | L14: ALCIDES FERNANDEZ PERALTA
B15: TARAPOTO | C15: 46226 | D15: Aprobada | G15: 71831726 | H15: PINEDO GUERRA GIAN CARLOS | I15: PNP | J15: Desembolsado | K15: 48000 | L15: ALCIDES FERNANDEZ PERALTA
B16: TARAPOTO | C16: 46227 | D16: Aprobada | G16: 76558570 | H16: CORREA COTRINA ERIKA YESENIA | I16: PNP | J16: Rechazado | K16: 0 | L16: ALCIDES FERNANDEZ PERALTA
B17: TARAPOTO | C17: 46231 | D17: Aprobada | G17: 71559808 | H17: SABOYA LOPEZ VICTOR | I17: PNP | J17: Desembolsado | K17: 80800 | L17: ALCIDES FERNANDEZ PERALTA
B18: TARAPOTO | C18: 46231 | D18: Aprobada | G18: 73883997 | H18: OBLITAS FERNANDEZ CRISTIAN | I18: PNP | J18: Evaluación BCP | K18: 73000 | L18: ALCIDES FERNANDEZ PERALTA

Sheet KENNY MORALES
D3: LIMA | E3: Meta | F3: Desembolsado | G3: Avance | H3: Pendiente De Documentar | I3: Pendiente De Remesa | J3: Pendiente De Backoffice | K3: Evaluación BCP | L3: Obs Backoffice | M3: Obs BCP | N3: Rechazado
D4: S/. | E4: 1000000 | F4: =SUMIFS(OPI_6[MAF NETO],OPI_6[ESTADO],"Desembolsado") -> 532500 | G4: =F4-E4 -> -467500 | H4: =SUMIFS(OPI_6[MAF NETO],OPI_6[ESTADO],H$3) -> 0 | I4: =SUMIFS(OPI_6[MAF NETO],OPI_6[ESTADO],I$3) -> 0 | J4: =SUMIFS(OPI_6[MAF NETO],OPI_6[ESTADO],J$3) -> 0 | K4: =SUMIFS(OPI_6[MAF NETO],OPI_6[ESTADO],K$3) -> 354000 | L4: =SUMIFS(OPI_6[MAF NETO],OPI_6[ESTADO],L$3) -> 0 | M4: =SUMIFS(OPI_6[MAF NETO],OPI_6[ESTADO],M$3) -> 0 | N4: =SUMIFS(OPI_6[MAF NETO],OPI_6[ESTADO],N$3) -> 0
D5: Q / % | E5: - | F5: =COUNTIFS(OPI_6[ESTADO],"Desembolsado") -> 7 | G5: =IFERROR(F4/E4,"") -> 0.5325 | H5: =COUNTIFS(OPI_6[ESTADO],H$3) -> 0 | I5: =COUNTIFS(OPI_6[ESTADO],I$3) -> 0 | J5: =COUNTIFS(OPI_6[ESTADO],J$3) -> 0 | K5: =COUNTIFS(OPI_6[ESTADO],K$3) -> 5 | L5: =COUNTIFS(OPI_6[ESTADO],L$3) -> 0 | M5: =COUNTIFS(OPI_6[ESTADO],M$3) -> 0 | N5: =COUNTIFS(OPI_6[ESTADO],N$3) -> 6
B9: PLAZA DE VENTA | C9: FECHA DE ENVIO DE REMESA | D9: ESTADO DE REMESA | E9: FECHA DE INGRESO | F9: FECHA DE DESEMBOLSO | G9: DOCUMENTO | H9: NOMBRES Y APELLIDOS | I9: CONVENIO | J9: ESTADO | K9: MAF NETO | L9: EJECUTIVO | M9: FILE ENVIADO A BANCO | N9: FECHA DE ENVIÓ CARTA PODER A BCP | O9: COMPRA DE DEUDA REALIZADA | P9: LIBERACIÓN | Q9: FEEDBACK
B10: LIMA | C10: 46209 | D10: Aprobada | E10: 46209 | F10: 46211 | G10: 73439812 | H10: ACUÑA LEON JHON ALEKSANOR | I10: PNP | J10: Desembolsado | K10: 57500 | L10: SILVIA CASTAÑEDA | N10: 46212.0
B11: LIMA | C11: 46241 | D11: Aprobada | E11: 46210 | G11: 72217881 | H11: HILARIO DIAZ DARWIN ALBERTO | I11: PNP | J11: Rechazado | K11: 0 | L11: SALLY SAAVEDRA
B12: LIMA | C12: 46211 | D12: Aprobada | E12: 46211 | F12: 46213 | G12: 43923529 | H12: DAMIAN QUITO JOSH BECKER | I12: PNP | J12: Desembolsado | K12: 80100 | L12: SALLY SAAVEDRA
B13: LIMA | C13: 46211 | D13: Aprobada | E13: 46211 | G13: 10721455 | H13: PINCHI MORI ELENCIT | I13: DIRIS ESTE | J13: Desembolsado | K13: 70400 | L13: SALLY SAAVEDRA
B14: LIMA | C14: 46242 | D14: Aprobada | E14: 46211 | G14: 42368559 | H14: DIAZ FIGUEROA RONALD MILTON | I14: PNP | J14: Rechazado | K14: 0 | L14: SANDRO AVALOS | Q14: TIENE REFINANCIAMIENTO CON ALFIN, ATENDER PROXIMO MES, PAGARA DEUDA
B15: LIMA | C15: 46212 | D15: Aprobada | E15: 119261 | G15: 75227807 | H15: DE LA CRUZ PALOMINO JULIO DAVID FELICIANO | I15: PNP | J15: Rechazado | K15: 0 | L15: SANDRO AVALOS
B16: LIMA | C16: 46212 | D16: Aprobada | E16: 46212 | G16: 06646480 | H16: ROSAS MENDOZA CARMEN AMALIA | I16: ESSALUD | J16: Evaluación BCP | K16: 45500 | L16: PAOLA REYES
B17: LIMA | C17: 46216 | D17: Aprobada | E17: 46216 | G17: 10449742 | H17: PACHECO SOLSOL LOURDES ALICIA | I17: FAP | J17: Desembolsado | K17: 71500 | L17: PAOLA REYES
B18: LIMA | C18: 46216 | D18: Aprobada | E18: 46216 | F18: 46219 | G18: 42062037 | H18: ARI MAMANI MAGALY MARIA | I18: PNP | J18: Desembolsado | K18: 83500 | L18: SILVIA CASTAÑEDA | M18: Si
B19: LIMA | C19: 46217 | D19: Aprobada | E19: 46217 | G19: 10612262 | H19: GUTIERREZ LOPEZ MARILU | I19: DIRIS ESTE | J19: Desembolsado | K19: 127500 | L19: SALLY SAAVEDRA
B20: LIMA | C20: 46220 | D20: Aprobada | E20: 46220 | F20: 46225 | G20: 44470924 | H20: VIRRUETA CUBA JHONATAN JESUS | I20: PNP | J20: Desembolsado | K20: 42000 | L20: JENNY CARRANZA | Q20: -
B21: LIMA | C21: 46223 | D21: Aprobada | E21: 46223 | G21: 09645876 | H21: FERNANDEZ CAMARGO SABY MARGARITA | I21: FAP | J21: Rechazado | K21: 0 | L21: PAOLA REYES
B22: CAJAMARCA | C22: 46225 | D22: Rechazada | E22: 46225 | G22: 09859053 | H22: MORENO DIAZ FIDEL HJALMAR | I22: MIN. VIVIENDA | J22: Rechazado | K22: 0 | L22: SANDRO AVALOS | Q22: PENDIENTE DE FIRMAR EN AGENCIA CAJAMARCA
B23: HUANUCO | C23: 46233 | D23: Aprobada | E23: 46225 | G23: 70996559 | H23: LOPEZ VILLACREZ LINDER | I23: PNP | J23: Evaluación BCP | K23: 70400 | L23: SALLY SAAVEDRA | Q23: PENDIENTE POR FIRMAR
B24: PUCALPA | C24: 46227 | D24: Aprobada | E24: 46227 | G24: 73099958 | H24: DEL AGUILA PEREZ LUIS ABERTO | I24: MGP | J24: Evaluación BCP | K24: 82000 | L24: PAOLA REYES
B25: LIMA | C25: 46958 | D25: Aprobada | E25: 46227 | G25: 10162067 | H25: CAMARGO SANTOS LENIN LUIS | I25: DIRIS CENTRO | J25: Evaluación BCP | K25: 75000 | L25: SALLY SAAVEDRA
B26: LIMA | C26: 46233 | D26: Rechazada | E26: 46233 | F26: PARA AGOSTO | G26: 77078116 | H26: ADRIANZEN TIMANA OMAR PAUL | I26: PNP | J26: Rechazado | K26: 0 | L26: ROXANA FERNANDEZ
B27: liMA | C27: 46233 | D27: Aprobada | E27: 46234 | G27: 46286134 | H27: GUTARRA LORENZO MERCEDES VERENISSE | I27: DIRIS LIMA ESTE | J27: Evaluación BCP | K27: 81100 | L27: SALLY SAAVEDRA

Sheet WINNIE ESCALANTE
D3: LIMA | E3: Meta | F3: Desembolsado | G3: Avance | H3: Pendiente De Documentar | I3: Pendiente De Remesa | J3: Pendiente De Backoffice | K3: Evaluación BCP | L3: Obs Backoffice | M3: Obs BCP | N3: Rechazado
D4: S/. | E4: 2000000 | F4: =SUMIFS(OPI_10[MAF NETO],OPI_10[ESTADO],"Desembolsado") -> 2030440 | G4: =F4-E4 -> 30440 | H4: =SUMIFS(OPI_10[MAF NETO],OPI_10[ESTADO],H$3) -> 0 | I4: =SUMIFS(OPI_10[MAF NETO],OPI_10[ESTADO],I$3) -> 0 | J4: =SUMIFS(OPI_10[MAF NETO],OPI_10[ESTADO],J$3) -> 0 | K4: =SUMIFS(OPI_10[MAF NETO],OPI_10[ESTADO],K$3) -> 65000 | L4: =SUMIFS(OPI_10[MAF NETO],OPI_10[ESTADO],L$3) -> 0 | M4: =SUMIFS(OPI_10[MAF NETO],OPI_10[ESTADO],M$3) -> 0 | N4: =SUMIFS(OPI_10[MAF NETO],OPI_10[ESTADO],N$3) -> 0
D5: Q / % | E5: - | F5: =COUNTIFS(OPI_10[ESTADO],"Desembolsado") -> 33 | G5: =IFERROR(F4/E4,"") -> 1.01522 | H5: =COUNTIFS(OPI_10[ESTADO],H$3) -> 0 | I5: =COUNTIFS(OPI_10[ESTADO],I$3) -> 0 | J5: =COUNTIFS(OPI_10[ESTADO],J$3) -> 0 | K5: =COUNTIFS(OPI_10[ESTADO],K$3) -> 1 | L5: =COUNTIFS(OPI_10[ESTADO],L$3) -> 0 | M5: =COUNTIFS(OPI_10[ESTADO],M$3) -> 1 | N5: =COUNTIFS(OPI_10[ESTADO],N$3) -> 3
B9: PLAZA DE VENTA | C9: FECHA DE ENVIO DE REMESA | D9: ESTADO DE REMESA | E9: FECHA DE INGRESO | F9: FECHA DE DESEMBOLSO | G9: DOCUMENTO | H9: NOMBRES Y APELLIDOS | I9: CONVENIO | J9: ESTADO | K9: MAF NETO | L9: EJECUTIVO | M9: FILE ENVIADO A BANCO | N9: FECHA DE ENVIÓ CARTA PODER A BCP | O9: COMPRA DE DEUDA REALIZADA | P9: LIBERACIÓN | Q9: FEEDBACK
D10: Aprobada | E10: 46204 | F10: 0-07-2026 | G10: 71541694 | H10: GARCIA TRUJILLO EBERTH | I10: PNP | J10: Desembolsado | K10: 79530 | L10: MILY FERNANDEZ
D11: Aprobada | E11: 46206 | F11: 46206 | G11: 75523889 | H11: YUPANQUI ESTRADA,JEANCARLOS RAFAEL | I11: PNP | J11: Desembolsado | K11: 50300 | L11: LEIDY EGOAVIL
D12: Aprobada | E12: 46206 | G12: 76420743 | H12: CUBAS RAMIREZ,BELERMINA | I12: PNP | J12: Desembolsado | K12: 57150 | L12: ELIZABETH ESQUIVEL
D13: Aprobada | E13: 46209 | G13: 76588636 | H13: PERALTA GOMEZ,JOSE GRIMALDO | I13: PNP | J13: Desembolsado | K13: 82250 | L13: MILY FERNANDEZ
D14: Aprobada | F14: 46218 | G14: 09956180 | H14: REYES INFANTE ADALBERTO LIZARDO | I14: DIRIS | J14: Desembolsado | K14: 71400 | L14: MILY FERNANDEZ
D15: Aprobada | E15: 46209 | G15: 46575092 | H15: SUSANIBAR RIVERA LUIS DONAIRE | I15: ESSALUD | J15: Desembolsado | K15: 15000 | L15: ELIZABETH ESQUIVEL
D16: Aprobada | E16: 46209 | F16: 46216 | G16: 48008941 | H16: SANCHEZ ORE DAVID | I16: EP | J16: Desembolsado | K16: 80000 | L16: MILY FERNANDEZ
D17: Aprobada | E17: 46206 | F17: 46209 | G17: 70171724 | H17: LAURA DAMIANO,YAQUELIN | I17: PNP | J17: Desembolsado | K17: 35650 | L17: MARIELA JURADO
D18: Aprobada | E18: 46209 | F18: 46209 | G18: 72724697 | H18: ZAVALA ILLATOPA,LUIGI PAOLO | I18: PNP | J18: Desembolsado | K18: 75700 | L18: PIO FERREYRA
D19: Aprobada | E19: 46209 | G19: 70421309 | H19: CCARHUAYPIÑA PARIONA ERIC ELIAL | I19: EP | J19: Obs BCP | K19: 0 | L19: PIO FERREYRA
D20: Aprobada | E20: 46209 | G20: 74124929 | H20: ROJAS HIDALGO,NILTHON ANDRE | I20: PNP | J20: Desembolsado | K20: 73580 | L20: PIO FERREYRA
C21: 46209 | D21: Aprobada | E21: 46210 | F21: 46212 | G21: 74500582 | H21: CRIOLLO CORNEJO,KLIVER JEFFERSON | I21: PNP | J21: Desembolsado | K21: 82780 | L21: CARLA CORNEJO
D22: Aprobada | E22: 46209 | G22: 74349550 | H22: OSORES HUAMAN,ANTHONY CLAUDIO | I22: PNP | J22: Desembolsado | K22: 83300 | L22: MILY FERNANDEZ
C23: 46210 | D23: Aprobada | E23: 46211 | G23: 44254146 | H23: MENDOZA MAZA EDWIN FABIAN | I23: EP | J23: Desembolsado | K23: 85250 | L23: MILY FERNANDEZ
D24: Aprobada | G24: 42633545 | H24: CRUZADO VASQUEZ MIRELLA KATHERINE | I24: ESSALUD | J24: Desembolsado | K24: 39850 | L24: ELIZABETH ESQUIVEL
