Workbook

Sheet CONSOLIDADO
B2: Tablas de Gestión:
B4: SUPERVISOR | C4: ZONA | D4: TOTAL DESEMBOLSO | E4: Q DESEMBOLSO | F4: EVALUACION BCP | G4: PENDIENTE DE BACK | H4: PENDIENTE DE REMESA | I4: PENDIENTE DE DOCUMENTAR | J4: META OBJETIVO | K4: AVANCE | L4: Q EVALUACION BCP | M4: Q PENDIENTE DE BACK
B5: JIMMY COLLAZOS | C5: ='JIMMY COLLAZOS'!D3 -> TARAPOTO | D5: ='JIMMY COLLAZOS'!$F$4 -> 258960 | E5: ='JIMMY COLLAZOS'!$F$5 -> 4 | F5: ='JIMMY COLLAZOS'!$K$4 -> 0 | G5: ='JIMMY COLLAZOS'!$J$4 -> 0 | H5: ='JIMMY COLLAZOS'!$I$4 -> 0 | I5: ='JIMMY COLLAZOS'!$H$4 -> 0 | J5: ='JIMMY COLLAZOS'!E4 -> 800000 | K5: =D5/J5 -> 0.3237 | L5: ='JIMMY COLLAZOS'!$K$5 -> 0 | M5: ='JIMMY COLLAZOS'!$J$5 -> 0
B6: ALEXANDRA GUZMAN | C6: ='ALEXANDRA GUZMAN'!D3 -> PIURA | D6: ='ALEXANDRA GUZMAN'!$F$4 -> 39650 | E6: ='ALEXANDRA GUZMAN'!$F$5 -> 1 | F6: ='ALEXANDRA GUZMAN'!$K$4 -> 0 | G6: ='ALEXANDRA GUZMAN'!$J$4 -> 0 | H6: ='ALEXANDRA GUZMAN'!$I$4 -> 0 | I6: ='ALEXANDRA GUZMAN'!$H$4 -> 0 | J6: 1000000 | K6: =D6/J6 -> 0.03965 | L6: ='ALEXANDRA GUZMAN'!$K$5 -> 0 | M6: ='ALEXANDRA GUZMAN'!$J$5 -> 0
B7: AMALIA QUINDE | C7: ='AMALIA QUINDE'!D3 -> PIURA | D7: ='AMALIA QUINDE'!$F$4 -> 64200 | E7: ='AMALIA QUINDE'!$F$5 -> 1 | F7: ='AMALIA QUINDE'!$K$4 -> 0 | G7: ='AMALIA QUINDE'!$J$4 -> 0 | H7: ='AMALIA QUINDE'!$I$4 -> 0 | I7: ='AMALIA QUINDE'!$H$4 -> 0 | J7: 1000000 | K7: =D7/J7 -> 0.0642 | L7: ='AMALIA QUINDE'!$K$5 -> 0 | M7: ='AMALIA QUINDE'!$J$5 -> 0
B8: JORGE CASTILLO | C8: ='JORGE CASTILLO'!D3 -> PIURA | D8: ='JORGE CASTILLO'!$F$4 -> 123500 | E8: ='JORGE CASTILLO'!$F$5 -> 2 | F8: ='JORGE CASTILLO'!$K$4 -> 0 | G8: ='JORGE CASTILLO'!$J$4 -> 0 | H8: ='JORGE CASTILLO'!$I$4 -> 0 | I8: ='JORGE CASTILLO'!$H$4 -> 0 | J8: 1000000 | K8: =D8/J8 -> 0.1235 | L8: ='JORGE CASTILLO'!$K$5 -> 0 | M8: ='JORGE CASTILLO'!$J$5 -> 0
B9: WENDY IPANAQUÉ | C9: ='WENDY IPANEQUE'!D3 -> PIURA | D9: ='WENDY IPANEQUE'!$F$4 -> 451270 | E9: ='WENDY IPANEQUE'!$F$5 -> 7 | F9: ='WENDY IPANEQUE'!$K$4 -> 0 | G9: ='WENDY IPANEQUE'!$J$4 -> 0 | H9: ='WENDY IPANEQUE'!$I$4 -> 0 | I9: ='WENDY IPANEQUE'!$H$4 -> 0 | J9: 1000000 | K9: =D9/J9 -> 0.45127 | L9: ='WENDY IPANEQUE'!$K$5 -> 0 | M9: ='WENDY IPANEQUE'!$J$5 -> 0
B10: ANGIE SILVERA | C10: ='ANGIE SILVERA'!D3 -> LIMA | D10: ='ANGIE SILVERA'!$F$4 -> 1083450 | E10: ='ANGIE SILVERA'!$F$5 -> 16 | F10: ='ANGIE SILVERA'!$K$4 -> 0 | G10: ='ANGIE SILVERA'!$J$4 -> 0 | H10: ='ANGIE SILVERA'!$I$4 -> 0 | I10: ='ANGIE SILVERA'!$H$4 -> 0 | J10: ='ANGIE SILVERA'!E4 -> 2000000 | K10: =D10/J10 -> 0.541725 | L10: ='ANGIE SILVERA'!$K$5 -> 0 | M10: ='ANGIE SILVERA'!$J$5 -> 0
B11: KENNY MORALES | C11: ='KENNY MORALES'!D3 -> LIMA | D11: ='KENNY MORALES'!$F$4 -> 836020 | E11: ='KENNY MORALES'!$F$5 -> 12 | F11: ='KENNY MORALES'!$K$4 -> 0 | G11: ='KENNY MORALES'!$J$4 -> 0 | H11: ='KENNY MORALES'!$I$4 -> 0 | I11: ='KENNY MORALES'!$H$4 -> 0 | J11: ='KENNY MORALES'!E4 -> 1000000 | K11: =D11/J11 -> 0.83602 | L11: ='KENNY MORALES'!$K$5 -> 0 | M11: ='KENNY MORALES'!$J$5 -> 0
B12: LUIS CHUSE | C12: ='LUIS CHUSE'!D3 -> LIMA | D12: ='LUIS CHUSE'!$F$4 -> 1428953 | E12: ='LUIS CHUSE'!$F$5 -> 21 | F12: ='LUIS CHUSE'!$K$4 -> 0 | G12: ='LUIS CHUSE'!$J$4 -> 0 | H12: ='LUIS CHUSE'!$I$4 -> 0 | I12: ='LUIS CHUSE'!$H$4 -> 0 | J12: ='LUIS CHUSE'!E4 -> 2000000 | K12: =D12/J12 -> 0.7144765 | L12: ='LUIS CHUSE'!$K$5 -> 0 | M12: ='LUIS CHUSE'!$J$5 -> 0
B13: MARIELLA PAÑAHUA | C13: ='MARIELLA PAÑAHUA'!D3 -> AYACUCHO | D13: ='MARIELLA PAÑAHUA'!$F$4 -> 857400 | E13: ='MARIELLA PAÑAHUA'!$F$5 -> 14 | F13: ='MARIELLA PAÑAHUA'!$K$4 -> 0 | G13: ='MARIELLA PAÑAHUA'!$J$4 -> 0 | H13: ='MARIELLA PAÑAHUA'!$I$4 -> 0 | I13: ='MARIELLA PAÑAHUA'!$H$4 -> 0 | J13: ='MARIELLA PAÑAHUA'!E4 -> 800000 | K13: =D13/J13 -> 1.07175 | L13: ='MARIELLA PAÑAHUA'!$K$5 -> 0 | M13: ='MARIELLA PAÑAHUA'!$J$5 -> 0
B14: MILAGROS TUESTA | C14: ='MILAGROS TUESTA'!D3 -> LIMA | D14: ='MILAGROS TUESTA'!$F$4 -> 1049520 | E14: ='MILAGROS TUESTA'!$F$5 -> 16 | F14: ='MILAGROS TUESTA'!$K$4 -> 0 | G14: ='MILAGROS TUESTA'!$J$4 -> 0 | H14: ='MILAGROS TUESTA'!$I$4 -> 0 | I14: ='MILAGROS TUESTA'!$H$4 -> 0 | J14: ='MILAGROS TUESTA'!E4 -> 2000000 | K14: =D14/J14 -> 0.52476 | L14: ='MILAGROS TUESTA'!$K$5 -> 0 | M14: ='MILAGROS TUESTA'!$J$5 -> 0
B15: JOSE LUIS QUINTEROS | C15: LIMA | D15: ='JOSE LUIS QUINTEROS'!$F$4 -> 68200 | E15: ='JOSE LUIS QUINTEROS'!$F$5 -> 1 | F15: ='JOSE LUIS QUINTEROS'!$K$4 -> 0 | G15: ='JOSE LUIS QUINTEROS'!$J$4 -> 0 | H15: ='JOSE LUIS QUINTEROS'!$I$4 -> 0 | I15: ='JOSE LUIS QUINTEROS'!$H$4 -> 0 | J15: ='JOSE LUIS QUINTEROS'!E4 -> 1000000 | K15: =D15/J15 -> 0.0682 | L15: ='JOSE LUIS QUINTEROS'!$K$5 -> 0 | M15: ='JOSE LUIS QUINTEROS'!$J$5 -> 0
B16: CRISTINA BRACAMONTE | C16: ='CRISTINA BRACAMONTE'!D3 -> TRUJILLO | D16: ='CRISTINA BRACAMONTE'!$F$4 -> 0 | E16: ='CRISTINA BRACAMONTE'!$F$5 -> 0 | F16: ='CRISTINA BRACAMONTE'!$K$4 -> 0 | G16: ='CRISTINA BRACAMONTE'!$J$4 -> 0 | H16: ='CRISTINA BRACAMONTE'!$I$4 -> 0 | I16: ='CRISTINA BRACAMONTE'!$H$4 -> 0 | J16: 1000000 | K16: =D16/J16 -> 0 | L16: ='CRISTINA BRACAMONTE'!$K$5 -> 0 | M16: ='CRISTINA BRACAMONTE'!$J$5 -> 0
B17: JHON ZAMORA | C17: ='JHON ZAMORA'!D3 -> CHICLAYO | D17: ='JHON ZAMORA'!$F$4 -> 505900 | E17: ='JHON ZAMORA'!$F$5 -> 7 | F17: ='JHON ZAMORA'!$K$4 -> 0 | G17: ='JHON ZAMORA'!$J$4 -> 0 | H17: ='JHON ZAMORA'!$I$4 -> 0 | I17: ='JHON ZAMORA'!$H$4 -> 0 | J17: 1000000 | K17: =#REF!/J17 -> #REF! | L17: ='JHON ZAMORA'!$K$5 -> 0 | M17: ='JHON ZAMORA'!$J$5 -> 0
B18: OMAR MINAYA | C18: ='OMAR MINAYA'!D3 -> CHICLAYO | D18: ='OMAR MINAYA'!$F$4 -> 327840 | E18: ='OMAR MINAYA'!$F$5 -> 5 | F18: ='OMAR MINAYA'!$K$4 -> 0 | G18: ='OMAR MINAYA'!$J$4 -> 0 | H18: ='OMAR MINAYA'!$I$4 -> 0 | I18: ='OMAR MINAYA'!$H$4 -> 0 | J18: 1000000 | K18: 19899 | L18: ='OMAR MINAYA'!$K$5 -> 0 | M18: ='OMAR MINAYA'!$J$5 -> 0
B19: NAHOMI DIAZ | C19: ='NAHOMI DIAZ'!D3 -> CHICLAYO | D19: ='NAHOMI DIAZ'!$F$4 -> 1022083 | E19: ='NAHOMI DIAZ'!$F$5 -> 15 | F19: ='NAHOMI DIAZ'!$K$4 -> 0 | G19: ='NAHOMI DIAZ'!$J$4 -> 0 | H19: ='NAHOMI DIAZ'!$I$4 -> 0 | I19: ='NAHOMI DIAZ'!$H$4 -> 0 | J19: 1000000 | K19: =D19/J19 -> 1.022083 | L19: ='NAHOMI DIAZ'!$K$5 -> 0 | M19: ='NAHOMI DIAZ'!$J$5 -> 0
B20: VIOLETA LLERENA | C20: ='VIOLETA LLERENA'!D3 -> AREQUIPA | D20: ='VIOLETA LLERENA'!$F$4 -> 522050 | E20: ='VIOLETA LLERENA'!$F$5 -> 7 | F20: ='VIOLETA LLERENA'!$K$4 -> 0 | G20: ='VIOLETA LLERENA'!$J$4 -> 0 | H20: ='VIOLETA LLERENA'!$I$4 -> 0 | I20: ='VIOLETA LLERENA'!$H$4 -> 0 | J20: 1000000 | K20: =D20/J20 -> 0.52205 | L20: ='VIOLETA LLERENA'!$K$5 -> 0 | M20: ='VIOLETA LLERENA'!$J$5 -> 0
B21: TOTAL | D21: =SUM(D5:D20) -> 8638996 | E21: =SUM(E5:E20) -> 129 | F21: =SUM(F5:F20) -> 0 | G21: =SUM(G5:G20) -> 0 | H21: =SUM(H5:H20) -> 0 | I21: =SUM(I5:I20) -> 0 | J21: =SUM(J5:J20) -> 18600000 | K21: =D21/J21 -> 0.46446215 | L21: =SUM(L5:L20) -> 0 | M21: =SUM(M5:M20) -> 0
B24: PLAZA | D24: TOTAL DESEMBOLSO | E24: Q DESEMBOLSO | F24: EVALUACION BCP | G24: PENDIENTE DE BACK | H24: PENDIENTE DE REMESA | I24: PENDIENTE DE DOCUMENTAR | J24: META OBJETIVO | K24: AVANCE | L24: Q EVALUACION BCP | M24: Q PENDIENTE DE BACK
B25: LIMA | D25: =SUMIFS(D$5:D$20,$C$5:$C$20,$B25) -> 4466143 | E25: =SUMIFS(E$5:E$20,$C$5:$C$20,$B25) -> 66 | F25: =SUMIFS(F$5:F$20,$C$5:$C$20,$B25) -> 0 | G25: =SUMIFS(G$5:G$20,$C$5:$C$20,$B25) -> 0 | H25: =SUMIFS(H$5:H$20,$C$5:$C$20,$B25) -> 0 | I25: =SUMIFS(I$5:I$20,$C$5:$C$20,$B25) -> 0 | J25: =SUMIFS(J$5:J$20,$C$5:$C$20,$B25) -> 8000000 | K25: =D25/J25 -> 0.55826787 | L25: =SUMIFS(L$5:L$20,$C$5:$C$20,$B25) -> 0 | M25: =SUMIFS(M$5:M$20,$C$5:$C$20,$B25) -> 0
B26: NORTE | D26: =SUMIFS(D5:D20,$C$5:$C$20,"CHICLAYO")+SUMIFS(D5:D20,$C$5:$C$20,"TRUJILLO")+SUMIFS(D5:D20,$C$5:$C$20,"PIURA") -> 2534443 | E26: =SUMIFS(E5:E20,$C$5:$C$20,"CHICLAYO")+SUMIFS(E5:E20,$C$5:$C$20,"TRUJILLO")+SUMIFS(E5:E20,$C$5:$C$20,"PIURA") -> 38 | F26: =SUMIFS(F5:F20,$C$5:$C$20,"CHICLAYO")+SUMIFS(F5:F20,$C$5:$C$20,"TRUJILLO")+SUMIFS(F5:F20,$C$5:$C$20,"PIURA") -> 0 | G26: =SUMIFS(G5:G20,$C$5:$C$20,"CHICLAYO")+SUMIFS(G5:G20,$C$5:$C$20,"TRUJILLO")+SUMIFS(G5:G20,$C$5:$C$20,"PIURA") -> 0 | H26: =SUMIFS(H5:H20,$C$5:$C$20,"CHICLAYO")+SUMIFS(H5:H20,$C$5:$C$20,"TRUJILLO")+SUMIFS(H5:H20,$C$5:$C$20,"PIURA") -> 0 | I26: =SUMIFS(I5:I20,$C$5:$C$20,"CHICLAYO")+SUMIFS(I5:I20,$C$5:$C$20,"TRUJILLO")+SUMIFS(I5:I20,$C$5:$C$20,"PIURA") -> 0 | J26: =SUMIFS(J5:J20,$C$5:$C$20,"CHICLAYO")+SUMIFS(J5:J20,$C$5:$C$20,"TRUJILLO")+SUMIFS(J5:J20,$C$5:$C$20,"PIURA") -> 8000000 | K26: =D26/J26 -> 0.31680538 | L26: =SUMIFS(L5:L20,$C$5:$C$20,"CHICLAYO")+SUMIFS(L5:L20,$C$5:$C$20,"TRUJILLO")+SUMIFS(L5:L20,$C$5:$C$20,"PIURA") -> 0 | M26: =SUMIFS(M5:M20,$C$5:$C$20,"CHICLAYO")+SUMIFS(M5:M20,$C$5:$C$20,"TRUJILLO")+SUMIFS(M5:M20,$C$5:$C$20,"PIURA") -> 0
B27: TARAPOTO | D27: =SUMIFS(D5:D20,$C$5:$C$20,"TARAPOTO") -> 258960 | E27: =SUMIFS(E5:E20,$C$5:$C$20,"TARAPOTO") -> 4 | F27: =SUMIFS(F5:F20,$C$5:$C$20,"TARAPOTO") -> 0 | G27: =SUMIFS(G5:G20,$C$5:$C$20,"TARAPOTO") -> 0 | H27: =SUMIFS(H5:H20,$C$5:$C$20,"TARAPOTO") -> 0 | I27: =SUMIFS(I5:I20,$C$5:$C$20,"TARAPOTO") -> 0 | J27: =SUMIFS(J5:J20,$C$5:$C$20,"TARAPOTO") -> 800000 | K27: =D27/J27 -> 0.3237 | L27: =SUMIFS(L5:L20,$C$5:$C$20,"TARAPOTO") -> 0 | M27: =SUMIFS(M5:M20,$C$5:$C$20,"TARAPOTO") -> 0
B28: AYACUCHO | D28: =SUMIFS(D5:D20,$C$5:$C$20,"AYACUCHO") -> 857400 | E28: =SUMIFS(E5:E20,$C$5:$C$20,"AYACUCHO") -> 14 | F28: =SUMIFS(F5:F20,$C$5:$C$20,"AYACUCHO") -> 0 | G28: =SUMIFS(G5:G20,$C$5:$C$20,"AYACUCHO") -> 0 | H28: =SUMIFS(H5:H20,$C$5:$C$20,"AYACUCHO") -> 0 | I28: =SUMIFS(I5:I20,$C$5:$C$20,"AYACUCHO") -> 0 | J28: =SUMIFS(J5:J20,$C$5:$C$20,"AYACUCHO") -> 800000 | K28: =D28/J28 -> 1.07175 | L28: =SUMIFS(L5:L20,$C$5:$C$20,"AYACUCHO") -> 0 | M28: =SUMIFS(M5:M20,$C$5:$C$20,"AYACUCHO") -> 0
B29: AREQUIPA | D29: =SUMIFS(D5:D20,$C$5:$C$20,"AREQUIPA") -> 522050 | E29: =SUMIFS(E5:E20,$C$5:$C$20,"AREQUIPA") -> 7 | F29: =SUMIFS(F5:F20,$C$5:$C$20,"AREQUIPA") -> 0 | G29: =SUMIFS(G5:G20,$C$5:$C$20,"AREQUIPA") -> 0 | H29: =SUMIFS(H5:H20,$C$5:$C$20,"AREQUIPA") -> 0 | I29: =SUMIFS(I5:I20,$C$5:$C$20,"AREQUIPA") -> 0 | J29: =SUMIFS(J5:J20,$C$5:$C$20,"AREQUIPA") -> 1000000 | K29: =D29/J29 -> 0.52205 | L29: =SUMIFS(L5:L20,$C$5:$C$20,"AREQUIPA") -> 0 | M29: =SUMIFS(M6:M21,$C$5:$C$20,"TARAPOTO") -> 0
B30: TOTAL | D30: =SUM(D25:D29) -> 8638996 | E30: =SUM(E25:E29) -> 129 | F30: =SUM(F25:F29) -> 0 | G30: =SUM(G25:G29) -> 0 | H30: =SUM(H25:H29) -> 0 | I30: =SUM(I25:I29) -> 0 | J30: =SUM(J25:J29) -> 18600000 | K30: =D30/J30 -> 0.46446215 | L30: =SUM(L25:L29) -> 0 | M30: =SUM(M25:M29) -> 0

Sheet NAHOMI DIAZ
D3: CHICLAYO | E3: Meta | F3: Desembolsado | G3: Avance | H3: Pendiente De Documentar | I3: Pendiente De Remesa | J3: Pendiente De Backoffice | K3: Evaluación BCP | L3: Obs Backoffice | M3: Obs BCP | N3: Rechazado
D4: S/. | E4: 1000000 | F4: =SUMIFS(OPI_11[MAF NETO],OPI_11[ESTADO],"Desembolsado") -> 1022083 | G4: =F4-E4 -> 22083 | H4: =SUMIFS(OPI_11[MAF NETO],OPI_11[ESTADO],H$3) -> 0 | I4: =SUMIFS(OPI_11[MAF NETO],OPI_11[ESTADO],I$3) -> 0 | J4: =SUMIFS(OPI_11[MAF NETO],OPI_11[ESTADO],J$3) -> 0 | K4: =SUMIFS(OPI_11[MAF NETO],OPI_11[ESTADO],K$3) -> 0 | L4: =SUMIFS(OPI_11[MAF NETO],OPI_11[ESTADO],L$3) -> 0 | M4: =SUMIFS(OPI_11[MAF NETO],OPI_11[ESTADO],M$3) -> 0 | N4: =SUMIFS(OPI_11[MAF NETO],OPI_11[ESTADO],N$3) -> 75000
D5: Q / % | E5: - | F5: =COUNTIFS(OPI_11[ESTADO],"Desembolsado") -> 15 | G5: =IFERROR(F4/E4,"") -> 1.022083 | H5: =COUNTIFS(OPI_11[ESTADO],H$3) -> 0 | I5: =COUNTIFS(OPI_11[ESTADO],I$3) -> 0 | J5: =COUNTIFS(OPI_11[ESTADO],J$3) -> 0 | K5: =COUNTIFS(OPI_11[ESTADO],K$3) -> 0 | L5: =COUNTIFS(OPI_11[ESTADO],L$3) -> 0 | M5: =COUNTIFS(OPI_11[ESTADO],M$3) -> 0 | N5: =COUNTIFS(OPI_11[ESTADO],N$3) -> 1
B9: PLAZA DE VENTA | C9: FECHA DE ENVIO DE REMESA | D9: ESTADO DE REMESA | E9: FECHA DE INGRESO | F9: FECHA DE DESEMBOLSO | G9: DOCUMENTO | H9: NOMBRES Y APELLIDOS | I9: CONVENIO | J9: ESTADO | K9: MAF NETO | L9: EJECUTIVO | M9: FILE ENVIADO A BANCO | N9: FECHA DE ENVIÓ CARTA PODER A BCP | O9: COMPRA DE DEUDA REALIZADA | P9: LIBERACIÓN | Q9: FEEDBACK
C10: 46175 | D10: Aprobada | E10: 46176 | F10: 46176.0 | G10: 41514627 | H10: CARRION CAVERO ROSA AMARILIS | I10: PNP | J10: Desembolsado | K10: 85800 | L10: AZUCENA BARBA
C11: 46177 | D11: Aprobada | G11: 77666939 | H11: MAMANI INQUILLA VICTOR HUGO | I11: EP | J11: Desembolsado | K11: 67300 | L11: AZUCENA BARBA
C12: 46177 | D12: Aprobada | G12: 46250678 | H12: RAMOS SOPLAPUCO JOSE EDWARD | I12: PNP | J12: Desembolsado | K12: 38380 | L12: AZUCENA BARBA | M12: Si
C13: 46182 | D13: Aprobada | G13: 76214250 | H13: VELA UPIACHIHUA IMELDA CRISTINA | I13: EP | J13: Desembolsado | K13: 84750 | L13: AZUCENA BARBA
C14: 46177 | D14: Aprobada | G14: 72147906 | H14: FLOREZ SUICO MARCO ANTONIO | I14: EP | J14: Desembolsado | K14: 62900 | L14: EYLIN VELASCO
C15: 46172 | D15: Aprobada | G15: 78019686 | H15: BARRANTES GRAVELO KENNEDY JEAN | I15: PNP | J15: Desembolsado | K15: 68000 | L15: EYLIN VELASCO
C16: 46188 | D16: Aprobada | G16: 46127105 | H16: SUCLUPE MATALLANA PABLO EDUARDO | I16: EP | J16: Desembolsado | K16: 82430 | L16: EYLIN VELASCO
C17: 46188 | D17: Aprobada | G17: 44833448 | H17: LABRIN PEÑA JUAN HUMBERTO | I17: PNP | J17: Desembolsado | K17: 54400 | L17: EYLIN VELASCO | M17: Si | Q17: AN FUERTE
C18: 46196 | D18: Aprobada | G18: 72295901 | H18: TORRES INGA VICTOR MATEO | I18: PNP | J18: Desembolsado | K18: 99800 | L18: EYLIN VELASCO
C19: 46196 | D19: Rechazada | G19: 10710796 | H19: ÑAUPAS NEGRETE ROBERTO ALEXANDER | I19: EP | J19: Rechazado | K19: 75000 | L19: EYLIN VELASCO
C20: 46183 | D20: Aprobada | G20: 47057610 | H20: BRAVO GALVEZ NOHELY MARISOL | I20: PNP | J20: Desembolsado | K20: 65000 | L20: EYLIN VELASCO | M20: Si
C21: 46176 | D21: Aprobada | G21: 48319584 | H21: VALLADOLID VALLEJOS ESGAR ANDRES | I21: PNP | J21: Desembolsado | K21: 62000 | L21: JUDITH FARRO
C22: 46188 | D22: Aprobada | G22: 73526922 | H22: NUÑEZ OLIVERA JONATHAN JAIR | I22: PNP | J22: Desembolsado | K22: 63623 | L22: JUDITH FARRO
C23: 46199 | D23: Aprobada | G23: 42541929 | H23: SANCHEZ CHONATE JULIO CESAR | I23: PNP | J23: Desembolsado | K23: 59300 | L23: JUDITH FARRO | M23: Si
C24: 46189 | D24: Aprobada | G24: 73341946 | H24: CORONEL LLAMO GEINER OMAR | I24: PNP | J24: Desembolsado | K24: 75000 | L24: JUDITH FARRO | M24: Si
C25: 46175 | D25: Aprobada | G25: 72307920 | H25: FUSTAMANTE HERRERA CARLOS ALBERTO | I25: PNP | J25: Desembolsado | K25: 53400 | L25: YURIKO OSPINO

Sheet ANGIE SILVERA
D3: LIMA | E3: Meta | F3: Desembolsado | G3: Avance | H3: Pendiente De Documentar | I3: Pendiente De Remesa | J3: Pendiente De Backoffice | K3: Evaluación BCP | L3: Obs Backoffice | M3: Obs BCP | N3: Rechazado
D4: S/. | E4: 2000000 | F4: =SUMIFS(OPI[MAF NETO],OPI[ESTADO],"Desembolsado") -> 1083450 | G4: =F4-E4 -> -916550 | H4: =SUMIFS(OPI[MAF NETO],OPI[ESTADO],H$3) -> 0 | I4: =SUMIFS(OPI[MAF NETO],OPI[ESTADO],I$3) -> 0 | J4: =SUMIFS(OPI[MAF NETO],OPI[ESTADO],J$3) -> 0 | K4: =SUMIFS(OPI[MAF NETO],OPI[ESTADO],K$3) -> 0 | L4: =SUMIFS(OPI[MAF NETO],OPI[ESTADO],L$3) -> 0 | M4: =SUMIFS(OPI[MAF NETO],OPI[ESTADO],M$3) -> 0 | N4: =SUMIFS(OPI[MAF NETO],OPI[ESTADO],N$3) -> 0
D5: Q / % | E5: - | F5: =COUNTIFS(OPI[ESTADO],"Desembolsado") -> 16 | G5: =IFERROR(F4/E4,"") -> 0.541725 | H5: =COUNTIFS(OPI[ESTADO],H$3) -> 0 | I5: =COUNTIFS(OPI[ESTADO],I$3) -> 0 | J5: =COUNTIFS(OPI[ESTADO],J$3) -> 0 | K5: =COUNTIFS(OPI[ESTADO],K$3) -> 0 | L5: =COUNTIFS(OPI[ESTADO],L$3) -> 0 | M5: =COUNTIFS(OPI[ESTADO],M$3) -> 0 | N5: =COUNTIFS(OPI[ESTADO],N$3) -> 0
B9: PLAZA DE VENTA | C9: FECHA DE ENVIO DE REMESA | D9: ESTADO DE REMESA | E9: FECHA DE INGRESO | F9: FECHA DE DESEMBOLSO | G9: DOCUMENTO | H9: NOMBRES Y APELLIDOS | I9: CONVENIO | J9: ESTADO | K9: MAF NETO | L9: EJECUTIVO | M9: FILE ENVIADO A BANCO | N9: FECHA DE ENVIÓ CARTA PODER A BCP | O9: COMPRA DE DEUDA REALIZADA | P9: LIBERACIÓN | Q9: FEEDBACK
B10: LIMA | C10: 46174 | D10: Aprobada | E10: 46175 | F10: 46175 | G10: 44988215 | H10: TICONA SOTO WILSON | I10: PNP | J10: Desembolsado | K10: 64000 | L10: JUAN CORDOVA
B11: LIMA | C11: 46115 | D11: Aprobada | E11: 46181 | F11: 46182 | G11: 70618860 | H11: MARQUEZ ANDRES LUDDY JACINTO | I11: DIRIS CENTRO | J11: Desembolsado | K11: 49000 | L11: AURELIA FERNANDEZ
B12: LIMA | C12: 46181 | D12: Aprobada | E12: 46183 | F12: 46183 | G12: 44386537 | H12: BERNAOLA FLORES SUSANA CATHERINE | I12: ESSALUD | J12: Desembolsado | K12: 47000 | L12: AURELIA FERNANDEZ
B13: LIMA | C13: 46181 | D13: Aprobada | E13: 46181 | F13: 46181 | G13: 77235490 | H13: ELUQUIZ SANTISTEBAN KANDY MARICIELO | I13: PNP | J13: Desembolsado | K13: 40000 | L13: AURELIA FERNANDEZ
B14: PUCALLPA | C14: 46177 | D14: Aprobada | E14: 46181 | F14: 46184 | G14: 00126266 | H14: PEÑA TORRES MARLLULY YUSVILDE | I14: ESSALUD | J14: Desembolsado | K14: 37600 | L14: AURELIA FERNANDEZ
B15: LIMA | C15: 46181 | D15: Aprobada | E15: 46182 | F15: 46183 | G15: 48547143 | H15: VALUIS BERNUY GILMER ROMELIO | I15: PNP | J15: Desembolsado | K15: 47000 | L15: AURELIA FERNANDEZ
B16: TRUJILLO | C16: 46183 | D16: Aprobada | E16: 46188 | F16: 46189 | G16: 17815555 | H16: FLORIAN PAREDES JUAN ENRIQUE | I16: ESSALUD | J16: Desembolsado | K16: 56400 | L16: AURELIA FERNANDEZ
B17: LIMA | C17: 46183 | D17: Aprobada | E17: 46184 | F17: 46185 | G17: 74556306 | H17: GARCIA MENDOZA EDWIN | I17: PNP | J17: Desembolsado | K17: 77300 | L17: JUAN CORDOVA
B18: LIMA | C18: 46183 | D18: Aprobada | E18: 46184 | F18: 46185 | G18: 40342749 | H18: BENITES CARTY DE COBOS LORENA | I18: MGP | J18: Desembolsado | K18: 124950 | L18: AURELIA FERNANDEZ
B19: LIMA | C19: 46185 | D19: Aprobada | E19: 46188 | F19: 46189 | G19: 70652455 | H19: ROSAS OLORTEGUI CARLOS | I19: PNP | J19: Desembolsado | K19: 77300 | L19: YESICA HEREDIA
B20: LIMA | C20: 46188 | D20: Aprobada | E20: 46190 | F20: 46193 | G20: 10408873 | H20: CHUCTAYA BAUTISTA RAUL | I20: ESSALUD | J20: Desembolsado | K20: 137000 | L20: AURELIA FERNANDEZ
B21: CAJAMARCA | C21: 46189 | D21: Aprobada | E21: 46191 | F21: 46191 | G21: 73468156 | H21: RAFAEL BUSTAMANTE FRANCISCO JAVIER | I21: ESSALUD | J21: Desembolsado | K21: 87000 | L21: AURELIA FERNANDEZ
... B25: LIMA | C25: 46195 | D25: Aprobada | E25: 46196 | F25: 46197 | G25: 71769225 | H25: GOMEZ GARCIA SERGIO FERNANDO | I25: MGP | J25: Desembolsado | K25: 83300 | L25: AURELIA FERNANDEZ

Sheet JIMMY COLLAZOS
D3: TARAPOTO | E3: Meta | F3: Desembolsado | G3: Avance | H3: Pendiente De Documentar | I3: Pendiente De Remesa | J3: Pendiente De Backoffice | K3: Evaluación BCP | L3: Obs Backoffice | M3: Obs BCP | N3: Rechazado
D4: S/. | E4: 800000 | F4: =SUMIFS(OPI_4[MAF NETO],OPI_4[ESTADO],"Desembolsado") -> 258960 | G4: =F4-E4 -> -541040 | H4: =SUMIFS(OPI_4[MAF NETO],OPI_4[ESTADO],H$3) -> 0 | I4: =SUMIFS(OPI_4[MAF NETO],OPI_4[ESTADO],I$3) -> 0 | J4: =SUMIFS(OPI_4[MAF NETO],OPI_4[ESTADO],J$3) -> 0 | K4: =SUMIFS(OPI_4[MAF NETO],OPI_4[ESTADO],K$3) -> 0 | L4: =SUMIFS(OPI_4[MAF NETO],OPI_4[ESTADO],L$3) -> 0 | M4: =SUMIFS(OPI_4[MAF NETO],OPI_4[ESTADO],M$3) -> 0 | N4: =SUMIFS(OPI_4[MAF NETO],OPI_4[ESTADO],N$3) -> 0
D5: Q / % | E5: - | F5: =COUNTIFS(OPI_4[ESTADO],"Desembolsado") -> 4 | G5: =IFERROR(F4/E4,"") -> 0.3237 | H5: =COUNTIFS(OPI_4[ESTADO],H$3) -> 0 | I5: =COUNTIFS(OPI_4[ESTADO],I$3) -> 0 | J5: =COUNTIFS(OPI_4[ESTADO],J$3) -> 0 | K5: =COUNTIFS(OPI_4[ESTADO],K$3) -> 0 | L5: =COUNTIFS(OPI_4[ESTADO],L$3) -> 0 | M5: =COUNTIFS(OPI_4[ESTADO],M$3) -> 0 | N5: =COUNTIFS(OPI_4[ESTADO],N$3) -> 1
B9: PLAZA DE VENTA | C9: FECHA DE ENVIO DE REMESA | D9: ESTADO DE REMESA | E9: FECHA DE INGRESO | F9: FECHA DE DESEMBOLSO | G9: DOCUMENTO | H9: NOMBRES Y APELLIDOS | I9: CONVENIO | J9: ESTADO | K9: MAF NETO | L9: EJECUTIVO | M9: FILE ENVIADO A BANCO | N9: FECHA DE ENVIÓ CARTA PODER A BCP | O9: COMPRA DE DEUDA REALIZADA | P9: LIBERACIÓN | Q9: FEEDBACK
B10: TARAPOTO | C10: 46183 | D10: Aprobada | E10: 46184 | F10: 46185 | G10: 75730489 | H10: TORRES MURAYARI PIERO ALBERTO | I10: PNP | J10: Desembolsado | K10: 68030 | L10: ELVIS ACOSTA BARBARAN | O10: No
B11: TARAPOTO | C11: 46192 | D11: Aprobada | E11: 46195 | F11: 46196 | G11: 45521394 | H11: FERNANDEZ GARCIA GLORIA JESUS | I11: PNP | J11: Desembolsado | K11: 45580 | L11: ALCIDES FERNANDEZ PERALTA
B12: TARAPOTO | C12: 46285 | D12: Aprobada | E12: 46195 | F12: 46196 | G12: 76403160 | H12: IZQUIERDO DIAZ ANDER | I12: PNP | J12: Desembolsado | K12: 61800 | L12: ALCIDES FERNANDEZ PERALTA
B13: TARAPOTO | C13: 46192 | D13: Aprobada | E13: 46196 | F13: 0 | G13: 71666083 | H13: MAS TORRES CRISTIAN NILO | I13: PNP | J13: Rechazado | K13: 0 | L13: ALCIDES FERNANDEZ PERALTA | Q13: esperar que actualice SCORE BCP
B14: TARAPOTO | C14: 46197 | D14: Aprobada | E14: 46197 | F14: 46200 | G14: 42650106 | H14: PONCE SANCHEZ CESAR JUNIOR | I14: PNP | J14: Desembolsado | K14: 83550 | L14: ALCIDES FERNANDEZ PERALTA

Sheet JHON ZAMORA
D3: CHICLAYO | E3: Meta | F3: Desembolsado | G3: Avance | H3: Pendiente De Documentar | I3: Pendiente De Remesa | J3: Pendiente De Backoffice | K3: Evaluación BCP | L3: Obs Backoffice | M3: Obs BCP | N3: Rechazado
D4: S/. | E4: 1000000 | F4: =SUMIFS(OPI_3[MAF NETO],OPI_3[ESTADO],"Desembolsado") -> 505900 | G4: =F4-E4 -> -494100 | H4: =SUMIFS(OPI_3[MAF NETO],OPI_3[ESTADO],H$3) -> 0 | I4: =SUMIFS(OPI_3[MAF NETO],OPI_3[ESTADO],I$3) -> 0 | J4: =SUMIFS(OPI_3[MAF NETO],OPI_3[ESTADO],J$3) -> 0 | K4: =SUMIFS(OPI_3[MAF NETO],OPI_3[ESTADO],K$3) -> 0 | L4: =SUMIFS(OPI_3[MAF NETO],OPI_3[ESTADO],L$3) -> 0 | M4: =SUMIFS(OPI_3[MAF NETO],OPI_3[ESTADO],M$3) -> 0 | N4: =SUMIFS(OPI_3[MAF NETO],OPI_3[ESTADO],N$3) -> 305800
D5: Q / % | E5: - | F5: =COUNTIFS(OPI_3[ESTADO],"Desembolsado") -> 7 | G5: =IFERROR(F4/E4,"") -> 0.5059 | H5: =COUNTIFS(OPI_3[ESTADO],H$3) -> 0 | I5: =COUNTIFS(OPI_3[ESTADO],I$3) -> 0 | J5: =COUNTIFS(OPI_3[ESTADO],J$3) -> 0 | K5: =COUNTIFS(OPI_3[ESTADO],K$3) -> 0 | L5: =COUNTIFS(OPI_3[ESTADO],L$3) -> 0 | M5: =COUNTIFS(OPI_3[ESTADO],M$3) -> 0 | N5: =COUNTIFS(OPI_3[ESTADO],N$3) -> 4
B9: PLAZA DE VENTA | C9: FECHA DE ENVIO DE REMESA | D9: ESTADO DE REMESA | E9: FECHA DE INGRESO | F9: FECHA DE DESEMBOLSO | G9: DOCUMENTO | H9: NOMBRES Y APELLIDOS | I9: CONVENIO | J9: ESTADO | K9: MAF NETO | L9: EJECUTIVO | M9: FILE ENVIADO A BANCO | N9: FECHA DE ENVIÓ CARTA PODER A BCP | O9: COMPRA DE DEUDA REALIZADA | P9: LIBERACIÓN | Q9: FEEDBACK
B10: CHICLAYO | C10: 46182 | D10: Aprobada | E10: 46182 | G10: 70489731 | H10: FAJARDO MONROY CHRISTIAN JUNIOR | I10: PNP | J10: Rechazado | K10: 85800 | L10: NORMA ARRAIZA | Q10: NO PROCEDE POR CARTERA TRANSFERIDA
B11: CHICLAYO | C11: 46185 | D11: Aprobada | E11: 46185 | G11: 73121372 | H11: ROMERO GARCIA WALTER LUIS | I11: PNP | J11: Desembolsado | K11: 82500 | L11: FLOR LLATAS | M11: No | O11: No
B12: CHICLAYO | C12: 46185 | D12: Aprobada | E12: SIN INGRESO | G12: 42047411 | H12: CUMPEN LARA EDGAR SMITH | I12: PNP | J12: Rechazado | K12: 82800 | L12: FLOR LLATAS | O12: No | Q12: SOBREENDEUDADO
B13: CHICLAYO | C13: 46185 | D13: Aprobada | E13: 46185 | F13: 46188 | G13: 76394324 | H13: PALIZA USCAPI ALVARO | I13: PNP | J13: Desembolsado | K13: 54500 | L13: FLOR LLATAS | O13: No
B14: CHICLAYO | C14: 46185 | D14: Aprobada | E14: 46185 | F14: 46188 | G14: 72625968 | H14: ALFARO VASQUEZ ALEXANDER WILMER | I14: PNP | J14: Desembolsado | K14: 72800 | L14: FLOR LLATAS | O14: No
B15: CHICLAYO | C15: 46185 | D15: Aprobada | E15: 46185 | F15: 46188 | G15: 72625309 | H15: PACHERREZ MARRUFO JAMES MAYKOL DNI | I15: PNP | J15: Desembolsado | K15: 68400 | L15: FLOR LLATAS | O15: No
B16: CHICLAYO | C16: 46185 | D16: Aprobada | G16: 48409811 | H16: MUCHA HUARACA JHOEL KENDELL DNI | I16: PNP | J16: Desembolsado | K16: 72800 | L16: FLOR LLATAS | O16: No
B17: CHICLAYO | C17: 46185 | D17: Aprobada | E17: 46185 | G17: 47277730 | H17: UBILLUS SILVA JHONATAN ALEXANDER DNI | I17: PNP | J17: Desembolsado | K17: 78200 | L17: FLOR LLATAS | O17: No
B18: CHICLAYO | C18: 46190 | D18: Aprobada | G18: 70557656 | H18: PACOTAIPE QUISPE,YANET MILAGROS | I18: EP | J18: Rechazado | K18: 68900 | L18: NORMA ARRAIZA | Q18: AMPLIO EN GNB
B19: CHICLAYO | C19: 46191 | D19: Rechazada | E19: 46193 | G19: 75019634 | H19: PEÑA ORTIZ CRISTHIAN OMAR | I19: PNP | J19: Rechazado | K19: 68300 | L19: NORMA ARRAIZA
B20: CHICLAYO | C20: 46203 | D20: Aprobada | E20: 46203 | F20: 46203 | G20: 73787399 | H20: SUAREZ HERNANDEZ EDITH MADELEYNE | I20: PNP | J20: Desembolsado | K20: 76700 | L20: FLOR LLATAS

Sheet LUIS CHUSE
D3: LIMA | E3: Meta | F3: Desembolsado | G3: Avance | H3: Pendiente De Documentar | I3: Pendiente De Remesa | J3: Pendiente De Backoffice | K3: Evaluación BCP | L3: Obs Backoffice | M3: Obs BCP | N3: Rechazado
D4: S/. | E4: 2000000 | F4: =SUMIFS(OPI_7[MAF NETO],OPI_7[ESTADO],"Desembolsado") -> 1428953 | G4: =F4-E4 -> -571047 | H4: =SUMIFS(OPI_7[MAF NETO],OPI_7[ESTADO],H$3) -> 0 | I4: =SUMIFS(OPI_7[MAF NETO],OPI_7[ESTADO],I$3) -> 0 | J4: =SUMIFS(OPI_7[MAF NETO],OPI_7[ESTADO],J$3) -> 0 | K4: =SUMIFS(OPI_7[MAF NETO],OPI_7[ESTADO],K$3) -> 0 | L4: =SUMIFS(OPI_7[MAF NETO],OPI_7[ESTADO],L$3) -> 0 | M4: =SUMIFS(OPI_7[MAF NETO],OPI_7[ESTADO],M$3) -> 0 | N4: =SUMIFS(OPI_7[MAF NETO],OPI_7[ESTADO],N$3) -> 268350
D5: Q / % | E5: - | F5: =COUNTIFS(OPI_7[ESTADO],"Desembolsado") -> 21 | G5: =IFERROR(F4/E4,"") -> 0.7144765 | H5: =COUNTIFS(OPI_7[ESTADO],H$3) -> 0 | I5: =COUNTIFS(OPI_7[ESTADO],I$3) -> 0 | J5: =COUNTIFS(OPI_7[ESTADO],J$3) -> 0 | K5: =COUNTIFS(OPI_7[ESTADO],K$3) -> 0 | L5: =COUNTIFS(OPI_7[ESTADO],L$3) -> 0 | M5: =COUNTIFS(OPI_7[ESTADO],M$3) -> 0 | N5: =COUNTIFS(OPI_7[ESTADO],N$3) -> 8
B9: PLAZA DE VENTA | C9: FECHA DE ENVIO DE REMESA | D9: ESTADO DE REMESA | E9: FECHA DE INGRESO | F9: FECHA DE DESEMBOLSO | G9: DOCUMENTO | H9: NOMBRES Y APELLIDOS | I9: CONVENIO | J9: ESTADO | K9: MAF NETO | L9: EJECUTIVO | M9: FILE ENVIADO A BANCO | N9: FECHA DE ENVIÓ CARTA PODER A BCP | O9: COMPRA DE DEUDA REALIZADA | P9: LIBERACIÓN | Q9: FEEDBACK
B10: LIMA | C10: 46177 | D10: Aprobada | E10: 46177 | G10: 73803001 | H10: SANGAMA SANTILLAN CESAR VALERIO | I10: MGP | J10: Rechazado | K10: 0 | L10: EDGAR CHOTA | M10: No
B11: LIMA | C11: 46176 | D11: Aprobada | E11: 46181 | F11: 46184 | G11: 09570721 | H11: ESPINOZA BRAVO ESTHER CARIDAD | I11: DIRIS ESTE | J11: Desembolsado | K11: 150000 | L11: LUIS SHEPERD | M11: No
B12: LIMA | C12: 46177 | D12: Aprobada | E12: 46181 | G12: 70394920 | H12: ESCUDERO BORDA DIEGO ARMANDO | I12: PNP | J12: Desembolsado | K12: 73150 | L12: KELLY SARMIENTO
B13: LIMA | C13: 46177 | D13: Aprobada | E13: 46183 | G13: 40866413 | H13: PADILLA FIESTAS CARMEN ROSA | I13: EP | J13: Desembolsado | K13: 79000 | L13: KELLY SARMIENTO
B14: LIMA | C14: 46177 | D14: Aprobada | E14: 46198 | G14: 40863375 | H14: SALDAÑA RAMIREZ JAVIER | I14: DIRIS ESTE | J14: Desembolsado | K14: 66550 | L14: LUIS SHEPERD
B15: LIMA | C15: 46178 | D15: Aprobada | E15: 46183 | G15: 74373039 | H15: GONZALES SERNAQUE SANDRO | I15: PNP | J15: Desembolsado | K15: 73000 | L15: LUIS MENDOZA
B16: LIMA | C16: 46181 | D16: Aprobada | E16: 46185 | G16: 76586265 | H16: CAQUI VARGAS ALFREDO | I16: PNP | J16: Desembolsado | K16: 77200 | L16: LUIS MENDOZA
B17: LIMA | C17: 46179 | D17: Aprobada | E17: 46191 | G17: 45858644 | H17: CASTILLA NAVA PAOLA SILVANA | I17: PNP | J17: Desembolsado | K17: 84390 | L17: KELLY SARMIENTO
B18: LIMA | C18: 46179 | D18: Aprobada | E18: 46181 | G18: 71777971 | H18: MAYTA PALOMINO HELEN SHARON | I18: PNP | J18: Desembolsado | K18: 65000 | L18: CARLOS ESPINOZA
B19: LIMA | C19: 46183 | D19: Aprobada | E19: 46183 | G19: 71074332 | H19: CHOQUE GOMEZ JOSE ANTONIO | I19: PNP | J19: Desembolsado | K19: 68740 | L19: KELLY SARMIENTO
B20: LIMA | C20: 46182 | D20: Aprobada | E20: 46189 | G20: 06629783 | H20: QUIROZ MENESES PEDRO JESUS | I20: ESSALUD | J20: Desembolsado | K20: 50000 | L20: LUIS MENDOZA
B21: LIMA | C21: 46182 | D21: Aprobada | E21: 46182 | G21: 10431123 | H21: CASTROMONTE MONTES GILMER RENZO | I21: DIRIS CENTRO | J21: Desembolsado | K21: 51650 | L21: LUIS SHEPERD
B22: LIMA | C22: 46185 | D22: Aprobada | G22: 45939401 | H22: FERNANDEZ SOLAR ALDO JUNIOR | I22: EP | J22: Rechazado | K22: 0 | L22: KELLY SARMIENTO
B23: LIMA | C23: 46185 | D23: Aprobada | E23: 46192 | G23: 45459949 | H23: CANGALAYA MONTALVO IVONNE STEPHANI | I23: ESSALUD | J23: Desembolsado | K23: 6300 | L23: CARLOS ESPINOZA
B24: LIMA | C24: 46185 | D24: Aprobada | E24: 46188 | G24: 46394010 | H24: YOVERA PAZ CLORINDA | I24: EP | J24: Desembolsado | K24: 83000 | L24: KELLY SARMIENTO
B25: LIMA | C25: 46188 | D25: Aprobada | E25: 46189 | G25: 76013469 | H25: PILCO NORIEGA MACLINDER STIWEN | I25: MGP | J25: Desembolsado | K25: 9013 | L25: LUIS SHEPERD
B26: LIMA | C26: 46190 | D26: Aprobada | E26: 46203 | G26: 72188058 | H26: SANTILLAN RUIZ LIZANDRO GIAMPIER | I26: EP | J26: Rechazado | K26: 0 | L26: KELLY SARMIENTO
B27: LIMA | C27: 46191 | D27: Aprobada | E27: 46198 | G27: 40340008 | H27: QUIÑONES TALLEDO CHARLES HARRINSON | I27: MINJUS | J27: Desembolsado | K27: 107750 | L27: LUIS SHEPERD
B28: LIMA | C28: 46191 | D28: Aprobada | E28: 46195 | G28: 76793329 | H28: CISNEROS CERCADO JEYNER ALEXANDER | I28: EP | J28: Desembolsado | K28: 73800 | L28: LUIS MENDOZA
B29: LIMA | C29: 46192 | D29: Aprobada | E29: 46197 | G29: 48161791 | H29: JOSEFAT CERVANTES MELCHOR | I29: PNP | J29: Desembolsado | K29: 73580 | L29: CARLOS ESPINOZA
B30: LIMA | C30: 46193 | D30: Aprobada | E30: 46197 | G30: 47596637 | H30: DIAZ MIRANDA JUNIOR | I30: PNP | J30: Desembolsado | K30: 35600 | L30: CARLOS ESPINOZA
B31: LIMA | C31: 46193 | D31: Aprobada | E31: 46195 | G31: 48641487 | H31: SAAVEDRA PRINCIPE DAVID JERSON | I31: PNP | J31: Desembolsado | K31: 67630 | L31: KELLY SARMIENTO
B32: LIMA | C32: 46195 | D32: Aprobada | E32: 46195 | G32: 43357799 | H32: POMA MATOS ELEM | I32: PNP | J32: Desembolsado | K32: 50000 | L32: CARLOS ESPINOZA
B33: LIMA | C33: 46196 | D33: Aprobada | E33: 46198 | G33: 45243969 | H33: YLLACONZA CAYO KAREN LUISA | I33: MGP | J33: Desembolsado | K33: 83600 | L33: LUIS MENDOZA
B34: LIMA | C34: 46198 | D34: Aprobada | E34: 46203 | G34: 72436908 | H34: PONCE ABANTO LICETH | I34: PNP | J34: Rechazado | K34: 78050 | L34: JOSSEF PFARE
... B36: LIMA | C36: 46199 | D36: Aprobada | E36: 46203 | G36: 46083895 | H36: MARTIN ZAVALETA KATHERINE LIZETH | I36: DIRIS CENTRO | J36: Rechazado | K36: 29100 | L36: JOSSEF PFARE
B37: LIMA | C37: 46199 | D37: Aprobada | G37: 77505087 | H37: PAREDES TICONA ANTONY FRANK | I37: PNP | J37: Rechazado | K37: 67100 | L37: KELLY SARMIENTO
B38: LIMA | C38: 46203 | D38: Aprobada | E38: 46203 | G38: 44477675 | H38: LAZO MURRIETA DIANA CAROLINA | I38: EP | J38: Rechazado | K38: 58700 | L38: KELLY SARMIENTO

Sheet OMAR MINAYA
D3: CHICLAYO | E3: Meta | F3: Desembolsado | G3: Avance | H3: Pendiente De Documentar | I3: Pendiente De Remesa | J3: Pendiente De Backoffice | K3: Evaluación BCP | L3: Obs Backoffice | M3: Obs BCP | N3: Rechazado
D4: S/. | E4: 1000000 | F4: =SUMIFS(OPI_5[MAF NETO],OPI_5[ESTADO],"Desembolsado") -> 327840 | G4: =F4-E4 -> -672160 | H4: =SUMIFS(OPI_5[MAF NETO],OPI_5[ESTADO],H$3) -> 0 | I4: =SUMIFS(OPI_5[MAF NETO],OPI_5[ESTADO],I$3) -> 0 | J4: =SUMIFS(OPI_5[MAF NETO],OPI_5[ESTADO],J$3) -> 0 | K4: =SUMIFS(OPI_5[MAF NETO],OPI_5[ESTADO],K$3) -> 0 | L4: =SUMIFS(OPI_5[MAF NETO],OPI_5[ESTADO],L$3) -> 0 | M4: =SUMIFS(OPI_5[MAF NETO],OPI_5[ESTADO],M$3) -> 0 | N4: =SUMIFS(OPI_5[MAF NETO],OPI_5[ESTADO],N$3) -> 166870
D5: Q / % | E5: - | F5: =COUNTIFS(OPI_5[ESTADO],"Desembolsado") -> 5 | G5: =IFERROR(F4/E4,"") -> 0.32784 | H5: =COUNTIFS(OPI_5[ESTADO],H$3) -> 0 | I5: =COUNTIFS(OPI_5[ESTADO],I$3) -> 0 | J5: =COUNTIFS(OPI_5[ESTADO],J$3) -> 0 | K5: =COUNTIFS(OPI_5[ESTADO],K$3) -> 0 | L5: =COUNTIFS(OPI_5[ESTADO],L$3) -> 0 | M5: =COUNTIFS(OPI_5[ESTADO],M$3) -> 0 | N5: =COUNTIFS(OPI_5[ESTADO],N$3) -> 3
B9: PLAZA DE VENTA | C9: FECHA DE ENVIO DE REMESA | D9: ESTADO DE REMESA | E9: FECHA DE INGRESO | F9: FECHA DE DESEMBOLSO | G9: DOCUMENTO | H9: NOMBRES Y APELLIDOS | I9: CONVENIO | J9: ESTADO | K9: MAF NETO | L9: EJECUTIVO | M9: FILE ENVIADO A BANCO | N9: FECHA DE ENVIÓ CARTA PODER A BCP | O9: COMPRA DE DEUDA REALIZADA | P9: LIBERACIÓN | Q9: FEEDBACK
B10: CHICLAYO | C10: 46168 | D10: Aprobada | G10: 46180058 | H10: VASQUEZ EFFIO SMITH ALAN | I10: PNP | J10: Rechazado | K10: 34250 | L10: VICTOR CIEZA LA MADRID | M10: Si | Q10: NO VA POR SEGMENTO PYME
B11: CHICLAYO | C11: 46175 | D11: Rechazada | G11: 76930166 | H11: CASTRO MILLONES ROBERT CRISTIAN MIGUEL | I11: EP | J11: Desembolsado | K11: 46700 | L11: VICTOR CIEZA LA MADRID | M11: Si | Q11: MANDAR EL 15 CON LA NUEVA BOLETA
B12: CHICLAYO | C12: 46183 | D12: Aprobada | G12: 74838041 | H12: RAMOS TORO MAYK KEVIN | I12: EP | J12: Desembolsado | K12: 73790 | L12: VICTOR CIEZA LA MADRID | M12: Si | Q12: PENDIENTE DE FIRMA CLIENTE
B13: CHICLAYO | C13: 46186 | D13: Aprobada | G13: 73812702 | H13: SANCHEZ GALVEZ PIERO CESAR | I13: EP | J13: Rechazado | K13: 59720 | L13: VICTOR CIEZA LA MADRID | M13: Si | Q13: EN ESPERA DE REMESA Y DOCUMENTACION
B14: CHICLAYO | C14: 46195 | D14: Rechazada | G14: 77084817 | H14: NAPA CASTILLA WALTER JORDAN | I14: EP | J14: Rechazado | K14: 72900 | L14: VICTOR CIEZA LA MADRID | M14: Si
B15: CHICLAYO | C15: 46197 | D15: Aprobada | G15: 77415152 | H15: DIAZ SANDOVAL JHENNYFER TATIANA | I15: PNP | J15: Desembolsado | K15: 78500 | L15: VICTOR CIEZA LA MADRID | M15: Si
B16: CHICLAYO | C16: 46198 | D16: Aprobada | G16: 43370018 | H16: CARMONA CORTES SANIEL JHONATAN | I16: PNP | J16: Desembolsado | K16: 40550 | L16: VICTOR CIEZA LA MADRID
B17: CHICLAYO | C17: 46198 | D17: Aprobada | G17: 73998174 | H17: RIVEROS QUICO,JULIO ALONSO | I17: PNP | J17: Desembolsado | K17: 88300 | L17: VICTOR CIEZA LA MADRID

Sheet KENNY MORALES
D3: LIMA | E3: Meta | F3: Desembolsado | G3: Avance | H3: Pendiente De Documentar | I3: Pendiente De Remesa | J3: Pendiente De Backoffice | K3: Evaluación BCP | L3: Obs Backoffice | M3: Obs BCP | N3: Rechazado
D4: S/. | E4: 1000000 | F4: =SUMIFS(OPI_6[MAF NETO],OPI_6[ESTADO],"Desembolsado") -> 836020 | G4: =F4-E4 -> -163980 | H4: =SUMIFS(OPI_6[MAF NETO],OPI_6[ESTADO],H$3) -> 0 | I4: =SUMIFS(OPI_6[MAF NETO],OPI_6[ESTADO],I$3) -> 0 | J4: =SUMIFS(OPI_6[MAF NETO],OPI_6[ESTADO],J$3) -> 0 | K4: =SUMIFS(OPI_6[MAF NETO],OPI_6[ESTADO],K$3) -> 0 | L4: =SUMIFS(OPI_6[MAF NETO],OPI_6[ESTADO],L$3) -> 0 | M4: =SUMIFS(OPI_6[MAF NETO],OPI_6[ESTADO],M$3) -> 0 | N4: =SUMIFS(OPI_6[MAF NETO],OPI_6[ESTADO],N$3) -> 0
D5: Q / % | E5: - | F5: =COUNTIFS(OPI_6[ESTADO],"Desembolsado") -> 12 | G5: =IFERROR(F4/E4,"") -> 0.83602 | H5: =COUNTIFS(OPI_6[ESTADO],H$3) -> 0 | I5: =COUNTIFS(OPI_6[ESTADO],I$3) -> 0 | J5: =COUNTIFS(OPI_6[ESTADO],J$3) -> 0 | K5: =COUNTIFS(OPI_6[ESTADO],K$3) -> 0 | L5: =COUNTIFS(OPI_6[ESTADO],L$3) -> 0 | M5: =COUNTIFS(OPI_6[ESTADO],M$3) -> 0 | N5: =COUNTIFS(OPI_6[ESTADO],N$3) -> 0
B9: PLAZA DE VENTA | C9: FECHA DE ENVIO DE REMESA | D9: ESTADO DE REMESA | E9: FECHA DE INGRESO | F9: FECHA DE DESEMBOLSO | G9: DOCUMENTO | H9: NOMBRES Y APELLIDOS | I9: CONVENIO | J9: ESTADO | K9: MAF NETO | L9: EJECUTIVO | M9: FILE ENVIADO A BANCO | N9: FECHA DE ENVIÓ CARTA PODER A BCP | O9: COMPRA DE DEUDA REALIZADA | P9: LIBERACIÓN | Q9: FEEDBACK
B10: LIMA | C10: 46171 | D10: Aprobada | E10: 46171 | F10: 46181 | G10: 77050724 | H10: FLORES CORMAN MARYORI VERONICA | I10: FAP | J10: Desembolsado | K10: 72000 | L10: PAOLA REYES | Q10: ESPERANDO QUE BCP APRUEBE OPERATIVA DE COMPRA COOP. MUTUALISTA
B11: LIMA | C11: 46175 | D11: Aprobada | E11: 46175 | F11: 46178 | G11: 73340045 | H11: MORENO CODINA JHONATTAN JUNIOR | I11: AGRORURAL | J11: Desembolsado | K11: 23300 | L11: PAOLA REYES | M11: Si | Q11: --
B12: LIMA | C12: 46182 | D12: Aprobada | E12: 46182 | F12: 46184 | G12: 44613353 | H12: RIOS LAURA DANIELA FLOR DE MARIA | I12: PNP | J12: Desembolsado | K12: 81200 | L12: SILVIA CASTAÑEDA | M12: Si
B13: HUANCAYO | C13: 46185 | D13: Aprobada | E13: 46183 | F13: 46189 | G13: 19873855 | H13: MONTOYA PIÑAS LUZ VIOLETA | I13: AGRORURAL | J13: Desembolsado | K13: 121300 | L13: PAOLA REYES | Q13: -
B14: LIMA | C14: 46183 | D14: Aprobada | E14: 46183 | F14: 46188 | G14: 48209353 | H14: GUTIERREZ SOLANO JOSE JAVIER | I14: PNP | J14: Desembolsado | K14: 85070 | L14: SILVIA CASTAÑEDA
B15: LIMA | C15: 46196 | D15: Aprobada | E15: 46196 | F15: 46198 | G15: 22514212 | H15: BRANCACHO GARAY ANDRES EUGENIO | I15: AGRORURAL | J15: Desembolsado | K15: 54500 | L15: PAOLA REYES
B16: LIMA | C16: 46193 | D16: Aprobada | E16: 46193 | F16: 46198 | G16: 42196321 | H16: HUARACA ZECENARRO GABRIEL FERNANDO | I16: PRONABEC | J16: Desembolsado | K16: 10500 | L16: PAOLA REYES | Q16: SE OBSERVO FECHA DE VENCIMIENTO DE DNI
B17: LIMA | C17: 46198 | D17: Aprobada | E17: 46197 | F17: 46200 | G17: 42070102 | H17: OTINIANO GONZALES MIGUEL ANGEL | I17: DIRIS ESTE | J17: Desembolsado | K17: 72700 | L17: SALLY SAAVEDRA
B18: LIMA | C18: 46198 | D18: Aprobada | E18: 46198 | F18: 46200 | G18: 44378424 | H18: SATALAYA GUTIERREZ PATRICIA | I18: DIRIS ESTE | J18: Desembolsado | K18: 77900 | L18: SALLY SAAVEDRA | Q18: TOMA DE FIRMA EN AGENCIA CARABAYLLO
B19: LIMA | C19: 46199 | D19: Aprobada | E19: 46198 | F19: 46203 | G19: 10150655 | H19: CHAVEZ VASQUEZ HENRY FREDY | I19: DIRIS ESTE | J19: Desembolsado | K19: 67100 | L19: SALLY SAAVEDRA | Q19: TOMA DE FIRMA EN AGENCIA CHOSICA
B20: LIMA | C20: 46199 | D20: Aprobada | E20: 46198 | F20: 46203 | G20: 16748464 | H20: ALARCON CUBAS PAUL ALEXANDER | I20: MINISTERIO JUSTICIA | J20: Desembolsado | K20: 64950 | L20: ROXANA FERNANDEZ
B21: LIMA | C21: 46199 | D21: Aprobada | E21: 46199 | F21: 46203 | G21: 45862778 | H21: GAMERO MUÑOZ NELIDA CRISTINA | I21: PNP | J21: Desembolsado | K21: 105500 | L21: ROXANA FERNANDEZ

Sheet WENDY IPANEQUE
D3: PIURA | E3: Meta | F3: Desembolsado | G3: Avance | H3: Pendiente De Documentar | I3: Pendiente De Remesa | J3: Pendiente De Backoffice | K3: Evaluación BCP | L3: Obs Backoffice | M3: Obs BCP | N3: Rechazado
D4: S/. | E4: 1000000 | F4: =SUMIFS(OPI_14[MAF NETO],OPI_14[ESTADO],"Desembolsado") -> 451270 | G4: =F4-E4 -> -548730 | H4: =SUMIFS(OPI_14[MAF NETO],OPI_14[ESTADO],H$3) -> 0 | I4: =SUMIFS(OPI_14[MAF NETO],OPI_14[ESTADO],I$3) -> 0 | J4: =SUMIFS(OPI_14[MAF NETO],OPI_14[ESTADO],J$3) -> 0 | K4: =SUMIFS(OPI_14[MAF NETO],OPI_14[ESTADO],K$3) -> 0 | L4: =SUMIFS(OPI_14[MAF NETO],OPI_14[ESTADO],L$3) -> 0 | M4: =SUMIFS(OPI_14[MAF NETO],OPI_14[ESTADO],M$3) -> 0 | N4: =SUMIFS(OPI_14[MAF NETO],OPI_14[ESTADO],N$3) -> 157100
D5: Q / % | E5: - | F5: =COUNTIFS(OPI_14[ESTADO],"Desembolsado") -> 7 | G5: =IFERROR(F4/E4,"") -> 0.45127 | H5: =COUNTIFS(OPI_14[ESTADO],H$3) -> 0 | I5: =COUNTIFS(OPI_14[ESTADO],I$3) -> 0 | J5: =COUNTIFS(OPI_14[ESTADO],J$3) -> 0 | K5: =COUNTIFS(OPI_14[ESTADO],K$3) -> 0 | L5: =COUNTIFS(OPI_14[ESTADO],L$3) -> 0 | M5: =COUNTIFS(OPI_14[ESTADO],M$3) -> 0 | N5: =COUNTIFS(OPI_14[ESTADO],N$3) -> 2
B9: PLAZA DE VENTA | C9: FECHA DE ENVIO DE REMESA | D9: ESTADO DE REMESA | E9: FECHA DE INGRESO | F9: FECHA DE DESEMBOLSO | G9: DOCUMENTO | H9: NOMBRES Y APELLIDOS | I9: CONVENIO | J9: ESTADO | K9: MAF NETO | L9: EJECUTIVO | M9: FILE ENVIADO A BANCO | N9: FECHA DE ENVIÓ CARTA PODER A BCP | O9: COMPRA DE DEUDA REALIZADA | P9: LIBERACIÓN | Q9: FEEDBACK
B10: PIURA | C10: 46181 | D10: Aprobada | E10: 46182 | F10: 46188 | G10: 76441686 | H10: BRIAN STUARD ZAPATA BRAVO | I10: PNP | J10: Desembolsado | K10: 78000 | L10: KRIS BARRAGAN | M10: No
B11: PIURA | C11: 46181 | D11: Aprobada | E11: 46182 | G11: 46314307 | H11: DIOMEDES ENRIQUE IZQUIERDO TRONCOS | I11: ESSALUD | J11: Desembolsado | K11: 69100 | L11: KRIS BARRAGAN | M11: No | Q11: AN CONYUGE, SE ENVIO CARTA DE NO ADEUDO
B12: PIURA | C12: 46182 | D12: Rechazada | E12: 46182 | G12: 45796061 | H12: DEYVIS FRANCISCO ADRIANO VALENCIA | I12: ESSALUD | J12: Rechazado | K12: 74500 | L12: MILAGROS IPANAQUÉ | M12: No | Q12: SE INGRESARÁ CON BOLETA DE JULIO
B13: PIURA | C13: 46184 | D13: Aprobada | E13: 46188 | G13: 42676370 | H13: LUCIANA CECILIA SOSA GARAY | I13: ESSALUD | J13: Desembolsado | K13: 55500 | L13: KRIS BARRAGAN | M13: No | Q13: AN CONYUGE, SE ENVIO CARTA DE NO ADEUDO
B14: PIURA | C14: 46185 | D14: Aprobada | E14: 46188 | G14: 48607422 | H14: VARGAS MALDONADO FELICIANO | I14: PNP | J14: Desembolsado | K14: 50000 | L14: MILAGROS IPANAQUÉ | M14: No
B15: PIURA | C15: 46190 | D15: Aprobada | G15: 41149463 | H15: AGURTO CASTRO BLANCA LUCIA | I15: ESSALUD | J15: Desembolsado | K15: 52400 | L15: KRIS BARRAGAN | M15: No | Q15: FALTA NÚMERO DE CUENTA
B16: PIURA | C16: 46191 | D16: Aprobada | G16: 45868982 | H16: CORDOVA PALOMINO JOYSI STEPHANIE | I16: PNP | J16: Desembolsado | K16: 70000 | L16: KRIS BARRAGAN | M16: No | Q16: EN TOMA DE FIRMAS LIMA
B17: PIURA | C17: 46193 | D17: Aprobada | G17: 73045033 | H17: MORAN RAMOS BRAYAN KENYI | I17: PNP | J17: Desembolsado | K17: 76270 | L17: KRIS BARRAGAN | M17: No
B18: PIURA | C18: 46200 | D18: Rechazada | G18: 41487157 | H18: COSQUILLO MENDOZA KENNY DANIEL | I18: EP | J18: Rechazado | K18: 82600 | L18: KRIS BARRAGAN | M18: No

Sheet JOSE LUIS QUINTEROS
B1: wq | C1: qsAZ>
D3: LIMA | E3: Meta | F3: Desembolsado | G3: Avance | H3: Pendiente De Documentar | I3: Pendiente De Remesa | J3: Pendiente De Backoffice | K3: Evaluación BCP | L3: Obs Backoffice | M3: Obs BCP | N3: Rechazado
D4: S/. | E4: 1000000 | F4: =SUMIFS(OPI_8[MAF NETO],OPI_8[ESTADO],"Desembolsado") -> 68200 | G4: =F4-E4 -> -931800 | H4: =SUMIFS(OPI_8[MAF NETO],OPI_8[ESTADO],H$3) -> 0 | I4: =SUMIFS(OPI_8[MAF NETO],OPI_8[ESTADO],I$3) -> 0 | J4: =SUMIFS(OPI_8[MAF NETO],OPI_8[ESTADO],J$3) -> 0 | K4: =SUMIFS(OPI_8[MAF NETO],OPI_8[ESTADO],K$3) -> 0 | L4: =SUMIFS(OPI_8[MAF NETO],OPI_8[ESTADO],L$3) -> 0 | M4: =SUMIFS(OPI_8[MAF NETO],OPI_8[ESTADO],M$3) -> 0 | N4: =SUMIFS(OPI_8[MAF NETO],OPI_8[ESTADO],N$3) -> 0
D5: Q / % | E5: - | F5: =COUNTIFS(OPI_8[ESTADO],"Desembolsado") -> 1 | G5: =IFERROR(F4/E4,"") -> 0.0682 | H5: =COUNTIFS(OPI_8[ESTADO],H$3) -> 0 | I5: =COUNTIFS(OPI_8[ESTADO],I$3) -> 0 | J5: =COUNTIFS(OPI_8[ESTADO],J$3) -> 0 | K5: =COUNTIFS(OPI_8[ESTADO],K$3) -> 0 | L5: =COUNTIFS(OPI_8[ESTADO],L$3) -> 0 | M5: =COUNTIFS(OPI_8[ESTADO],M$3) -> 0 | N5: =COUNTIFS(OPI_8[ESTADO],N$3) -> 1
B9: PLAZA DE VENTA | C9: FECHA DE ENVIO DE REMESA | D9: ESTADO DE REMESA | E9: FECHA DE INGRESO | F9: FECHA DE DESEMBOLSO | G9: DOCUMENTO | H9: NOMBRES Y APELLIDOS | I9: CONVENIO | J9: ESTADO | K9: MAF NETO | L9: EJECUTIVO | M9: FILE ENVIADO A BANCO | N9: FECHA DE ENVIÓ CARTA PODER A BCP | O9: COMPRA DE DEUDA REALIZADA | P9: LIBERACIÓN | Q9: FEEDBACK
B10: LIMA | C10: 46183 | D10: Aprobada | G10: 77566032 | H10: YEVGENY ANDRE LOAYZA BENITES | I10: EP | J10: Rechazado | L10: MARIA VERGARA
D11: Aprobada | E11: 46199 | G11: 10557824 | H11: GUZMAN ARMAS JULIO CESAR | I11: EP | J11: Desembolsado | K11: 68200 | L11: ERIKA EZETA

Sheet MILAGROS TUESTA
D3: LIMA | E3: Meta | F3: Desembolsado | G3: Avance | H3: Pendiente De Documentar | I3: Pendiente De Remesa | J3: Pendiente De Backoffice | K3: Evaluación BCP | L3: Obs Backoffice | M3: Obs BCP | N3: Rechazado
D4: S/. | E4: 2000000 | F4: =SUMIFS(OPI_10[MAF NETO],OPI_10[ESTADO],"Desembolsado") -> 1049520 | G4: =F4-E4 -> -950480 | H4: =SUMIFS(OPI_10[MAF NETO],OPI_10[ESTADO],H$3) -> 0 | I4: =SUMIFS(OPI_10[MAF NETO],OPI_10[ESTADO],I$3) -> 0 | J4: =SUMIFS(OPI_10[MAF NETO],OPI_10[ESTADO],J$3) -> 0 | K4: =SUMIFS(OPI_10[MAF NETO],OPI_10[ESTADO],K$3) -> 0 | L4: =SUMIFS(OPI_10[MAF NETO],OPI_10[ESTADO],L$3) -> 0 | M4: =SUMIFS(OPI_10[MAF NETO],OPI_10[ESTADO],M$3) -> 0 | N4: =SUMIFS(OPI_10[MAF NETO],OPI_10[ESTADO],N$3) -> 0
D5: Q / % | E5: - | F5: =COUNTIFS(OPI_10[ESTADO],"Desembolsado") -> 16 | G5: =IFERROR(F4/E4,"") -> 0.52476 | H5: =COUNTIFS(OPI_10[ESTADO],H$3) -> 0 | I5: =COUNTIFS(OPI_10[ESTADO],I$3) -> 0 | J5: =COUNTIFS(OPI_10[ESTADO],J$3) -> 0 | K5: =COUNTIFS(OPI_10[ESTADO],K$3) -> 0 | L5: =COUNTIFS(OPI_10[ESTADO],L$3) -> 0 | M5: =COUNTIFS(OPI_10[ESTADO],M$3) -> 0 | N5: =COUNTIFS(OPI_10[ESTADO],N$3) -> 5
B9: PLAZA DE VENTA | C9: FECHA DE ENVIO DE REMESA | D9: ESTADO DE REMESA | E9: FECHA DE INGRESO | F9: FECHA DE DESEMBOLSO | G9: DOCUMENTO | H9: NOMBRES Y APELLIDOS | I9: CONVENIO | J9: ESTADO | K9: MAF NETO | L9: EJECUTIVO | M9: FILE ENVIADO A BANCO | N9: FECHA DE ENVIÓ CARTA PODER A BCP | O9: COMPRA DE DEUDA REALIZADA | P9: LIBERACIÓN | Q9: FEEDBACK
B10: LIMA | C10: 46171 | D10: Aprobada | E10: 46176 | F10: 46176 | G10: 72504753 | H10: PAREDES CARRILLO,ARELIS ELIZBETH .MARIELLA | I10: PNP | J10: Desembolsado | K10: 71000 | L10: MILY FERNANDEZ | M10: Si | N10: 46177
B11: LIMA | C11: 46172 | D11: Aprobada | E11: 46176 | F11: 46177 | G11: 71657103 | H11: BAZAN CHUQUIPIONDO,SHIRLY MARILYN | I11: PNP | J11: Desembolsado | K11: 54800 | L11: JOSE CONTRERAS | M11: Si
C12: 46177 | D12: Aprobada | G12: 75370680 | H12: CACERES SOTELO, JOSE ANTONIO- PIO | I12: FAP | J12: Desembolsado | K12: 76500 | L12: MILY FERNANDEZ
D13: Aprobada | E13: 45086 | F13: 46182 | G13: 72509274 | H13: QUISPE SUPO,JORGE MANUEL | I13: PNP | J13: Desembolsado | K13: 60000 | L13: JOSE CONTRERAS
D14: Aprobada | G14: 73017905 | H14: SULCA AGAPITO DIEGO ARMAND | I14: MGP | J14: Desembolsado | K14: 77000 | L14: MILY FERNANDEZ
C15: 46184 | D15: Aprobada | G15: 4353402 | H15: MOGOLLON ORTIZ JEFFERSON MODESTO | I15: EP | J15: Desembolsado | K15: 77520 | L15: JOSE CONTRERAS
D16: Aprobada | G16: 76581719 | H16: PAREDES SAQUIRAY TONY GARDEL - CARLA | I16: PNP | J16: Desembolsado | K16: 79550 | L16: MILY FERNANDEZ
D17: Aprobada | G17: 73209640 | H17: MEZA QUISPE,LIZANDRO | I17: PNP | J17: Desembolsado | K17: 44000 | L17: ELIZABETH ESQUIVEL
D18: Aprobada | L18: JOSE CONTRERAS
C19: 46183 | D19: Aprobada | E19: 46184 | F19: 46184 | G19: 73800486 | H19: MALDONADO VILLANUEVA,WILDER ARNOLD MATTH- fer | I19: PNP | J19: Desembolsado | K19: 71000 | L19: MILY FERNANDEZ
C20: 46184 | D20: Aprobada | G20: 74572463 | H20: HURTADO QUISPE CARLOS JHONATAN | I20: PNP | J20: Desembolsado | K20: 63150 | L20: MILY FERNANDEZ
C21: 46188 | D21: Aprobada | E21: 46189 | F21: 46189 | G21: 72295711 | H21: BAZAN SANTA CRUZ ROBERT ISABEL | I21: PNP | J21: Desembolsado | K21: 68690 | L21: JOSE CONTRERAS
G22: 76631246 | H22: CAUNA HUAMAN LUCIO | I22: PNP | J22: Desembolsado | K22: 46000 | L22: JOSE CONTRERAS
D23: Aprobada | G23: 72174572 | H23: REYES CORAL,PERCY JHOAREET | I23: PNP | J23: Desembolsado | K23: 80340 | L23: JOSE CONTRERAS
D24: Aprobada | G24: 45723291 | H24: ENCINAS HERNANI,URIEL GUIDO | I24: PNP | J24: Desembolsado | K24: 80270 | L24: JOSE CONTRERAS
D25: Aprobada | G25: 73800437 | H25: CHOQUE CCAMA,JHAIR PEDRO | I25: PNP | J25: Desembolsado | K25: 68700 | L25: JOSE CONTRERAS
D26: Aprobada | G26: 73088037 | H26: DELGADO CUBAS,YORSIN OMAR | I26: PNP | J26: Desembolsado | K26: 31000 | L26: ELIZABETH ESQUIVEL
G27: 72724697 | I27: PNP | J27: Rechazado | K27: 0
G28: -70171724 | I28: PNP | J28: Rechazado | K28: 0
G29: 44254146 | I29: EP | J29: Rechazado | K29: 0
G30: 73241946 | I30: FAP | J30: Rechazado | K30: 0
G31: 75523889 | I31: PNP | J31: Rechazado

Sheet MARIELLA PAÑAHUA
D3: AYACUCHO | E3: Meta | F3: Desembolsado | G3: Avance | H3: Pendiente De Documentar | I3: Pendiente De Remesa | J3: Pendiente De Backoffice | K3: Evaluación BCP | L3: Obs Backoffice | M3: Obs BCP | N3: Rechazado
D4: S/. | E4: 800000 | F4: =SUMIFS(OPI_9[MAF NETO],OPI_9[ESTADO],"Desembolsado") -> 857400 | G4: =F4-E4 -> 57400 | H4: =SUMIFS(OPI_9[MAF NETO],OPI_9[ESTADO],H$3) -> 0 | I4: =SUMIFS(OPI_9[MAF NETO],OPI_9[ESTADO],I$3) -> 0 | J4: =SUMIFS(OPI_9[MAF NETO],OPI_9[ESTADO],J$3) -> 0 | K4: =SUMIFS(OPI_9[MAF NETO],OPI_9[ESTADO],K$3) -> 0 | L4: =SUMIFS(OPI_9[MAF NETO],OPI_9[ESTADO],L$3) -> 0 | M4: =SUMIFS(OPI_9[MAF NETO],OPI_9[ESTADO],M$3) -> 0 | N4: =SUMIFS(OPI_9[MAF NETO],OPI_9[ESTADO],N$3) -> 0
D5: Q / % | E5: - | F5: =COUNTIFS(OPI_9[ESTADO],"Desembolsado") -> 14 | G5: =IFERROR(F4/E4,"") -> 1.07175 | H5: =COUNTIFS(OPI_9[ESTADO],H$3) -> 0 | I5: =COUNTIFS(OPI_9[ESTADO],I$3) -> 0 | J5: =COUNTIFS(OPI_9[ESTADO],J$3) -> 0 | K5: =COUNTIFS(OPI_9[ESTADO],K$3) -> 0 | L5: =COUNTIFS(OPI_9[ESTADO],L$3) -> 0 | M5: =COUNTIFS(OPI_9[ESTADO],M$3) -> 0 | N5: =COUNTIFS(OPI_9[ESTADO],N$3) -> 3
B9: PLAZA DE VENTA | C9: FECHA DE ENVIO DE REMESA | D9: ESTADO DE REMESA | E9: FECHA DE INGRESO | F9: FECHA DE DESEMBOLSO | G9: DOCUMENTO | H9: NOMBRES Y APELLIDOS | I9: CONVENIO | J9: ESTADO | K9: MAF NETO | L9: EJECUTIVO | M9: FILE ENVIADO A BANCO | N9: FECHA DE ENVIÓ CARTA PODER A BCP | O9: COMPRA DE DEUDA REALIZADA | P9: LIBERACIÓN | Q9: FEEDBACK
B10: AYACUCHO | C10: 46175 | D10: Aprobada | E10: 46181 | F10: 46185 | G10: 43225556 | H10: CLAUDIO ALANYA NIDIA CELICA | I10: ESSALUD | J10: Desembolsado | K10: 74300 | L10: DELIA VENTURA | M10: Si | O10: TC INTERBANK
B11: AYACUCHO | C11: 46176 | D11: Aprobada | E11: 46176 | G11: 43697933 | H11: ESCRIBA MITMA GILSON | I11: PNP | J11: Desembolsado | K11: 37500 | L11: DELIA VENTURA | M11: Si
B12: AYACUCHO | C12: 46176 | D12: Aprobada | E12: 46176 | F12: 46177 | G12: 74479930 | H12: GUTIERREZ GAMBOA PERCY MIRCO | I12: PNP | J12: Desembolsado | K12: 68000 | L12: DELIA VENTURA | M12: Si | O12: BANCO GNB
B13: AYACUCHO | C13: 46185 | D13: Aprobada | E13: 46188 | G13: 71228638 | H13: TABOADA PAICO JACSSON | I13: PNP | J13: Desembolsado | K13: 23500 | L13: JORGE ALFARO | M13: Si | O13: BANCO GNB
B14: AYACUCHO | C14: 46188 | D14: Rechazada | G14: 46333960 | H14: HUAMANI | I14: PNP | J14: Rechazado | K14: 0 | L14: DELIA VENTURA | M14: No | O14: BANCO GNB
B15: AYACUCHO | C15: 46191 | D15: Aprobada | E15: 46191 | G15: 45294287 | H15: TOVAR SULCA SHIRLEY | I15: PNP | J15: Desembolsado | K15: 80600 | L15: DELIA VENTURA | M15: No | O15: SCOTIABANK
D16: Aprobada | G16: 71040822 | H16: CARDENAS JERI ALEXANDER | I16: PNP | J16: Desembolsado | K16: 67000 | L16: DELIA VENTURA
D17: Aprobada | G17: 28316557 | H17: YUPANQUI QUIQUIN MONICA | I17: ESSALUD | J17: Desembolsado | K17: 30000 | L17: EDDY HUAYNALAYA
D18: Aprobada | G18: 71227850 | H18: PARIONA RAMIREZ YAANDI | I18: PNP | J18: Desembolsado | K18: 79500 | L18: DELIA VENTURA
D19: Aprobada | G19: 71248471 | H19: GARCIA CRISANTI, MAXITO | I19: PNP | J19: Desembolsado | K19: 38200 | L19: DELIA VENTURA
D20: Aprobada | G20: 70455739 | H20: CHAVEZ GAMBOA ROQUE | I20: PNP | J20: Desembolsado | K20: 63500 | L20: DELIA VENTURA
C21: 46198 | D21: Aprobada | G21: 77566245 | H21: MONDRAGON PEREZ JAYNS YARLEY | I21: PNP | J21: Desembolsado | K21: 78500 | L21: DELIA VENTURA
D22: Aprobada | G22: 46249059 | H22: CUBAS NUÑEZ GILMER | I22: PNP | J22: Desembolsado | K22: 60900 | L22: DELIA VENTURA
C23: 46199 | D23: Aprobada | G23: 75452035 | H23: FLORES TINEO, JHOVAN | I23: PNP | J23: Desembolsado | K23: 70700 | L23: JORGE ALFARO
C24: 46199 | D24: Rechazada | G24: 45485936 | H24: YUPANQUI CCOICCA JULIO CESAR | I24: PNP | J24: Rechazado | K24: 0 | L24: DELIA VENTURA
D25: Aprobada | G25: 47312284 | H25: ROSEL LLANQUE YUCRA | I25: PNP | J25: Desembolsado | K25: 85200 | L25: DELIA VENTURA
D26: Aprobada | G26: 71561365 | H26: ALCAYAURI CUCHUÑAUPA BERNABE | I26: PNP | J26: Rechazado | K26: 0 | L26: DELIA VENTURA

Sheet ALEXANDRA GUZMAN
D3: PIURA | E3: Meta | F3: Desembolsado | G3: Avance | H3: Pendiente De Documentar | I3: Pendiente De Remesa | J3: Pendiente De Backoffice | K3: Evaluación BCP | L3: Obs Backoffice | M3: Obs BCP | N3: Rechazado
D4: S/. | E4: 1000000 | F4: =SUMIFS(OPI_15[MAF NETO],OPI_15[ESTADO],"Desembolsado") -> 39650 | G4: =F4-E4 -> -960350 | H4: =SUMIFS(OPI_15[MAF NETO],OPI_15[ESTADO],H$3) -> 0 | I4: =SUMIFS(OPI_15[MAF NETO],OPI_15[ESTADO],I$3) -> 0 | J4: =SUMIFS(OPI_15[MAF NETO],OPI_15[ESTADO],J$3) -> 0 | K4: =SUMIFS(OPI_15[MAF NETO],OPI_15[ESTADO],K$3) -> 0 | L4: =SUMIFS(OPI_15[MAF NETO],OPI_15[ESTADO],L$3) -> 0 | M4: =SUMIFS(OPI_15[MAF NETO],OPI_15[ESTADO],M$3) -> 0 | N4: =SUMIFS(OPI_15[MAF NETO],OPI_15[ESTADO],N$3) -> 0
D5: Q / % | E5: - | F5: =COUNTIFS(OPI_15[ESTADO],"Desembolsado") -> 1 | G5: =IFERROR(F4/E4,"") -> 0.03965 | H5: =COUNTIFS(OPI_15[ESTADO],H$3) -> 0 | I5: =COUNTIFS(OPI_15[ESTADO],I$3) -> 0 | J5: =COUNTIFS(OPI_15[ESTADO],J$3) -> 0 | K5: =COUNTIFS(OPI_15[ESTADO],K$3) -> 0 | L5: =COUNTIFS(OPI_15[ESTADO],L$3) -> 0 | M5: =COUNTIFS(OPI_15[ESTADO],M$3) -> 0 | N5: =COUNTIFS(OPI_15[ESTADO],N$3) -> 0
B9: PLAZA DE VENTA | C9: FECHA DE ENVIO DE REMESA | D9: ESTADO DE REMESA | E9: FECHA DE INGRESO | F9: FECHA DE DESEMBOLSO | G9: DOCUMENTO | H9: NOMBRES Y APELLIDOS | I9: CONVENIO | J9: ESTADO | K9: MAF NETO | L9: EJECUTIVO | M9: FILE ENVIADO A BANCO | N9: FECHA DE ENVIÓ CARTA PODER A BCP | O9: COMPRA DE DEUDA REALIZADA | P9: LIBERACIÓN | Q9: FEEDBACK
B10: PIURA | C10: 46182 | D10: Aprobada | G10: 47713443 | H10: LUIS ALBERTO ZURITA RIVERA | I10: ESSALUD | J10: Desembolsado | K10: 39650 | L10: NICOLAS MORE | M10: No
B11: PIURA | C11: 46183

Sheet AMALIA QUINDE
D3: PIURA | E3: Meta | F3: Desembolsado | G3: Avance | H3: Pendiente De Documentar | I3: Pendiente De Remesa | J3: Pendiente De Backoffice | K3: Evaluación BCP | L3: Obs Backoffice | M3: Obs BCP | N3: Rechazado
D4: S/. | E4: 1000000 | F4: =SUMIFS(OPI_16[MAF NETO],OPI_16[ESTADO],"Desembolsado") -> 64200 | G4: =F4-E4 -> -935800 | H4: =SUMIFS(OPI_16[MAF NETO],OPI_16[ESTADO],H$3) -> 0 | I4: =SUMIFS(OPI_16[MAF NETO],OPI_16[ESTADO],I$3) -> 0 | J4: =SUMIFS(OPI_16[MAF NETO],OPI_16[ESTADO],J$3) -> 0 | K4: =SUMIFS(OPI_16[MAF NETO],OPI_16[ESTADO],K$3) -> 0 | L4: =SUMIFS(OPI_16[MAF NETO],OPI_16[ESTADO],L$3) -> 0 | M4: =SUMIFS(OPI_16[MAF NETO],OPI_16[ESTADO],M$3) -> 0 | N4: =SUMIFS(OPI_16[MAF NETO],OPI_16[ESTADO],N$3) -> 150650
D5: Q / % | E5: - | F5: =COUNTIFS(OPI_16[ESTADO],"Desembolsado") -> 1 | G5: =IFERROR(F4/E4,"") -> 0.0642 | H5: =COUNTIFS(OPI_16[ESTADO],H$3) -> 0 | I5: =COUNTIFS(OPI_16[ESTADO],I$3) -> 0 | J5: =COUNTIFS(OPI_16[ESTADO],J$3) -> 0 | K5: =COUNTIFS(OPI_16[ESTADO],K$3) -> 0 | L5: =COUNTIFS(OPI_16[ESTADO],L$3) -> 0 | M5: =COUNTIFS(OPI_16[ESTADO],M$3) -> 0 | N5: =COUNTIFS(OPI_16[ESTADO],N$3) -> 2
B9: PLAZA DE VENTA | C9: FECHA DE ENVIO DE REMESA | D9: ESTADO DE REMESA | E9: FECHA DE INGRESO | F9: FECHA DE DESEMBOLSO | G9: DOCUMENTO | H9: NOMBRES Y APELLIDOS | I9: CONVENIO | J9: ESTADO | K9: MAF NETO | L9: EJECUTIVO | M9: FILE ENVIADO A BANCO | N9: FECHA DE ENVIÓ CARTA PODER A BCP | O9: COMPRA DE DEUDA REALIZADA | P9: LIBERACIÓN | Q9: FEEDBACK
C10: 46183 | D10: Rechazada | E10: 46183 | G10: 71423781 | H10: RODRIGO AARON ROCA FLORES | I10: EP | J10: Rechazado | K10: 75450 | L10: MIXSY SANJINEZ BERMEO
C11: 46188 | D11: Aprobada | E11: 46188 | G11: 73095622 | H11: VELASQUEZ ALZAMORA JOSE MIGUEL | I11: ESSALUD | J11: Desembolsado | K11: 64200 | L11: MIXSY SANJINEZ BERMEO
C12: 46192 | D12: Rechazada | E12: 46192 | G12: 71423781 | H12: RODRIGO AARON ROCA FLORES | I12: EP | J12: Rechazado | K12: 75200 | L12: MIXSY SANJINEZ BERMEO

Sheet JORGE CASTILLO
D3: PIURA | E3: Meta | F3: Desembolsado | G3: Avance | H3: Pendiente De Documentar | I3: Pendiente De Remesa | J3: Pendiente De Backoffice | K3: Evaluación BCP | L3: Obs Backoffice | M3: Obs BCP | N3: Rechazado
D4: S/. | E4: 1000000 | F4: =SUMIFS(OPI_17[MAF NETO],OPI_17[ESTADO],"Desembolsado") -> 123500 | G4: =F4-E4 -> -876500 | H4: =SUMIFS(OPI_17[MAF NETO],OPI_17[ESTADO],H$3) -> 0 | I4: =SUMIFS(OPI_17[MAF NETO],OPI_17[ESTADO],I$3) -> 0 | J4: =SUMIFS(OPI_17[MAF NETO],OPI_17[ESTADO],J$3) -> 0 | K4: =SUMIFS(OPI_17[MAF NETO],OPI_17[ESTADO],K$3) -> 0 | L4: =SUMIFS(OPI_17[MAF NETO],OPI_17[ESTADO],L$3) -> 0 | M4: =SUMIFS(OPI_17[MAF NETO],OPI_17[ESTADO],M$3) -> 0 | N4: =SUMIFS(OPI_17[MAF NETO],OPI_17[ESTADO],N$3) -> 50190
D5: Q / % | E5: - | F5: =COUNTIFS(OPI_17[ESTADO],"Desembolsado") -> 2 | G5: =IFERROR(F4/E4,"") -> 0.1235 | H5: =COUNTIFS(OPI_17[ESTADO],H$3) -> 0 | I5: =COUNTIFS(OPI_17[ESTADO],I$3) -> 0 | J5: =COUNTIFS(OPI_17[ESTADO],J$3) -> 0 | K5: =COUNTIFS(OPI_17[ESTADO],K$3) -> 0 | L5: =COUNTIFS(OPI_17[ESTADO],L$3) -> 0 | M5: =COUNTIFS(OPI_17[ESTADO],M$3) -> 0 | N5: =COUNTIFS(OPI_17[ESTADO],N$3) -> 1
B9: PLAZA DE VENTA | C9: FECHA DE ENVIO DE REMESA | D9: ESTADO DE REMESA | E9: FECHA DE INGRESO | F9: FECHA DE DESEMBOLSO | G9: DOCUMENTO | H9: NOMBRES Y APELLIDOS | I9: CONVENIO | J9: ESTADO | K9: MAF NETO | L9: EJECUTIVO | M9: FILE ENVIADO A BANCO | N9: FECHA DE ENVIÓ CARTA PODER A BCP | O9: COMPRA DE DEUDA REALIZADA | P9: LIBERACIÓN | Q9: FEEDBACK
C10: 46183 | D10: Rechazada | E10: 46181 | F10: 46181 | G10: 40029056 | H10: LEOPOLDO NEIRA CHAMBA | I10: ESSALUD | J10: Rechazado | K10: 50190 | L10: FLOR LESCANO ZAPATA | M10: No
C11: 46188 | D11: Aprobada | E11: 46188 | F11: 46188 | G11: 40029056 | H11: LEOPOLDO NEIRA CHAMBA | I11: ESSALUD | J11: Desembolsado | K11: 49000 | L11: FLOR LESCANO ZAPATA | M11: No
C12: 46186 | D12: Aprobada | E12: 46200 | F12: 46200 | G12: 45517847 | H12: CHAVEZ IRAZAVAL RUGGIRI | I12: PNP | J12: Desembolsado | K12: 74500 | L12: FLOR LESCANO ZAPATA
D13: Aprobada | M13: No

Sheet VIOLETA LLERENA
D3: AREQUIPA | E3: Meta | F3: Desembolsado | G3: Avance | H3: Pendiente De Documentar | I3: Pendiente De Remesa | J3: Pendiente De Backoffice | K3: Evaluación BCP | L3: Obs Backoffice | M3: Obs BCP | N3: Rechazado
D4: S/. | E4: 1000000 | F4: =SUMIFS(OPI_13[MAF NETO],OPI_13[ESTADO],"Desembolsado") -> 522050 | G4: =F4-E4 -> -477950 | H4: =SUMIFS(OPI_13[MAF NETO],OPI_13[ESTADO],H$3) -> 0 | I4: =SUMIFS(OPI_13[MAF NETO],OPI_13[ESTADO],I$3) -> 0 | J4: =SUMIFS(OPI_13[MAF NETO],OPI_13[ESTADO],J$3) -> 0 | K4: =SUMIFS(OPI_13[MAF NETO],OPI_13[ESTADO],K$3) -> 0 | L4: =SUMIFS(OPI_13[MAF NETO],OPI_13[ESTADO],L$3) -> 0 | M4: =SUMIFS(OPI_13[MAF NETO],OPI_13[ESTADO],M$3) -> 0 | N4: =SUMIFS(OPI_13[MAF NETO],OPI_13[ESTADO],N$3) -> 0
D5: Q / % | E5: - | F5: =COUNTIFS(OPI_13[ESTADO],"Desembolsado") -> 7 | G5: =IFERROR(F4/E4,"") -> 0.52205 | H5: =COUNTIFS(OPI_13[ESTADO],H$3) -> 0 | I5: =COUNTIFS(OPI_13[ESTADO],I$3) -> 0 | J5: =COUNTIFS(OPI_13[ESTADO],J$3) -> 0 | K5: =COUNTIFS(OPI_13[ESTADO],K$3) -> 0 | L5: =COUNTIFS(OPI_13[ESTADO],L$3) -> 0 | M5: =COUNTIFS(OPI_13[ESTADO],M$3) -> 0 | N5: =COUNTIFS(OPI_13[ESTADO],N$3) -> 0
B9: PLAZA DE VENTA | C9: FECHA DE ENVIO DE REMESA | D9: ESTADO DE REMESA | E9: FECHA DE INGRESO | F9: FECHA DE DESEMBOLSO | G9: DOCUMENTO | H9: NOMBRES Y APELLIDOS | I9: CONVENIO | J9: ESTADO | K9: MAF NETO | L9: EJECUTIVO | M9: FILE ENVIADO A BANCO | N9: FECHA DE ENVIÓ CARTA PODER A BCP | O9: COMPRA DE DEUDA REALIZADA | P9: LIBERACIÓN | Q9: FEEDBACK
B10: AREQUIPA | C10: 46184 | D10: Aprobada | E10: 46185 | F10: 46185 | G10: 46995464 | H10: CONDORCALLO CAMA LOURDES | I10: PNP | J10: Desembolsado | K10: 78260 | L10: RUTH CLARITA CJURO URACCAHUA | M10: No | N10: 46189 | O10: Si | P10: Si
B11: AREQUIPA | C11: 46185 | D11: Aprobada | E11: 46190 | F11: 46164 | G11: 29409175 | H11: MANSILLA FLORES GIOVANNA MARIBEL | I11: ESSALUD | J11: Desembolsado | K11: 39990 | L11: RUTH CLARITA CJURO URACCAHUA | M11: No | N11: 46195 | O11: Si | P11: Si
B12: AREQUIPA | C12: 46189 | D12: Aprobada | E12: 46190 | F12: 46191 | G12: 41032897 | H12: VELASQUEZ ALMEIDA GALO RODOLFO | I12: PNP | J12: Desembolsado | K12: 110900 | L12: RUTH CLARITA CJURO URACCAHUA | M12: No | N12: 46197 | O12: Si | P12: Si
B13: AREQUIPA | C13: 46192 | D13: Aprobada | E13: 46192 | F13: 46196 | G13: 75781848 | H13: GUPIO DELGADO LLERMIS ESMEÑA | I13: FAP | J13: Desembolsado | K13: 75300 | L13: RUTH CLARITA CJURO URACCAHUA | M13: No | N13: 46198 | O13: Si | P13: Si
B14: AREQUIPA | C14: 46192 | D14: Aprobada | E14: 46192 | F14: 46195 | G14: 74563351 | H14: FERNANDEZ LLERENA RUFFO LEONARDO | I14: PNP | J14: Desembolsado | K14: 78000 | L14: RUTH CLARITA CJURO URACCAHUA | M14: No | N14: 46197 | O14: Si | P14: Si
B15: AREQUIPA | C15: 46193 | D15: Aprobada | E15: 46193 | F15: 46199 | G15: 70981515 | H15: CHINCHAYHUARA LOPEZ JASMIN STEFANNY | I15: EP | J15: Desembolsado | K15: 84600 | L15: RUTH CLARITA CJURO URACCAHUA | M15: No | N15: 46203 | O15: Si
B16: AREQUIPA | C16: 46197 | D16: Aprobada | E16: 46197 | F16: 46203 | G16: 75356882 | H16: FLORES HUAYHUAS PATRICIA MARIELA | I16: FAP | J16: Desembolsado | K16: 55000 | L16: RUTH CLARITA CJURO URACCAHUA | M16: No

Sheet CRISTINA BRACAMONTE
D3: TRUJILLO | E3: Meta | F3: Desembolsado | G3: Avance | H3: Pendiente De Documentar | I3: Pendiente De Remesa | J3: Pendiente De Backoffice | K3: Evaluación BCP | L3: Obs Backoffice | M3: Obs BCP | N3: Rechazado
