Workbook

Sheet CONSOLIDADO
B2: Tablas de Gestión:
B4: SUPERVISOR | C4: ZONA | D4: TOTAL DESEMBOLSO | E4: Q DESEMBOLSO | F4: EVALUACION BCP | G4: PENDIENTE DE BACK | H4: PENDIENTE DE REMESA | I4: PENDIENTE DE DOCUMENTAR | J4: META OBJETIVO | K4: AVANCE | L4: Q EVALUACION BCP | M4: Q PENDIENTE DE BACK
B5: ANGIE SILVERA | C5: LIMA | D5: ='ANGIE SILVERA'!$F$4 -> 2071000 | E5: ='ANGIE SILVERA'!$F$5 -> 30 | F5: ='ANGIE SILVERA'!$K$4 -> 0 | G5: ='ANGIE SILVERA'!$J$4 -> 0 | H5: ='ANGIE SILVERA'!$I$4 -> 0 | I5: ='ANGIE SILVERA'!$H$4 -> 0 | J5: 2500000 | K5: =D5/J5 -> 0.8284 | L5: ='ANGIE SILVERA'!$K$5 -> 0 | M5: ='ANGIE SILVERA'!$J$5 -> 0
B6: CRISTINA BRACAMONTE | C6: CHICLAYO | D6: ='CRISTINA BRACAMONTE'!$F$4 -> 46000 | E6: ='CRISTINA BRACAMONTE'!$F$5 -> 1 | F6: ='CRISTINA BRACAMONTE'!$K$4 -> 0 | G6: ='CRISTINA BRACAMONTE'!$J$4 -> 0 | H6: ='CRISTINA BRACAMONTE'!$I$4 -> 0 | I6: ='CRISTINA BRACAMONTE'!$H$4 -> 0 | J6: 1000000 | K6: =D6/J6 -> 0.046 | L6: ='CRISTINA BRACAMONTE'!$K$5 -> 0 | M6: ='CRISTINA BRACAMONTE'!$J$5 -> 0
B7: JHON ZAMORA | C7: CHICLAYO | D7: ='JHON ZAMORA'!$F$4 -> 554150 | E7: ='JHON ZAMORA'!$F$5 -> 7 | F7: ='JHON ZAMORA'!$K$4 -> 0 | G7: ='JHON ZAMORA'!$J$4 -> 0 | H7: ='JHON ZAMORA'!$I$4 -> 0 | I7: ='JHON ZAMORA'!$H$4 -> 0 | J7: 1000000 | K7: =D7/J7 -> 0.55415 | L7: ='JHON ZAMORA'!$K$5 -> 0 | M7: ='JHON ZAMORA'!$J$5 -> 0
B8: JIMMY COLLAZOS | C8: TARAPOTO | D8: ='JIMMY COLLAZOS'!$F$4 -> 447530 | E8: ='JIMMY COLLAZOS'!$F$5 -> 6 | F8: ='JIMMY COLLAZOS'!$K$4 -> 0 | G8: ='JIMMY COLLAZOS'!$J$4 -> 0 | H8: ='JIMMY COLLAZOS'!$I$4 -> 0 | I8: ='JIMMY COLLAZOS'!$H$4 -> 0 | J8: 1000000 | K8: =D8/J8 -> 0.44753 | L8: ='JIMMY COLLAZOS'!$K$5 -> 0 | M8: ='JIMMY COLLAZOS'!$J$5 -> 0
B9: OMAR MINAYA | C9: CHICLAYO | D9: ='OMAR MINAYA'!$F$4 -> 157100 | E9: ='OMAR MINAYA'!$F$5 -> 3 | F9: ='OMAR MINAYA'!$K$4 -> 0 | G9: ='OMAR MINAYA'!$J$4 -> 0 | H9: ='OMAR MINAYA'!$I$4 -> 0 | I9: ='OMAR MINAYA'!$H$4 -> 0 | J9: 1000000 | K9: =D9/J9 -> 0.1571 | L9: ='OMAR MINAYA'!$K$5 -> 0 | M9: ='OMAR MINAYA'!$J$5 -> 0
B10: KENNY MORALES | C10: LIMA | D10: ='KENNY MORALES'!$F$4 -> 292600 | E10: ='KENNY MORALES'!$F$5 -> 6 | F10: ='KENNY MORALES'!$K$4 -> 0 | G10: ='KENNY MORALES'!$J$4 -> 0 | H10: ='KENNY MORALES'!$I$4 -> 0 | I10: ='KENNY MORALES'!$H$4 -> 0 | J10: 1000000 | K10: =D10/J10 -> 0.2926 | L10: ='KENNY MORALES'!$K$5 -> 0 | M10: ='KENNY MORALES'!$J$5 -> 0
B11: LUIS CHUSE | C11: LIMA | D11: ='LUIS CHUSE'!$F$4 -> 789451 | E11: ='LUIS CHUSE'!$F$5 -> 10 | F11: ='LUIS CHUSE'!$K$4 -> 0 | G11: ='LUIS CHUSE'!$J$4 -> 0 | H11: ='LUIS CHUSE'!$I$4 -> 0 | I11: ='LUIS CHUSE'!$H$4 -> 0 | J11: 1500000 | K11: =D11/J11 -> 0.52630067 | L11: ='LUIS CHUSE'!$K$5 -> 0 | M11: ='LUIS CHUSE'!$J$5 -> 0
B12: LUIS MENDOZA | C12: LIMA | D12: ='LUIS MENDOZA'!$F$4 -> 444390 | E12: ='LUIS MENDOZA'!$F$5 -> 6 | F12: ='LUIS MENDOZA'!$K$4 -> 0 | G12: ='LUIS MENDOZA'!$J$4 -> 0 | H12: ='LUIS MENDOZA'!$I$4 -> 0 | I12: ='LUIS MENDOZA'!$H$4 -> 0 | J12: 1000000 | K12: =D12/J12 -> 0.44439 | L12: ='LUIS MENDOZA'!$K$5 -> 0 | M12: ='LUIS MENDOZA'!$J$5 -> 0
B13: MARIELLA PAÑAHUA | C13: LIMA | D13: ='MARIELLA PAÑAHUA'!$F$4 -> 287000 | E13: ='MARIELLA PAÑAHUA'!$F$5 -> 5 | F13: ='MARIELLA PAÑAHUA'!$K$4 -> 0 | G13: ='MARIELLA PAÑAHUA'!$J$4 -> 0 | H13: ='MARIELLA PAÑAHUA'!$I$4 -> 0 | I13: ='MARIELLA PAÑAHUA'!$H$4 -> 0 | J13: 1000000 | K13: =D13/J13 -> 0.287 | L13: ='MARIELLA PAÑAHUA'!$K$5 -> 0 | M13: ='MARIELLA PAÑAHUA'!$J$5 -> 0
B14: MILAGROS TUESTA | C14: LIMA | D14: ='MILAGROS TUESTA'!$F$4 -> 2081240 | E14: ='MILAGROS TUESTA'!$F$5 -> 28 | F14: ='MILAGROS TUESTA'!$K$4 -> 0 | G14: ='MILAGROS TUESTA'!$J$4 -> 0 | H14: ='MILAGROS TUESTA'!$I$4 -> 0 | I14: ='MILAGROS TUESTA'!$H$4 -> 0 | J14: 1500000 | K14: =D14/J14 -> 1.3874933 | L14: ='MILAGROS TUESTA'!$K$5 -> 0 | M14: ='MILAGROS TUESTA'!$J$5 -> 0
B15: NAHOMI DIAZ | C15: CHICLAYO | D15: ='NAHOMI DIAZ'!$F$4 -> 1225220 | E15: ='NAHOMI DIAZ'!$F$5 -> 18 | F15: ='NAHOMI DIAZ'!$K$4 -> 0 | G15: ='NAHOMI DIAZ'!$J$4 -> 0 | H15: ='NAHOMI DIAZ'!$I$4 -> 54000 | I15: ='NAHOMI DIAZ'!$H$4 -> 0 | J15: 1000000 | K15: =D15/J15 -> 1.22522 | L15: ='NAHOMI DIAZ'!$K$5 -> 0 | M15: ='NAHOMI DIAZ'!$J$5 -> 0
B16: VIOLETA LLERENA | C16: AREQUIPA | D16: ='VIOLETA LLERENA'!$F$4 -> 279880 | E16: ='VIOLETA LLERENA'!$F$5 -> 4 | F16: ='VIOLETA LLERENA'!$K$4 -> 0 | G16: ='VIOLETA LLERENA'!$J$4 -> 0 | H16: ='VIOLETA LLERENA'!$I$4 -> 0 | I16: ='VIOLETA LLERENA'!$H$4 -> 0 | J16: 1000000 | K16: =D16/J16 -> 0.27988 | L16: ='VIOLETA LLERENA'!$K$5 -> 0 | M16: ='VIOLETA LLERENA'!$J$5 -> 0
B17: ALEXANDRA GUZMAN | C17: PIURA | D17: ='ALEXANDRA GUZMAN'!$F$4 -> 0 | E17: ='ALEXANDRA GUZMAN'!$F$5 -> 0 | F17: ='ALEXANDRA GUZMAN'!$K$4 -> 0 | G17: ='ALEXANDRA GUZMAN'!$J$4 -> 0 | H17: ='ALEXANDRA GUZMAN'!$I$4 -> 0 | I17: ='ALEXANDRA GUZMAN'!$H$4 -> 0 | J17: 1000000 | K17: =D17/J17 -> 0 | L17: ='ALEXANDRA GUZMAN'!$K$5 -> 0 | M17: ='ALEXANDRA GUZMAN'!$J$5 -> 0
B18: AMALIA QUINDE | C18: PIURA | D18: ='AMALIA QUINDE'!$F$4 -> 62000 | E18: ='AMALIA QUINDE'!$F$5 -> 1 | F18: ='AMALIA QUINDE'!$K$4 -> 0 | G18: ='AMALIA QUINDE'!$J$4 -> 0 | H18: ='AMALIA QUINDE'!$I$4 -> 0 | I18: ='AMALIA QUINDE'!$H$4 -> 0 | J18: 1000000 | K18: =D18/J18 -> 0.062 | L18: ='AMALIA QUINDE'!$K$5 -> 0 | M18: ='AMALIA QUINDE'!$J$5 -> 0
B19: JORGE CASTILLO | C19: PIURA | D19: ='JORGE CASTILLO'!$F$4 -> 0 | E19: ='JORGE CASTILLO'!$F$5 -> 0 | F19: ='JORGE CASTILLO'!$K$4 -> 0 | G19: ='JORGE CASTILLO'!$J$4 -> 0 | H19: ='JORGE CASTILLO'!$I$4 -> 0 | I19: ='JORGE CASTILLO'!$H$4 -> 0 | J19: 1000000 | K19: =D19/J19 -> 0 | L19: ='JORGE CASTILLO'!$K$5 -> 0 | M19: ='JORGE CASTILLO'!$J$5 -> 0
B20: WENDY IPANEQUE | C20: PIURA | D20: ='WENDY IPANEQUE'!$F$4 -> 0 | E20: ='WENDY IPANEQUE'!$F$5 -> 0 | F20: ='WENDY IPANEQUE'!$K$4 -> 0 | G20: ='WENDY IPANEQUE'!$J$4 -> 0 | H20: ='WENDY IPANEQUE'!$I$4 -> 0 | I20: ='WENDY IPANEQUE'!$H$4 -> 0 | J20: 1000000 | K20: =D20/J20 -> 0 | L20: ='WENDY IPANEQUE'!$K$5 -> 0 | M20: ='WENDY IPANEQUE'!$J$5 -> 0
B21: TOTAL | D21: =SUM(D5:D20) -> 8737561 | E21: =SUM(E5:E20) -> 125 | F21: =SUM(F5:F20) -> 0 | G21: =SUM(G5:G20) -> 0 | H21: =SUM(H5:H20) -> 54000 | I21: =SUM(I5:I20) -> 0 | J21: =SUM(J5:J20) -> 18500000 | K21: =D21/J21 -> 0.47230059 | L21: =SUM(L5:L20) -> 0 | M21: =SUM(M5:M20) -> 0
B24: PLAZA | D24: TOTAL DESEMBOLSO | E24: Q DESEMBOLSO | F24: EVALUACION BCP | G24: PENDIENTE DE BACK | H24: PENDIENTE DE REMESA | I24: PENDIENTE DE DOCUMENTAR | J24: META OBJETIVO | K24: AVANCE | L24: Q EVALUACION BCP | M24: Q PENDIENTE DE BACK
B25: LIMA | D25: =SUMIFS(D$5:D$20,$C$5:$C$20,$B25) -> 5965681 | E25: =SUMIFS(E$5:E$20,$C$5:$C$20,$B25) -> 85 | F25: =SUMIFS(F$5:F$20,$C$5:$C$20,$B25) -> 0 | G25: =SUMIFS(G$5:G$20,$C$5:$C$20,$B25) -> 0 | H25: =SUMIFS(H$5:H$20,$C$5:$C$20,$B25) -> 0 | I25: =SUMIFS(I$5:I$20,$C$5:$C$20,$B25) -> 0 | J25: =SUMIFS(J$5:J$20,$C$5:$C$20,$B25) -> 8500000 | K25: =D25/J25 -> 0.70184482 | L25: =SUMIFS(L$5:L$20,$C$5:$C$20,$B25) -> 0 | M25: =SUMIFS(M$5:M$20,$C$5:$C$20,$B25) -> 0
B26: NORTE | D26: =SUMIFS(D5:D20,$C$5:$C$20,"CHICLAYO")+SUMIFS(D5:D20,$C$5:$C$20,"TRUJILLO")+SUMIFS(D5:D20,$C$5:$C$20,"PIURA") -> 2044470 | E26: =SUMIFS(E5:E20,$C$5:$C$20,"CHICLAYO")+SUMIFS(E5:E20,$C$5:$C$20,"TRUJILLO")+SUMIFS(E5:E20,$C$5:$C$20,"PIURA") -> 30 | F26: =SUMIFS(F5:F20,$C$5:$C$20,"CHICLAYO")+SUMIFS(F5:F20,$C$5:$C$20,"TRUJILLO")+SUMIFS(F5:F20,$C$5:$C$20,"PIURA") -> 0 | G26: =SUMIFS(G5:G20,$C$5:$C$20,"CHICLAYO")+SUMIFS(G5:G20,$C$5:$C$20,"TRUJILLO")+SUMIFS(G5:G20,$C$5:$C$20,"PIURA") -> 0 | H26: =SUMIFS(H5:H20,$C$5:$C$20,"CHICLAYO")+SUMIFS(H5:H20,$C$5:$C$20,"TRUJILLO")+SUMIFS(H5:H20,$C$5:$C$20,"PIURA") -> 54000 | I26: =SUMIFS(I5:I20,$C$5:$C$20,"CHICLAYO")+SUMIFS(I5:I20,$C$5:$C$20,"TRUJILLO")+SUMIFS(I5:I20,$C$5:$C$20,"PIURA") -> 0 | J26: =SUMIFS(J5:J20,$C$5:$C$20,"CHICLAYO")+SUMIFS(J5:J20,$C$5:$C$20,"TRUJILLO")+SUMIFS(J5:J20,$C$5:$C$20,"PIURA") -> 8000000 | K26: =D26/J26 -> 0.25555875 | L26: =SUMIFS(L5:L20,$C$5:$C$20,"CHICLAYO")+SUMIFS(L5:L20,$C$5:$C$20,"TRUJILLO")+SUMIFS(L5:L20,$C$5:$C$20,"PIURA") -> 0 | M26: =SUMIFS(M5:M20,$C$5:$C$20,"CHICLAYO")+SUMIFS(M5:M20,$C$5:$C$20,"TRUJILLO")+SUMIFS(M5:M20,$C$5:$C$20,"PIURA") -> 0
B27: TARAPOTO | D27: =SUMIFS(D5:D20,$C$5:$C$20,"TARAPOTO") -> 447530 | E27: =SUMIFS(E5:E20,$C$5:$C$20,"TARAPOTO") -> 6 | F27: =SUMIFS(F5:F20,$C$5:$C$20,"TARAPOTO") -> 0 | G27: =SUMIFS(G5:G20,$C$5:$C$20,"TARAPOTO") -> 0 | H27: =SUMIFS(H5:H20,$C$5:$C$20,"TARAPOTO") -> 0 | I27: =SUMIFS(I5:I20,$C$5:$C$20,"TARAPOTO") -> 0 | J27: =SUMIFS(J5:J20,$C$5:$C$20,"TARAPOTO") -> 1000000 | K27: =D27/J27 -> 0.44753 | L27: =SUMIFS(L5:L20,$C$5:$C$20,"TARAPOTO") -> 0 | M27: =SUMIFS(M5:M20,$C$5:$C$20,"TARAPOTO") -> 0
B28: AREQUIPA | D28: =SUMIFS(D5:D20,$C$5:$C$20,"AREQUIPA") -> 279880 | E28: =SUMIFS(E5:E20,$C$5:$C$20,"AREQUIPA") -> 4 | F28: =SUMIFS(F5:F20,$C$5:$C$20,"AREQUIPA") -> 0 | G28: =SUMIFS(G5:G20,$C$5:$C$20,"AREQUIPA") -> 0 | H28: =SUMIFS(H5:H20,$C$5:$C$20,"AREQUIPA") -> 0 | I28: =SUMIFS(I5:I20,$C$5:$C$20,"AREQUIPA") -> 0 | J28: =SUMIFS(J5:J20,$C$5:$C$20,"AREQUIPA") -> 1000000 | K28: =D28/J28 -> 0.27988 | L28: =SUMIFS(L5:L20,$C$5:$C$20,"AREQUIPA") -> 0 | M28: =SUMIFS(M6:M21,$C$5:$C$20,"TARAPOTO") -> 0
B29: TOTAL | D29: =SUM(D25:D28) -> 8737561 | E29: =SUM(E25:E28) -> 125 | F29: =SUM(F25:F28) -> 0 | G29: =SUM(G25:G28) -> 0 | H29: =SUM(H25:H28) -> 54000 | I29: =SUM(I25:I28) -> 0 | J29: =SUM(J25:J28) -> 18500000 | K29: =D29/J29 -> 0.47230059 | L29: =SUM(L25:L28) -> 0 | M29: =SUM(M25:M28) -> 0

Sheet NAHOMI DIAZ
D3: CHICLAYO | E3: Meta | F3: Desembolsado | G3: Avance | H3: Pendiente De Documentar | I3: Pendiente De Remesa | J3: Pendiente De Backoffice | K3: Evaluación BCP | L3: Obs Backoffice | M3: Obs BCP | N3: Rechazado
D4: S/. | E4: 1000000 | F4: =SUMIFS(OPI_11[MAF NETO],OPI_11[ESTADO],"Desembolsado") -> 1225220 | G4: =F4-E4 -> 225220 | H4: =SUMIFS(OPI_11[MAF NETO],OPI_11[ESTADO],H$3) -> 0 | I4: =SUMIFS(OPI_11[MAF NETO],OPI_11[ESTADO],I$3) -> 54000 | J4: =SUMIFS(OPI_11[MAF NETO],OPI_11[ESTADO],J$3) -> 0 | K4: =SUMIFS(OPI_11[MAF NETO],OPI_11[ESTADO],K$3) -> 0 | L4: =SUMIFS(OPI_11[MAF NETO],OPI_11[ESTADO],L$3) -> 0 | M4: =SUMIFS(OPI_11[MAF NETO],OPI_11[ESTADO],M$3) -> 0 | N4: =SUMIFS(OPI_11[MAF NETO],OPI_11[ESTADO],N$3) -> 727840
D5: Q / % | E5: - | F5: =COUNTIFS(OPI_11[ESTADO],"Desembolsado") -> 18 | G5: =IFERROR(F4/E4,"") -> 1.22522 | H5: =COUNTIFS(OPI_11[ESTADO],H$3) -> 0 | I5: =COUNTIFS(OPI_11[ESTADO],I$3) -> 1 | J5: =COUNTIFS(OPI_11[ESTADO],J$3) -> 0 | K5: =COUNTIFS(OPI_11[ESTADO],K$3) -> 0 | L5: =COUNTIFS(OPI_11[ESTADO],L$3) -> 0 | M5: =COUNTIFS(OPI_11[ESTADO],M$3) -> 0 | N5: =COUNTIFS(OPI_11[ESTADO],N$3) -> 10
B9: PLAZA DE VENTA | C9: FECHA DE ENVIO DE REMESA | D9: ESTADO DE REMESA | E9: FECHA DE INGRESO | F9: FECHA DE DESEMBOLSO | G9: DOCUMENTO | H9: NOMBRES Y APELLIDOS | I9: CONVENIO | J9: ESTADO | K9: MAF NETO | L9: EJECUTIVO | M9: FILE ENVIADO A BANCO | N9: FECHA DE ENVIÓ CARTA PODER A BCP | O9: COMPRA DE DEUDA REALIZADA | P9: LIBERACIÓN | Q9: FEEDBACK
B10: CHICLAYO | C10: 46147 | D10: Aprobada | E10: 46148 | G10: 71448501 | H10: ACUÑA TERRONES VICTOR AGUSTO | I10: PNP | J10: Rechazado | K10: 71450 | L10: AZUCENA BARBA | Q10: CAMBIO SCORE
B11: CHICLAYO | C11: 46147 | D11: Aprobada | E11: 46148 | F11: 46149 | G11: 45489069 | H11: MORENO SANTA MARIA PETER WILLY | I11: PNP | J11: Desembolsado | K11: 82850 | L11: JUDITH FARRO
B12: CHICLAYO | C12: 46146 | D12: Aprobada | E12: 46147 | F12: 46147 | G12: 70581599 | H12: YUMBATO MURAYARI WALTER | I12: EJERCITO | J12: Desembolsado | K12: 62900 | L12: VIDALINA ESTELA
B13: CHICLAYO | C13: 46150 | D13: Aprobada | E13: 46153 | F13: 46157 | G13: 71582043 | H13: BANDA MEDINA JOSE OMAR | I13: PNP | J13: Desembolsado | K13: 14500 | L13: AZUCENA BARBA
B14: CHICLAYO | C14: 46150 | D14: Rechazada | G14: 76286201 | H14: FRETEL CHANAME EDSON RONALDO | I14: PNP | J14: Rechazado | K14: 75700 | L14: VIDALINA ESTELA | Q14: DESEMBOLSÓ BBVA
B15: CHICLAYO | C15: 46150 | D15: Aprobada | E15: 46156 | F15: 46156 | G15: 75793286 | H15: CASANA VELASQUEZ JEAN CARLO | I15: PNP | J15: Desembolsado | K15: 66400 | L15: VIDALINA ESTELA
B16: CHICLAYO | C16: 46150 | D16: Rechazada | G16: 75910205 | H16: ORTIZ SANCHEZ JOSEPH ALAIN | I16: PNP | J16: Rechazado | K16: 78190 | L16: YURIKO OSPINO
B17: CHICLAYO | C17: 46150 | D17: Rechazada | G17: 46005010 | H17: PALACIOS SUXO JOSE EDUARDO | I17: EJERCITO | J17: Rechazado | K17: 74600 | L17: JUDITH FARRO
B18: CHICLAYO | C18: 46153 | D18: Aprobada | E18: 46153 | F18: 46153 | G18: 75831834 | H18: ZARATE RECALDE YANNER | I18: PNP | J18: Desembolsado | K18: 69100 | L18: VIDALINA ESTELA
B19: CHICLAYO | C19: 46151 | D19: Aprobada | E19: . | G19: 47040995 | H19: NUÑEZ TERRONES | I19: PNP | J19: Desembolsado | K19: 79760 | L19: JUDITH FARRO
B20: CHICLAYO | C20: 42502 | D20: Aprobada | E20: 46155 | F20: 46156 | G20: 46146763 | H20: VERGARA HUALLPARIMACCHI AMILCAR | I20: PNP | J20: Desembolsado | K20: 77550 | L20: JUDITH FARRO
B21: CHICLAYO | D21: Rechazada | G21: 47301103 | H21: BURGA REGALADO | I21: PNP | J21: Rechazado | K21: 83000 | L21: YURIKO OSPINO | M21: No | Q21: A ESPERA DE BOLETA MAYO
B22: CHICLAYO | C22: 46157 | D22: Rechazada | G22: 47325317 | H22: FERNANDEZ DAVILA CLEVER RAUL | I22: PNP | J22: Rechazado | K22: 71900 | L22: VIDALINA ESTELA | Q22: REFINANCIADO
B23: CHICLAYO | D23: Aprobada | G23: 76392800 | H23: AVELLANEDA ESPINOZA MILTE NESTOR | I23: EJERCITO | J23: Desembolsado | K23: 70390 | L23: AZUCENA BARBA | Q23: .
B24: CHICLAYO | C24: 46158 | D24: Rechazada | G24: 46127105 | H24: SUCLUPE MATALLANA PABLO EDUARDO | I24: EJERCITO | J24: Rechazado | K24: 88600 | L24: VIDALINA ESTELA | Q24: LE FALTA 1 DSCTO BOLETA
B25: CHICLAYO | C25: 46161 | D25: Aprobada | E25: 46161 | F25: 46162 | G25: 77239342 | H25: BUSTAMANTE ENRIQUEZ YASSER BILL | I25: EJERCITO | J25: Desembolsado | K25: 90500 | L25: VIDALINA ESTELA
B26: CHICLAYO | C26: 46162 | D26: Aprobada | E26: 46162 | G26: 71374506 | H26: HUAROTTO CORDOVA ELVIS CRISTIAN | I26: PNP | J26: Desembolsado | K26: 35700 | L26: VIDALINA ESTELA
B27: CHICLAYO | C27: 46163 | D27: Aprobada | E27: 46165 | G27: 48130160 | H27: VERA RAMOS RICHARD OSMIN | I27: PNP | J27: Desembolsado | K27: 80900 | L27: VIDALINA ESTELA
B28: CHICLAYO | C28: 46163 | D28: Aprobada | E28: 46168 | G28: 73569726 | H28: SORIANO CARRASCO JEFFERSON JAMIR | I28: EJERCITO | J28: Desembolsado | K28: 76500 | L28: YURIKO OSPINO
B29: CHICLAYO | C29: 46167 | D29: Enviada | F29: 26.0 | G29: 74635454 | H29: IRIGOÍN GONZÁLES FRANKLIN MARLO | I29: PNP | J29: Desembolsado | K29: 78000 | L29: VIDALINA ESTELA
B30: CHICLAYO | C30: 46164 | D30: Aprobada | E30: 46168 | G30: 71238364 | H30: RENGIFO USHIÑAHUA JESSICA YADIRA | I30: pnp | J30: Desembolsado | K30: 33000 | L30: AZUCENA BARBA
B31: CHICLAYO | C31: 46165 | D31: Rechazada | G31: 73489789 | H31: VALLEJOS GOICOCHEA LUIS | I31: pnp | J31: Rechazado | K31: 33000 | L31: VIDALINA ESTELA | Q31: DESISTIO
B32: CHICLAYO | C32: 46168 | D32: Aprobada | G32: 46949222 | H32: BAUTISTA ALVA GOMVY NAPOLEON | I32: PNP | J32: Desembolsado | K32: 81600 | L32: YURIKO OSPINO
B33: CHICLAYO | C33: 46199 | D33: Aprobada | E33: 46200 | G33: 48667414 | H33: RAMIREZ VALLEJOS DEIBY | I33: PNP | J33: Desembolsado | K33: 78550 | L33: VIDALINA ESTELA
B34: CHICLAYO | C34: 46168 | D34: Enviada | G34: 72307920 | H34: FUSTAMANTE HERRERA CARLOS ALBERTO | I34: PNP | J34: Pendiente De Remesa | K34: 54000 | L34: YURIKO OSPINO
B35: CHICLAYO | C35: 46169 | D35: Rechazada | G35: 74909280 | H35: OJEDA PRADA ADRIAN AUGUSTO | I35: EJERCITO | J35: Rechazado | K35: 63600 | L35: VIDALINA ESTELA | Q35: CARTERA TRANSFERIDA
B36: CHICLAYO | C36: 46169 | D36: Enviada | G36: 72225176 | H36: NIETO VENTURA LUIGGI VLADIMIR | I36: PNP | J36: Desembolsado | K36: 63500 | L36: VIDALINA ESTELA
B37: CHICLAYO | C37: 46170 | D37: Enviada | G37: 43261552 | H37: REJAS VELASCO EVELYN MARGOT | I37: EJERCITO | J37: Rechazado | K37: 87800 | L37: VIDALINA ESTELA | Q37: INSTITUCION RECHAZO EL MAXIMO MONTO
C38: 47266 | D38: Aprobada | E38: 46170 | G38: 70948146 | H38: MORE BRAVO RENZO EDGAR JESUS | I38: EJERCITO | J38: Desembolsado | K38: 83520 | L38: YURIKO OSPINO

Sheet OMAR MINAYA
D3: CHICLAYO | E3: Meta | F3: Desembolsado | G3: Avance | H3: Pendiente De Documentar | I3: Pendiente De Remesa | J3: Pendiente De Backoffice | K3: Evaluación BCP | L3: Obs Backoffice | M3: Obs BCP | N3: Rechazado
D4: S/. | E4: 1000000 | F4: =SUMIFS(OPI_5[MAF NETO],OPI_5[ESTADO],"Desembolsado") -> 157100 | G4: =F4-E4 -> -842900 | H4: =SUMIFS(OPI_5[MAF NETO],OPI_5[ESTADO],H$3) -> 0 | I4: =SUMIFS(OPI_5[MAF NETO],OPI_5[ESTADO],I$3) -> 0 | J4: =SUMIFS(OPI_5[MAF NETO],OPI_5[ESTADO],J$3) -> 0 | K4: =SUMIFS(OPI_5[MAF NETO],OPI_5[ESTADO],K$3) -> 0 | L4: =SUMIFS(OPI_5[MAF NETO],OPI_5[ESTADO],L$3) -> 0 | M4: =SUMIFS(OPI_5[MAF NETO],OPI_5[ESTADO],M$3) -> 0 | N4: =SUMIFS(OPI_5[MAF NETO],OPI_5[ESTADO],N$3) -> 118300
D5: Q / % | E5: - | F5: =COUNTIFS(OPI_5[ESTADO],"Desembolsado") -> 3 | G5: =IFERROR(F4/E4,"") -> 0.1571 | H5: =COUNTIFS(OPI_5[ESTADO],H$3) -> 0 | I5: =COUNTIFS(OPI_5[ESTADO],I$3) -> 0 | J5: =COUNTIFS(OPI_5[ESTADO],J$3) -> 0 | K5: =COUNTIFS(OPI_5[ESTADO],K$3) -> 0 | L5: =COUNTIFS(OPI_5[ESTADO],L$3) -> 0 | M5: =COUNTIFS(OPI_5[ESTADO],M$3) -> 0 | N5: =COUNTIFS(OPI_5[ESTADO],N$3) -> 2
B9: PLAZA DE VENTA | C9: FECHA DE ENVIO DE REMESA | D9: ESTADO DE REMESA | E9: FECHA DE INGRESO | F9: FECHA DE DESEMBOLSO | G9: DOCUMENTO | H9: NOMBRES Y APELLIDOS | I9: CONVENIO | J9: ESTADO | K9: MAF NETO | L9: EJECUTIVO | M9: FILE ENVIADO A BANCO | N9: FECHA DE ENVIÓ CARTA PODER A BCP | O9: COMPRA DE DEUDA REALIZADA | P9: LIBERACIÓN | Q9: FEEDBACK
B10: CHICLAYO | C10: 46154 | D10: Aprobada | E10: 46157 | G10: 73865661 | H10: GEANPIEER GRIMALDO BRAVO VILLA | I10: PNP | J10: Desembolsado | K10: 52300 | L10: VICTOR CIEZA | M10: Si | O10: Si | P10: Si
B11: CHICLAYO | C11: 46161 | D11: Aprobada | E11: 46163 | G11: 72774091 | H11: SEGURA RAMOS GUSTAVO EDUARDO | I11: PNP | J11: Desembolsado | K11: 64250 | L11: VICTOR CIEZA | M11: No | O11: Si | P11: No
B12: CHICLAYO | C12: 46161 | D12: Aprobada | G12: 77415152 | H12: JHENNYFER TATIANA DIAZ SANDOVAL | I12: PNP | J12: Rechazado | K12: 83700 | L12: VICTOR CIEZA | M12: Si | Q12: CLIENTE DESISTIÓ DE CREDITO
B13: CHICLAYO | C13: 46168 | D13: Aprobada | E13: 46169 | G13: 75771722 | H13: CRISANTO ALVARADO JUNIOR JOSUE | I13: PNP | J13: Desembolsado | K13: 40550 | L13: VICTOR CIEZA | M13: No | Q13: .
B14: CHICLAYO | C14: 46168 | D14: Aprobada | E14: 46169 | G14: 46180058 | H14: VASQUEZ EFFIO SMITH ALAN | I14: PNP | J14: Rechazado | K14: 34600 | L14: VICTOR CIEZA | M14: Si | N14: El estado de la solicitud para el cliente Vasquez Effio Smith Alan es "Rechazado" (columna J), por lo que no corresponde el envío de una carta poder al BCP. En las filas anteriores con un estado similar o sin el trámite realizado, esta celda se deja vacía. En un formato de celda de texto o vacío, se puede representar con un espacio en blanco o un guion si se sigue la consistencia de las filas vacías de la tabla. Dado el contexto de la fila anterior rechazada que no tiene datos en esa columna: | Q14: .

Sheet JHON ZAMORA
D3: CHICLAYO | E3: Meta | F3: Desembolsado | G3: Avance | H3: Pendiente De Documentar | I3: Pendiente De Remesa | J3: Pendiente De Backoffice | K3: Evaluación BCP | L3: Obs Backoffice | M3: Obs BCP | N3: Rechazado
D4: S/. | E4: 1000000 | F4: =SUMIFS(OPI_3[MAF NETO],OPI_3[ESTADO],"Desembolsado") -> 554150 | G4: =F4-E4 -> -445850 | H4: =SUMIFS(OPI_3[MAF NETO],OPI_3[ESTADO],H$3) -> 0 | I4: =SUMIFS(OPI_3[MAF NETO],OPI_3[ESTADO],I$3) -> 0 | J4: =SUMIFS(OPI_3[MAF NETO],OPI_3[ESTADO],J$3) -> 0 | K4: =SUMIFS(OPI_3[MAF NETO],OPI_3[ESTADO],K$3) -> 0 | L4: =SUMIFS(OPI_3[MAF NETO],OPI_3[ESTADO],L$3) -> 0 | M4: =SUMIFS(OPI_3[MAF NETO],OPI_3[ESTADO],M$3) -> 0 | N4: =SUMIFS(OPI_3[MAF NETO],OPI_3[ESTADO],N$3) -> 63380
D5: Q / % | E5: - | F5: =COUNTIFS(OPI_3[ESTADO],"Desembolsado") -> 7 | G5: =IFERROR(F4/E4,"") -> 0.55415 | H5: =COUNTIFS(OPI_3[ESTADO],H$3) -> 0 | I5: =COUNTIFS(OPI_3[ESTADO],I$3) -> 0 | J5: =COUNTIFS(OPI_3[ESTADO],J$3) -> 0 | K5: =COUNTIFS(OPI_3[ESTADO],K$3) -> 0 | L5: =COUNTIFS(OPI_3[ESTADO],L$3) -> 0 | M5: =COUNTIFS(OPI_3[ESTADO],M$3) -> 0 | N5: =COUNTIFS(OPI_3[ESTADO],N$3) -> 4
B9: PLAZA DE VENTA | C9: FECHA DE ENVIO DE REMESA | D9: ESTADO DE REMESA | E9: FECHA DE INGRESO | F9: FECHA DE DESEMBOLSO | G9: DOCUMENTO | H9: NOMBRES Y APELLIDOS | I9: CONVENIO | J9: ESTADO | K9: MAF NETO | L9: EJECUTIVO | M9: FILE ENVIADO A BANCO | N9: FECHA DE ENVIÓ CARTA PODER A BCP | O9: COMPRA DE DEUDA REALIZADA | P9: LIBERACIÓN | Q9: FEEDBACK
C10: 46146 | D10: Aprobada | E10: 05-05.2026 | F10: 46149 | G10: 70775368 | H10: PALOMINO VALENCIA KENYO | I10: PNP | J10: Desembolsado | K10: 82200 | L10: FLOR LLATAS | M10: Si | O10: Si | P10: No
C11: 46147 | D11: Rechazada | G11: 74314651 | H11: CHAFLOQUE LEON CARLOS DHYACO | I11: PNP | J11: Rechazado | L11: FLOR LLATAS | Q11: CLTE CON FOVIPOL NO PROCEDE CD NACION POR FALTA DE LIQUIDEZ
C12: 46148 | D12: Rechazada | G12: 71934007 | H12: VASQUEZ FLORES ELIAS FERNANDO | I12: EJERCITO PERUANO | J12: Rechazado | L12: FLOR LLATAS | Q12: REMESA RECHAZADA
C13: 46150 | D13: Aprobada | E13: 46152 | F13: 46153 | G13: 46043653 | H13: NECIOSUP CIURLIZZA ARMANDO EDUARDO | I13: PNP | J13: Desembolsado | K13: 79500 | L13: FLOR LLATAS | M13: Si | N13: 46155 | O13: No | P13: No
C14: 46157 | D14: Enviada | G14: 73859445 | H14: TICLIAHUANCA BRAVO MARLON SAID | I14: PNP | J14: Rechazado | K14: 63380 | L14: FLOR LLATAS | Q14: CLIENTE FIRMÓ OTRO BANCO
C15: 46160 | D15: Enviada | E15: 46160 | F15: 46161 | G15: 48681594 | H15: OJANAMA ACOSTA LARRY | I15: PNP | J15: Desembolsado | K15: 75750 | L15: FLOR LLATAS | M15: No | O15: No
C16: 46163 | D16: Enviada | E16: 46163 | G16: 46910174 | H16: FRIAS BERECHE KAREN ANDREA | I16: PNP | J16: Desembolsado | K16: 79150 | L16: FLOR LLATAS | M16: No | O16: No
D17: Enviada | E17: 46167 | G17: 71109206 | H17: BARDALES VEGA FRANZ WILER | I17: PNP | J17: Rechazado | Q17: remesa rechazada por liquides
G18: 76354199 | H18: CASTILLO ZETA KATHERINE LISBETH | I18: PNP | J18: Desembolsado | K18: 78000 | L18: FLOR LLATAS | Q18: .
G19: 43128829 | H19: PERALTA PAREDES WILMER ALBERTO | I19: PNP | J19: Desembolsado | K19: 78300 | L19: FLOR LLATAS | Q19: .
G20: 42421324 | H20: ZULOETA ZULOETA JOSE LUIS | I20: PNP | J20: Desembolsado | K20: 81250 | L20: FLOR LLATAS

Sheet ANGIE SILVERA
D3: LIMA | E3: Meta | F3: Desembolsado | G3: Avance | H3: Pendiente De Documentar | I3: Pendiente De Remesa | J3: Pendiente De Backoffice | K3: Evaluación BCP | L3: Obs Backoffice | M3: Obs BCP | N3: Rechazado
D4: S/. | E4: 2500000 | F4: =SUMIFS(OPI[MAF NETO],OPI[ESTADO],"Desembolsado") -> 2071000 | G4: =F4-E4 -> -429000 | H4: =SUMIFS(OPI[MAF NETO],OPI[ESTADO],H$3) -> 0 | I4: =SUMIFS(OPI[MAF NETO],OPI[ESTADO],I$3) -> 0 | J4: =SUMIFS(OPI[MAF NETO],OPI[ESTADO],J$3) -> 0 | K4: =SUMIFS(OPI[MAF NETO],OPI[ESTADO],K$3) -> 0 | L4: =SUMIFS(OPI[MAF NETO],OPI[ESTADO],L$3) -> 0 | M4: =SUMIFS(OPI[MAF NETO],OPI[ESTADO],M$3) -> 0 | N4: =SUMIFS(OPI[MAF NETO],OPI[ESTADO],N$3) -> 0
D5: Q / % | E5: - | F5: =COUNTIFS(OPI[ESTADO],"Desembolsado") -> 30 | G5: =IFERROR(F4/E4,"") -> 0.8284 | H5: =COUNTIFS(OPI[ESTADO],H$3) -> 0 | I5: =COUNTIFS(OPI[ESTADO],I$3) -> 0 | J5: =COUNTIFS(OPI[ESTADO],J$3) -> 0 | K5: =COUNTIFS(OPI[ESTADO],K$3) -> 0 | L5: =COUNTIFS(OPI[ESTADO],L$3) -> 0 | M5: =COUNTIFS(OPI[ESTADO],M$3) -> 0 | N5: =COUNTIFS(OPI[ESTADO],N$3) -> 0
B9: PLAZA DE VENTA | C9: FECHA DE ENVIO DE REMESA | D9: ESTADO DE REMESA | E9: FECHA DE INGRESO | F9: FECHA DE DESEMBOLSO | G9: DOCUMENTO | H9: NOMBRES Y APELLIDOS | I9: CONVENIO | J9: ESTADO | K9: MAF NETO | L9: EJECUTIVO | M9: FILE ENVIADO A BANCO | N9: FECHA DE ENVIÓ CARTA PODER A BCP | O9: COMPRA DE DEUDA REALIZADA | P9: LIBERACIÓN | Q9: FEEDBACK
B10: LIMA | C10: 46146 | D10: Aprobada | E10: 46147 | F10: 46150 | G10: 73265306 | H10: ACOSTA HUAMAN JESUS ALEXANDER | I10: PNP | J10: Desembolsado | K10: 67000 | L10: MARIA LLONTOP | M10: Si | N10: 46153 | O10: Si
B11: LIMA | C11: 46147 | D11: Aprobada | E11: 46149 | F11: 46150 | G11: 74610530 | H11: ZAVALA OLIVERA ABRAHAM JONAS | I11: MARINA | J11: Desembolsado | K11: 83400 | L11: AURELIA FERNANDEZ | M11: Si | N11: 46153 | O11: Si
B12: PUERTO MALDONADO | C12: 46148 | D12: Aprobada | E12: 46150 | F12: 46150 | G12: 41224372 | H12: ROMAN ROMAN ISMAEL JACOB | I12: PNP | J12: Desembolsado | K12: 52500 | L12: AURELIA FERNANDEZ | M12: Si | N12: 46157
B13: LIMA | C13: 46153 | D13: Aprobada | E13: 46155 | F13: 46155 | G13: 44781528 | H13: CAMONES RAMOS GLADYS ELIZABETH | I13: PNP | J13: Desembolsado | K13: 57200 | L13: YESICA HEREDIA | M13: Si | N13: 46157
B14: LIMA | C14: 46153 | D14: Aprobada | E14: 46157 | F14: 46160 | G14: 41280974 | H14: HERMOZA ARANA CARMEN ROSA | I14: FAP | J14: Desembolsado | K14: 70500 | L14: MARIA LLONTOP | M14: Si
B15: LIMA | C15: 46155 | D15: Aprobada | E15: 46156 | F15: 46156 | G15: 70046499 | H15: LLONTOP RAMIREZ BRANDON JANPIER | I15: PNP | J15: Desembolsado | K15: 61000 | L15: MARIA LLONTOP | M15: Si | N15: 46157
B16: CHICLAYO | C16: 46156 | D16: Aprobada | E16: 46157 | F16: 46157 | G16: 71599463 | H16: ALIAGA VALERIANO JHEREMY JESUS | I16: PNP | J16: Desembolsado | K16: 82000 | L16: AURELIA FERNANDEZ | M16: Si
B17: LIMA | C17: 46156 | D17: Aprobada | E17: 46157 | F17: 46160 | G17: 45920500 | H17: CHAVEZ PEREZ CESAR GUILLERMO | I17: PNP | J17: Desembolsado | K17: 10000 | L17: JUAN CORDOVA
B18: LIMA | C18: 46156 | D18: Aprobada | E18: 46157 | F18: 46160 | G18: 73741384 | H18: PILCO BRAVO ROEL NEIL | I18: PNP | J18: Desembolsado | K18: 74700 | L18: AURELIA FERNANDEZ
B19: LIMA | C19: 46155 | D19: Aprobada | E19: 46157 | F19: 46157 | G19: 46946411 | H19: PUANCHA CHIJIAP OMERO | I19: FAP | J19: Desembolsado | K19: 71000 | L19: MARIA LLONTOP | M19: Si
B20: TUMBES | C20: 46156 | D20: Aprobada | E20: 46157 | F20: 46160 | G20: 71314321 | H20: CHUNGA SANCHEZ CHRISTIAN AUGUSTO | I20: EP | J20: Desembolsado | K20: 62000 | L20: YESICA HEREDIA
B21: LIMA | C21: 46160 | D21: Aprobada | E21: 46161 | F21: 46164 | G21: 70114022 | H21: JARA FLORENTINO XIOMARA NAOMI | I21: PNP | J21: Desembolsado | K21: 25000 | L21: JUAN CORDOVA
B22: LIMA | C22: 46162 | D22: Aprobada | E22: 46162 | F22: 46164 | G22: 70204889 | H22: SANCHEZ LICAPA LUIS ALBERTO | I22: PNP | J22: Desembolsado | K22: 73850 | L22: AURELIA FERNANDEZ
B23: CHICLAYO | C23: 46162 | D23: Aprobada | E23: 46166 | F23: 46167 | G23: 74762869 | H23: ALVARADO TAYPE DIMAS EDWIN | I23: PNP | J23: Desembolsado | K23: 40900 | L23: AURELIA FERNANDEZ
B24: LIMA | C24: 46167 | D24: Aprobada | E24: 46167 | F24: 46168 | G24: 63692650 | H24: GUZMAN CAHUACHI FRANKLIN ELIAN | I24: PNP | J24: Desembolsado | K24: 66000 | L24: YESICA HEREDIA
B25: LIMA | C25: 46167 | D25: Aprobada | E25: 46167 | F25: 46168 | G25: 46880757 | H25: HUAPAYA PERALTA JUAN JESUS | I25: PNP | J25: Desembolsado | K25: 61300 | L25: MARIA LLONTOP
B26: LIMA | C26: 46167 | D26: Aprobada | E26: 46167 | F26: 46168 | G26: 06666637 | H26: FABIAN CELIS MIRIAM LUISA | I26: FAP | J26: Desembolsado | K26: 68000 | L26: AURELIA FERNANDEZ
B27: LIMA | C27: 46167 | D27: Aprobada | E27: 46168 | F27: 46169 | G27: 74239685 | H27: SAAVEDRA FARFAN JOEL | I27: PNP | J27: Desembolsado | K27: 71300 | L27: MARIA LLONTOP
B28: LIMA | C28: 46164 | D28: Aprobada | E28: 46168 | F28: 46169 | G28: 73816026 | H28: PRETEL ROJAS MAURO GIANPIERRE | I28: EP | J28: Desembolsado | K28: 86000 | L28: AURELIA FERNANDEZ
B29: LIMA | C29: 46167 | D29: Aprobada | E29: 46168 | F29: 46169 | G29: 45918277 | H29: QUISPE CANCHARI ILICH DARWIN | I29: PNP | J29: Desembolsado | K29: 78000 | L29: JUAN CORDOVA
B30: LIMA | C30: 46167 | D30: Aprobada | E30: 46168 | F30: 46169 | G30: 47993666 | H30: CABANILLAS ROMERO MARIA EVILA | I30: PNP | J30: Desembolsado | K30: 78000 | L30: AURELIA FERNANDEZ
B31: LIMA | C31: 46167 | D31: Aprobada | E31: 46168 | F31: 46169 | G31: 77344757 | H31: GONZALO GALLARDO ISRAEL | I31: PNP | J31: Desembolsado | K31: 68500 | L31: MARIA LLONTOP
... B37: LIMA | C37: 46168 | D37: Aprobada | E37: 46170 | F37: 46171 | G37: 71246855 | H37: JIMENEZ MENDOZA DARWIN | I37: PNP | J37: Desembolsado | K37: 60000 | L37: JUAN CORDOVA
C38: 46170 | D38: Aprobada | E38: 46170 | F38: 46171 | G38: 72201533 | H38: MAZA RAMOS ANGEL ARNALDO | I38: PNP | J38: Desembolsado | K38: 25000 | L38: AURELIA FERNANDEZ
C39: 46170 | D39: Aprobada | E39: 46170 | F39: 46171 | G39: 74403892 | H39: PARAGUAY MEZA FOREX MAYKY | I39: PNP | J39: Desembolsado | K39: 80300 | L39: JUAN CORDOVA

Sheet LUIS CHUSE
D3: LIMA | E3: Meta | F3: Desembolsado | G3: Avance | H3: Pendiente De Documentar | I3: Pendiente De Remesa | J3: Pendiente De Backoffice | K3: Evaluación BCP | L3: Obs Backoffice | M3: Obs BCP | N3: Rechazado
D4: S/. | E4: 1500000 | F4: =SUMIFS(OPI_7[MAF NETO],OPI_7[ESTADO],"Desembolsado") -> 789451 | G4: =F4-E4 -> -710549 | H4: =SUMIFS(OPI_7[MAF NETO],OPI_7[ESTADO],H$3) -> 0 | I4: =SUMIFS(OPI_7[MAF NETO],OPI_7[ESTADO],I$3) -> 0 | J4: =SUMIFS(OPI_7[MAF NETO],OPI_7[ESTADO],J$3) -> 0 | K4: =SUMIFS(OPI_7[MAF NETO],OPI_7[ESTADO],K$3) -> 0 | L4: =SUMIFS(OPI_7[MAF NETO],OPI_7[ESTADO],L$3) -> 0 | M4: =SUMIFS(OPI_7[MAF NETO],OPI_7[ESTADO],M$3) -> 0 | N4: =SUMIFS(OPI_7[MAF NETO],OPI_7[ESTADO],N$3) -> 348600
D5: Q / % | E5: - | F5: =COUNTIFS(OPI_7[ESTADO],"Desembolsado") -> 10 | G5: =IFERROR(F4/E4,"") -> 0.52630067 | H5: =COUNTIFS(OPI_7[ESTADO],H$3) -> 0 | I5: =COUNTIFS(OPI_7[ESTADO],I$3) -> 0 | J5: =COUNTIFS(OPI_7[ESTADO],J$3) -> 0 | K5: =COUNTIFS(OPI_7[ESTADO],K$3) -> 0 | L5: =COUNTIFS(OPI_7[ESTADO],L$3) -> 0 | M5: =COUNTIFS(OPI_7[ESTADO],M$3) -> 0 | N5: =COUNTIFS(OPI_7[ESTADO],N$3) -> 4
B9: PLAZA DE VENTA | C9: FECHA DE ENVIO DE REMESA | D9: ESTADO DE REMESA | E9: FECHA DE INGRESO | F9: FECHA DE DESEMBOLSO | G9: DOCUMENTO | H9: NOMBRES Y APELLIDOS | I9: CONVENIO | J9: ESTADO | K9: MAF NETO | L9: EJECUTIVO | M9: FILE ENVIADO A BANCO | N9: FECHA DE ENVIÓ CARTA PODER A BCP | O9: COMPRA DE DEUDA REALIZADA | P9: LIBERACIÓN | Q9: FEEDBACK
B10: LIMA | C10: 46146 | D10: Aprobada | E10: 46148 | F10: 46150 | G10: 43919534 | H10: SANTE MENDOZA CARLOS CORONADO | I10: PNP | J10: Desembolsado | K10: 91050 | L10: JEANNETTE MENDEZ | M10: No
B11: LIMA | C11: 46147 | D11: Aprobada | E11: 46150 | G11: 73335956 | H11: TICLIAHUANCA HUANCAS MAYR LOT | I11: PNP | J11: Desembolsado | K11: 78500 | L11: RAUL ALCA | M11: No | Q11: CLIENTE PYME , SE SOLICITO CAMBIO
B12: LIMA | C12: 46148 | D12: Aprobada | E12: 46149 | F12: 46150 | G12: 43378472 | H12: RANTES LOPEZ MICHAEL HOWARD LEE | I12: DIRIS CENTRO | J12: Desembolsado | K12: 150285 | L12: LUIS SHEPERD | M12: No
B13: LIMA | C13: 46149 | D13: Aprobada | E13: 46150 | G13: 40284449 | H13: IBARRA LEON RICARDO MASIAS | I13: DIRIS ESTE | J13: Desembolsado | K13: 116250 | L13: LUIS SHEPERD | M13: No
B14: LIMA | C14: 46150 | D14: Aprobada | E14: 46153 | F14: 46154 | G14: 71111316 | H14: CORDOVA CAMACHO LEODAN | I14: PNP | J14: Desembolsado | K14: 72000 | L14: EDGAR CHOTA | M14: No
B15: LIMA | C15: 46154 | D15: Aprobada | E15: 46158 | F15: 46160 | G15: 45789138 | H15: JAZMINA REYNA OREJON MARCA | I15: ESSALUD | J15: Desembolsado | K15: 11996 | L15: CARLOS ESPINOZA | M15: Si
B16: LIMA | C16: 46155 | D16: Aprobada | E16: 46160 | F16: 46162 | G16: 42675444 | H16: FLOREANO RODRIGUEZ TAYLOR ELI | I16: DIRIS ESTE | J16: Desembolsado | K16: 73200 | L16: LUIS SHEPERD | M16: No
B17: LIMA | C17: 46156 | D17: Aprobada | E17: 46158 | F17: 46161 | G17: 47496367 | H17: QUISPE CONTRERAS MYCKOL JONATHAN | I17: FAP | J17: Desembolsado | K17: 58890 | L17: JOSSEF | M17: No
B18: LIMA | C18: 46160 | D18: Aprobada | E18: 46160 | F18: 46162 | G18: 09570721 | H18: ESPINOZA BRAVO ESTHER CARIDAD | I18: DIRIS ESTE | J18: Rechazado | K18: 150000 | L18: LUIS SHEPERD | M18: No
B19: LIMA | C19: 46160 | D19: Aprobada | E19: 46162 | G19: 09655248 | H19: SALVO CHUQUICAJA ADA LUZ | I19: DIRIS LIMA CENTRO | J19: Rechazado | K19: 56400 | L19: LUIS SHEPERD | M19: No
B20: LIMA | C20: 46161 | D20: Aprobada | E20: 46162 | G20: 46696117 | H20: VEGA CHUCO ANGELINE MARIA SOLANGE | I20: MGP | J20: Desembolsado | K20: 53100 | L20: JORGE SALAZAR | M20: No
B21: LIMA | C21: 46164 | D21: Aprobada | F21: 46170 | G21: 44864050 | H21: BENITES ARBULU MIGUEL ARMANDO | I21: EP | J21: Desembolsado | K21: 84180 | L21: EDGAR CHOTA | M21: No
B22: LIMA | C22: 46168 | D22: Enviada | G22: 73803001 | H22: SANGAMA SANTILLAN CESAR VALERIO | I22: MGP | J22: Rechazado | K22: 70400 | L22: EDGAR CHOTA | M22: No
B23: LIMA | C23: 46168 | D23: Aprobada | G23: 76416084 | H23: VILLACORTA TAPIA ANTHONY JAIR | I23: PNP | J23: Rechazado | K23: 71800 | L23: EDGAR CHOTA | M23: No

Sheet JIMMY COLLAZOS
D3: TARAPOTO | E3: Meta | F3: Desembolsado | G3: Avance | H3: Pendiente De Documentar | I3: Pendiente De Remesa | J3: Pendiente De Backoffice | K3: Evaluación BCP | L3: Obs Backoffice | M3: Obs BCP | N3: Rechazado
D4: S/. | E4: 1000000 | F4: =SUMIFS(OPI_4[MAF NETO],OPI_4[ESTADO],"Desembolsado") -> 447530 | G4: =F4-E4 -> -552470 | H4: =SUMIFS(OPI_4[MAF NETO],OPI_4[ESTADO],H$3) -> 0 | I4: =SUMIFS(OPI_4[MAF NETO],OPI_4[ESTADO],I$3) -> 0 | J4: =SUMIFS(OPI_4[MAF NETO],OPI_4[ESTADO],J$3) -> 0 | K4: =SUMIFS(OPI_4[MAF NETO],OPI_4[ESTADO],K$3) -> 0 | L4: =SUMIFS(OPI_4[MAF NETO],OPI_4[ESTADO],L$3) -> 0 | M4: =SUMIFS(OPI_4[MAF NETO],OPI_4[ESTADO],M$3) -> 0 | N4: =SUMIFS(OPI_4[MAF NETO],OPI_4[ESTADO],N$3) -> 0
D5: Q / % | E5: - | F5: =COUNTIFS(OPI_4[ESTADO],"Desembolsado") -> 6 | G5: =IFERROR(F4/E4,"") -> 0.44753 | H5: =COUNTIFS(OPI_4[ESTADO],H$3) -> 0 | I5: =COUNTIFS(OPI_4[ESTADO],I$3) -> 0 | J5: =COUNTIFS(OPI_4[ESTADO],J$3) -> 0 | K5: =COUNTIFS(OPI_4[ESTADO],K$3) -> 0 | L5: =COUNTIFS(OPI_4[ESTADO],L$3) -> 0 | M5: =COUNTIFS(OPI_4[ESTADO],M$3) -> 0 | N5: =COUNTIFS(OPI_4[ESTADO],N$3) -> 0
B9: PLAZA DE VENTA | C9: FECHA DE ENVIO DE REMESA | D9: ESTADO DE REMESA | E9: FECHA DE INGRESO | F9: FECHA DE DESEMBOLSO | G9: DOCUMENTO | H9: NOMBRES Y APELLIDOS | I9: CONVENIO | J9: ESTADO | K9: MAF NETO | L9: EJECUTIVO | M9: FILE ENVIADO A BANCO | N9: FECHA DE ENVIÓ CARTA PODER A BCP | O9: COMPRA DE DEUDA REALIZADA | P9: LIBERACIÓN | Q9: FEEDBACK
B10: TARAPOTO | C10: 46142 | D10: Aprobada | E10: 46148 | F10: 46149 | G10: 74357803 | H10: QUISPE CORONEL LUIS ANGEL | I10: PNP | J10: Desembolsado | K10: 78500 | L10: ALCIDES FERNANDEZ | O10: No
B11: TARAPOTO | C11: 46148 | D11: Aprobada | E11: 46148 | F11: 46149 | G11: 46274228 | H11: NAVARRETE SALCEDO GLEIDER | I11: PNP | J11: Desembolsado | K11: 85640 | L11: ALCIDES FERNANDEZ | O11: Si
B12: TARAPOTO | C12: 46156 | D12: Aprobada | E12: 46157 | F12: 46157 | G12: 77232610 | H12: TAFUR GUERRA CRISTIAN RICARDO | I12: PNP | J12: Desembolsado | K12: 54420 | L12: ALCIDES FERNANDEZ | O12: Si
B13: TARAPOTO | C13: 46162 | D13: Aprobada | E13: 46162 | F13: 46162 | G13: 71772724 | H13: RAMIREZ ALVA DEYVI | I13: PNP | J13: Desembolsado | K13: 84770 | L13: ALCIDES FERNANDEZ | O13: Si
B14: TARAPOTO | C14: 46167 | D14: Aprobada | E14: 46167 | F14: 46167 | G14: 70432835 | H14: CORDOVA SORIA KIELA JOYS | I14: PNP | J14: Desembolsado | K14: 66200 | L14: ALCIDES FERNANDEZ | O14: Si
B15: TARAPOTO | C15: 46168 | D15: Aprobada | E15: 46169 | F15: 46169 | G15: 77279982 | H15: GUEVARA MARTINEZ MELVER | I15: PNP | J15: Desembolsado | K15: 78000 | L15: ALCIDES FERNANDEZ | O15: Si
K16: 0

Sheet LUIS MENDOZA
D3: LIMA | E3: Meta | F3: Desembolsado | G3: Avance | H3: Pendiente De Documentar | I3: Pendiente De Remesa | J3: Pendiente De Backoffice | K3: Evaluación BCP | L3: Obs Backoffice | M3: Obs BCP | N3: Rechazado
D4: S/. | E4: 1000000 | F4: =SUMIFS(OPI_8[MAF NETO],OPI_8[ESTADO],"Desembolsado") -> 444390 | G4: =F4-E4 -> -555610 | H4: =SUMIFS(OPI_8[MAF NETO],OPI_8[ESTADO],H$3) -> 0 | I4: =SUMIFS(OPI_8[MAF NETO],OPI_8[ESTADO],I$3) -> 0 | J4: =SUMIFS(OPI_8[MAF NETO],OPI_8[ESTADO],J$3) -> 0 | K4: =SUMIFS(OPI_8[MAF NETO],OPI_8[ESTADO],K$3) -> 0 | L4: =SUMIFS(OPI_8[MAF NETO],OPI_8[ESTADO],L$3) -> 0 | M4: =SUMIFS(OPI_8[MAF NETO],OPI_8[ESTADO],M$3) -> 0 | N4: =SUMIFS(OPI_8[MAF NETO],OPI_8[ESTADO],N$3) -> 189670
D5: Q / % | E5: - | F5: =COUNTIFS(OPI_8[ESTADO],"Desembolsado") -> 6 | G5: =IFERROR(F4/E4,"") -> 0.44439 | H5: =COUNTIFS(OPI_8[ESTADO],H$3) -> 0 | I5: =COUNTIFS(OPI_8[ESTADO],I$3) -> 0 | J5: =COUNTIFS(OPI_8[ESTADO],J$3) -> 0 | K5: =COUNTIFS(OPI_8[ESTADO],K$3) -> 0 | L5: =COUNTIFS(OPI_8[ESTADO],L$3) -> 0 | M5: =COUNTIFS(OPI_8[ESTADO],M$3) -> 0 | N5: =COUNTIFS(OPI_8[ESTADO],N$3) -> 3
B9: PLAZA DE VENTA | C9: FECHA DE ENVIO DE REMESA | D9: ESTADO DE REMESA | E9: FECHA DE INGRESO | F9: FECHA DE DESEMBOLSO | G9: DOCUMENTO | H9: NOMBRES Y APELLIDOS | I9: CONVENIO | J9: ESTADO | K9: MAF NETO | L9: EJECUTIVO | M9: FILE ENVIADO A BANCO | N9: FECHA DE ENVIÓ CARTA PODER A BCP | O9: COMPRA DE DEUDA REALIZADA | P9: LIBERACIÓN | Q9: FEEDBACK
B10: LIMA | C10: 46140 | D10: Aprobada | E10: 46146 | F10: 46147 | G10: 43342601 | H10: JOSE ANTONIO APAZA HUANCACURI | I10: MARINA | J10: Desembolsado | K10: 76660 | L10: CAROL URBISAGASTEGUI | O10: Si
B11: LIMA | C11: 46147 | D11: Rechazada | G11: 46662556 | H11: SINTIA ESTEFANIA CACHAY LEZCANO | I11: EJERCITO | J11: Rechazado | K11: 74100 | L11: CAROL URBISAGASTEGUI | Q11: EN JUNIO
B12: LIMA | C12: 46150 | D12: Aprobada | E12: 46153 | F12: 46154 | G12: 45309223 | H12: MAS GUIVIN GENRY | I12: PNP | J12: Desembolsado | K12: 65000 | L12: CLAUDIA LEYVA
B13: LIMA | C13: 46155 | D13: Aprobada | E13: 46156 | F13: 46157 | G13: 40060107 | H13: CHIQUIAN FLORES GILBER JAVIER | I13: EJERCITO | J13: Desembolsado | K13: 89000 | L13: CAROL URBISAGASTEGUI | M13: Si | N13: 46162
B14: LIMA | C14: 46156 | D14: Aprobada | E14: 46160 | F14: 46160 | G14: 41013455 | H14: HIGA GUILLEN DIANA | I14: PNP | J14: Desembolsado | K14: 86390 | L14: CLAUDIA LEYVA
B15: LIMA | C15: 46160 | D15: Aprobada | E15: 46161 | F15: 46162 | G15: 72963579 | H15: CHUQUIPIONDO HIDALGO TEOFILO | I15: PNP | J15: Desembolsado | K15: 66500 | L15: CLAUDIA LEYVA
B16: LIMA | C16: 46161 | D16: Aprobada | E16: 46161 | G16: 46610741 | H16: MORENO PANTOJA ELISBEL | I16: FAP | J16: Rechazado | K16: 72980 | L16: CLAUDIA LEYVA
B17: LIMA | C17: 46162 | D17: Aprobada | E17: 46162 | F17: 46164 | G17: 72841302 | H17: RAMIREZ GONZALES DANNY | I17: PNP | J17: Desembolsado | K17: 60840 | L17: CAROL URBISAGASTEGUI
B18: LIMA | C18: 46169 | D18: Aprobada | E18: 46169 | G18: 70544838 | H18: NIMA ZETA JACSON LEANDRO | I18: PNP | J18: Rechazado | K18: 42590 | L18: CAROL URBISAGASTEGUI
H19: XXX | K19: 0

Sheet KENNY MORALES
D3: LIMA | E3: Meta | F3: Desembolsado | G3: Avance | H3: Pendiente De Documentar | I3: Pendiente De Remesa | J3: Pendiente De Backoffice | K3: Evaluación BCP | L3: Obs Backoffice | M3: Obs BCP | N3: Rechazado
D4: S/. | E4: 1000000 | F4: =SUMIFS(OPI_6[MAF NETO],OPI_6[ESTADO],"Desembolsado") -> 292600 | G4: =F4-E4 -> -707400 | H4: =SUMIFS(OPI_6[MAF NETO],OPI_6[ESTADO],H$3) -> 0 | I4: =SUMIFS(OPI_6[MAF NETO],OPI_6[ESTADO],I$3) -> 0 | J4: =SUMIFS(OPI_6[MAF NETO],OPI_6[ESTADO],J$3) -> 0 | K4: =SUMIFS(OPI_6[MAF NETO],OPI_6[ESTADO],K$3) -> 0 | L4: =SUMIFS(OPI_6[MAF NETO],OPI_6[ESTADO],L$3) -> 0 | M4: =SUMIFS(OPI_6[MAF NETO],OPI_6[ESTADO],M$3) -> 0 | N4: =SUMIFS(OPI_6[MAF NETO],OPI_6[ESTADO],N$3) -> 412590
D5: Q / % | E5: - | F5: =COUNTIFS(OPI_6[ESTADO],"Desembolsado") -> 6 | G5: =IFERROR(F4/E4,"") -> 0.2926 | H5: =COUNTIFS(OPI_6[ESTADO],H$3) -> 0 | I5: =COUNTIFS(OPI_6[ESTADO],I$3) -> 0 | J5: =COUNTIFS(OPI_6[ESTADO],J$3) -> 0 | K5: =COUNTIFS(OPI_6[ESTADO],K$3) -> 0 | L5: =COUNTIFS(OPI_6[ESTADO],L$3) -> 0 | M5: =COUNTIFS(OPI_6[ESTADO],M$3) -> 0 | N5: =COUNTIFS(OPI_6[ESTADO],N$3) -> 6
B9: PLAZA DE VENTA | C9: FECHA DE ENVIO DE REMESA | D9: ESTADO DE REMESA | E9: FECHA DE INGRESO | F9: FECHA DE DESEMBOLSO | G9: DOCUMENTO | H9: NOMBRES Y APELLIDOS | I9: CONVENIO | J9: ESTADO | K9: MAF NETO | L9: EJECUTIVO | M9: FILE ENVIADO A BANCO | N9: FECHA DE ENVIÓ CARTA PODER A BCP | O9: COMPRA DE DEUDA REALIZADA | P9: LIBERACIÓN | Q9: FEEDBACK
B10: LIMA | C10: 46147 | D10: Rechazada | E10: 0 | G10: 75952684 | H10: BADAJOS PLASENCIA JASON BRAYAN | I10: PNP | J10: Rechazado | K10: 45000 | L10: ROXANA FERNANDEZ | M10: No | Q10: VOLVER A CONTACTAR 10 MAYO, AUN NO CARGAN SU TERCERA CUOTA PAGADA DE CREDITO
B11: IQUITOS | C11: 46147 | D11: Aprobada | G11: 47259225 | H11: POLANCO SALAZAR LUIS ALFREDO | I11: EP | J11: Rechazado | K11: 88700 | L11: ROXANA FERNANDEZ
B12: LIMA | C12: 46148 | D12: Rechazada | G12: 74151082 | H12: RAMOS QUISPE CRISTHIAN JOSE | I12: EP | J12: Rechazado | K12: 75900 | L12: ROXANA FERNANDEZ | Q12: PARA JUNIO LEFALTA 1 DSCTO
B13: LIMA | C13: 46149 | G13: 75737866 | H13: BENITES ACOSTA JULIO CESAR | I13: FAP | J13: Rechazado | K13: 50000 | L13: PAOLA REYES | Q13: YA NO DESEA
B14: LIMA | C14: 46157 | D14: Aprobada | E14: 46150.0 | F14: 46164 | G14: 75672282 | H14: MARTOS AUQUI ERIK VILHEM | I14: EP | J14: Desembolsado | K14: 61900 | L14: ROXANA FERNANDEZ | M14: Si | Q14: -
B15: LIMA | C15: 46154 | D15: Aprobada | E15: 46154 | F15: 46155 | G15: 70780311 | H15: MEJIA CORONEL ELMER | I15: PNP | J15: Desembolsado | K15: 80900 | L15: SALY SAAVEDRA | M15: Si
B16: APURIMAC | C16: 46161 | D16: Aprobada | E16: 46164 | F16: 46165 | G16: 40499787 | H16: GUTIERREZ ONTON JUAN JOSE | I16: PRONABEC | J16: Desembolsado | K16: 50000 | L16: PAOLA REYES | M16: Si | Q16: TOMA DE FIRMAS AGENCIA ANDAHUYLAS
B17: LIMA | C17: 46161 | D17: Enviada | E17: 46161 | G17: 77050724 | H17: FLORES CORMAN MARYORI VERONICA | I17: FAP | J17: Rechazado | K17: 63000 | L17: PAOLA REYES | Q17: REMESA EN EVALUACION
B18: LIMA | C18: 46167 | D18: Aprobada | E18: 46167 | F18: 46169 | G18: 62471942 | H18: RIVAS GUTIERREZ CARLOS ENRIQUE | I18: PNP | J18: Desembolsado | K18: 12000 | L18: ROXANA FERNANDEZ | M18: Si
B19: LIMA | C19: 46167 | D19: Enviada | E19: 46167 | G19: 72217881 | H19: HILARIO DIAZ DARWIN ALBERTO | I19: PNP | J19: Rechazado | K19: 89990 | L19: SALY SAAVEDRA
B20: LIMA | C20: 46169 | D20: Aprobada | E20: 46169 | F20: 46171 | G20: 47109780 | H20: CALDAS CAMPOS JOSE | I20: PNP | J20: Desembolsado | K20: 48000 | L20: SILVIA CASTAÑEDA | M20: Si
B21: LIMA | C21: 46170 | D21: Aprobada | E21: 46170 | F21: 46172 | G21: 10760910 | H21: ARIAS DOMINGUEZ JUAN JAVIER | I21: AGRORURAL | J21: Desembolsado | K21: 39800 | L21: PAOLA REYES | M21: Si

Sheet MILAGROS TUESTA
D3: LIMA | E3: Meta | F3: Desembolsado | G3: Avance | H3: Pendiente De Documentar | I3: Pendiente De Remesa | J3: Pendiente De Backoffice | K3: Evaluación BCP | L3: Obs Backoffice | M3: Obs BCP | N3: Rechazado
D4: S/. | E4: 1500000 | F4: =SUMIFS(OPI_10[MAF NETO],OPI_10[ESTADO],"Desembolsado") -> 2081240 | G4: =F4-E4 -> 581240 | H4: =SUMIFS(OPI_10[MAF NETO],OPI_10[ESTADO],H$3) -> 0 | I4: =SUMIFS(OPI_10[MAF NETO],OPI_10[ESTADO],I$3) -> 0 | J4: =SUMIFS(OPI_10[MAF NETO],OPI_10[ESTADO],J$3) -> 0 | K4: =SUMIFS(OPI_10[MAF NETO],OPI_10[ESTADO],K$3) -> 0 | L4: =SUMIFS(OPI_10[MAF NETO],OPI_10[ESTADO],L$3) -> 0 | M4: =SUMIFS(OPI_10[MAF NETO],OPI_10[ESTADO],M$3) -> 0 | N4: =SUMIFS(OPI_10[MAF NETO],OPI_10[ESTADO],N$3) -> 0
D5: Q / % | E5: - | F5: =COUNTIFS(OPI_10[ESTADO],"Desembolsado") -> 28 | G5: =IFERROR(F4/E4,"") -> 1.3874933 | H5: =COUNTIFS(OPI_10[ESTADO],H$3) -> 0 | I5: =COUNTIFS(OPI_10[ESTADO],I$3) -> 0 | J5: =COUNTIFS(OPI_10[ESTADO],J$3) -> 0 | K5: =COUNTIFS(OPI_10[ESTADO],K$3) -> 0 | L5: =COUNTIFS(OPI_10[ESTADO],L$3) -> 0 | M5: =COUNTIFS(OPI_10[ESTADO],M$3) -> 1 | N5: =COUNTIFS(OPI_10[ESTADO],N$3) -> 1
B9: PLAZA DE VENTA | C9: FECHA DE ENVIO DE REMESA | D9: ESTADO DE REMESA | E9: FECHA DE INGRESO | F9: FECHA DE DESEMBOLSO | G9: DOCUMENTO | H9: NOMBRES Y APELLIDOS | I9: CONVENIO | J9: ESTADO | K9: MAF NETO | L9: EJECUTIVO | M9: FILE ENVIADO A BANCO | N9: FECHA DE ENVIÓ CARTA PODER A BCP | O9: COMPRA DE DEUDA REALIZADA | P9: LIBERACIÓN | Q9: FEEDBACK
B10: LIMA | C10: 46139 | D10: Aprobada | E10: 46140 | F10: 46146 | G10: 74087321 | H10: TAPIA DE LA CRUZ DANNY ALEXIS | I10: PNP | J10: Desembolsado | K10: 74250 | L10: PIO FERREYRA | M10: Si
B11: LIMA | C11: 46141 | D11: Aprobada | E11: 46141 | F11: 46146 | G11: 47210580 | H11: CHOCAN VELASCO,ARBEY | I11: PNP | J11: Desembolsado | K11: 78950 | L11: ELIZABETH RAMIREZ | M11: Si | N11: 46146 | Q11: AUN NO APARECE EN LISTA PARA PAGOS
B12: LIMA | C12: 46141 | D12: Aprobada | E12: 46142 | F12: 46146 | G12: 70693424 | H12: YAPU PORTUGAL EDUARDO ERICK | I12: PNP | J12: Desembolsado | K12: 69000 | L12: MILY FERNANDEZ | M12: Si
B13: LIMA | C13: 46148 | D13: Aprobada | E13: 46148 | F13: 46153 | G13: 45437194 | H13: LONGOBARDI PALOMINO ROY ERWIN | I13: PNP | J13: Desembolsado | K13: 78600 | L13: JOSE CONTRERAS | M13: Si
B14: PROVINCIA | C14: 46153 | D14: Aprobada | E14: 46153 | F14: 46154 | G14: 46418564 | H14: CASTRO QUINTANILLA,ARTURO EDUARDO | I14: PNP | J14: Desembolsado | K14: 98000 | L14: MILY FERNANDEZ | M14: Si
B15: LIMA | C15: 46154 | D15: Aprobada | E15: 46157 | F15: 46157 | G15: 75410222 | H15: IDROGO RUIZ ROLI | I15: MGP | J15: Desembolsado | K15: 70000 | L15: PIO FERREYRA | M15: Si
B16: LIMA | C16: 46149 | D16: Aprobada | E16: 46149 | F16: 46155 | G16: 44818447 | H16: VITON CUSMA,ELFERES | I16: PNP | J16: Desembolsado | K16: 80100 | L16: LEYDY EGOAVIL | M16: Si
B17: LIMA | C17: 46149 | D17: Aprobada | E17: 46167 | G17: 70004734 | H17: JAPURA FLORES,YIANMARCO | I17: PNP | J17: Desembolsado | K17: 65000 | L17: MILY FERNANDEZ | M17: No
B18: PROVINCIA | C18: 46150 | D18: Aprobada | E18: 46155 | F18: 46156 | G18: 70355664 | H18: ALVA RAMOS,FERNANDO ALONSO | I18: PNP | J18: Desembolsado | K18: 79500 | L18: JOSE CONTRERAS | M18: Si
B19: PROVINCIA | C19: 46150 | D19: Aprobada | E19: 46153 | F19: 46153 | G19: 43679818 | H19: PORRAS MESCUA HOMERO | I19: EP | J19: Desembolsado | K19: 106800 | L19: ELIZABETH ESQUIVEL | M19: Si
B20: LIMA | C20: 46160 | D20: Aprobada | E20: 46253 | F20: 46253 | G20: 73584774 | H20: HUAMAN APAZA,RICARDO | I20: PNP | J20: Desembolsado | K20: 72830 | L20: MILY FERNANDEZ | M20: Si
B21: LIMA | C21: 46155 | D21: Aprobada | F21: 46157 | G21: 70950330 | H21: CANTORIN HUANCA JOSE | I21: MGP | J21: Desembolsado | K21: 50000 | L21: PIO FERREYRA | M21: Si
B22: LIMA | C22: 46155 | D22: Aprobada | E22: 46157 | F22: 0 | G22: 44908360 | H22: ZAPATA SILVA EDER | I22: EP | J22: Desembolsado | K22: 69000 | L22: ELIZABETH ESQUIVEL | M22: No
C23: 46156 | D23: Aprobada | E23: 46160 | F23: 46161 | G23: 73382037 | H23: RAMIREZ JULCARIMA, JERSON JAMES | I23: FAP | J23: Desembolsado | K23: 60000 | L23: MILY FERNANDEZ | M23: Si
C24: 46167 | D24: Aprobada | G24: 73766227 | H24: BUSTAMANTE HUAMAN,ESTIVEN ALEJANDRO | I24: PNP | J24: Desembolsado | K24: 79960 | L24: MILY FERNANDEZ | M24: No
C25: 46163 | D25: Aprobada | E25: 46168 | G25: 43511372 | H25: KASENG GAMARRA,JOHEL RUDY | I25: PNP | J25: Desembolsado | K25: 86500 | L25: LEYDI EGOAVIL | M25: No
C26: 46164 | D26: Aprobada | E26: 46168 | G26: 76836821 | H26: GUERRA DIAZ,DEIVY MOISES | I26: PNP | J26: Desembolsado | K26: 70300 | L26: MILI FERNANDEZ
C27: 46167 | D27: Aprobada | E27: 46168 | G27: 48438639 | H27: MAMANI PAURO,JUAN MANUEL | I27: pnp | J27: Desembolsado | K27: 73500 | L27: PIO FERREYRA
D28: Aprobada | F28: 46170 | G28: 41647421 | H28: ESPINOZA PEZO JACKELINE FRANCESCA | I28: PNP | J28: Desembolsado | K28: 79300 | L28: PIO FERREYRA
D29: Aprobada | G29: 75317361 | H29: GORDILLO YNGA OSMER | I29: PNP | J29: Desembolsado | K29: 60000 | L29: PIO FERREYRA
C30: 46167 | D30: Aprobada | G30: 71543890 | H30: SANTAMARIA SANTAMARIA,MIGUEL ANGEL | I30: PNP | J30: Desembolsado | K30: 78000 | L30: JOSE CONTRERAS
C31: 46168 | D31: Aprobada | G31: 70071920 | H31: HUAMANI TORRES,PIERO ROGGER | I31: PNP | J31: Desembolsado | K31: 59100 | L31: CARMEN QUISPE
C32: 46168 | D32: Rechazada | G32: 70981379 | H32: ACOSTA ROSADO MARCELO PAOLO | I32: FAP | J32: Rechazado | K32: 0 | L32: CARMEN QUISPE
D33: Aprobada | G33: 72504753 | H33: PAREDES CARRILLO,ARELIS ELIZBETH | I33: PNP | J33: Obs BCP | L33: MILY FERNANDEZ
D34: Aprobada | G34: 72489925 | H34: QUIROZ YACE,YEREMI ROSA | I34: PNP | J34: Desembolsado | K34: 73500 | L34: ELIZABETH ESQUIVEL
D35: Aprobada | G35: 47101769 | H35: ALVARO HUAMAN,JOSE LUIS | I35: PNP | J35: Desembolsado | K35: 43000 | L35: CARMEN QUISPE
C36: 46168 | D36: Aprobada | G36: 70433820 | H36: CARREON CAHUANA HAROLD FERNANDO0 | I36: EP | J36: Desembolsado | K36: 100200 | L36: ELIZABETH ESQUIVEL
D37: Aprobada | G37: 75261316 | H37: GONZALEZ BERNAL ALEX YENEIBER | I37: PNP | J37: Desembolsado | K37: 75000 | L37: PIO FERREYRA
C38: 46170 | D38: Aprobada | G38: 72461488 | H38: IGLESIAS HINOSTROZA,LUIS ENRIQUE | I38: PNP | J38: Desembolsado | K38: 72750 | L38: MILY FERNANDEZ
C39: 46170 | D39: Aprobada | G39: 70931728 | H39: ACOSTA SALAZAR AKEMY CRISTINA | I39: PNP | J39: Desembolsado | K39: 78100 | L39: PIO FERREYRA

Sheet MARIELLA PAÑAHUA
D3: AYACUCHO | E3: Meta | F3: Desembolsado | G3: Avance | H3: Pendiente De Documentar | I3: Pendiente De Remesa | J3: Pendiente De Backoffice | K3: Evaluación BCP | L3: Obs Backoffice | M3: Obs BCP | N3: Rechazado
D4: S/. | E4: 1000000 | F4: =SUMIFS(OPI_9[MAF NETO],OPI_9[ESTADO],"Desembolsado") -> 287000 | G4: =F4-E4 -> -713000 | H4: =SUMIFS(OPI_9[MAF NETO],OPI_9[ESTADO],H$3) -> 0 | I4: =SUMIFS(OPI_9[MAF NETO],OPI_9[ESTADO],I$3) -> 0 | J4: =SUMIFS(OPI_9[MAF NETO],OPI_9[ESTADO],J$3) -> 0 | K4: =SUMIFS(OPI_9[MAF NETO],OPI_9[ESTADO],K$3) -> 0 | L4: =SUMIFS(OPI_9[MAF NETO],OPI_9[ESTADO],L$3) -> 0 | M4: =SUMIFS(OPI_9[MAF NETO],OPI_9[ESTADO],M$3) -> 0 | N4: =SUMIFS(OPI_9[MAF NETO],OPI_9[ESTADO],N$3) -> 0
D5: Q / % | E5: - | F5: =COUNTIFS(OPI_9[ESTADO],"Desembolsado") -> 5 | G5: =IFERROR(F4/E4,"") -> 0.287 | H5: =COUNTIFS(OPI_9[ESTADO],H$3) -> 0 | I5: =COUNTIFS(OPI_9[ESTADO],I$3) -> 0 | J5: =COUNTIFS(OPI_9[ESTADO],J$3) -> 0 | K5: =COUNTIFS(OPI_9[ESTADO],K$3) -> 0 | L5: =COUNTIFS(OPI_9[ESTADO],L$3) -> 0 | M5: =COUNTIFS(OPI_9[ESTADO],M$3) -> 0 | N5: =COUNTIFS(OPI_9[ESTADO],N$3) -> 0
B9: PLAZA DE VENTA | C9: FECHA DE ENVIO DE REMESA | D9: ESTADO DE REMESA | E9: FECHA DE INGRESO | F9: FECHA DE DESEMBOLSO | G9: DOCUMENTO | H9: NOMBRES Y APELLIDOS | I9: CONVENIO | J9: ESTADO | K9: MAF NETO | L9: EJECUTIVO | M9: FILE ENVIADO A BANCO | N9: FECHA DE ENVIÓ CARTA PODER A BCP | O9: COMPRA DE DEUDA REALIZADA | P9: LIBERACIÓN | Q9: FEEDBACK
B10: AYACUCHO | C10: 46145 | D10: Aprobada | E10: 46146 | G10: 48564560 | H10: PRADO VELITO, ANTONIO MISAEL | I10: PNP | J10: Desembolsado | K10: 29100 | L10: DELIA VENTURA | M10: Si | O10: BANCO COMERCIO, TC NACION
B11: AYACUCHO | C11: 46153 | D11: Aprobada | E11: 46157 | G11: 70875333 | H11: CALDERON ESPINOZA JUAN ALEXIS | I11: PNP | J11: Desembolsado | K11: 82800 | L11: DELIA VENTURA | M11: Si
B12: AYACUCHO | C12: 46161 | D12: Aprobada | E12: 46161 | G12: 46931432 | H12: PRADO CERDA, MARIEBEL | I12: ESSALUD | J12: Desembolsado | K12: 20000 | L12: DELIA VENTURA
B13: AYACUCHO | C13: 46164 | D13: Aprobada | E13: 46164 | G13: 70050053 | H13: CHUCHON REYMUNDEZ EDITH DORIS | I13: PNP | J13: Desembolsado | K13: 76600 | L13: DELIA VENTURA
B14: AYACUCHO | C14: 46167 | D14: Aprobada | G14: 70396504 | H14: BUSTAMANTE BARRIOS MAYRA BETSABE | I14: PNP | J14: Desembolsado | K14: 78500 | L14: DELIA VENTURA
K15: 0

Sheet WENDY IPANEQUE
D3: PIURA | E3: Meta | F3: Desembolsado | G3: Avance | H3: Pendiente De Documentar | I3: Pendiente De Remesa | J3: Pendiente De Backoffice | K3: Evaluación BCP | L3: Obs Backoffice | M3: Obs BCP | N3: Rechazado
D4: S/. | E4: 1000000 | F4: =SUMIFS(OPI_14[MAF NETO],OPI_14[ESTADO],"Desembolsado") -> 0 | G4: =F4-E4 -> -1000000 | H4: =SUMIFS(OPI_14[MAF NETO],OPI_14[ESTADO],H$3) -> 0 | I4: =SUMIFS(OPI_14[MAF NETO],OPI_14[ESTADO],I$3) -> 0 | J4: =SUMIFS(OPI_14[MAF NETO],OPI_14[ESTADO],J$3) -> 0 | K4: =SUMIFS(OPI_14[MAF NETO],OPI_14[ESTADO],K$3) -> 0 | L4: =SUMIFS(OPI_14[MAF NETO],OPI_14[ESTADO],L$3) -> 0 | M4: =SUMIFS(OPI_14[MAF NETO],OPI_14[ESTADO],M$3) -> 0 | N4: =SUMIFS(OPI_14[MAF NETO],OPI_14[ESTADO],N$3) -> 0
D5: Q / % | E5: - | F5: =COUNTIFS(OPI_14[ESTADO],"Desembolsado") -> 0 | G5: =IFERROR(F4/E4,"") -> 0 | H5: =COUNTIFS(OPI_14[ESTADO],H$3) -> 0 | I5: =COUNTIFS(OPI_14[ESTADO],I$3) -> 0 | J5: =COUNTIFS(OPI_14[ESTADO],J$3) -> 0 | K5: =COUNTIFS(OPI_14[ESTADO],K$3) -> 0 | L5: =COUNTIFS(OPI_14[ESTADO],L$3) -> 0 | M5: =COUNTIFS(OPI_14[ESTADO],M$3) -> 0 | N5: =COUNTIFS(OPI_14[ESTADO],N$3) -> 0
B9: PLAZA DE VENTA | C9: FECHA DE ENVIO DE REMESA | D9: ESTADO DE REMESA | E9: FECHA DE INGRESO | F9: FECHA DE DESEMBOLSO | G9: DOCUMENTO | H9: NOMBRES Y APELLIDOS | I9: CONVENIO | J9: ESTADO | K9: MAF NETO | L9: EJECUTIVO | M9: FILE ENVIADO A BANCO | N9: FECHA DE ENVIÓ CARTA PODER A BCP | O9: COMPRA DE DEUDA REALIZADA | P9: LIBERACIÓN | Q9: FEEDBACK

Sheet ALEXANDRA GUZMAN
D3: PIURA | E3: Meta | F3: Desembolsado | G3: Avance | H3: Pendiente De Documentar | I3: Pendiente De Remesa | J3: Pendiente De Backoffice | K3: Evaluación BCP | L3: Obs Backoffice | M3: Obs BCP | N3: Rechazado
D4: S/. | E4: 1000000 | F4: =SUMIFS(OPI_15[MAF NETO],OPI_15[ESTADO],"Desembolsado") -> 0 | G4: =F4-E4 -> -1000000 | H4: =SUMIFS(OPI_15[MAF NETO],OPI_15[ESTADO],H$3) -> 0 | I4: =SUMIFS(OPI_15[MAF NETO],OPI_15[ESTADO],I$3) -> 0 | J4: =SUMIFS(OPI_15[MAF NETO],OPI_15[ESTADO],J$3) -> 0 | K4: =SUMIFS(OPI_15[MAF NETO],OPI_15[ESTADO],K$3) -> 0 | L4: =SUMIFS(OPI_15[MAF NETO],OPI_15[ESTADO],L$3) -> 0 | M4: =SUMIFS(OPI_15[MAF NETO],OPI_15[ESTADO],M$3) -> 0 | N4: =SUMIFS(OPI_15[MAF NETO],OPI_15[ESTADO],N$3) -> 0
D5: Q / % | E5: - | F5: =COUNTIFS(OPI_15[ESTADO],"Desembolsado") -> 0 | G5: =IFERROR(F4/E4,"") -> 0 | H5: =COUNTIFS(OPI_15[ESTADO],H$3) -> 0 | I5: =COUNTIFS(OPI_15[ESTADO],I$3) -> 0 | J5: =COUNTIFS(OPI_15[ESTADO],J$3) -> 0 | K5: =COUNTIFS(OPI_15[ESTADO],K$3) -> 0 | L5: =COUNTIFS(OPI_15[ESTADO],L$3) -> 0 | M5: =COUNTIFS(OPI_15[ESTADO],M$3) -> 0 | N5: =COUNTIFS(OPI_15[ESTADO],N$3) -> 0
B9: PLAZA DE VENTA | C9: FECHA DE ENVIO DE REMESA | D9: ESTADO DE REMESA | E9: FECHA DE INGRESO | F9: FECHA DE DESEMBOLSO | G9: DOCUMENTO | H9: NOMBRES Y APELLIDOS | I9: CONVENIO | J9: ESTADO | K9: MAF NETO | L9: EJECUTIVO | M9: FILE ENVIADO A BANCO | N9: FECHA DE ENVIÓ CARTA PODER A BCP | O9: COMPRA DE DEUDA REALIZADA | P9: LIBERACIÓN | Q9: FEEDBACK

Sheet AMALIA QUINDE
D3: PIURA | E3: Meta | F3: Desembolsado | G3: Avance | H3: Pendiente De Documentar | I3: Pendiente De Remesa | J3: Pendiente De Backoffice | K3: Evaluación BCP | L3: Obs Backoffice | M3: Obs BCP | N3: Rechazado
D4: S/. | E4: 1000000 | F4: =SUMIFS(OPI_16[MAF NETO],OPI_16[ESTADO],"Desembolsado") -> 62000 | G4: =F4-E4 -> -938000 | H4: =SUMIFS(OPI_16[MAF NETO],OPI_16[ESTADO],H$3) -> 0 | I4: =SUMIFS(OPI_16[MAF NETO],OPI_16[ESTADO],I$3) -> 0 | J4: =SUMIFS(OPI_16[MAF NETO],OPI_16[ESTADO],J$3) -> 0 | K4: =SUMIFS(OPI_16[MAF NETO],OPI_16[ESTADO],K$3) -> 0 | L4: =SUMIFS(OPI_16[MAF NETO],OPI_16[ESTADO],L$3) -> 0 | M4: =SUMIFS(OPI_16[MAF NETO],OPI_16[ESTADO],M$3) -> 0 | N4: =SUMIFS(OPI_16[MAF NETO],OPI_16[ESTADO],N$3) -> 0
D5: Q / % | E5: - | F5: =COUNTIFS(OPI_16[ESTADO],"Desembolsado") -> 1 | G5: =IFERROR(F4/E4,"") -> 0.062 | H5: =COUNTIFS(OPI_16[ESTADO],H$3) -> 0 | I5: =COUNTIFS(OPI_16[ESTADO],I$3) -> 0 | J5: =COUNTIFS(OPI_16[ESTADO],J$3) -> 0 | K5: =COUNTIFS(OPI_16[ESTADO],K$3) -> 0 | L5: =COUNTIFS(OPI_16[ESTADO],L$3) -> 0 | M5: =COUNTIFS(OPI_16[ESTADO],M$3) -> 0 | N5: =COUNTIFS(OPI_16[ESTADO],N$3) -> 0
B9: PLAZA DE VENTA | C9: FECHA DE ENVIO DE REMESA | D9: ESTADO DE REMESA | E9: FECHA DE INGRESO | F9: FECHA DE DESEMBOLSO | G9: DOCUMENTO | H9: NOMBRES Y APELLIDOS | I9: CONVENIO | J9: ESTADO | K9: MAF NETO | L9: EJECUTIVO | M9: FILE ENVIADO A BANCO | N9: FECHA DE ENVIÓ CARTA PODER A BCP | O9: COMPRA DE DEUDA REALIZADA | P9: LIBERACIÓN | Q9: FEEDBACK
B10: PIURA | D10: Aprobada | E10: 46168 | F10: 46169 | G10: 76967576 | H10: ROJAS COLLANTES NOE ELIAS | I10: PNP | J10: Desembolsado | K10: 62000 | L10: MIXSI SANJINEZ

Sheet JORGE CASTILLO
D3: PIURA | E3: Meta | F3: Desembolsado | G3: Avance | H3: Pendiente De Documentar | I3: Pendiente De Remesa | J3: Pendiente De Backoffice | K3: Evaluación BCP | L3: Obs Backoffice | M3: Obs BCP | N3: Rechazado
D4: S/. | E4: 1000000 | F4: =SUMIFS(OPI_17[MAF NETO],OPI_17[ESTADO],"Desembolsado") -> 0 | G4: =F4-E4 -> -1000000 | H4: =SUMIFS(OPI_17[MAF NETO],OPI_17[ESTADO],H$3) -> 0 | I4: =SUMIFS(OPI_17[MAF NETO],OPI_17[ESTADO],I$3) -> 0 | J4: =SUMIFS(OPI_17[MAF NETO],OPI_17[ESTADO],J$3) -> 0 | K4: =SUMIFS(OPI_17[MAF NETO],OPI_17[ESTADO],K$3) -> 0 | L4: =SUMIFS(OPI_17[MAF NETO],OPI_17[ESTADO],L$3) -> 0 | M4: =SUMIFS(OPI_17[MAF NETO],OPI_17[ESTADO],M$3) -> 0 | N4: =SUMIFS(OPI_17[MAF NETO],OPI_17[ESTADO],N$3) -> 0
D5: Q / % | E5: - | F5: =COUNTIFS(OPI_17[ESTADO],"Desembolsado") -> 0 | G5: =IFERROR(F4/E4,"") -> 0 | H5: =COUNTIFS(OPI_17[ESTADO],H$3) -> 0 | I5: =COUNTIFS(OPI_17[ESTADO],I$3) -> 0 | J5: =COUNTIFS(OPI_17[ESTADO],J$3) -> 0 | K5: =COUNTIFS(OPI_17[ESTADO],K$3) -> 0 | L5: =COUNTIFS(OPI_17[ESTADO],L$3) -> 0 | M5: =COUNTIFS(OPI_17[ESTADO],M$3) -> 0 | N5: =COUNTIFS(OPI_17[ESTADO],N$3) -> 0
B9: PLAZA DE VENTA | C9: FECHA DE ENVIO DE REMESA | D9: ESTADO DE REMESA | E9: FECHA DE INGRESO | F9: FECHA DE DESEMBOLSO | G9: DOCUMENTO | H9: NOMBRES Y APELLIDOS | I9: CONVENIO | J9: ESTADO | K9: MAF NETO | L9: EJECUTIVO | M9: FILE ENVIADO A BANCO | N9: FECHA DE ENVIÓ CARTA PODER A BCP | O9: COMPRA DE DEUDA REALIZADA | P9: LIBERACIÓN | Q9: FEEDBACK

Sheet VIOLETA LLERENA
D3: AREQUIPA | E3: Meta | F3: Desembolsado | G3: Avance | H3: Pendiente De Documentar | I3: Pendiente De Remesa | J3: Pendiente De Backoffice | K3: Evaluación BCP | L3: Obs Backoffice | M3: Obs BCP | N3: Rechazado
D4: S/. | E4: 1000000 | F4: =SUMIFS(OPI_13[MAF NETO],OPI_13[ESTADO],"Desembolsado") -> 279880 | G4: =F4-E4 -> -720120 | H4: =SUMIFS(OPI_13[MAF NETO],OPI_13[ESTADO],H$3) -> 0 | I4: =SUMIFS(OPI_13[MAF NETO],OPI_13[ESTADO],I$3) -> 0 | J4: =SUMIFS(OPI_13[MAF NETO],OPI_13[ESTADO],J$3) -> 0 | K4: =SUMIFS(OPI_13[MAF NETO],OPI_13[ESTADO],K$3) -> 0 | L4: =SUMIFS(OPI_13[MAF NETO],OPI_13[ESTADO],L$3) -> 0 | M4: =SUMIFS(OPI_13[MAF NETO],OPI_13[ESTADO],M$3) -> 0 | N4: =SUMIFS(OPI_13[MAF NETO],OPI_13[ESTADO],N$3) -> 175920
D5: Q / % | E5: - | F5: =COUNTIFS(OPI_13[ESTADO],"Desembolsado") -> 4 | G5: =IFERROR(F4/E4,"") -> 0.27988 | H5: =COUNTIFS(OPI_13[ESTADO],H$3) -> 0 | I5: =COUNTIFS(OPI_13[ESTADO],I$3) -> 0 | J5: =COUNTIFS(OPI_13[ESTADO],J$3) -> 0 | K5: =COUNTIFS(OPI_13[ESTADO],K$3) -> 0 | L5: =COUNTIFS(OPI_13[ESTADO],L$3) -> 0 | M5: =COUNTIFS(OPI_13[ESTADO],M$3) -> 0 | N5: =COUNTIFS(OPI_13[ESTADO],N$3) -> 2
B9: PLAZA DE VENTA | C9: FECHA DE ENVIO DE REMESA | D9: ESTADO DE REMESA | E9: FECHA DE INGRESO | F9: FECHA DE DESEMBOLSO | G9: DOCUMENTO | H9: NOMBRES Y APELLIDOS | I9: CONVENIO | J9: ESTADO | K9: MAF NETO | L9: EJECUTIVO | M9: FILE ENVIADO A BANCO | N9: FECHA DE ENVIÓ CARTA PODER A BCP | O9: COMPRA DE DEUDA REALIZADA | P9: LIBERACIÓN | Q9: FEEDBACK
B10: AREQUIPA | C10: 46158 | D10: Rechazada | G10: 45078558 | H10: MANDUJANO ROMERO JESUS ERICK | I10: EJERCITO | J10: Rechazado | K10: 130900 | L10: RUTH CJURO | M10: No | O10: SCOTIABANK | Q10: PARA JUNIO FALTA 1 DSCTO
B11: AREQUIPA | C11: 46158 | D11: Aprobada | G11: 46924176 | H11: MEDINA MAMANI YESSICA KARINA | I11: PNP | J11: Desembolsado | K11: 83800 | L11: RUTH CJURO | M11: No | O11: BANCO GNB
B12: AREQUIPA | C12: 46163 | D12: Aprobada | G12: 42734844 | H12: MONTOYA FLORES ANTONIO ELVIS | I12: FAP | J12: Desembolsado | K12: 81350 | L12: RUTH CJURO | M12: No | O12: BANCO DE COMERCIO
B13: AREQUIPA | C13: 46163 | D13: Aprobada | G13: 29669391 | H13: GARATE COAGUILA CARLOS EDUARDO | I13: EJERCITO | J13: Rechazado | K13: 45020 | L13: ALESANDRA SANCHEZ | M13: No | O13: BANCO DE COMERCIO | Q13: EDAD/PLAZO
B14: AREQUIPA | C14: 46169 | D14: Aprobada | G14: 47137304 | H14: BELLIDO OCHOCHOQUE YOEL | I14: FAP | J14: Desembolsado | K14: 69500 | L14: RUTH CJURO | M14: No | O14: BANCO BBVA
B15: AREQUIPA | C15: 46170 | D15: Aprobada | G15: 43571006 | H15: RAMIREZ TORRES JOHNNY RONALD | I15: PNP | J15: Desembolsado | K15: 45230 | L15: ALESANDRA SANCHEZ | M15: No | O15: BANCO DE LA NACION

Sheet CRISTINA BRACAMONTE
D3: CHICLAYO | E3: Meta | F3: Desembolsado | G3: Avance | H3: Pendiente De Documentar | I3: Pendiente De Remesa | J3: Pendiente De Backoffice | K3: Evaluación BCP | L3: Obs Backoffice | M3: Obs BCP | N3: Rechazado
