Workbook

Sheet CONSOLIDADO
A1: ,
B2: Tablas de Gestión:
B4: SUPERVISOR | C4: ZONA | D4: TOTAL DESEMBOLSO | E4: Q DESEMBOLSO | F4: EVALUACION BCP | G4: PENDIENTE DE BACK | H4: PENDIENTE DE REMESA | I4: PENDIENTE DE DOCUMENTAR | J4: META OBJETIVO | K4: AVANCE | L4: Q EVALUACION BCP | M4: Q PENDIENTE DE BACK
B5: JIMMY COLLAZOS | C5: ='JIMMY COLLAZOS'!D3 -> TARAPOTO | D5: ='JIMMY COLLAZOS'!$F$4 -> 42000 | E5: ='JIMMY COLLAZOS'!$F$5 -> 1 | F5: ='JIMMY COLLAZOS'!$K$4 -> 50100 | G5: ='JIMMY COLLAZOS'!$J$4 -> 259500 | H5: ='JIMMY COLLAZOS'!$I$4 -> 0 | I5: ='JIMMY COLLAZOS'!$H$4 -> 0 | J5: ='JIMMY COLLAZOS'!E4 -> 800000 | K5: =D5/J5 -> 0.0525 | L5: ='JIMMY COLLAZOS'!$K$5 -> 1 | M5: ='JIMMY COLLAZOS'!$J$5 -> 4
B6: ALEXANDRA GUZMAN | C6: ='ALEXANDRA GUZMAN'!D3 -> PIURA | D6: ='ALEXANDRA GUZMAN'!$F$4 -> 0 | E6: ='ALEXANDRA GUZMAN'!$F$5 -> 0 | F6: ='ALEXANDRA GUZMAN'!$K$4 -> 0 | G6: ='ALEXANDRA GUZMAN'!$J$4 -> 0 | H6: ='ALEXANDRA GUZMAN'!$I$4 -> 0 | I6: ='ALEXANDRA GUZMAN'!$H$4 -> 0 | J6: 1000000 | K6: =D6/J6 -> 0 | L6: ='ALEXANDRA GUZMAN'!$K$5 -> 0 | M6: ='ALEXANDRA GUZMAN'!$J$5 -> 0
B7: RENZO CACEDA | C7: ='RENZO CACEDA'!D3 -> TRUJILLO | D7: ='RENZO CACEDA'!$F$4 -> 86200 | E7: ='RENZO CACEDA'!$F$5 -> 1 | F7: ='RENZO CACEDA'!$K$4 -> 0 | G7: ='RENZO CACEDA'!$J$4 -> 0 | H7: ='RENZO CACEDA'!$I$4 -> 0 | I7: ='RENZO CACEDA'!$H$4 -> 0 | J7: 1000000 | K7: =D7/J7 -> 0.0862 | L7: ='RENZO CACEDA'!$K$5 -> 0 | M7: ='RENZO CACEDA'!$J$5 -> 0
B8: WENDY IPANAQUÉ | C8: ='WENDY IPANEQUE'!D3 -> PIURA | D8: ='WENDY IPANEQUE'!$F$4 -> 83800 | E8: ='WENDY IPANEQUE'!$F$5 -> 1 | F8: ='WENDY IPANEQUE'!$K$4 -> 773320 | G8: ='WENDY IPANEQUE'!$J$4 -> 252050 | H8: ='WENDY IPANEQUE'!$I$4 -> 82000 | I8: ='WENDY IPANEQUE'!$H$4 -> 48850 | J8: 1000000 | K8: =D8/J8 -> 0.0838 | L8: ='WENDY IPANEQUE'!$K$5 -> 10 | M8: ='WENDY IPANEQUE'!$J$5 -> 3
B9: ANGIE SILVERA | C9: ='ANGIE SILVERA'!D3 -> LIMA 1 | D9: ='ANGIE SILVERA'!$F$4 -> 158300 | E9: ='ANGIE SILVERA'!$F$5 -> 2 | F9: ='ANGIE SILVERA'!$K$4 -> 189400 | G9: ='ANGIE SILVERA'!$J$4 -> 0 | H9: ='ANGIE SILVERA'!$I$4 -> 250700 | I9: ='ANGIE SILVERA'!$H$4 -> 0 | J9: ='ANGIE SILVERA'!E4 -> 2000000 | K9: =D9/J9 -> 0.07915 | L9: ='ANGIE SILVERA'!$K$5 -> 3 | M9: ='ANGIE SILVERA'!$J$5 -> 0
B10: KENNY MORALES | C10: ='KENNY MORALES'!D3 -> LIMA 1 | D10: ='KENNY MORALES'!$F$4 -> 83000 | E10: ='KENNY MORALES'!$F$5 -> 3 | F10: ='KENNY MORALES'!$K$4 -> 204400 | G10: ='KENNY MORALES'!$J$4 -> 24600 | H10: ='KENNY MORALES'!$I$4 -> 0 | I10: ='KENNY MORALES'!$H$4 -> 0 | J10: ='KENNY MORALES'!E4 -> 1000000 | K10: =D10/J10 -> 0.083 | L10: ='KENNY MORALES'!$K$5 -> 3 | M10: ='KENNY MORALES'!$J$5 -> 1
B11: LUIS CHUSE | C11: ='LUIS CHUSE'!D3 -> LIMA 2 | D11: ='LUIS CHUSE'!$F$4 -> 0 | E11: ='LUIS CHUSE'!$F$5 -> 0 | F11: ='LUIS CHUSE'!$K$4 -> 0 | G11: ='LUIS CHUSE'!$J$4 -> 0 | H11: ='LUIS CHUSE'!$I$4 -> 0 | I11: ='LUIS CHUSE'!$H$4 -> 0 | J11: ='LUIS CHUSE'!E4 -> 2000000 | K11: =D11/J11 -> 0 | L11: ='LUIS CHUSE'!$K$5 -> 0 | M11: ='LUIS CHUSE'!$J$5 -> 0
B12: MARIELLA PAÑAHUA | C12: ='MARIELLA PAÑAHUA'!D3 -> AYACUCHO | D12: ='MARIELLA PAÑAHUA'!$F$4 -> 0 | E12: ='MARIELLA PAÑAHUA'!$F$5 -> 0 | F12: ='MARIELLA PAÑAHUA'!$K$4 -> 0 | G12: ='MARIELLA PAÑAHUA'!$J$4 -> 0 | H12: ='MARIELLA PAÑAHUA'!$I$4 -> 0 | I12: ='MARIELLA PAÑAHUA'!$H$4 -> 0 | J12: ='MARIELLA PAÑAHUA'!E4 -> 800000 | K12: =D12/J12 -> 0 | L12: ='MARIELLA PAÑAHUA'!$K$5 -> 0 | M12: ='MARIELLA PAÑAHUA'!$J$5 -> 0
B13: WINNIE ESCALANTE | C13: ='WINNIE ESCALANTE'!D3 -> LIMA 1 | D13: ='WINNIE ESCALANTE'!$F$4 -> 299450 | E13: ='WINNIE ESCALANTE'!$F$5 -> 5 | F13: ='WINNIE ESCALANTE'!$K$4 -> 177250 | G13: ='WINNIE ESCALANTE'!$J$4 -> 224300 | H13: ='WINNIE ESCALANTE'!$I$4 -> 333700 | I13: ='WINNIE ESCALANTE'!$H$4 -> 108500 | J13: ='WINNIE ESCALANTE'!E4 -> 2000000 | K13: =D13/J13 -> 0.149725 | L13: ='WINNIE ESCALANTE'!$K$5 -> 3 | M13: ='WINNIE ESCALANTE'!$J$5 -> 3
B14: JOSE LUIS QUINTEROS | C14: ='JOSE LUIS QUINTEROS'!D3 -> LIMA 1 | D14: ='JOSE LUIS QUINTEROS'!$F$4 -> 0 | E14: ='JOSE LUIS QUINTEROS'!$F$5 -> 0 | F14: ='JOSE LUIS QUINTEROS'!$K$4 -> 40500 | G14: ='JOSE LUIS QUINTEROS'!$J$4 -> 0 | H14: ='JOSE LUIS QUINTEROS'!$I$4 -> 235050 | I14: ='JOSE LUIS QUINTEROS'!$H$4 -> 89600 | J14: ='JOSE LUIS QUINTEROS'!E4 -> 1000000 | K14: =D14/J14 -> 0 | L14: ='JOSE LUIS QUINTEROS'!$K$5 -> 1 | M14: ='JOSE LUIS QUINTEROS'!$J$5 -> 0
B15: NATHALIE ARANDA | C15: ='NATHALIE ARANDA'!D3 -> LIMA 2 | D15: ='NATHALIE ARANDA'!$F$4 -> 224850 | E15: ='NATHALIE ARANDA'!$F$5 -> 3 | F15: ='NATHALIE ARANDA'!$K$4 -> 111250 | G15: ='NATHALIE ARANDA'!$J$4 -> 135750 | H15: ='NATHALIE ARANDA'!$I$4 -> 336100 | I15: ='NATHALIE ARANDA'!$H$4 -> 99400 | J15: ='NATHALIE ARANDA'!E4 -> 500000 | K15: =D15/J15 -> 0.4497 | L15: ='NATHALIE ARANDA'!$K$5 -> 2 | M15: ='NATHALIE ARANDA'!$J$5 -> 3
B16: ARACELY VENTURA | C16: ='ARACELY VENTURA'!D3 -> CHICLAYO | D16: ='ARACELY VENTURA'!$F$4 -> 167300 | E16: ='ARACELY VENTURA'!$F$5 -> 2 | F16: ='ARACELY VENTURA'!$K$4 -> 0 | G16: ='ARACELY VENTURA'!$J$4 -> 78300 | H16: ='ARACELY VENTURA'!$I$4 -> 0 | I16: ='ARACELY VENTURA'!$H$4 -> 0 | J16: 1000000 | K16: =D16/J16 -> 0.1673 | L16: ='ARACELY VENTURA'!$K$5 -> 0 | M16: ='ARACELY VENTURA'!$J$5 -> 1
B17: JHON ZAMORA | C17: ='JHON ZAMORA'!D3 -> CHICLAYO | D17: ='JHON ZAMORA'!$F$4 -> 83130 | E17: ='JHON ZAMORA'!$F$5 -> 1 | F17: ='JHON ZAMORA'!$K$4 -> 0 | G17: ='JHON ZAMORA'!$J$4 -> 0 | H17: ='JHON ZAMORA'!$I$4 -> 240400 | I17: ='JHON ZAMORA'!$H$4 -> 0 | J17: 1000000 | K17: =D17/J17 -> 0.08313 | L17: ='JHON ZAMORA'!$K$5 -> 0 | M17: ='JHON ZAMORA'!$J$5 -> 0
B18: OMAR MINAYA | C18: ='OMAR MINAYA'!D3 -> CHICLAYO | D18: ='OMAR MINAYA'!$F$4 -> 74700 | E18: ='OMAR MINAYA'!$F$5 -> 2 | F18: ='OMAR MINAYA'!$K$4 -> 89600 | G18: ='OMAR MINAYA'!$J$4 -> 0 | H18: ='OMAR MINAYA'!$I$4 -> 941800 | I18: ='OMAR MINAYA'!$H$4 -> 0 | J18: 1000000 | K18: =D18/J18 -> 0.0747 | L18: ='OMAR MINAYA'!$K$5 -> 1 | M18: ='OMAR MINAYA'!$J$5 -> 0
B19: NAHOMI DIAZ | C19: ='NAHOMI DIAZ'!D3 -> CHICLAYO | D19: ='NAHOMI DIAZ'!$F$4 -> 219300 | E19: ='NAHOMI DIAZ'!$F$5 -> 3 | F19: ='NAHOMI DIAZ'!$K$4 -> 289500 | G19: ='NAHOMI DIAZ'!$J$4 -> 0 | H19: ='NAHOMI DIAZ'!$I$4 -> 103510 | I19: ='NAHOMI DIAZ'!$H$4 -> 303217 | J19: 1000000 | K19: =D19/J19 -> 0.2193 | L19: ='NAHOMI DIAZ'!$K$5 -> 6 | M19: ='NAHOMI DIAZ'!$J$5 -> 0
B20: VIOLETA LLERENA | C20: ='VIOLETA LLERENA'!D3 -> AREQUIPA | D20: ='VIOLETA LLERENA'!$F$4 -> 113000 | E20: ='VIOLETA LLERENA'!$F$5 -> 2 | F20: ='VIOLETA LLERENA'!$K$4 -> 3000 | G20: ='VIOLETA LLERENA'!$J$4 -> 59800 | H20: ='VIOLETA LLERENA'!$I$4 -> 119300 | I20: ='VIOLETA LLERENA'!$H$4 -> 88350 | J20: 1000000 | K20: =D20/J20 -> 0.113 | L20: ='VIOLETA LLERENA'!$K$5 -> 1 | M20: ='VIOLETA LLERENA'!$J$5 -> 1
B21: MILUSKA LINARES | C21: ='MILUSKA LINARES'!D3 -> TRUJILLO | D21: ='MILUSKA LINARES'!$F$4 -> 0 | E21: ='MILUSKA LINARES'!$F$5 -> 0 | F21: ='MILUSKA LINARES'!$K$4 -> 0 | G21: ='MILUSKA LINARES'!$J$4 -> 0 | H21: ='MILUSKA LINARES'!$I$4 -> 0 | I21: ='MILUSKA LINARES'!$H$4 -> 0 | J21: 1000000 | K21: =D21/J21 -> 0 | L21: ='MILUSKA LINARES'!$K$5 -> 0 | M21: ='MILUSKA LINARES'!$J$5 -> 0
B22: THALIA SALOME | C22: ='THALIA SALOME'!D3 -> HUANCAYO | D22: ='THALIA SALOME'!$F$4 -> 0 | E22: ='THALIA SALOME'!$F$5 -> 0 | F22: ='THALIA SALOME'!$K$4 -> 0 | G22: ='THALIA SALOME'!$J$4 -> 0 | H22: ='THALIA SALOME'!$I$4 -> 0 | I22: ='THALIA SALOME'!$H$4 -> 0 | J22: 1000000 | K22: =D22/J22 -> 0 | L22: ='THALIA SALOME'!$K$5 -> 0 | M22: ='THALIA SALOME'!$J$5 -> 0
B23: ELIZABETH ESQUIVEL | C23: ='ELIZABETH ESQUIVEL'!D3 -> LIMA 1 | D23: ='ELIZABETH ESQUIVEL'!$F$4 -> 0 | E23: ='ELIZABETH ESQUIVEL'!$F$5 -> 0 | F23: ='ELIZABETH ESQUIVEL'!$K$4 -> 0 | G23: ='ELIZABETH ESQUIVEL'!$J$4 -> 0 | H23: ='ELIZABETH ESQUIVEL'!$I$4 -> 0 | I23: ='ELIZABETH ESQUIVEL'!$H$4 -> 0 | J23: 500000 | K23: =D23/J23 -> 0 | L23: ='ELIZABETH ESQUIVEL'!$K$5 -> 1 | M23: ='ELIZSABETH ESQUIVEL'!$J$5 -> #REF!
B24: ANA ALIAGA | C24: ='ANA ALIAGA'!D3 -> LIMA 1 | D24: ='ANA ALIAGA'!$F$4 -> 160880 | E24: ='ANA ALIAGA'!$F$5 -> 2 | F24: ='ANA ALIAGA'!$K$4 -> 0 | G24: ='ANA ALIAGA'!$J$4 -> 0 | H24: ='ANA ALIAGA'!$I$4 -> 149500 | I24: ='ANA ALIAGA'!$H$4 -> 113500 | J24: 1000000 | K24: =D24/J24 -> 0.16088 | L24: ='ANA ALIAGA'!$K$5 -> 0 | M24: ='ANA ALIAGA'!$J$5 -> 0
B25: MERCEDES GIRALDO | C25: ='MERCEDES GIRALDO'!D3 -> LIMA 1 | D25: ='MERCEDES GIRALDO'!$F$4 -> 113400 | E25: ='MERCEDES GIRALDO'!$F$5 -> 3 | F25: ='MERCEDES GIRALDO'!$K$4 -> 0 | G25: ='MERCEDES GIRALDO'!$J$4 -> 0 | H25: ='MERCEDES GIRALDO'!$I$4 -> 157750 | I25: ='MERCEDES GIRALDO'!$H$4 -> 49300 | J25: 1000000 | K25: =D25/J25 -> 0.1134 | L25: ='MERCEDES GIRALDO'!$K$5 -> 0 | M25: ='MERCEDES GIRALDO'!$J$5 -> 0
B26: MELISSA BRAVO | C26: S/. | D26: ='MERCEDES GIRALDO'!$F$4 -> 113400 | E26: ='MERCEDES GIRALDO'!$F$5 -> 3 | F26: ='MERCEDES GIRALDO'!$K$4 -> 0 | G26: ='MERCEDES GIRALDO'!$J$4 -> 0 | H26: ='MERCEDES GIRALDO'!$I$4 -> 157750 | I26: ='MERCEDES GIRALDO'!$H$4 -> 49300 | J26: 1000000 | K26: =D26/J26 -> 0.1134 | L26: ='MERCEDES GIRALDO'!$K$5 -> 0
B27: TOTAL | D27: =SUM(D5:D25) -> 1909310 | E27: =SUM(E5:E25) -> 31 | F27: =SUM(F5:F25) -> 1928320 | G27: =SUM(G5:G25) -> 1034300 | H27: =SUM(H5:H25) -> 2949810 | I27: =SUM(I5:I25) -> 900717 | J27: =SUM(J5:J25) -> 22600000 | K27: 76246407239819 | L27: =SUM(L5:L25) -> 32 | M27: =SUM(M5:M25) -> #REF!
B30: PLAZA | D30: TOTAL DESEMBOLSO | E30: Q DESEMBOLSO | F30: EVALUACION BCP | G30: PENDIENTE DE BACK | H30: PENDIENTE DE REMESA | I30: PENDIENTE DE DOCUMENTAR | J30: META OBJETIVO | K30: AVANCE | L30: Q EVALUACION BCP | M30: Q PENDIENTE DE BACK
B31: LIMA 1 | D31: =SUMIFS(D$5:D$25,$C$5:$C$25,$B31) -> 815030 | E31: =SUMIFS(E$5:E$25,$C$5:$C$25,$B31) -> 15 | F31: =SUMIFS(F$5:F$25,$C$5:$C$25,$B31) -> 611550 | G31: =SUMIFS(G$5:G$25,$C$5:$C$25,$B31) -> 248900 | H31: =SUMIFS(H$5:H$25,$C$5:$C$25,$B31) -> 1126700 | I31: =SUMIFS(I$5:I$25,$C$5:$C$25,$B31) -> 360900 | J31: =SUMIFS(J$5:J$25,$C$5:$C$25,$B31) -> 8500000 | K31: =D31/J31 -> 0.095885882 | L31: =SUMIFS(L$5:L$25,$C$5:$C$25,$B31) -> 11 | M31: =SUMIFS(M$5:M$25,$C$5:$C$25,$B31) -> #REF!
B32: LIMA 2 | D32: =SUMIFS(D$5:D$25,$C$5:$C$25,$B32) -> 224850 | E32: =SUMIFS(E$5:E$25,$C$5:$C$25,$B32) -> 3 | F32: =SUMIFS(F$5:F$25,$C$5:$C$25,$B32) -> 111250 | G32: =SUMIFS(G$5:G$25,$C$5:$C$25,$B32) -> 135750 | H32: =SUMIFS(H$5:H$25,$C$5:$C$25,$B32) -> 336100 | I32: =SUMIFS(I$5:I$25,$C$5:$C$25,$B32) -> 99400 | J32: =SUMIFS(J$5:J$25,$C$5:$C$25,$B32) -> 2500000 | K32: =D32/J32 -> 0.08994 | L32: =SUMIFS(L$5:L$25,$C$5:$C$25,$B32) -> 2 | M32: =SUMIFS(M$5:M$25,$C$5:$C$25,$B32) -> 3
B33: NORTE | D33: =SUMIFS(D5:D25,$C$5:$C$25,"CHICLAYO")+SUMIFS(D5:D25,$C$5:$C$25,"TRUJILLO")+SUMIFS(D5:D25,$C$5:$C$25,"PIURA") -> 714430 | E33: =SUMIFS(E5:E25,$C$5:$C$25,"CHICLAYO")+SUMIFS(E5:E25,$C$5:$C$25,"TRUJILLO")+SUMIFS(E5:E25,$C$5:$C$25,"PIURA") -> 10 | F33: =SUMIFS(F5:F25,$C$5:$C$25,"CHICLAYO")+SUMIFS(F5:F25,$C$5:$C$25,"TRUJILLO")+SUMIFS(F5:F25,$C$5:$C$25,"PIURA") -> 1152420 | G33: =SUMIFS(G5:G25,$C$5:$C$25,"CHICLAYO")+SUMIFS(G5:G25,$C$5:$C$25,"TRUJILLO")+SUMIFS(G5:G25,$C$5:$C$25,"PIURA") -> 330350 | H33: =SUMIFS(H5:H25,$C$5:$C$25,"CHICLAYO")+SUMIFS(H5:H25,$C$5:$C$25,"TRUJILLO")+SUMIFS(H5:H25,$C$5:$C$25,"PIURA") -> 1367710 | I33: =SUMIFS(I5:I25,$C$5:$C$25,"CHICLAYO")+SUMIFS(I5:I25,$C$5:$C$25,"TRUJILLO")+SUMIFS(I5:I25,$C$5:$C$25,"PIURA") -> 352067 | J33: =SUMIFS(J5:J25,$C$5:$C$25,"CHICLAYO")+SUMIFS(J5:J25,$C$5:$C$25,"TRUJILLO")+SUMIFS(J5:J25,$C$5:$C$25,"PIURA") -> 8000000 | K33: =D33/J33 -> 0.08930375 | L33: =SUMIFS(L5:L25,$C$5:$C$25,"CHICLAYO")+SUMIFS(L5:L25,$C$5:$C$25,"TRUJILLO")+SUMIFS(L5:L25,$C$5:$C$25,"PIURA") -> 17 | M33: =SUMIFS(M5:M25,$C$5:$C$25,"CHICLAYO")+SUMIFS(M5:M25,$C$5:$C$25,"TRUJILLO")+SUMIFS(M5:M25,$C$5:$C$25,"PIURA") -> 4
B34: TARAPOTO | D34: =SUMIFS(D5:D22,$C$5:$C$22,"TARAPOTO") -> 42000 | E34: =SUMIFS(E5:E22,$C$5:$C$22,"TARAPOTO") -> 1 | F34: =SUMIFS(F5:F22,$C$5:$C$22,"TARAPOTO") -> 50100 | G34: =SUMIFS(G5:G22,$C$5:$C$22,"TARAPOTO") -> 259500 | H34: =SUMIFS(H5:H22,$C$5:$C$22,"TARAPOTO") -> 0 | I34: =SUMIFS(I5:I22,$C$5:$C$22,"TARAPOTO") -> 0 | J34: =SUMIFS(J5:J22,$C$5:$C$22,"TARAPOTO") -> 800000 | K34: =D34/J34 -> 0.0525 | L34: =SUMIFS(L5:L22,$C$5:$C$22,"TARAPOTO") -> 1 | M34: =SUMIFS(M5:M22,$C$5:$C$22,"TARAPOTO") -> 4
B35: AYACUCHO | D35: =SUMIFS(D5:D22,$C$5:$C$22,"AYACUCHO") -> 0 | E35: =SUMIFS(E5:E22,$C$5:$C$22,"AYACUCHO") -> 0 | F35: =SUMIFS(F5:F22,$C$5:$C$22,"AYACUCHO") -> 0 | G35: =SUMIFS(G5:G22,$C$5:$C$22,"AYACUCHO") -> 0 | H35: =SUMIFS(H5:H22,$C$5:$C$22,"AYACUCHO") -> 0 | I35: =SUMIFS(I5:I22,$C$5:$C$22,"AYACUCHO") -> 0 | J35: =SUMIFS(J5:J22,$C$5:$C$22,"AYACUCHO") -> 800000 | K35: =D35/J35 -> 0 | L35: =SUMIFS(L5:L22,$C$5:$C$22,"AYACUCHO") -> 0 | M35: =SUMIFS(M5:M22,$C$5:$C$22,"AYACUCHO") -> 0
B36: AREQUIPA | D36: =SUMIFS(D5:D22,$C$5:$C$22,"AREQUIPA") -> 113000 | E36: =SUMIFS(E5:E22,$C$5:$C$22,"AREQUIPA") -> 2 | F36: =SUMIFS(F5:F22,$C$5:$C$22,"AREQUIPA") -> 3000 | G36: =SUMIFS(G5:G22,$C$5:$C$22,"AREQUIPA") -> 59800 | H36: =SUMIFS(H5:H22,$C$5:$C$22,"AREQUIPA") -> 119300 | I36: =SUMIFS(I5:I22,$C$5:$C$22,"AREQUIPA") -> 88350 | J36: =SUMIFS(J5:J22,$C$5:$C$22,"AREQUIPA") -> 1000000 | K36: =D36/J36 -> 0.113 | L36: =SUMIFS(L6:L24,$C$5:$C$22,"AREQUIPA") -> #VALUE! | M36: =SUMIFS(M6:M24,$C$5:$C$22,"AREQUIPA") -> #VALUE!
B37: HUANCAYO | D37: =SUMIFS(D$5:D$25,$C$5:$C$25,$B37) -> 0 | E37: =SUMIFS(E$5:E$25,$C$5:$C$25,$B37) -> 0 | F37: =SUMIFS(F$5:F$25,$C$5:$C$25,$B37) -> 0 | G37: =SUMIFS(G$5:G$25,$C$5:$C$25,$B37) -> 0 | H37: =SUMIFS(H$5:H$25,$C$5:$C$25,$B37) -> 0 | I37: =SUMIFS(I$5:I$25,$C$5:$C$25,$B37) -> 0 | J37: =SUMIFS(J$5:J$25,$C$5:$C$25,$B37) -> 1000000 | K37: =D37/J37 -> 0 | L37: =SUMIFS(L$5:L$25,$C$5:$C$25,$B37) -> 0 | M37: =SUMIFS(M$5:M$25,$C$5:$C$25,$B37) -> 0
B38: TOTAL | D38: =SUM(D31:D37) -> 1909310 | E38: =SUM(E31:E37) -> 31 | F38: =SUM(F31:F37) -> 1928320 | G38: =SUM(G31:G37) -> 1034300 | H38: =SUM(H31:H37) -> 2949810 | I38: =SUM(I31:I37) -> 900717 | J38: =SUM(J31:J37) -> 22600000 | K38: =D38/J38 -> 0.084482743 | L38: =SUM(L31:L37) -> #VALUE! | M38: =SUM(M31:M37) -> #REF!

Sheet ANGIE SILVERA
D3: LIMA 1 | E3: Meta | F3: Desembolsado | G3: Avance | H3: Pendiente De Documentar | I3: Pendiente De Remesa | J3: Pendiente De Backoffice | K3: Evaluación BCP | L3: Obs Backoffice | M3: Obs BCP | N3: Rechazado
D4: S/. | E4: 2000000 | F4: =SUMIFS(OPI[MAF NETO],OPI[ESTADO],"Desembolsado") -> 158300 | G4: =F4-E4 -> -1841700 | H4: =SUMIFS(OPI[MAF NETO],OPI[ESTADO],H$3) -> 0 | I4: =SUMIFS(OPI[MAF NETO],OPI[ESTADO],I$3) -> 250700 | J4: =SUMIFS(OPI[MAF NETO],OPI[ESTADO],J$3) -> 0 | K4: =SUMIFS(OPI[MAF NETO],OPI[ESTADO],K$3) -> 189400 | L4: =SUMIFS(OPI[MAF NETO],OPI[ESTADO],L$3) -> 0 | M4: =SUMIFS(OPI[MAF NETO],OPI[ESTADO],M$3) -> 0 | N4: =SUMIFS(OPI[MAF NETO],OPI[ESTADO],N$3) -> 0
D5: Q / % | E5: - | F5: =COUNTIFS(OPI[ESTADO],"Desembolsado") -> 2 | G5: =IFERROR(F4/E4,"") -> 0.07915 | H5: =COUNTIFS(OPI[ESTADO],H$3) -> 0 | I5: =COUNTIFS(OPI[ESTADO],I$3) -> 3 | J5: =COUNTIFS(OPI[ESTADO],J$3) -> 0 | K5: =COUNTIFS(OPI[ESTADO],K$3) -> 3 | L5: =COUNTIFS(OPI[ESTADO],L$3) -> 0 | M5: =COUNTIFS(OPI[ESTADO],M$3) -> 0 | N5: =COUNTIFS(OPI[ESTADO],N$3) -> 0
B9: PLAZA DE VENTA | C9: FECHA DE ENVIO DE REMESA | D9: ESTADO DE REMESA | E9: FECHA DE INGRESO | F9: FECHA DE DESEMBOLSO | G9: DOCUMENTO | H9: NOMBRES Y APELLIDOS | I9: CONVENIO | J9: ESTADO | K9: MAF NETO | L9: EJECUTIVO | M9: FILE ENVIADO A BANCO | N9: FECHA DE ENVIÓ CARTA PODER A BCP | O9: COMPRA DE DEUDA REALIZADA | P9: LIBERACIÓN | Q9: FEEDBACK
C10: 46267 | D10: Enviada | E10: 46268 | F10: cambio seg | G10: 75877653 | H10: CAMPOS ESPINOZA KAROLAY MELISA | I10: PNP | J10: Evaluación BCP | K10: 82200 | L10: JUAN CORDOVA
C11: 46268 | D11: Enviada | E11: 46268 | F11: 46269 | G11: 44900885 | H11: GUTIERREZ URDANIVIA EDSON BRAYAN GUILLERMO | I11: PNP | J11: Desembolsado | K11: 75000 | L11: JUAN CORDOVA
C12: 46268 | D12: Enviada | E12: 46268 | G12: 70167787 | H12: GARCIA RAMOS ANGELO CRISTHOFER | I12: PNP | J12: Evaluación BCP | K12: 54500 | L12: JUAN CORDOVA
G13: 47067580 | H13: RUIZ MELCHOR JORGE ALBERTO | I13: MGP | J13: Desembolsado | K13: 83300 | L13: JUAN CORDOVA
G14: 44742744 | H14: ORTEGA RIVERA GISSELA JULIA | I14: FAP | J14: Evaluación BCP | K14: 52700 | L14: MARIA LLONTOP
G15: 48304033 | H15: DELGADO LAZARO MARIO MIGUEL | I15: MARINA | J15: Pendiente De Remesa | K15: 88000 | L15: JUAN CORDOVA
G16: 72151068 | H16: DIONISIO GOMEZ WILDER EVER | I16: PNP | J16: Pendiente De Remesa | K16: 82700 | L16: JUAN CORDOVA
G17: 71639629 | H17: BERNAOLA UTANI EDISON GUILLERMO | I17: PNP | J17: Pendiente De Remesa | K17: 80000 | L17: JUAN CORDOVA

Sheet NAHOMI DIAZ
D3: CHICLAYO | E3: Meta | F3: Desembolsado | G3: Avance | H3: Pendiente De Documentar | I3: Pendiente De Remesa | J3: Pendiente De Backoffice | K3: Evaluación BCP | L3: Obs Backoffice | M3: Obs BCP | N3: Rechazado
D4: S/. | E4: 1000000 | F4: =SUMIFS(OPI_11[MAF NETO],OPI_11[ESTADO],"Desembolsado") -> 219300 | G4: =F4-E4 -> -780700 | H4: =SUMIFS(OPI_11[MAF NETO],OPI_11[ESTADO],H$3) -> 303217 | I4: =SUMIFS(OPI_11[MAF NETO],OPI_11[ESTADO],I$3) -> 103510 | J4: =SUMIFS(OPI_11[MAF NETO],OPI_11[ESTADO],J$3) -> 0 | K4: =SUMIFS(OPI_11[MAF NETO],OPI_11[ESTADO],K$3) -> 289500 | L4: =SUMIFS(OPI_11[MAF NETO],OPI_11[ESTADO],L$3) -> 0 | M4: =SUMIFS(OPI_11[MAF NETO],OPI_11[ESTADO],M$3) -> 248250 | N4: =SUMIFS(OPI_11[MAF NETO],OPI_11[ESTADO],N$3) -> 83100
D5: Q / % | E5: - | F5: =COUNTIFS(OPI_11[ESTADO],"Desembolsado") -> 3 | G5: =IFERROR(F4/E4,"") -> 0.2193 | H5: =COUNTIFS(OPI_11[ESTADO],H$3) -> 5 | I5: =COUNTIFS(OPI_11[ESTADO],I$3) -> 2 | J5: =COUNTIFS(OPI_11[ESTADO],J$3) -> 0 | K5: =COUNTIFS(OPI_11[ESTADO],K$3) -> 6 | L5: =COUNTIFS(OPI_11[ESTADO],L$3) -> 0 | M5: =COUNTIFS(OPI_11[ESTADO],M$3) -> 3 | N5: =COUNTIFS(OPI_11[ESTADO],N$3) -> 1
B9: PLAZA DE VENTA | C9: FECHA DE ENVIO DE REMESA | D9: ESTADO DE REMESA | E9: FECHA DE INGRESO | F9: FECHA DE DESEMBOLSO | G9: DOCUMENTO | H9: NOMBRES Y APELLIDOS | I9: CONVENIO | J9: ESTADO | K9: MAF NETO | L9: EJECUTIVO | M9: FILE ENVIADO A BANCO | N9: FECHA DE ENVIÓ CARTA PODER A BCP | O9: COMPRA DE DEUDA REALIZADA | P9: LIBERACIÓN | Q9: FEEDBACK
C10: 46261 | D10: Aprobada | E10: 46262 | F10: 46268 | G10: 73228908 | H10: CHAÑA CARBAJAL MICHAEL PATRICK | I10: EJERCITO | J10: Desembolsado | K10: 58950 | L10: EYLIN VELASCO
C11: 46261 | D11: Aprobada | E11: 46267 | G11: 73352687 | H11: GARCIA YOVERA JEFRI MANUEL | I11: EJERCITO | J11: Desembolsado | K11: 92350 | L11: JOSE CORTEZ
C12: 46266 | D12: Enviada | G12: 73219721 | H12: NAUCA RIVANEIRA DICKSON STALIN | I12: EJERCITO | J12: Evaluación BCP | K12: 73400 | L12: JOSE CORTEZ
C13: 46266 | D13: Aprobada | G13: 47941390 | H13: CHAPOÑAN HUAMAN FIORELLA RUBI | I13: EJERCITO | J13: Desembolsado | K13: 68000 | L13: FARITH FARIAS
C14: 46260 | D14: Aprobada | G14: 77080881 | H14: HERNANDEZ LEON LUIS DAVID | I14: PNP | J14: Rechazado | K14: 83100 | L14: PIERO LOPEZ | Q14: CLIENTE PYME DEUDA SUNAT
C15: 46266 | D15: Aprobada | G15: 73109359 | H15: ALVARADO BUSTAMANTE JAZMIN GRESIA | I15: PNP | J15: Evaluación BCP | K15: 40000 | L15: EYLIN VELASCO
C16: 46268 | D16: Enviada | G16: 77084670 | H16: POMA JUSTUS CARLOS JOSE | I16: EJERCITO | J16: Pendiente De Documentar | K16: 81050 | L16: EYLIN VELASCO
C17: 3/092026 | D17: Enviada | G17: 42510241 | H17: BERNAL GONZALES MARCO ALBERTO | I17: EJERCITO | J17: Evaluación BCP | K17: 55000 | L17: EYLIN VELASCO
C18: 46269 | D18: Enviada | G18: 71400285 | H18: PIZARRO MAMANI ASTRI KAROLINA | I18: PNP | J18: Obs BCP | K18: 82200 | L18: EYLIN VELASCO
C19: 46269 | D19: Enviada | G19: 73366141 | H19: TARRILLO MEGO DENIS OSCAR | I19: PNP | J19: Evaluación BCP | K19: 74100 | L19: PIERO LOPEZ
C20: 46269 | D20: Enviada | G20: 44319380 | H20: CAHUANA CONDORI NELSON WILLIAN | I20: PNP | J20: Evaluación BCP | K20: 47000 | L20: JAVIER QUESQUEN
C21: 46269 | D21: Enviada | G21: 74288819 | H21: ALARCON MOLOCHO DEIVIS ESNESTOR | I21: PNP | J21: Evaluación BCP | K21: 61,490.00 | L21: AZUCENA BARBA
C22: 46269 | D22: Enviada | G22: 77015562 | H22: GUEVARA ZELADA ADILVER APARICIO | I22: PNP | J22: Obs BCP | K22: 82250 | L22: EYLIN VELASCO
C23: 46269 | D23: Enviada | G23: 75621329 | H23: PEREZ VASQUEZ JEAN ROBERT | I23: PNP | J23: Pendiente De Documentar | K23: 10000 | L23: FARITH FARIAS
C24: 46269 | D24: Enviada | G24: 72532327 | H24: HUANCAS PADILLA JOSE ALEX | I24: PNP | J24: Pendiente De Documentar | K24: 57617 | L24: AZUCENA BARBA
C25: 46269 | D25: Enviada | G25: 73461397 | H25: ATOCHE DELGADO EDWIN GABRIEL | I25: EJERCITO | J25: Pendiente De Remesa | K25: 103510 | L25: JOSE CORTEZ
C26: 46269 | D26: Enviada | G26: 45862310 | H26: CASTILLO PEREZ YOBAR DEYNER | I26: EJERCITO | J26: Obs BCP | K26: 83800 | L26: EYLIN VELASCO
D27: Enviada | G27: 74295926 | H27: VERGARA GAMARRA KEVIN ALDAIR | I27: PNP | J27: Pendiente De Documentar | K27: 60000 | L27: AZUCENA BARBA
D28: Enviada | G28: 44143917 | H28: MONDRAGON MAMANI RODOLFO HUNTHEY | I28: EJERCITO | J28: Pendiente De Documentar | K28: 94550 | L28: FARITH FARIAS
G29: 44081864 | H29: BURGOS VIGO VANESSA PAOLA | I29: EJERCITO | J29: Pendiente De Remesa | K29: 62,860.00 | L29: JOSE CORTEZ

Sheet WENDY IPANEQUE
D3: PIURA | E3: Meta | F3: Desembolsado | G3: Avance | H3: Pendiente De Documentar | I3: Pendiente De Remesa | J3: Pendiente De Backoffice | K3: Evaluación BCP | L3: Obs Backoffice | M3: Obs BCP | N3: Rechazado
D4: S/. | E4: 1000000 | F4: =SUMIFS(OPI_14[MAF NETO],OPI_14[ESTADO],"Desembolsado") -> 83800 | G4: =F4-E4 -> -916200 | H4: =SUMIFS(OPI_14[MAF NETO],OPI_14[ESTADO],H$3) -> 48850 | I4: =SUMIFS(OPI_14[MAF NETO],OPI_14[ESTADO],I$3) -> 82000 | J4: =SUMIFS(OPI_14[MAF NETO],OPI_14[ESTADO],J$3) -> 252050 | K4: =SUMIFS(OPI_14[MAF NETO],OPI_14[ESTADO],K$3) -> 773320 | L4: =SUMIFS(OPI_14[MAF NETO],OPI_14[ESTADO],L$3) -> 0 | M4: =SUMIFS(OPI_14[MAF NETO],OPI_14[ESTADO],M$3) -> 70600 | N4: =SUMIFS(OPI_14[MAF NETO],OPI_14[ESTADO],N$3) -> 85500
D5: Q / % | E5: - | F5: =COUNTIFS(OPI_14[ESTADO],"Desembolsado") -> 1 | G5: =IFERROR(F4/E4,"") -> 0.0838 | H5: =COUNTIFS(OPI_14[ESTADO],H$3) -> 2 | I5: =COUNTIFS(OPI_14[ESTADO],I$3) -> 1 | J5: =COUNTIFS(OPI_14[ESTADO],J$3) -> 3 | K5: =COUNTIFS(OPI_14[ESTADO],K$3) -> 10 | L5: =COUNTIFS(OPI_14[ESTADO],L$3) -> 0 | M5: =COUNTIFS(OPI_14[ESTADO],M$3) -> 1 | N5: =COUNTIFS(OPI_14[ESTADO],N$3) -> 1
B9: PLAZA DE VENTA | C9: FECHA DE ENVIO DE REMESA | D9: ESTADO DE REMESA | E9: FECHA DE INGRESO | F9: FECHA DE DESEMBOLSO | G9: DOCUMENTO | H9: NOMBRES Y APELLIDOS | I9: CONVENIO | J9: ESTADO | K9: MAF NETO | L9: EJECUTIVO | M9: FILE ENVIADO A BANCO | N9: FECHA DE ENVIÓ CARTA PODER A BCP | O9: COMPRA DE DEUDA REALIZADA | P9: LIBERACIÓN | Q9: FEEDBACK
B10: PIURA | C10: 46260 | D10: Aprobada | G10: 80262692 | H10: COLUPU PURIZACA WALTER | I10: MPV | J10: Desembolsado | K10: 83800 | L10: KRIS BARRAGAN RODRIGUEZ | Q10: CD IBK Y REHABILITADORA: PENDIENTE RPTA DESEMBOLSOS
B11: PIURA | C11: 46260 | D11: Aprobada | G11: 42984845 | H11: ZAPATA OLAVARRIA CHRISTIAN EDWAR | I11: MPV | J11: Pendiente de BackOffice | K11: 72350 | L11: KRIS BARRAGAN RODRIGUEZ | Q11: CD BANCOM Y REHABILITADORA: se solicito nuevamente remesa
B12: PIURA | C12: 46267 | D12: Enviada | G12: 41871561 | H12: GALARZA PAKER JAVIER ALEXANDER | I12: HOSPITAL SANTA ROSA | J12: Evaluación BCP | K12: 66750 | L12: KRIS BARRAGAN RODRIGUEZ | Q12: CD BANBIF: en envio correo de seguimiento para aprobacion de remesa
B13: PIURA | C13: 46267 | D13: Aprobada | G13: 73118366 | H13: SUAREZ FLORES GREYCCI KATHERINE | I13: DSRLCC | J13: Pendiente de BackOffice | K13: 110700 | L13: KRIS BARRAGAN RODRIGUEZ | Q13: CD SCOTIABANK: bo enviar file
B14: PIURA | C14: 46268 | D14: Enviada | G14: 76359950 | H14: FLORES CABREDO JOSE FELIX | I14: HOSPITAL ESPECIALIDADES SULLANA | J14: Evaluación BCP | K14: 47750 | L14: KRIS BARRAGAN RODRIGUEZ | Q14: CD BANBIF: PENDIENTE RESPUESTA DE REMESA
B15: PIURA | C15: 46267 | D15: Enviada | G15: 46720028 | H15: CHUMACERO ABAD ADELA | I15: HOSPITAL ESPECIALIDADES SULLANA | J15: Evaluación BCP | K15: 54800 | L15: KRIS BARRAGAN RODRIGUEZ | Q15: CD BANCO DE COMERCIO: se envio correo de seguimiento para respuesta de remesa
B16: PIURA | C16: 46267 | D16: Aprobada | E16: 46269 | G16: 71485463 | H16: ROJAS FLORES JOSE CALIN | I16: PNP | J16: Obs BCP | K16: 70600 | L16: KRIS BARRAGAN RODRIGUEZ | Q16: CLIENTE GESTIONARA CAMBIO DE SEGMENTACION PYME 07/09
B17: PIURA | C17: 46268 | D17: Aprobada | E17: 46269 | G17: 44561073 | H17: SAAVEDRA RIVAS DAYANA YESSABELLA | I17: PNP | J17: Evaluación BCP | K17: 85920 | L17: KRIS BARRAGAN RODRIGUEZ | Q17: DESEMBOLSO PENDIENTE
B18: PIURA | C18: 46269 | D18: Enviada | E18: 46269 | G18: 70977830 | H18: SUCAPUCA CAMASITA EFRAIN | I18: PNP | J18: Pendiente de BackOffice | K18: 69000 | L18: KRIS BARRAGAN RODRIGUEZ | Q18: PENDIENTE RESPUESTA DE REMESA
B19: PIURA | C19: 46265 | D19: Enviada | G19: 78200844 | H19: CUESTAS PATAZCA NEYSER EMMANUEL | I19: EP | J19: Rechazado | K19: 85500 | L19: KRIS BARRAGAN RODRIGUEZ | Q19: CD SCOTIABANK. CUOTA 1/4
B20: PIURA | C20: 46265 | D20: Aprobada | G20: 71664793 | H20: GONZALES ALEJANDRO LUIS ALBERTO | I20: PNP | J20: Evaluación BCP | K20: 80400 | L20: KRIS BARRAGAN RODRIGUEZ | Q20: REMESA APROBADA CD 77K HACER NUEVA CALCULADORA 78500 SINCERAR SU EECC DE GNB
B21: PIURA | C21: 46269 | D21: Enviada | G21: 47563698 | H21: BARRIOS RODRIGUEZ WILMER ENRIQUE | I21: HOSPITAL ESPECIALIDADES SULLANA | J21: Evaluación BCP | K21: 42000 | L21: KRIS BARRAGAN RODRIGUEZ | Q21: CD BANCOM: PENDIENTE RESPUESTA DE REMESA
B22: PIURA | C22: 46272 | D22: Enviada | G22: 73855212 | H22: HERRERA AGUILAR GABRIEL ADRIAN | I22: PNP | J22: Evaluación BCP | K22: 79000 | L22: KRIS BARRAGAN RODRIGUEZ | Q22: CD SCOTIABANK
B23: PIURA | C23: 46272 | D23: Enviada | G23: 40460400 | H23: CRUZ ARRIETA DAYANARA DEL CARMEN | I23: ESSALUD | J23: Evaluación BCP | K23: 115600 | L23: KRIS BARRAGAN RODRIGUEZ | Q23: CD BANCO DE COMERCIO
B24: PIURA | G24: 02852919 | H24: MULATILLO VALLE RIGOBERTO | I24: EP | J24: Pendiente De Documentar | K24: 16850 | L24: KRIS BARRAGAN RODRIGUEZ | Q24: CREDITO NUEVO: EN TOMA DE FIRMAS
B25: PIURA | C25: 46272 | D25: Enviada | G25: 16714200 | H25: ADANAQUE DELGADO DANTE ISAIAS | I25: DSRLLC | J25: Evaluación BCP | K25: 163600 | Q25: CD BANCOM: EN TOMA DE FIRMAS
B26: PIURA | G26: 48511402 | H26: RAIME QUISPE JORGE ALFREDO | I26: PNP | J26: Pendiente De Documentar | K26: 32000 | Q26: CREDITO NUEVO: SUBIR REMESA
B27: PIURA | C27: 46272 | D27: Enviada | G27: 42472052 | H27: NAVARRO APARICIO JUANA ANDREA | I27: HOSPITAL ESPECIALIDADES SULLANA | J27: Evaluación BCP | K27: 37500 | L27: KRIS BARRAGAN RODRIGUEZ | Q27: CD BANBIF
B28: PIURA | C28: 46272 | D28: Enviada | E28: 46272 | G28: 70509951 | H28: ARELLANO LEON BRAYAN DAIL | I28: EP | J28: Pendiente De Remesa | K28: 82000 | Q28: CD INTERBANK

Sheet OMAR MINAYA
D3: CHICLAYO | E3: Meta | F3: Desembolsado | G3: Avance | H3: Pendiente De Documentar | I3: Pendiente De Remesa | J3: Pendiente De Backoffice | K3: Evaluación BCP | L3: Obs Backoffice | M3: Obs BCP | N3: Rechazado
D4: S/. | E4: 1000000 | F4: =SUMIFS(OPI_5[MAF NETO],OPI_5[ESTADO],"Desembolsado") -> 74700 | G4: =F4-E4 -> -925300 | H4: =SUMIFS(OPI_5[MAF NETO],OPI_5[ESTADO],H$3) -> 0 | I4: =SUMIFS(OPI_5[MAF NETO],OPI_5[ESTADO],I$3) -> 941800 | J4: =SUMIFS(OPI_5[MAF NETO],OPI_5[ESTADO],J$3) -> 0 | K4: =SUMIFS(OPI_5[MAF NETO],OPI_5[ESTADO],K$3) -> 89600 | L4: =SUMIFS(OPI_5[MAF NETO],OPI_5[ESTADO],L$3) -> 0 | M4: =SUMIFS(OPI_5[MAF NETO],OPI_5[ESTADO],M$3) -> 0 | N4: =SUMIFS(OPI_5[MAF NETO],OPI_5[ESTADO],N$3) -> 0
D5: Q / % | E5: - | F5: =COUNTIFS(OPI_5[ESTADO],"Desembolsado") -> 2 | G5: =IFERROR(F4/E4,"") -> 0.0747 | H5: =COUNTIFS(OPI_5[ESTADO],H$3) -> 0 | I5: =COUNTIFS(OPI_5[ESTADO],I$3) -> 12 | J5: =COUNTIFS(OPI_5[ESTADO],J$3) -> 0 | K5: =COUNTIFS(OPI_5[ESTADO],K$3) -> 1 | L5: =COUNTIFS(OPI_5[ESTADO],L$3) -> 0 | M5: =COUNTIFS(OPI_5[ESTADO],M$3) -> 0 | N5: =COUNTIFS(OPI_5[ESTADO],N$3) -> 0
B9: PLAZA DE VENTA | C9: FECHA DE ENVIO DE REMESA | D9: ESTADO DE REMESA | E9: FECHA DE INGRESO | F9: FECHA DE DESEMBOLSO | G9: DOCUMENTO | H9: NOMBRES Y APELLIDOS | I9: CONVENIO | J9: ESTADO | K9: MAF NETO | L9: EJECUTIVO | M9: FILE ENVIADO A BANCO | N9: FECHA DE ENVIÓ CARTA PODER A BCP | O9: COMPRA DE DEUDA REALIZADA | P9: LIBERACIÓN | Q9: FEEDBACK
B10: CHICLAYO | C10: 46258 | D10: Aprobada | E10: 46267 | G10: 48297343 | H10: HUAMANI QUISPE JHON WILLIAN | I10: EP | J10: Desembolsado | K10: 23700 | L10: GABRIELA VELASQUEZ
B11: CHICLAYO | C11: 46259 | D11: Aprobada | E11: 46263 | F11: 46267 | G11: 15753995 | H11: PADILLA FALCON AMERICO JAVIER | I11: MARINA | J11: Desembolsado | K11: 51000 | L11: YURIKO OSPINO
B12: CHICLAYO | C12: 46260 | D12: Aprobada | E12: 46265 | G12: 75202880 | H12: CORDOVA QUESADA ROCIO MARILIN | I12: EP | J12: Evaluación BCP | K12: 89600 | L12: GABRIELA VELASQUEZ
B13: CHICLAYO | C13: 46268 | D13: Enviada | G13: 76643587 | H13: ORTIZ AREVALO DOYSI MAIDELI | I13: MARINA | J13: Pendiente De Remesa | K13: 30000 | L13: HENRY CARCAMO
B14: CHICLAYO | C14: 46269 | D14: Enviada | G14: 46436786 | H14: IPARRAGUIRRE QUISPE SEGUNDO MANUEL | I14: EP | J14: Pendiente De Remesa | K14: 73800 | L14: YOVANA BACA
B15: CHICLAYO | C15: 46269 | D15: Enviada | G15: 41873838 | H15: ASENJO QUISPE ROXANA JAKELENE | I15: ESSALUD | J15: Pendiente De Remesa | K15: 123500 | L15: JHONNY SANDOVAL
B16: CHICLAYO | C16: 46269 | D16: Enviada | G16: 46309599 | H16: ANGELES ROJAS LEYZY ROMINA | I16: ESSALUD | J16: Pendiente De Remesa | K16: 53500 | L16: YOVANA BACA
B17: CHICLAYO | C17: 46269 | D17: Enviada | G17: 42787348 | H17: SANGAMA ISHUIZA JOSE SANTOS | I17: EP | J17: Pendiente De Remesa | K17: 97400 | L17: RUBEN MEJIA
B18: CHICLAYO | C18: 46269 | D18: Enviada | G18: 77528460 | H18: FELIX SULCA JEFFERSON DIEGO ARMANDO | I18: MARINA | J18: Pendiente De Remesa | K18: 97900 | L18: HENRY CARCAMO
B19: CHICLAYO | C19: 46272 | D19: Enviada | G19: 48103620 | H19: PUMA AVILA ANTHONY JHORDY | I19: EP | J19: Pendiente De Remesa | K19: 84200 | L19: YOVANA BACA
B20: CHICLAYO | C20: 46272 | D20: Enviada | G20: 42732248 | H20: ALEGRE HUERTA MIGUEL VICTOR | I20: EP | J20: Pendiente De Remesa | K20: 95900 | L20: YOVANA BACA
B21: CHICLAYO | C21: 46272 | D21: Enviada | G21: 10761842 | H21: CHUQUIZUTA GRANDEZ PEDRO PABLO | I21: EP | J21: Pendiente De Remesa | K21: 34500 | L21: YOVANA BACA
B22: CHICLAYO | C22: 46272 | D22: Enviada | G22: 70751258 | H22: SANCHEZ RUIZ HANS PETE | I22: EP | J22: Pendiente De Remesa | K22: 80000 | L22: KAROL MOÑAN
B23: CHICLAYO | C23: 46272 | D23: Enviada | G23: 73579828 | H23: MILIAN HUAMAN EMMANUEL LEVIH | I23: EP | J23: Pendiente De Remesa | K23: 89200 | L23: CESAR SIESQUEN
B24: CHICLAYO | C24: 46272 | D24: Enviada | G24: 72933251 | H24: BERNAL SANTAMARIA MIGUEL ALONSO | I24: EP | J24: Pendiente De Remesa | K24: 81900 | L24: YOVANA BACA

Sheet JHON ZAMORA
D3: CHICLAYO | E3: Meta | F3: Desembolsado | G3: Avance | H3: Pendiente De Documentar | I3: Pendiente De Remesa | J3: Pendiente De Backoffice | K3: Evaluación BCP | L3: Obs Backoffice | M3: Obs BCP | N3: Rechazado
D4: S/. | E4: 1000000 | F4: =SUMIFS(OPI_3[MAF NETO],OPI_3[ESTADO],"Desembolsado") -> 83130 | G4: =F4-E4 -> -916870 | H4: =SUMIFS(OPI_3[MAF NETO],OPI_3[ESTADO],H$3) -> 0 | I4: =SUMIFS(OPI_3[MAF NETO],OPI_3[ESTADO],I$3) -> 240400 | J4: =SUMIFS(OPI_3[MAF NETO],OPI_3[ESTADO],J$3) -> 0 | K4: =SUMIFS(OPI_3[MAF NETO],OPI_3[ESTADO],K$3) -> 0 | L4: =SUMIFS(OPI_3[MAF NETO],OPI_3[ESTADO],L$3) -> 0 | M4: =SUMIFS(OPI_3[MAF NETO],OPI_3[ESTADO],M$3) -> 0 | N4: =SUMIFS(OPI_3[MAF NETO],OPI_3[ESTADO],N$3) -> 0
D5: Q / % | E5: - | F5: =COUNTIFS(OPI_3[ESTADO],"Desembolsado") -> 1 | G5: =IFERROR(F4/E4,"") -> 0.08313 | H5: =COUNTIFS(OPI_3[ESTADO],H$3) -> 0 | I5: =COUNTIFS(OPI_3[ESTADO],I$3) -> 3 | J5: =COUNTIFS(OPI_3[ESTADO],J$3) -> 0 | K5: =COUNTIFS(OPI_3[ESTADO],K$3) -> 0 | L5: =COUNTIFS(OPI_3[ESTADO],L$3) -> 0 | M5: =COUNTIFS(OPI_3[ESTADO],M$3) -> 0 | N5: =COUNTIFS(OPI_3[ESTADO],N$3) -> 0
B9: PLAZA DE VENTA | C9: FECHA DE ENVIO DE REMESA | D9: ESTADO DE REMESA | E9: FECHA DE INGRESO | F9: FECHA DE DESEMBOLSO | G9: DOCUMENTO | H9: NOMBRES Y APELLIDOS | I9: CONVENIO | J9: ESTADO | K9: MAF NETO | L9: EJECUTIVO | M9: FILE ENVIADO A BANCO | N9: FECHA DE ENVIÓ CARTA PODER A BCP | O9: COMPRA DE DEUDA REALIZADA | P9: LIBERACIÓN | Q9: FEEDBACK
B10: CHICLAYO | C10: 46266 | D10: Aprobada | E10: 46267 | F10: 46268 | G10: 77137634 | H10: USCAMAYTA USCAMAYTA,LEYDI DIANA | I10: PNP | J10: Desembolsado | K10: 83130 | L10: FLOR LLATAS
B11: CHICLAYO | C11: 46266 | D11: Enviada | G11: 48409811 | H11: MUCHA HUARACA JHOEL KENDELL | I11: PNP | J11: Pendiente De Remesa | K11: 78140 | L11: FLOR LLATAS
B12: CHICLAYO | C12: 46269 | D12: Enviada | G12: 44758659 | H12: NAVARRO MAMANCHURA KENEDY | I12: PNP | J12: Pendiente De Remesa | K12: 81760 | L12: ERICK GUEVARA
B13: CHICLAYO | C13: 46272 | D13: Enviada | G13: 77479805 | H13: BARRETO ANGULLA MARYORI VANESA | I13: PNP | J13: Pendiente De Remesa | K13: 80500 | L13: FLOR LLATAS

Sheet NATHALIE ARANDA
D3: LIMA 2 | E3: Meta | F3: Desembolsado | G3: Avance | H3: Pendiente De Documentar | I3: Pendiente De Remesa | J3: Pendiente De Backoffice | K3: Evaluación BCP | L3: Obs Backoffice | M3: Obs BCP | N3: Rechazado
D4: S/. | E4: 500000 | F4: =SUMIFS(OPI_12[MAF NETO],OPI_12[ESTADO],"Desembolsado") -> 224850 | G4: =F4-E4 -> -275150 | H4: =SUMIFS(OPI_12[MAF NETO],OPI_12[ESTADO],H$3) -> 99400 | I4: =SUMIFS(OPI_12[MAF NETO],OPI_12[ESTADO],I$3) -> 336100 | J4: =SUMIFS(OPI_12[MAF NETO],OPI_12[ESTADO],J$3) -> 135750 | K4: =SUMIFS(OPI_12[MAF NETO],OPI_12[ESTADO],K$3) -> 111250 | L4: =SUMIFS(OPI_12[MAF NETO],OPI_12[ESTADO],L$3) -> 0 | M4: =SUMIFS(OPI_12[MAF NETO],OPI_12[ESTADO],M$3) -> 0 | N4: =SUMIFS(OPI_12[MAF NETO],OPI_12[ESTADO],N$3) -> 0
D5: Q / % | E5: - | F5: =COUNTIFS(OPI_12[ESTADO],"Desembolsado") -> 3 | G5: =IFERROR(F4/E4,"") -> 0.4497 | H5: =COUNTIFS(OPI_12[ESTADO],H$3) -> 2 | I5: =COUNTIFS(OPI_12[ESTADO],I$3) -> 4 | J5: =COUNTIFS(OPI_12[ESTADO],J$3) -> 3 | K5: =COUNTIFS(OPI_12[ESTADO],K$3) -> 2 | L5: =COUNTIFS(OPI_12[ESTADO],L$3) -> 0 | M5: =COUNTIFS(OPI_12[ESTADO],M$3) -> 0 | N5: =COUNTIFS(OPI_12[ESTADO],N$3) -> 0
B9: PLAZA DE VENTA | C9: FECHA DE ENVIO DE REMESA | D9: ESTADO DE REMESA | E9: FECHA DE INGRESO | F9: FECHA DE DESEMBOLSO | G9: DOCUMENTO | H9: NOMBRES Y APELLIDOS | I9: CONVENIO | J9: ESTADO | K9: MAF NETO | L9: EJECUTIVO | M9: FILE ENVIADO A BANCO | N9: FECHA DE ENVIÓ CARTA PODER A BCP | O9: COMPRA DE DEUDA REALIZADA | P9: LIBERACIÓN | Q9: FEEDBACK
B10: TACNA | C10: 46259 | D10: Aprobada | E10: 46261 | F10: 46266 | G10: 46559043 | H10: JORGE ANDRE LINARES PORTUGAL | I10: PNP | J10: Desembolsado | K10: 84200 | L10: EVELYN GUTIERREZ
B11: LIMA | C11: 46262 | D11: Aprobada | E11: 46265 | F11: 46266 | G11: 43506674 | H11: SHENO CHRISTIAN MUNGI CASTILLON | I11: PNP | J11: Desembolsado | K11: 66050 | L11: MELINA LEYVA
B12: LIMA | C12: 46261 | D12: Aprobada | E12: 46262 | F12: 46268 | G12: 76670984 | H12: ANSONY MARCOS MUÑOZ TEMOCHE | I12: PNP | J12: Desembolsado | K12: 74600 | L12: MERLY ROJAS
B13: LIMA | C13: 46268 | D13: Enviada | G13: 45387374 | H13: MATT CHERIE DEL AGUILA RAMIREZ | I13: MGP | J13: Pendiente De Remesa | K13: 99000 | L13: EVELYN GUTIERREZ
B14: HUANCAYO | C14: 46266 | D14: Aprobada | E14: 46267 | G14: 74854997 | H14: ROYER CAMILO ALVARADO OTEO | I14: PNP | J14: Evaluación BCP | K14: 34800 | L14: EVELYN GUTIERREZ
B15: LIMA | C15: 46266 | D15: Aprobada | E15: 46269 | G15: 41843888 | H15: WENDY JACQUELINE VALENZUELA QUINTANA | I15: DIRIS LIMA NORTE | J15: Pendiente de BackOffice | K15: 54400 | L15: MELINA LEYVA
B16: LA MERCED | C16: 46268 | D16: Aprobada | E16: 46269 | G16: 47893379 | H16: ELVIS KELVIN CARBAJAL HUAMAN | I16: PNP | J16: Evaluación BCP | K16: 76450 | L16: EVELYN GUTIERREZ
B17: YURIMAGUAS | C17: 46267 | D17: Aprobada | E17: 46269 | G17: 42971795 | H17: BERTHA NOELIA REQUEJO SANCHEZ | I17: PNP | J17: Pendiente de BackOffice | K17: 47250 | L17: EVELYN GUTIERREZ
B18: LIMA | C18: 46267 | D18: Aprobada | G18: 46134037 | H18: PEDRO LUIS MORAN HUAPAYA | I18: EP | J18: Pendiente De Documentar | K18: 99400 | L18: EVELYN GUTIERREZ
B19: LIMA | C19: 46268 | D19: Aprobada | E19: 46269 | G19: 48130636 | H19: DAVID BRYAN QUISPE SANCARRANCO | I19: PNP | J19: Pendiente de BackOffice | K19: 34100 | L19: MERLY ROJAS
B20: LIMA | C20: 46268 | D20: Enviada | G20: 72201915 | H20: LENIN FERNANDO HERNANDEZ ZAPATA | I20: EP | J20: Pendiente De Documentar | L20: MELINA LEYVA
B21: TACNA | G21: 70560233 | H21: RICHARD CHANG BENEGAS MOLLO | I21: PNP | J21: Pendiente De Remesa | K21: 79300 | L21: EVELYN GUTIERREZ
C22: 46272 | D22: Enviada | G22: 76791939 | H22: LUISA HERMINIA CHOQUE LEON | I22: EP | J22: Pendiente De Remesa | K22: 78900 | L22: EVELYN GUTIERREZ
B23: LIMA | G23: 73750622 | H23: DEYVI ROMARIO LOPEZ HUAMAN | I23: MGP | J23: Pendiente De Remesa | K23: 78900 | L23: EVELYN GUTIERREZ

Sheet LUIS CHUSE
D3: LIMA 2 | E3: Meta | F3: Desembolsado | G3: Avance | H3: Pendiente De Documentar | I3: Pendiente De Remesa | J3: Pendiente De Backoffice | K3: Evaluación BCP | L3: Obs Backoffice | M3: Obs BCP | N3: Rechazado
D4: S/. | E4: 2000000 | F4: =SUMIFS(OPI_7[MAF NETO],OPI_7[ESTADO],"Desembolsado") -> 0 | G4: =F4-E4 -> -2000000 | H4: =SUMIFS(OPI_7[MAF NETO],OPI_7[ESTADO],H$3) -> 0 | I4: =SUMIFS(OPI_7[MAF NETO],OPI_7[ESTADO],I$3) -> 0 | J4: =SUMIFS(OPI_7[MAF NETO],OPI_7[ESTADO],J$3) -> 0 | K4: =SUMIFS(OPI_7[MAF NETO],OPI_7[ESTADO],K$3) -> 0 | L4: =SUMIFS(OPI_7[MAF NETO],OPI_7[ESTADO],L$3) -> 0 | M4: =SUMIFS(OPI_7[MAF NETO],OPI_7[ESTADO],M$3) -> 0 | N4: =SUMIFS(OPI_7[MAF NETO],OPI_7[ESTADO],N$3) -> 0
D5: Q / % | E5: - | F5: =COUNTIFS(OPI_7[ESTADO],"Desembolsado") -> 0 | G5: =IFERROR(F4/E4,"") -> 0 | H5: =COUNTIFS(OPI_7[ESTADO],H$3) -> 0 | I5: =COUNTIFS(OPI_7[ESTADO],I$3) -> 0 | J5: =COUNTIFS(OPI_7[ESTADO],J$3) -> 0 | K5: =COUNTIFS(OPI_7[ESTADO],K$3) -> 0 | L5: =COUNTIFS(OPI_7[ESTADO],L$3) -> 0 | M5: =COUNTIFS(OPI_7[ESTADO],M$3) -> 0 | N5: =COUNTIFS(OPI_7[ESTADO],N$3) -> 0
B9: PLAZA DE VENTA | C9: FECHA DE ENVIO DE REMESA | D9: ESTADO DE REMESA | E9: FECHA DE INGRESO | F9: FECHA DE DESEMBOLSO | G9: DOCUMENTO | H9: NOMBRES Y APELLIDOS | I9: CONVENIO | J9: ESTADO | K9: MAF NETO | L9: EJECUTIVO | M9: FILE ENVIADO A BANCO | N9: FECHA DE ENVIÓ CARTA PODER A BCP | O9: COMPRA DE DEUDA REALIZADA | P9: LIBERACIÓN | Q9: FEEDBACK

Sheet ANA ALIAGA
D3: LIMA 1 | E3: Meta | F3: Desembolsado | G3: Avance | H3: Pendiente De Documentar | I3: Pendiente De Remesa | J3: Pendiente De Backoffice | K3: Evaluación BCP | L3: Obs Backoffice | M3: Obs BCP | N3: Rechazado
D4: S/. | E4: 1000000 | F4: =SUMIFS(OPI_20[MAF NETO],OPI_20[ESTADO],"Desembolsado") -> 160880 | G4: =F4-E4 -> -839120 | H4: =SUMIFS(OPI_20[MAF NETO],OPI_20[ESTADO],H$3) -> 113500 | I4: =SUMIFS(OPI_20[MAF NETO],OPI_20[ESTADO],I$3) -> 149500 | J4: =SUMIFS(OPI_20[MAF NETO],OPI_20[ESTADO],J$3) -> 0 | K4: =SUMIFS(OPI_20[MAF NETO],OPI_20[ESTADO],K$3) -> 0 | L4: =SUMIFS(OPI_20[MAF NETO],OPI_20[ESTADO],L$3) -> 0 | M4: =SUMIFS(OPI_20[MAF NETO],OPI_20[ESTADO],M$3) -> 0 | N4: =SUMIFS(OPI_20[MAF NETO],OPI_20[ESTADO],N$3) -> 0
D5: Q / % | E5: - | F5: =COUNTIFS(OPI_20[ESTADO],"Desembolsado") -> 2 | G5: =IFERROR(F4/E4,"") -> 0.16088 | H5: =COUNTIFS(OPI_20[ESTADO],H$3) -> 2 | I5: =COUNTIFS(OPI_20[ESTADO],I$3) -> 2 | J5: =COUNTIFS(OPI_20[ESTADO],J$3) -> 0 | K5: =COUNTIFS(OPI_20[ESTADO],K$3) -> 0 | L5: =COUNTIFS(OPI_20[ESTADO],L$3) -> 0 | M5: =COUNTIFS(OPI_20[ESTADO],M$3) -> 0 | N5: =COUNTIFS(OPI_20[ESTADO],N$3) -> 0
B9: PLAZA DE VENTA | C9: FECHA DE ENVIO DE REMESA | D9: ESTADO DE REMESA | E9: FECHA DE INGRESO | F9: FECHA DE DESEMBOLSO | G9: DOCUMENTO | H9: NOMBRES Y APELLIDOS | I9: CONVENIO | J9: ESTADO | K9: MAF NETO | L9: EJECUTIVO | M9: FILE ENVIADO A BANCO | N9: FECHA DE ENVIÓ CARTA PODER A BCP | O9: COMPRA DE DEUDA REALIZADA | P9: LIBERACIÓN | Q9: FEEDBACK
G10: 42155801 | H10: VASQUEZ BUITRON,ROCIO MARIA EUGENIA | I10: PNP | J10: Desembolsado | K10: 105600 | L10: CESAR MANUYAMA
G11: 72137066 | H11: MAMANI PUMA,JHORFFI ANTONIO | I11: PNP | J11: Pendiente De Remesa | K11: 62000 | L11: CESAR MANUYAMA
G12: 09364190 | H12: RODRIGUEZ JIMENEZ FILOMENA | I12: DIRIS ESTE | J12: Desembolsado | K12: 55280 | L12: CESAR MANUYAMA
G13: 70613717 | H13: DIAZ JAMES GERALDINE VILMA | I13: MARINA | J13: Pendiente De Remesa | K13: 87500 | L13: CESAR MANUYAMA
G14: 70523894 | H14: PUELLES CHAVEZ,ABEL | I14: PNP | J14: Pendiente De Documentar | K14: 40000 | L14: CESAR MANUYAMA
G15: 45223132 | H15: RAMOS CORONEL JAIME ENRIQUE | I15: EJERCITO | J15: Pendiente De Documentar | K15: 73500

Sheet MERCEDES GIRALDO
D3: LIMA 1 | E3: Meta | F3: Desembolsado | G3: Avance | H3: Pendiente De Documentar | I3: Pendiente De Remesa | J3: Pendiente De Backoffice | K3: Evaluación BCP | L3: Obs Backoffice | M3: Obs BCP | N3: Rechazado
D4: S/. | E4: 2000000 | F4: =SUMIFS(OPI_21[MAF NETO],OPI_21[ESTADO],"Desembolsado") -> 113400 | G4: =F4-E4 -> -1886600 | H4: =SUMIFS(OPI_21[MAF NETO],OPI_21[ESTADO],H$3) -> 49300 | I4: =SUMIFS(OPI_21[MAF NETO],OPI_21[ESTADO],I$3) -> 157750 | J4: =SUMIFS(OPI_21[MAF NETO],OPI_21[ESTADO],J$3) -> 0 | K4: =SUMIFS(OPI_21[MAF NETO],OPI_21[ESTADO],K$3) -> 0 | L4: =SUMIFS(OPI_21[MAF NETO],OPI_21[ESTADO],L$3) -> 0 | M4: =SUMIFS(OPI_21[MAF NETO],OPI_21[ESTADO],M$3) -> 0 | N4: =SUMIFS(OPI_21[MAF NETO],OPI_21[ESTADO],N$3) -> 0
D5: Q / % | E5: - | F5: =COUNTIFS(OPI_21[ESTADO],"Desembolsado") -> 3 | G5: =IFERROR(F4/E4,"") -> 0.0567 | H5: =COUNTIFS(OPI_21[ESTADO],H$3) -> 1 | I5: =COUNTIFS(OPI_21[ESTADO],I$3) -> 2 | J5: =COUNTIFS(OPI_21[ESTADO],J$3) -> 0 | K5: =COUNTIFS(OPI_21[ESTADO],K$3) -> 0 | L5: =COUNTIFS(OPI_21[ESTADO],L$3) -> 0 | M5: =COUNTIFS(OPI_21[ESTADO],M$3) -> 0 | N5: =COUNTIFS(OPI_21[ESTADO],N$3) -> 0
B9: PLAZA DE VENTA | C9: FECHA DE ENVIO DE REMESA | D9: ESTADO DE REMESA | E9: FECHA DE INGRESO | F9: FECHA DE DESEMBOLSO | G9: DOCUMENTO | H9: NOMBRES Y APELLIDOS | I9: CONVENIO | J9: ESTADO | K9: MAF NETO | L9: EJECUTIVO | M9: FILE ENVIADO A BANCO | N9: FECHA DE ENVIÓ CARTA PODER A BCP | O9: COMPRA DE DEUDA REALIZADA | P9: LIBERACIÓN | Q9: FEEDBACK
G10: 43974918 | H10: SALAZAR CONTRERAS SARALY SHIRLEY | I10: MGP | J10: Desembolsado | K10: 15300
G11: 72361321 | H11: MATOS GRANADOS DIEGO FRANCO | I11: MGP | J11: Desembolsado | K11: 25000
G12: 72978342 | H12: GALLEGOS APAZA,HILDA | I12: PNP | J12: Pendiente De Remesa | K12: 78600
G13: 70270464 | H13: FLORES PASACHE SERGIO LUIS | I13: PNP | J13: Pendiente De Remesa | K13: 79150
G14: 74541816 | H14: ANTEZANA ESCOBAR RICHAR | I14: PNP | J14: Desembolsado | K14: 73100
G15: 72192009 | H15: MONTALVO ALEGRE KIMBERLYN SANDY | I15: DIRIS NORTE | J15: Pendiente De Documentar | K15: 49300
G16: 75450121 | H16: PALACIOS PALOMINO JHAIR ALEXIS | I16: EP | K16: 57700
G17: 46396017 | H17: MOREY GUEVARA MARCO OSIAS | I17: EP | K17: 103950
G18: 44892769 | H18: ALVAREZ CHOQUEVILCA FREDI | I18: PNP | K18: 9000
G19: 47079851 | H19: CERVANTES MARTEL,TATIANA CELESTE | I19: PNP | K19: 97600
G20: 46962631 | H20: TAPIA GOMEZ,RICARDO SABINO | I20: PNP | K20: 82800
G21: 72892973 | H21: UBILLUS LOZADA MAURICIO RODRIGO | I21: EP | K21: 40000
G22: 74957853 | H22: MATOS TALLEDO MIGUEL ENRIQUE | I22: EP | K22: 95300
G23: 72905489 | H23: TINEO SINCHITULLO CHRISTHOPER MICHAEL | I23: MGP | K23: 90750
G24: 76521469 | H24: DE LAS CASAS DIAZ LUIS ALBERTO | I24: PNP | K24: 61200
G25: 71467196 | H25: DIAZ ULLOA SEBASTIAN | I25: MGP | K25: 64600
G26: 71503781 | H26: SOTO CHAMBI HEBER WILMAN | I26: EP | K26: 82000

Sheet JIMMY COLLAZOS
D3: TARAPOTO | E3: Meta | F3: Desembolsado | G3: Avance | H3: Pendiente De Documentar | I3: Pendiente De Remesa | J3: Pendiente De Backoffice | K3: Evaluación BCP | L3: Obs Backoffice | M3: Obs BCP | N3: Rechazado
D4: S/. | E4: 800000 | F4: =SUMIFS(OPI_4[MAF NETO],OPI_4[ESTADO],"Desembolsado") -> 42000 | G4: =F4-E4 -> -758000 | H4: =SUMIFS(OPI_4[MAF NETO],OPI_4[ESTADO],H$3) -> 0 | I4: =SUMIFS(OPI_4[MAF NETO],OPI_4[ESTADO],I$3) -> 0 | J4: =SUMIFS(OPI_4[MAF NETO],OPI_4[ESTADO],J$3) -> 259500 | K4: =SUMIFS(OPI_4[MAF NETO],OPI_4[ESTADO],K$3) -> 50100 | L4: =SUMIFS(OPI_4[MAF NETO],OPI_4[ESTADO],L$3) -> 0 | M4: =SUMIFS(OPI_4[MAF NETO],OPI_4[ESTADO],M$3) -> 0 | N4: =SUMIFS(OPI_4[MAF NETO],OPI_4[ESTADO],N$3) -> 0
D5: Q / % | E5: - | F5: =COUNTIFS(OPI_4[ESTADO],"Desembolsado") -> 1 | G5: =IFERROR(F4/E4,"") -> 0.0525 | H5: =COUNTIFS(OPI_4[ESTADO],H$3) -> 0 | I5: =COUNTIFS(OPI_4[ESTADO],I$3) -> 0 | J5: =COUNTIFS(OPI_4[ESTADO],J$3) -> 4 | K5: =COUNTIFS(OPI_4[ESTADO],K$3) -> 1 | L5: =COUNTIFS(OPI_4[ESTADO],L$3) -> 0 | M5: =COUNTIFS(OPI_4[ESTADO],M$3) -> 0 | N5: =COUNTIFS(OPI_4[ESTADO],N$3) -> 0
B9: PLAZA DE VENTA | C9: FECHA DE ENVIO DE REMESA | D9: ESTADO DE REMESA | E9: FECHA DE INGRESO | F9: FECHA DE DESEMBOLSO | G9: DOCUMENTO | H9: NOMBRES Y APELLIDOS | I9: CONVENIO | J9: ESTADO | K9: MAF NETO | L9: EJECUTIVO | M9: FILE ENVIADO A BANCO | N9: FECHA DE ENVIÓ CARTA PODER A BCP | O9: COMPRA DE DEUDA REALIZADA | P9: LIBERACIÓN | Q9: FEEDBACK
B10: TARAPOTO | C10: 46258 | D10: Aprobada | E10: 46260 | F10: 46266 | G10: 77693930 | H10: NUÑEZ NAVARRO LUDER JOEL | I10: PNP | J10: Desembolsado | K10: 42000 | L10: ALCIDES FERNANDEZ PERALTA
B11: TARAPOTO | C11: 46262 | D11: Aprobada | E11: 46269 | G11: 46776990 | H11: PAUCAR GRANDEZ BILLY JHON | I11: PNP | J11: Evaluación BCP | K11: 50100 | L11: ELVIS ACOSTA BARBARAN
B12: TARAPOTO | C12: 46267 | D12: Enviada | G12: 41202748 | H12: BARRAGAN GOMEZ YANTEH | I12: ESSALUD | J12: Pendiente de BackOffice | K12: 50000 | L12: MARVIN HUANAY RAMOS
B13: TARAPOTO | C13: 46269 | D13: Enviada | G13: 43005385 | H13: CHUMBE BORBOR JUAN CARLOS | I13: ESSALUD | J13: Pendiente de BackOffice | K13: 83000 | L13: ALCIDES FERNANDEZ PERALTA
B14: TARAPOTO | C14: 46266 | D14: Aprobada | E14: 46269 | G14: 74869031 | H14: HOYOS LÓPEZ LANDER RAMIRO | I14: PNP | J14: Pendiente de BackOffice | K14: 59500 | L14: ELVIS ACOSTA BARBARAN
B15: TARAPOTO | C15: 46268 | D15: Enviada | G15: 41513693 | H15: FLORES LOPEZ HAROLD JOAN | I15: RENIEC | J15: Pendiente de BackOffice | K15: 67000 | L15: ELVIS ACOSTA BARBARAN

Sheet KENNY MORALES
D3: LIMA 1 | E3: Meta | F3: Desembolsado | G3: Avance | H3: Pendiente De Documentar | I3: Pendiente De Remesa | J3: Pendiente De Backoffice | K3: Evaluación BCP | L3: Obs Backoffice | M3: Obs BCP | N3: Rechazado
D4: S/. | E4: 1000000 | F4: =SUMIFS(OPI_6[MAF NETO],OPI_6[ESTADO],"Desembolsado") -> 83000 | G4: =F4-E4 -> -917000 | H4: =SUMIFS(OPI_6[MAF NETO],OPI_6[ESTADO],H$3) -> 0 | I4: =SUMIFS(OPI_6[MAF NETO],OPI_6[ESTADO],I$3) -> 0 | J4: =SUMIFS(OPI_6[MAF NETO],OPI_6[ESTADO],J$3) -> 24600 | K4: =SUMIFS(OPI_6[MAF NETO],OPI_6[ESTADO],K$3) -> 204400 | L4: =SUMIFS(OPI_6[MAF NETO],OPI_6[ESTADO],L$3) -> 0 | M4: =SUMIFS(OPI_6[MAF NETO],OPI_6[ESTADO],M$3) -> 21160 | N4: =SUMIFS(OPI_6[MAF NETO],OPI_6[ESTADO],N$3) -> 0
D5: Q / % | E5: - | F5: =COUNTIFS(OPI_6[ESTADO],"Desembolsado") -> 3 | G5: =IFERROR(F4/E4,"") -> 0.083 | H5: =COUNTIFS(OPI_6[ESTADO],H$3) -> 0 | I5: =COUNTIFS(OPI_6[ESTADO],I$3) -> 0 | J5: =COUNTIFS(OPI_6[ESTADO],J$3) -> 1 | K5: =COUNTIFS(OPI_6[ESTADO],K$3) -> 3 | L5: =COUNTIFS(OPI_6[ESTADO],L$3) -> 0 | M5: =COUNTIFS(OPI_6[ESTADO],M$3) -> 1 | N5: =COUNTIFS(OPI_6[ESTADO],N$3) -> 0
B9: PLAZA DE VENTA | C9: FECHA DE ENVIO DE REMESA | D9: ESTADO DE REMESA | E9: FECHA DE INGRESO | F9: FECHA DE DESEMBOLSO | G9: DOCUMENTO | H9: NOMBRES Y APELLIDOS | I9: CONVENIO | J9: ESTADO | K9: MAF NETO | L9: EJECUTIVO | M9: FILE ENVIADO A BANCO | N9: FECHA DE ENVIÓ CARTA PODER A BCP | O9: COMPRA DE DEUDA REALIZADA | P9: LIBERACIÓN | Q9: FEEDBACK
B10: LIMA | C10: 46261 | D10: Aprobada | E10: 46261 | F10: 46266 | G10: 76408717 | H10: TAIPE AYME CRISTHIAN | I10: PNP | J10: Desembolsado | K10: 20000 | L10: SUSAN VELASQUEZ
B11: LIMA | C11: 46266 | D11: Enviada | E11: 46266 | G11: 47205342 | H11: SALAS MORALES CESAR GUSTAVO | I11: FAP | J11: Obs BCP | K11: 21160 | L11: PAOLA REYES
B12: PROVINCIA | C12: 46266 | D12: Aprobada | E12: 46266 | F12: 46269 | G12: 47527948 | H12: JAUREGUI VALLEJOS CAROL ELENA | I12: PRONABEC | J12: Desembolsado | K12: 3000 | L12: PAOLA REYES
B13: LIMA | C13: 46266 | D13: Aprobada | E13: 46266 | G13: 25771622 | H13: SAMAME FARFAN MABEL CRISTINA | I13: RENIEC | J13: Pendiente de BackOffice | K13: 24600 | L13: SALLY SAAVEDRA
B14: LIMA | C14: 46267 | D14: Aprobada | E14: 46266 | G14: 40817778 | H14: HUAYOLI LOPEZ IRMA LOIDA | I14: DIRIS LIMA ESTE | J14: Evaluación BCP | K14: 63600 | L14: SALLY SAVEDRA
B15: LIMA | C15: 46268 | D15: Aprobada | E15: 46267 | F15: 46272 | G15: 74900689 | H15: TAPIA OCHOA DAVID GERARDO | I15: FAP | J15: Desembolsado | K15: 60000 | L15: SALLY SAAVEDRA | Q15: FIRMA HOY 02/09/2026
B16: LIMA | C16: 46268 | D16: Aprobada | E16: 46267 | G16: 07760850 | H16: ARTEAGA RAEZ DAVID RICARDO | I16: DIRIS LIMA ESTE | J16: Evaluación BCP | K16: 79600 | L16: SALLY SAAVEDRA | Q16: FIRMA HOY 02/09/2026
B17: LIMA | K17: 72250
B18: LIMA | K18: 39300
B19: LIMA | C19: 46269 | D19: Enviada | E19: 46272 | G19: 43609767 | H19: IBAÑEZ CASTELO RENZO GABRUEL | I19: ESSALUD | J19: Evaluación BCP | K19: 61200 | L19: SALLY SAAVEDRA

Sheet WINNIE ESCALANTE
D3: LIMA 1 | E3: Meta | F3: Desembolsado | G3: Avance | H3: Pendiente De Documentar | I3: Pendiente De Remesa | J3: Pendiente De Backoffice | K3: Evaluación BCP | L3: Obs Backoffice | M3: Obs BCP | N3: Rechazado
D4: S/. | E4: 2000000 | F4: =SUMIFS(OPI_10[MAF NETO],OPI_10[ESTADO],"Desembolsado") -> 299450 | G4: =F4-E4 -> -1700550 | H4: =SUMIFS(OPI_10[MAF NETO],OPI_10[ESTADO],H$3) -> 108500 | I4: =SUMIFS(OPI_10[MAF NETO],OPI_10[ESTADO],I$3) -> 333700 | J4: =SUMIFS(OPI_10[MAF NETO],OPI_10[ESTADO],J$3) -> 224300 | K4: =SUMIFS(OPI_10[MAF NETO],OPI_10[ESTADO],K$3) -> 177250 | L4: =SUMIFS(OPI_10[MAF NETO],OPI_10[ESTADO],L$3) -> 0 | M4: =SUMIFS(OPI_10[MAF NETO],OPI_10[ESTADO],M$3) -> 0 | N4: =SUMIFS(OPI_10[MAF NETO],OPI_10[ESTADO],N$3) -> 0
D5: Q / % | E5: - | F5: =COUNTIFS(OPI_10[ESTADO],"Desembolsado") -> 5 | G5: =IFERROR(F4/E4,"") -> 0.149725 | H5: =COUNTIFS(OPI_10[ESTADO],H$3) -> 1 | I5: =COUNTIFS(OPI_10[ESTADO],I$3) -> 4 | J5: =COUNTIFS(OPI_10[ESTADO],J$3) -> 3 | K5: =COUNTIFS(OPI_10[ESTADO],K$3) -> 3 | L5: =COUNTIFS(OPI_10[ESTADO],L$3) -> 0 | M5: =COUNTIFS(OPI_10[ESTADO],M$3) -> 0 | N5: =COUNTIFS(OPI_10[ESTADO],N$3) -> 0
B9: PLAZA DE VENTA | C9: FECHA DE ENVIO DE REMESA | D9: ESTADO DE REMESA | E9: FECHA DE INGRESO | F9: FECHA DE DESEMBOLSO | G9: DOCUMENTO | H9: NOMBRES Y APELLIDOS | I9: CONVENIO | J9: ESTADO | K9: MAF NETO | L9: EJECUTIVO | M9: FILE ENVIADO A BANCO | N9: FECHA DE ENVIÓ CARTA PODER A BCP | O9: COMPRA DE DEUDA REALIZADA | P9: LIBERACIÓN | Q9: FEEDBACK
D10: Aprobada | G10: 02852965 | H10: SEMINARIO LOPEZ MARIA AUDELIA | I10: EP | J10: Desembolsado | K10: 68500 | L10: PIO FERREYRA
D11: Aprobada | G11: 45719983 | H11: LOAYZA PEÑA JOAN JAZMIN | I11: EP | J11: Evaluación BCP | K11: 68550 | L11: PIO FERREYRA
D12: Aprobada | G12: 45555251 | H12: CALUA RUIZ, FLOR CATALINA | I12: FAP | J12: Desembolsado | K12: 58000 | L12: PIO FERREYRA
D13: Aprobada | G13: 70004734 | H13: JAPURA FLORES,YIANMARCO | I13: PNP | J13: Evaluación BCP | K13: 17000 | L13: MILY FERNANDEZ
G14: 40645477 | H14: IZQUIERDO FERNANDEZ EDILBERTO NILO | I14: DIRIS | J14: Pendiente De Documentar | K14: 108500 | L14: MILY FERNANDEZ
G15: 02873157 | H15: MARTINEZ REYES JIMMY GIANCARLO | I15: RENIEC | J15: Pendiente de BackOffice | K15: 65300 | L15: CARLA CORMEJO
G16: 70920967 | H16: PUGA PEREZ JAVIER | I16: MGP | J16: Pendiente de BackOffice | K16: 71700 | L16: PIO FERREYRA
G17: 75997260 | H17: MEJIA ESQUEN JHON ANDERSON | I17: MGP | J17: Pendiente de BackOffice | K17: 87300 | L17: PIO FERREYRA
D18: Aprobada | G18: 74827611 | H18: TUERO RAMIREZ JOSUE RONNIE | I18: PNP | J18: Desembolsado | K18: 47400 | L18: PIO FERREYRA
D19: Aprobada | G19: 75234673 | H19: ZARATE AGUILAR ROYER VICENTE | I19: PNP | J19: Pendiente De Remesa | K19: 81200 | L19: PIO FERREYRA
D20: Aprobada | G20: 75129387 | H20: VALDIVIEZO FLORES,ANGIE ARACELI | I20: PNP | J20: Desembolsado | K20: 68550 | L20: MARIELLA JURADO
C21: 46266 | D21: Aprobada | E21: 46266 | G21: 73536042 | H21: TIBURCIO PONCE,JUAN | I21: PNP | J21: Desembolsado | K21: 57000 | L21: LEIDY EGOAVIL
D22: Aprobada | E22: 46268 | G22: 76093085 | H22: CRUZ AVELLANEDA,JEFFERSON JOBO | I22: pnp | J22: Evaluación BCP | K22: 91700 | L22: LEIDY EGOAVIL
G23: 41215301 | H23: SANCHEZ PACHECO ELVIS | I23: PNP | J23: Pendiente De Remesa | K23: 80750 | L23: PIO FERREYRA
G24: 75731869 | H24: CERAS ROJAS SAMUEL BERNARDO | I24: PNP | J24: Pendiente De Remesa | K24: 82200 | L24: JOSE CONTRERAS
G25: 43280373 | H25: LAZARO DE LA CRUZ MARIO ELVIRO | I25: PNP | J25: Pendiente De Remesa | K25: 89550 | L25: CARMEN QUISPE

Sheet MARIELLA PAÑAHUA
D3: AYACUCHO | E3: Meta | F3: Desembolsado | G3: Avance | H3: Pendiente De Documentar | I3: Pendiente De Remesa | J3: Pendiente De Backoffice | K3: Evaluación BCP | L3: Obs Backoffice | M3: Obs BCP | N3: Rechazado
D4: S/. | E4: 800000 | F4: =SUMIFS(OPI_9[MAF NETO],OPI_9[ESTADO],"Desembolsado") -> 0 | G4: =F4-E4 -> -800000 | H4: =SUMIFS(OPI_9[MAF NETO],OPI_9[ESTADO],H$3) -> 0 | I4: =SUMIFS(OPI_9[MAF NETO],OPI_9[ESTADO],I$3) -> 0 | J4: =SUMIFS(OPI_9[MAF NETO],OPI_9[ESTADO],J$3) -> 0 | K4: =SUMIFS(OPI_9[MAF NETO],OPI_9[ESTADO],K$3) -> 0 | L4: =SUMIFS(OPI_9[MAF NETO],OPI_9[ESTADO],L$3) -> 0 | M4: =SUMIFS(OPI_9[MAF NETO],OPI_9[ESTADO],M$3) -> 0 | N4: =SUMIFS(OPI_9[MAF NETO],OPI_9[ESTADO],N$3) -> 0
D5: Q / % | E5: - | F5: =COUNTIFS(OPI_9[ESTADO],"Desembolsado") -> 0 | G5: =IFERROR(F4/E4,"") -> 0 | H5: =COUNTIFS(OPI_9[ESTADO],H$3) -> 0 | I5: =COUNTIFS(OPI_9[ESTADO],I$3) -> 0 | J5: =COUNTIFS(OPI_9[ESTADO],J$3) -> 0 | K5: =COUNTIFS(OPI_9[ESTADO],K$3) -> 0 | L5: =COUNTIFS(OPI_9[ESTADO],L$3) -> 0 | M5: =COUNTIFS(OPI_9[ESTADO],M$3) -> 0 | N5: =COUNTIFS(OPI_9[ESTADO],N$3) -> 0
B9: PLAZA DE VENTA | C9: FECHA DE ENVIO DE REMESA | D9: ESTADO DE REMESA | E9: FECHA DE INGRESO | F9: FECHA DE DESEMBOLSO | G9: DOCUMENTO | H9: NOMBRES Y APELLIDOS | I9: CONVENIO | J9: ESTADO | K9: MAF NETO | L9: EJECUTIVO | M9: FILE ENVIADO A BANCO | N9: FECHA DE ENVIÓ CARTA PODER A BCP | O9: COMPRA DE DEUDA REALIZADA | P9: LIBERACIÓN | Q9: FEEDBACK

Sheet JOSE LUIS QUINTEROS
D3: LIMA 1 | E3: Meta | F3: Desembolsado | G3: Avance | H3: Pendiente De Documentar | I3: Pendiente De Remesa | J3: Pendiente De Backoffice | K3: Evaluación BCP | L3: Obs Backoffice | M3: Obs BCP | N3: Rechazado
D4: S/. | E4: 1000000 | F4: =SUMIFS(OPI_8[MAF NETO],OPI_8[ESTADO],"Desembolsado") -> 0 | G4: =F4-E4 -> -1000000 | H4: =SUMIFS(OPI_8[MAF NETO],OPI_8[ESTADO],H$3) -> 89600 | I4: =SUMIFS(OPI_8[MAF NETO],OPI_8[ESTADO],I$3) -> 235050 | J4: =SUMIFS(OPI_8[MAF NETO],OPI_8[ESTADO],J$3) -> 0 | K4: =SUMIFS(OPI_8[MAF NETO],OPI_8[ESTADO],K$3) -> 40500 | L4: =SUMIFS(OPI_8[MAF NETO],OPI_8[ESTADO],L$3) -> 126900 | M4: =SUMIFS(OPI_8[MAF NETO],OPI_8[ESTADO],M$3) -> 0 | N4: =SUMIFS(OPI_8[MAF NETO],OPI_8[ESTADO],N$3) -> 0
D5: Q / % | E5: - | F5: =COUNTIFS(OPI_8[ESTADO],"Desembolsado") -> 0 | G5: =IFERROR(F4/E4,"") -> 0 | H5: =COUNTIFS(OPI_8[ESTADO],H$3) -> 1 | I5: =COUNTIFS(OPI_8[ESTADO],I$3) -> 3 | J5: =COUNTIFS(OPI_8[ESTADO],J$3) -> 0 | K5: =COUNTIFS(OPI_8[ESTADO],K$3) -> 1 | L5: =COUNTIFS(OPI_8[ESTADO],L$3) -> 2 | M5: =COUNTIFS(OPI_8[ESTADO],M$3) -> 0 | N5: =COUNTIFS(OPI_8[ESTADO],N$3) -> 0
B9: PLAZA DE VENTA | C9: FECHA DE ENVIO DE REMESA | D9: ESTADO DE REMESA | E9: FECHA DE INGRESO | F9: FECHA DE DESEMBOLSO | G9: DOCUMENTO | H9: NOMBRES Y APELLIDOS | I9: CONVENIO | J9: ESTADO | K9: MAF NETO | L9: EJECUTIVO | M9: FILE ENVIADO A BANCO | N9: FECHA DE ENVIÓ CARTA PODER A BCP | O9: COMPRA DE DEUDA REALIZADA | P9: LIBERACIÓN | Q9: FEEDBACK
B10: AREQUIPA | C10: 46266 | D10: Enviada | G10: 01324890 | H10: RAMOS PEREZ FLOR ELIZABETH | I10: MINJUS | J10: Pendiente De Remesa | K10: 52000 | L10: SEBASTIAN QUINTEROS
B11: LIMA | C11: 46262 | D11: Enviada | G11: 45932507 | H11: YALAN SILVA YESENIA ISABEL- | I11: DIRIS LN | J11: Pendiente De Remesa | K11: 77250 | L11: GIOVANA BEDOYA
B12: LIMA | C12: 46261 | D12: Aprobada | F12: pendiente CNA itbk | G12: 43373053 | H12: HUGO AMADOR BARJA DAGA | I12: EP | J12: Obs BackOffice | K12: 88500 | L12: NELSON MUGARRA
B13: LIMA | C13: 46267 | D13: Aprobada | G13: 48003869 | H13: CHEPE PANIAGUA GLENDA | I13: MGP | J13: Pendiente De Documentar | K13: 89600 | L13: ERIKA EZETA
B14: LIMA | C14: 46268 | D14: Aprobada | G14: 45646265 | H14: FLORES DIAZ JONATHAN GIANCARLO | I14: FAP | J14: Obs BackOffice | K14: 38400 | L14: MARIA VERGARA
B15: LIMA | C15: 46268 | D15: Enviada | G15: 26728061 | H15: LUIS FERNANDO YANEZ CASTILLO | I15: MINJUS | J15: Pendiente De Remesa | K15: 105800 | L15: SEBASTIAN QUINTEROS
B16: LIMA | C16: 46268 | D16: Aprobada | G16: 43564129 | H16: MAYORGA CAMACHO MARCO ANTONIO | I16: EP | J16: Evaluación BCP | K16: 40500 | L16: CARLA ZAMBRANO

Sheet ELIZABETH ESQUIVEL
D3: LIMA 1 | E3: Meta | F3: Desembolsado | G3: Avance | H3: Pendiente De Documentar | I3: Pendiente De Remesa | J3: Pendiente De Backoffice | K3: Evaluación BCP | L3: Obs Backoffice | M3: Obs BCP | N3: Rechazado
D4: S/. | E4: 1000000 | F4: =SUMIFS(OPI_17[MAF NETO],OPI_17[ESTADO],"Desembolsado") -> 0 | G4: =F4-E4 -> -1000000 | H4: =SUMIFS(OPI_17[MAF NETO],OPI_17[ESTADO],H$3) -> 0 | I4: =SUMIFS(OPI_17[MAF NETO],OPI_17[ESTADO],I$3) -> 0 | J4: =SUMIFS(OPI_17[MAF NETO],OPI_17[ESTADO],J$3) -> 0 | K4: =SUMIFS(OPI_17[MAF NETO],OPI_17[ESTADO],K$3) -> 0 | L4: =SUMIFS(OPI_17[MAF NETO],OPI_17[ESTADO],L$3) -> 0 | M4: =SUMIFS(OPI_17[MAF NETO],OPI_17[ESTADO],M$3) -> 0 | N4: =SUMIFS(OPI_17[MAF NETO],OPI_17[ESTADO],N$3) -> 0
D5: Q / % | E5: - | F5: =COUNTIFS(OPI_17[ESTADO],"Desembolsado") -> 0 | G5: =IFERROR(F4/E4,"") -> 0 | H5: =COUNTIFS(OPI_17[ESTADO],H$3) -> 0 | I5: =COUNTIFS(OPI_17[ESTADO],I$3) -> 1 | J5: =COUNTIFS(OPI_17[ESTADO],J$3) -> 0 | K5: =COUNTIFS(OPI_17[ESTADO],K$3) -> 1 | L5: =COUNTIFS(OPI_17[ESTADO],L$3) -> 0 | M5: =COUNTIFS(OPI_17[ESTADO],M$3) -> 0 | N5: =COUNTIFS(OPI_17[ESTADO],N$3) -> 0
B9: PLAZA DE VENTA | C9: FECHA DE ENVIO DE REMESA | D9: ESTADO DE REMESA | E9: FECHA DE INGRESO | F9: FECHA DE DESEMBOLSO | G9: DOCUMENTO | H9: NOMBRES Y APELLIDOS | I9: CONVENIO | J9: ESTADO | K9: MAF NETO | L9: EJECUTIVO | M9: FILE ENVIADO A BANCO | N9: FECHA DE ENVIÓ CARTA PODER A BCP | O9: COMPRA DE DEUDA REALIZADA | P9: LIBERACIÓN | Q9: FEEDBACK
B10: LIMA | C10: 46259 | D10: Enviada | E10: 46236 | G10: 75462776 | H10: ENGELS CUEVA VALQUI | I10: PNP | J10: Evaluación BCP | K10: 63,400.00 | L10: GIOVANNI ALARCON
B11: LIMA | C11: 46266 | D11: Enviada | E11: 46266 | G11: 04067234 | H11: DIMAS EDGAR FLORES POVES | I11: RENIEC | J11: Pendiente De Remesa | K11: 100,000.00 | L11: CRISTHIAN TORRES
B12: LIMA | C12: 46236 | G12: 19260833 | H12: JORGE LUIS CHERO GRADOS | I12: ESSALUD | K12: 33,600.00 | L12: GIOVANNI ALARCON
B13: LIMA | C13: 46267 | G13: 41674814 | H13: SILVIA CRISTINA PINILLOS TORRES | I13: ESSALUD | K13: 85,600.00

Sheet THALIA SALOME
D3: HUANCAYO | E3: Meta | F3: Desembolsado | G3: Avance | H3: Pendiente De Documentar | I3: Pendiente De Remesa | J3: Pendiente De Backoffice | K3: Evaluación BCP | L3: Obs Backoffice | M3: Obs BCP | N3: Rechazado
D4: S/. | E4: 1000000 | F4: =SUMIFS(OPI_18[MAF NETO],OPI_18[ESTADO],"Desembolsado") -> 0 | G4: =F4-E4 -> -1000000 | H4: =SUMIFS(OPI_18[MAF NETO],OPI_18[ESTADO],H$3) -> 0 | I4: =SUMIFS(OPI_18[MAF NETO],OPI_18[ESTADO],I$3) -> 0 | J4: =SUMIFS(OPI_18[MAF NETO],OPI_18[ESTADO],J$3) -> 0 | K4: =SUMIFS(OPI_18[MAF NETO],OPI_18[ESTADO],K$3) -> 0 | L4: =SUMIFS(OPI_18[MAF NETO],OPI_18[ESTADO],L$3) -> 0 | M4: =SUMIFS(OPI_18[MAF NETO],OPI_18[ESTADO],M$3) -> 0 | N4: =SUMIFS(OPI_18[MAF NETO],OPI_18[ESTADO],N$3) -> 0
D5: Q / % | E5: - | F5: =COUNTIFS(OPI_18[ESTADO],"Desembolsado") -> 0 | G5: =IFERROR(F4/E4,"") -> 0 | H5: =COUNTIFS(OPI_18[ESTADO],H$3) -> 0 | I5: =COUNTIFS(OPI_18[ESTADO],I$3) -> 0 | J5: =COUNTIFS(OPI_18[ESTADO],J$3) -> 0 | K5: =COUNTIFS(OPI_18[ESTADO],K$3) -> 0 | L5: =COUNTIFS(OPI_18[ESTADO],L$3) -> 0 | M5: =COUNTIFS(OPI_18[ESTADO],M$3) -> 0 | N5: =COUNTIFS(OPI_18[ESTADO],N$3) -> 0
